Workbook

Sheet Nuclides
B2: n | C2: z | D2: halflife/s | F2: halflife/s
A3: 1001 | B3: 1 | C3: 0 | D3: 613.9 | F3: 613.9
A4: 1002 | B4: 1 | C4: 1 | D4: STABLE | E4: H2 | F4: STABLE
A5: 1003 | B5: 2 | C5: 1 | D5: 388789632 | E5: H3 | F5: 388789632
A6: 1005 | B6: 4 | C6: 1 | D6: 7.9947368e-23 | E6: H5 | F6: 7.9947368e-23
A7: 1006 | B7: 5 | C7: 1 | D7: 2.848125e-22 | E7: H6 | F7: 2.848125e-22
A8: 2003 | B8: 1 | C8: 2 | D8: STABLE | E8: He3 | F8: STABLE
A9: 2004 | B9: 2 | C9: 2 | D9: STABLE | E9: He4 | F9: STABLE
A10: 2005 | B10: 3 | C10: 2 | D10: 7.595e-22 | E10: He5 | F10: 7.595e-22
A11: 2006 | B11: 4 | C11: 2 | D11: 0.8067 | E11: He6 | F11: 0.8067
A12: 2007 | B12: 5 | C12: 2 | D12: 3.038e-21 | E12: He7 | F12: 3.038e-21
A13: 2008 | B13: 6 | C13: 2 | D13: 0.1191 | E13: He8 | F13: 0.1191
A14: 2010 | B14: 8 | C14: 2 | D14: 1.519e-21 | E14: He10 | F14: 1.519e-21
A15: 3004 | B15: 1 | C15: 3 | D15: 7.5572139e-23 | E15: Li4 | F15: 7.5572139e-23
A16: 3005 | B16: 2 | C16: 3 | D16: 3.038e-22 | E16: Li5 | F16: 3.038e-22
A17: 3006 | B17: 3 | C17: 3 | D17: STABLE | E17: Li6 | F17: STABLE
A18: 3007 | B18: 4 | C18: 3 | D18: STABLE | E18: Li7 | F18: STABLE
A19: 3008 | B19: 5 | C19: 3 | D19: 0.8399 | E19: Li8 | F19: 0.8399
A20: 3009 | B20: 6 | C20: 3 | D20: 0.1783 | E20: Li9 | F20: 0.1783
A21: 3011 | B21: 8 | C21: 3 | D21: 0.00875 | E21: Li11 | F21: 0.00875
A22: 4006 | B22: 2 | C22: 4 | D22: 4.9532609e-21 | E22: Be6 | F22: 4.9532609e-21
A23: 4007 | B23: 3 | C23: 4 | D23: 4598208 | E23: Be7 | F23: 4598208
A24: 4008 | B24: 4 | C24: 4 | D24: 8.1813285e-17 | E24: Be8 | F24: 8.1813285e-17
A25: 4009 | B25: 5 | C25: 4 | D25: STABLE | E25: Be9 | F25: STABLE
A26: 4010 | B26: 6 | C26: 4 | D26: 47651976000000 | E26: Be10 | F26: 47651976000000
A27: 4011 | B27: 7 | C27: 4 | D27: 13.76 | E27: Be11 | F27: 13.76
A28: 4012 | B28: 8 | C28: 4 | D28: 0.02147 | E28: Be12 | F28: 0.02147
A29: 4013 | B29: 9 | C29: 4 | D29: 2.7e-21 | E29: Be13 | F29: 2.7e-21
A30: 4014 | B30: 10 | C30: 4 | D30: 0.00435 | E30: Be14 | F30: 0.00435
A31: 4015 | B31: 11 | C31: 4 | D31: 7.8568966e-22 | E31: Be15 | F31: 7.8568966e-22
A32: 4016 | B32: 12 | C32: 4 | D32: 5.69625e-22 | E32: Be16 | F32: 5.69625e-22
A33: 5007 | B33: 2 | C33: 5 | D33: 3.255e-22 | E33: B7 | F33: 3.255e-22
A34: 5008 | B34: 3 | C34: 5 | D34: 0.77 | E34: B8 | F34: 0.77
A35: 5009 | B35: 4 | C35: 5 | D35: 8.4388889e-19 | E35: B9 | F35: 8.4388889e-19
A36: 5010 | B36: 5 | C36: 5 | D36: STABLE | E36: B10 | F36: STABLE
A37: 5011 | B37: 6 | C37: 5 | D37: STABLE | E37: B11 | F37: STABLE
A38: 5012 | B38: 7 | C38: 5 | D38: 0.0202 | E38: B12 | F38: 0.0202
A39: 5013 | B39: 8 | C39: 5 | D39: 0.01733 | E39: B13 | F39: 0.01733
A40: 5014 | B40: 9 | C40: 5 | D40: 0.01236 | E40: B14 | F40: 0.01236
A41: 5015 | B41: 10 | C41: 5 | D41: 0.01018 | E41: B15 | F41: 0.01018
...

Sheet Havar2
B1: Nuclides | C1: w | D1: Error | E1: Nuclides | F1: T1/2 | G1: T1/2 | H1: λ | I1: 60μA-2h | J1: cool-6h | K1: Nuclides
B4: 3006 | C4: 9e-08 | D4: 0.3333 | E4: =VLOOKUP(B4,[1]Nuclides!A:E,5,FALSE) -> Li6 | F4: =VLOOKUP(B4,[1]Nuclides!A:E,4,FALSE) -> STABLE | G4: =IF(F4="STABLE", "STABLE", IF(F4<60, F4&"s", IF(F4<3600, ROUND(F4/60,2)&"min", IF(F4<86400, ROUND(F4/3600,2)&"h", IF(F4<31536000, ROUND(F4/86400,2)&"d", ROUND(F4/31536000,2)&"y"))))) -> STABLE | H4: =LN(2)/F4 -> #VALUE! | I4: =60*6240000000000*C4*(1-EXP(-H4*2*3600)) -> #VALUE! | J4: =I4*EXP(-H4*96*3600) -> #VALUE! | K4: =E4 -> Li6
B5: 3007 | C5: 1e-07 | D5: 0.3162 | E5: =VLOOKUP(B5,[1]Nuclides!A:E,5,FALSE) -> Li7 | F5: =VLOOKUP(B5,[1]Nuclides!A:E,4,FALSE) -> STABLE | G5: =IF(F5="STABLE", "STABLE", IF(F5<60, F5&"s", IF(F5<3600, ROUND(F5/60,2)&"min", IF(F5<86400, ROUND(F5/3600,2)&"h", IF(F5<31536000, ROUND(F5/86400,2)&"d", ROUND(F5/31536000,2)&"y"))))) -> STABLE | H5: =LN(2)/F5 -> #VALUE! | I5: =60*6240000000000*C5*(1-EXP(-H5*2*3600)) -> #VALUE! | J5: =I5*EXP(-H5*96*3600) -> #VALUE! | K5: =E5 -> Li7
B6: 3008 | C6: 0 | D6: 0 | E6: =VLOOKUP(B6,[1]Nuclides!A:E,5,FALSE) -> Li8 | F6: =VLOOKUP(B6,[1]Nuclides!A:E,4,FALSE) -> 0.8399 | G6: =IF(F6="STABLE", "STABLE", IF(F6<60, F6&"s", IF(F6<3600, ROUND(F6/60,2)&"min", IF(F6<86400, ROUND(F6/3600,2)&"h", IF(F6<31536000, ROUND(F6/86400,2)&"d", ROUND(F6/31536000,2)&"y"))))) -> 0.8399s | H6: =LN(2)/F6 -> 0.82527346 | I6: =60*6240000000000*C6*(1-EXP(-H6*2*3600)) -> 0 | J6: =I6*EXP(-H6*96*3600) -> 0 | K6: =E6 -> Li8
B7: 3009 | C7: 0 | D7: 0 | E7: =VLOOKUP(B7,[1]Nuclides!A:E,5,FALSE) -> Li9 | F7: =VLOOKUP(B7,[1]Nuclides!A:E,4,FALSE) -> 0.1783 | G7: =IF(F7="STABLE", "STABLE", IF(F7<60, F7&"s", IF(F7<3600, ROUND(F7/60,2)&"min", IF(F7<86400, ROUND(F7/3600,2)&"h", IF(F7<31536000, ROUND(F7/86400,2)&"d", ROUND(F7/31536000,2)&"y"))))) -> 0.1783s | H7: =LN(2)/F7 -> 3.8875333 | I7: =60*6240000000000*C7*(1-EXP(-H7*2*3600)) -> 0 | J7: =I7*EXP(-H7*96*3600) -> 0 | K7: =E7 -> Li9
B8: 3010 | C8: 0 | D8: 0 | E8: =VLOOKUP(B8,[1]Nuclides!A:E,5,FALSE) -> #N/A | F8: =VLOOKUP(B8,[1]Nuclides!A:E,4,FALSE) -> #N/A | G8: =IF(F8="STABLE", "STABLE", IF(F8<60, F8&"s", IF(F8<3600, ROUND(F8/60,2)&"min", IF(F8<86400, ROUND(F8/3600,2)&"h", IF(F8<31536000, ROUND(F8/86400,2)&"d", ROUND(F8/31536000,2)&"y"))))) -> #N/A | H8: =LN(2)/F8 -> #N/A | I8: =60*6240000000000*C8*(1-EXP(-H8*2*3600)) -> #N/A | J8: =I8*EXP(-H8*96*3600) -> #N/A | K8: =E8 -> #N/A
B9: 3011 | C9: 0 | D9: 0 | E9: =VLOOKUP(B9,[1]Nuclides!A:E,5,FALSE) -> Li11 | F9: =VLOOKUP(B9,[1]Nuclides!A:E,4,FALSE) -> 0.00875 | G9: =IF(F9="STABLE", "STABLE", IF(F9<60, F9&"s", IF(F9<3600, ROUND(F9/60,2)&"min", IF(F9<86400, ROUND(F9/3600,2)&"h", IF(F9<31536000, ROUND(F9/86400,2)&"d", ROUND(F9/31536000,2)&"y"))))) -> 0.00875s | H9: =LN(2)/F9 -> 79.216821 | I9: =60*6240000000000*C9*(1-EXP(-H9*2*3600)) -> 0 | J9: =I9*EXP(-H9*96*3600) -> 0 | K9: =E9 -> Li11
B10: 4006 | C10: 0 | D10: 0 | E10: =VLOOKUP(B10,[1]Nuclides!A:E,5,FALSE) -> Be6 | F10: =VLOOKUP(B10,[1]Nuclides!A:E,4,FALSE) -> 4.9532609e-21 | G10: =IF(F10="STABLE", "STABLE", IF(F10<60, F10&"s", IF(F10<3600, ROUND(F10/60,2)&"min", IF(F10<86400, ROUND(F10/3600,2)&"h", IF(F10<31536000, ROUND(F10/86400,2)&"d", ROUND(F10/31536000,2)&"y"))))) -> 4.95326086956521E-21s | H10: =LN(2)/F10 -> 1.3993755e+20 | I10: =60*6240000000000*C10*(1-EXP(-H10*2*3600)) -> 0 | J10: =I10*EXP(-H10*96*3600) -> 0 | K10: =E10 -> Be6
B11: 4007 | C11: 6e-08 | D11: 0.4082 | E11: =VLOOKUP(B11,[1]Nuclides!A:E,5,FALSE) -> Be7 | F11: =VLOOKUP(B11,[1]Nuclides!A:E,4,FALSE) -> 4598208 | G11: =IF(F11="STABLE", "STABLE", IF(F11<60, F11&"s", IF(F11<3600, ROUND(F11/60,2)&"min", IF(F11<86400, ROUND(F11/3600,2)&"h", IF(F11<31536000, ROUND(F11/86400,2)&"d", ROUND(F11/31536000,2)&"y"))))) -> 53.22d | H11: =LN(2)/F11 -> 1.5074289e-07 | I11: =60*6240000000000*C11*(1-EXP(-H11*2*3600)) -> 24368.05 | J11: =I11*EXP(-H11*24*30*3600) -> 16486.589 | K11: =E11 -> Be7 | M11: =K11 -> Be7 | N11: =J11 -> 16486.589 | O11: =0 -> 0
B12: 4008 | C12: 0 | D12: 0 | E12: =VLOOKUP(B12,[1]Nuclides!A:E,5,FALSE) -> Be8 | F12: =VLOOKUP(B12,[1]Nuclides!A:E,4,FALSE) -> 8.1813285e-17 | G12: =IF(F12="STABLE", "STABLE", IF(F12<60, F12&"s", IF(F12<3600, ROUND(F12/60,2)&"min", IF(F12<86400, ROUND(F12/3600,2)&"h", IF(F12<31536000, ROUND(F12/86400,2)&"d", ROUND(F12/31536000,2)&"y"))))) -> 8.18132854578096E-17s | H12: =LN(2)/F12 -> 8.4723059e+15 | I12: =60*6240000000000*C12*(1-EXP(-H12*2*3600)) -> 0 | J12: =I12*EXP(-H12*96*3600) -> 0 | K12: =E12 -> Be8
B13: 4009 | C13: 8.1e-07 | D13: 0.1111 | E13: =VLOOKUP(B13,[1]Nuclides!A:E,5,FALSE) -> Be9 | F13: =VLOOKUP(B13,[1]Nuclides!A:E,4,FALSE) -> STABLE | G13: =IF(F13="STABLE", "STABLE", IF(F13<60, F13&"s", IF(F13<3600, ROUND(F13/60,2)&"min", IF(F13<86400, ROUND(F13/3600,2)&"h", IF(F13<31536000, ROUND(F13/86400,2)&"d", ROUND(F13/31536000,2)&"y"))))) -> STABLE | H13: =LN(2)/F13 -> #VALUE! | I13: =60*6240000000000*C13*(1-EXP(-H13*2*3600)) -> #VALUE! | J13: =I13*EXP(-H13*96*3600) -> #VALUE! | K13: =E13 -> Be9
B14: 4010 | C14: 0 | D14: 0 | E14: =VLOOKUP(B14,[1]Nuclides!A:E,5,FALSE) -> Be10 | F14: =VLOOKUP(B14,[1]Nuclides!A:E,4,FALSE) -> 47651976000000 | G14: =IF(F14="STABLE", "STABLE", IF(F14<60, F14&"s", IF(F14<3600, ROUND(F14/60,2)&"min", IF(F14<86400, ROUND(F14/3600,2)&"h", IF(F14<31536000, ROUND(F14/86400,2)&"d", ROUND(F14/31536000,2)&"y"))))) -> 1511034.25y | H14: =LN(2)/F14 -> 1.4546032e-14 | I14: =60*6240000000000*C14*(1-EXP(-H14*2*3600)) -> 0 | J14: =I14*EXP(-H14*96*3600) -> 0 | K14: =E14 -> Be10
B15: 4011 | C15: 0 | D15: 0 | E15: =VLOOKUP(B15,[1]Nuclides!A:E,5,FALSE) -> Be11 | F15: =VLOOKUP(B15,[1]Nuclides!A:E,4,FALSE) -> 13.76 | G15: =IF(F15="STABLE", "STABLE", IF(F15<60, F15&"s", IF(F15<3600, ROUND(F15/60,2)&"min", IF(F15<86400, ROUND(F15/3600,2)&"h", IF(F15<31536000, ROUND(F15/86400,2)&"d", ROUND(F15/31536000,2)&"y"))))) -> 13.76s | H15: =LN(2)/F15 -> 0.050374068 | I15: =60*6240000000000*C15*(1-EXP(-H15*2*3600)) -> 0 | J15: =I15*EXP(-H15*96*3600) -> 0 | K15: =E15 -> Be11
B16: 4012 | C16: 0 | D16: 0 | E16: =VLOOKUP(B16,[1]Nuclides!A:E,5,FALSE) -> Be12 | F16: =VLOOKUP(B16,[1]Nuclides!A:E,4,FALSE) -> 0.02147 | G16: =IF(F16="STABLE", "STABLE", IF(F16<60, F16&"s", IF(F16<3600, ROUND(F16/60,2)&"min", IF(F16<86400, ROUND(F16/3600,2)&"h", IF(F16<31536000, ROUND(F16/86400,2)&"d", ROUND(F16/31536000,2)&"y"))))) -> 0.02147s | H16: =LN(2)/F16 -> 32.284452 | I16: =60*6240000000000*C16*(1-EXP(-H16*2*3600)) -> 0 | J16: =I16*EXP(-H16*96*3600) -> 0 | K16: =E16 -> Be12
B17: 4013 | C17: 0 | D17: 0 | E17: =VLOOKUP(B17,[1]Nuclides!A:E,5,FALSE) -> Be13 | F17: =VLOOKUP(B17,[1]Nuclides!A:E,4,FALSE) -> 2.7e-21 | G17: =IF(F17="STABLE", "STABLE", IF(F17<60, F17&"s", IF(F17<3600, ROUND(F17/60,2)&"min", IF(F17<86400, ROUND(F17/3600,2)&"h", IF(F17<31536000, ROUND(F17/86400,2)&"d", ROUND(F17/31536000,2)&"y"))))) -> 2.7E-21s | H17: =LN(2)/F17 -> 2.5672118e+20 | I17: =60*6240000000000*C17*(1-EXP(-H17*2*3600)) -> 0 | J17: =I17*EXP(-H17*96*3600) -> 0 | K17: =E17 -> Be13
B18: 4014 | C18: 0 | D18: 0 | E18: =VLOOKUP(B18,[1]Nuclides!A:E,5,FALSE) -> Be14 | F18: =VLOOKUP(B18,[1]Nuclides!A:E,4,FALSE) -> 0.00435 | G18: =IF(F18="STABLE", "STABLE", IF(F18<60, F18&"s", IF(F18<3600, ROUND(F18/60,2)&"min", IF(F18<86400, ROUND(F18/3600,2)&"h", IF(F18<31536000, ROUND(F18/86400,2)&"d", ROUND(F18/31536000,2)&"y"))))) -> 0.00435s | H18: =LN(2)/F18 -> 159.34418 | I18: =60*6240000000000*C18*(1-EXP(-H18*2*3600)) -> 0 | J18: =I18*EXP(-H18*96*3600) -> 0 | K18: =E18 -> Be14
B19: 5008 | C19: 0 | D19: 0 | E19: =VLOOKUP(B19,[1]Nuclides!A:E,5,FALSE) -> B8 | F19: =VLOOKUP(B19,[1]Nuclides!A:E,4,FALSE) -> 0.77 | G19: =IF(F19="STABLE", "STABLE", IF(F19<60, F19&"s", IF(F19<3600, ROUND(F19/60,2)&"min", IF(F19<86400, ROUND(F19/3600,2)&"h", IF(F19<31536000, ROUND(F19/86400,2)&"d", ROUND(F19/31536000,2)&"y"))))) -> 0.77s | H19: =LN(2)/F19 -> 0.90019114 | I19: =60*6240000000000*C19*(1-EXP(-H19*2*3600)) -> 0 | J19: =I19*EXP(-H19*96*3600) -> 0 | K19: =E19 -> B8
B20: 5009 | C20: 0 | D20: 0 | E20: =VLOOKUP(B20,[1]Nuclides!A:E,5,FALSE) -> B9 | F20: =VLOOKUP(B20,[1]Nuclides!A:E,4,FALSE) -> 8.4388889e-19 | G20: =IF(F20="STABLE", "STABLE", IF(F20<60, F20&"s", IF(F20<3600, ROUND(F20/60,2)&"min", IF(F20<86400, ROUND(F20/3600,2)&"h", IF(F20<31536000, ROUND(F20/86400,2)&"d", ROUND(F20/31536000,2)&"y"))))) -> 8.43888888888888E-19s | H20: =LN(2)/F20 -> 8.2137256e+17 | I20: =60*6240000000000*C20*(1-EXP(-H20*2*3600)) -> 0 | J20: =I20*EXP(-H20*96*3600) -> 0 | K20: =E20 -> B9
B21: 5010 | C21: 0 | D21: 0 | E21: =VLOOKUP(B21,[1]Nuclides!A:E,5,FALSE) -> B10 | F21: =VLOOKUP(B21,[1]Nuclides!A:E,4,FALSE) -> STABLE | G21: =IF(F21="STABLE", "STABLE", IF(F21<60, F21&"s", IF(F21<3600, ROUND(F21/60,2)&"min", IF(F21<86400, ROUND(F21/3600,2)&"h", IF(F21<31536000, ROUND(F21/86400,2)&"d", ROUND(F21/31536000,2)&"y"))))) -> STABLE | H21: =LN(2)/F21 -> #VALUE! | I21: =60*6240000000000*C21*(1-EXP(-H21*2*3600)) -> #VALUE! | J21: =I21*EXP(-H21*96*3600) -> #VALUE! | K21: =E21 -> B10
B22: 5011 | C22: 0 | D22: 0 | E22: =VLOOKUP(B22,[1]Nuclides!A:E,5,FALSE) -> B11 | F22: =VLOOKUP(B22,[1]Nuclides!A:E,4,FALSE) -> STABLE | G22: =IF(F22="STABLE", "STABLE", IF(F22<60, F22&"s", IF(F22<3600, ROUND(F22/60,2)&"min", IF(F22<86400, ROUND(F22/3600,2)&"h", IF(F22<31536000, ROUND(F22/86400,2)&"d", ROUND(F22/31536000,2)&"y"))))) -> STABLE | H22: =LN(2)/F22 -> #VALUE! | I22: =60*6240000000000*C22*(1-EXP(-H22*2*3600)) -> #VALUE! | J22: =I22*EXP(-H22*96*3600) -> #VALUE! | K22: =E22 -> B11
B23: 5012 | C23: 0 | D23: 0 | E23: =VLOOKUP(B23,[1]Nuclides!A:E,5,FALSE) -> B12 | F23: =VLOOKUP(B23,[1]Nuclides!A:E,4,FALSE) -> 0.0202 | G23: =IF(F23="STABLE", "STABLE", IF(F23<60, F23&"s", IF(F23<3600, ROUND(F23/60,2)&"min", IF(F23<86400, ROUND(F23/3600,2)&"h", IF(F23<31536000, ROUND(F23/86400,2)&"d", ROUND(F23/31536000,2)&"y"))))) -> 0.0202s | H23: =LN(2)/F23 -> 34.314217 | I23: =60*6240000000000*C23*(1-EXP(-H23*2*3600)) -> 0 | J23: =I23*EXP(-H23*96*3600) -> 0 | K23: =E23 -> B12
... B280: 23048 | C280: 0 | D280: 0 | E280: =VLOOKUP(B280,[1]Nuclides!A:E,5,FALSE) -> V48 | F280: =VLOOKUP(B280,[1]Nuclides!A:E,4,FALSE) -> 1380110.4 | G280: =IF(F280="STABLE", "STABLE", IF(F280<60, F280&"s", IF(F280<3600, ROUND(F280/60,2)&"min", IF(F280<86400, ROUND(F280/3600,2)&"h", IF(F280<31536000, ROUND(F280/86400,2)&"d", ROUND(F280/31536000,2)&"y"))))) -> 15.97d | H280: =LN(2)/F280 -> 5.0224039e-07 | I280: =60*6240000000000*C280*(1-EXP(-H280*2*3600)) -> 0 | J280: =I280*EXP(-H280*96*3600) -> 0 | K280: =E280 -> V48
B281: 23049 | C281: 5.2e-07 | D281: 0.1387 | E281: =VLOOKUP(B281,[1]Nuclides!A:E,5,FALSE) -> V49 | F281: =VLOOKUP(B281,[1]Nuclides!A:E,4,FALSE) -> 28512000 | G281: =IF(F281="STABLE", "STABLE", IF(F281<60, F281&"s", IF(F281<3600, ROUND(F281/60,2)&"min", IF(F281<86400, ROUND(F281/3600,2)&"h", IF(F281<31536000, ROUND(F281/86400,2)&"d", ROUND(F281/31536000,2)&"y"))))) -> 330d | H281: =LN(2)/F281 -> 2.4310718e-08 | I281: =60*6240000000000*C281*(1-EXP(-H281*2*3600)) -> 34074.654 | J281: =I281*EXP(-H281*24*30*3600) -> 31993.746 | K281: =E281 -> V49 | M281: =K281 -> V49 | N281: =J281 -> 31993.746 | O281: =0 -> 0
B282: 23050 | C282: 1.4e-07 | D282: 0.2673 | E282: =VLOOKUP(B282,[1]Nuclides!A:E,5,FALSE) -> V50 | F282: =VLOOKUP(B282,[1]Nuclides!A:E,4,FALSE) -> 6.627096e+24 | G282: =IF(F282="STABLE", "STABLE", IF(F282<60, F282&"s", IF(F282<3600, ROUND(F282/60,2)&"min", IF(F282<86400, ROUND(F282/3600,2)&"h", IF(F282<31536000, ROUND(F282/86400,2)&"d", ROUND(F282/31536000,2)&"y"))))) -> 210143835616438000y | H282: =LN(2)/F282 -> 1.045929e-25 | I282: =60*6240000000000*C282*(1-EXP(-H282*2*3600)) -> 0 | J282: =I282*EXP(-H282*96*3600) -> 0 | K282: =E282 -> V50
B283: 23051 | C283: 3e-08 | D283: 0.5774 | E283: =VLOOKUP(B283,[1]Nuclides!A:E,5,FALSE) -> V51 | F283: =VLOOKUP(B283,[1]Nuclides!A:E,4,FALSE) -> STABLE | G283: =IF(F283="STABLE", "STABLE", IF(F283<60, F283&"s", IF(F283<3600, ROUND(F283/60,2)&"min", IF(F283<86400, ROUND(F283/3600,2)&"h", IF(F283<31536000, ROUND(F283/86400,2)&"d", ROUND(F283/31536000,2)&"y"))))) -> STABLE | H283: =LN(2)/F283 -> #VALUE! | I283: =60*6240000000000*C283*(1-EXP(-H283*2*3600)) -> #VALUE! | J283: =I283*EXP(-H283*96*3600) -> #VALUE! | K283: =E283 -> V51
B284: 23052 | C284: 0 | D284: 0 | E284: =VLOOKUP(B284,[1]Nuclides!A:E,5,FALSE) -> V52 | F284: =VLOOKUP(B284,[1]Nuclides!A:E,4,FALSE) -> 224.58 | G284: =IF(F284="STABLE", "STABLE", IF(F284<60, F284&"s", IF(F284<3600, ROUND(F284/60,2)&"min", IF(F284<86400, ROUND(F284/3600,2)&"h", IF(F284<31536000, ROUND(F284/86400,2)&"d", ROUND(F284/31536000,2)&"y"))))) -> 3.74min | H284: =LN(2)/F284 -> 0.0030864154 | I284: =60*6240000000000*C284*(1-EXP(-H284*2*3600)) -> 0 | J284: =I284*EXP(-H284*96*3600) -> 0 | K284: =E284 -> V52
B285: 23053 | C285: 0 | D285: 0 | E285: =VLOOKUP(B285,[1]Nuclides!A:E,5,FALSE) -> V53 | F285: =VLOOKUP(B285,[1]Nuclides!A:E,4,FALSE) -> 92.58 | G285: =IF(F285="STABLE", "STABLE", IF(F285<60, F285&"s", IF(F285<3600, ROUND(F285/60,2)&"min", IF(F285<86400, ROUND(F285/3600,2)&"h", IF(F285<31536000, ROUND(F285/86400,2)&"d", ROUND(F285/31536000,2)&"y"))))) -> 1.54min | H285: =LN(2)/F285 -> 0.0074870078 | I285: =60*6240000000000*C285*(1-EXP(-H285*2*3600)) -> 0 | J285: =I285*EXP(-H285*96*3600) -> 0 | K285: =E285 -> V53
B286: 23054 | C286: 0 | D286: 0 | E286: =VLOOKUP(B286,[1]Nuclides!A:E,5,FALSE) -> V54 | F286: =VLOOKUP(B286,[1]Nuclides!A:E,4,FALSE) -> 49.8 | G286: =IF(F286="STABLE", "STABLE", IF(F286<60, F286&"s", IF(F286<3600, ROUND(F286/60,2)&"min", IF(F286<86400, ROUND(F286/3600,2)&"h", IF(F286<31536000, ROUND(F286/86400,2)&"d", ROUND(F286/31536000,2)&"y"))))) -> 49.8s | H286: =LN(2)/F286 -> 0.013918618 | I286: =60*6240000000000*C286*(1-EXP(-H286*2*3600)) -> 0 | J286: =I286*EXP(-H286*96*3600) -> 0 | K286: =E286 -> V54
B287: 23055 | C287: 0 | D287: 0 | E287: =VLOOKUP(B287,[1]Nuclides!A:E,5,FALSE) -> V55 | F287: =VLOOKUP(B287,[1]Nuclides!A:E,4,FALSE) -> 6.54 | G287: =IF(F287="STABLE", "STABLE", IF(F287<60, F287&"s", IF(F287<3600, ROUND(F287/60,2)&"min", IF(F287<86400, ROUND(F287/3600,2)&"h", IF(F287<31536000, ROUND(F287/86400,2)&"d", ROUND(F287/31536000,2)&"y"))))) -> 6.54s | H287: =LN(2)/F287 -> 0.10598581 | I287: =60*6240000000000*C287*(1-EXP(-H287*2*3600)) -> 0 | J287: =I287*EXP(-H287*96*3600) -> 0 | K287: =E287 -> V55
B288: 23056 | C288: 0 | D288: 0 | E288: =VLOOKUP(B288,[1]Nuclides!A:E,5,FALSE) -> V56 | F288: =VLOOKUP(B288,[1]Nuclides!A:E,4,FALSE) -> 0.216 | G288: =IF(F288="STABLE", "STABLE", IF(F288<60, F288&"s", IF(F288<3600, ROUND(F288/60,2)&"min", IF(F288<86400, ROUND(F288/3600,2)&"h", IF(F288<31536000, ROUND(F288/86400,2)&"d", ROUND(F288/31536000,2)&"y"))))) -> 0.216s | H288: =LN(2)/F288 -> 3.2090147 | I288: =60*6240000000000*C288*(1-EXP(-H288*2*3600)) -> 0 | J288: =I288*EXP(-H288*96*3600) -> 0 | K288: =E288 -> V56
B289: 24045 | C289: 0 | D289: 0 | E289: =VLOOKUP(B289,[1]Nuclides!A:E,5,FALSE) -> Cr45 | F289: =VLOOKUP(B289,[1]Nuclides!A:E,4,FALSE) -> 0.0609 | G289: =IF(F289="STABLE", "STABLE", IF(F289<60, F289&"s", IF(F289<3600, ROUND(F289/60,2)&"min", IF(F289<86400, ROUND(F289/3600,2)&"h", IF(F289<31536000, ROUND(F289/86400,2)&"d", ROUND(F289/31536000,2)&"y"))))) -> 0.0609s | H289: =LN(2)/F289 -> 11.381727 | I289: =60*6240000000000*C289*(1-EXP(-H289*2*3600)) -> 0 | J289: =I289*EXP(-H289*96*3600) -> 0 | K289: =E289 -> Cr45
B290: 24046 | C290: 0 | D290: 0 | E290: =VLOOKUP(B290,[1]Nuclides!A:E,5,FALSE) -> Cr46 | F290: =VLOOKUP(B290,[1]Nuclides!A:E,4,FALSE) -> 0.26 | G290: =IF(F290="STABLE", "STABLE", IF(F290<60, F290&"s", IF(F290<3600, ROUND(F290/60,2)&"min", IF(F290<86400, ROUND(F290/3600,2)&"h", IF(F290<31536000, ROUND(F290/86400,2)&"d", ROUND(F290/31536000,2)&"y"))))) -> 0.26s | H290: =LN(2)/F290 -> 2.6659507 | I290: =60*6240000000000*C290*(1-EXP(-H290*2*3600)) -> 0 | J290: =I290*EXP(-H290*96*3600) -> 0 | K290: =E290 -> Cr46
B291: 24047 | C291: 0 | D291: 0 | E291: =VLOOKUP(B291,[1]Nuclides!A:E,5,FALSE) -> Cr47 | F291: =VLOOKUP(B291,[1]Nuclides!A:E,4,FALSE) -> 0.5 | G291: =IF(F291="STABLE", "STABLE", IF(F291<60, F291&"s", IF(F291<3600, ROUND(F291/60,2)&"min", IF(F291<86400, ROUND(F291/3600,2)&"h", IF(F291<31536000, ROUND(F291/86400,2)&"d", ROUND(F291/31536000,2)&"y"))))) -> 0.5s | H291: =LN(2)/F291 -> 1.3862944 | I291: =60*6240000000000*C291*(1-EXP(-H291*2*3600)) -> 0 | J291: =I291*EXP(-H291*96*3600) -> 0 | K291: =E291 -> Cr47
B292: 24048 | C292: 0 | D292: 0 | E292: =VLOOKUP(B292,[1]Nuclides!A:E,5,FALSE) -> Cr48 | F292: =VLOOKUP(B292,[1]Nuclides!A:E,4,FALSE) -> 77616 | G292: =IF(F292="STABLE", "STABLE", IF(F292<60, F292&"s", IF(F292<3600, ROUND(F292/60,2)&"min", IF(F292<86400, ROUND(F292/3600,2)&"h", IF(F292<31536000, ROUND(F292/86400,2)&"d", ROUND(F292/31536000,2)&"y"))))) -> 21.56h | H292: =LN(2)/F292 -> 8.9304677e-06 | I292: =60*6240000000000*C292*(1-EXP(-H292*2*3600)) -> 0 | J292: =I292*EXP(-H292*96*3600) -> 0 | K292: =E292 -> Cr48
B293: 24049 | C293: 0 | D293: 0 | E293: =VLOOKUP(B293,[1]Nuclides!A:E,5,FALSE) -> Cr49 | F293: =VLOOKUP(B293,[1]Nuclides!A:E,4,FALSE) -> 2538 | G293: =IF(F293="STABLE", "STABLE", IF(F293<60, F293&"s", IF(F293<3600, ROUND(F293/60,2)&"min", IF(F293<86400, ROUND(F293/3600,2)&"h", IF(F293<31536000, ROUND(F293/86400,2)&"d", ROUND(F293/31536000,2)&"y"))))) -> 42.3min | H293: =LN(2)/F293 -> 0.00027310764 | I293: =60*6240000000000*C293*(1-EXP(-H293*2*3600)) -> 0 | J293: =I293*EXP(-H293*96*3600) -> 0 | K293: =E293 -> Cr49
B294: 24050 | C294: 5.04e-06 | D294: 0.0445 | E294: =VLOOKUP(B294,[1]Nuclides!A:E,5,FALSE) -> Cr50 | F294: =VLOOKUP(B294,[1]Nuclides!A:E,4,FALSE) -> 4.102488e+25 | G294: =IF(F294="STABLE", "STABLE", IF(F294<60, F294&"s", IF(F294<3600, ROUND(F294/60,2)&"min", IF(F294<86400, ROUND(F294/3600,2)&"h", IF(F294<31536000, ROUND(F294/86400,2)&"d", ROUND(F294/31536000,2)&"y"))))) -> 1300890410958900000y | H294: =LN(2)/F294 -> 1.6895776e-26 | I294: =60*6240000000000*C294*(1-EXP(-H294*2*3600)) -> 0 | J294: =I294*EXP(-H294*96*3600) -> 0 | K294: =E294 -> Cr50
B295: 24051 | C295: 1e-08 | D295: 1 | E295: =VLOOKUP(B295,[1]Nuclides!A:E,5,FALSE) -> Cr51 | F295: =VLOOKUP(B295,[1]Nuclides!A:E,4,FALSE) -> 2393496 | G295: =IF(F295="STABLE", "STABLE", IF(F295<60, F295&"s", IF(F295<3600, ROUND(F295/60,2)&"min", IF(F295<86400, ROUND(F295/3600,2)&"h", IF(F295<31536000, ROUND(F295/86400,2)&"d", ROUND(F295/31536000,2)&"y"))))) -> 27.7d | H295: =LN(2)/F295 -> 2.8959613e-07 | I295: =60*6240000000000*C295*(1-EXP(-H295*2*3600)) -> 7798.4519 | J295: =I295*EXP(-H295*24*30*3600) -> 3681.3962 | K295: =E295 -> Cr51 | M295: =K295 -> Cr51 | N295: =J295 -> 3681.3962 | O295: =0 -> 0
B296: 24052 | C296: 7.898e-05 | D296: 0.0113 | E296: =VLOOKUP(B296,[1]Nuclides!A:E,5,FALSE) -> Cr52 | F296: =VLOOKUP(B296,[1]Nuclides!A:E,4,FALSE) -> STABLE | G296: =IF(F296="STABLE", "STABLE", IF(F296<60, F296&"s", IF(F296<3600, ROUND(F296/60,2)&"min", IF(F296<86400, ROUND(F296/3600,2)&"h", IF(F296<31536000, ROUND(F296/86400,2)&"d", ROUND(F296/31536000,2)&"y"))))) -> STABLE | H296: =LN(2)/F296 -> #VALUE! | I296: =60*6240000000000*C296*(1-EXP(-H296*2*3600)) -> #VALUE! | J296: =I296*EXP(-H296*96*3600) -> #VALUE! | K296: =E296 -> Cr52
B297: 24053 | C297: 6.58e-06 | D297: 0.039 | E297: =VLOOKUP(B297,[1]Nuclides!A:E,5,FALSE) -> Cr53 | F297: =VLOOKUP(B297,[1]Nuclides!A:E,4,FALSE) -> STABLE | G297: =IF(F297="STABLE", "STABLE", IF(F297<60, F297&"s", IF(F297<3600, ROUND(F297/60,2)&"min", IF(F297<86400, ROUND(F297/3600,2)&"h", IF(F297<31536000, ROUND(F297/86400,2)&"d", ROUND(F297/31536000,2)&"y"))))) -> STABLE | H297: =LN(2)/F297 -> #VALUE! | I297: =60*6240000000000*C297*(1-EXP(-H297*2*3600)) -> #VALUE! | J297: =I297*EXP(-H297*96*3600) -> #VALUE! | K297: =E297 -> Cr53
B298: 24054 | C298: 1.87e-06 | D298: 0.0731 | E298: =VLOOKUP(B298,[1]Nuclides!A:E,5,FALSE) -> Cr54 | F298: =VLOOKUP(B298,[1]Nuclides!A:E,4,FALSE) -> STABLE | G298: =IF(F298="STABLE", "STABLE", IF(F298<60, F298&"s", IF(F298<3600, ROUND(F298/60,2)&"min", IF(F298<86400, ROUND(F298/3600,2)&"h", IF(F298<31536000, ROUND(F298/86400,2)&"d", ROUND(F298/31536000,2)&"y"))))) -> STABLE | H298: =LN(2)/F298 -> #VALUE! | I298: =60*6240000000000*C298*(1-EXP(-H298*2*3600)) -> #VALUE! | J298: =I298*EXP(-H298*96*3600) -> #VALUE! | K298: =E298 -> Cr54
...

Sheet data
B4: 1次2h辐照后冷却不同时间靶体表面剂量当量
B5: 12h | C5: 12.4mSv/h | F5: 12 | G5: 12.4
B6: 24h | C6: 11.2mSv/h | F6: 24 | G6: 11.2
B7: 48h | C7: 8.65mSv/h | F7: 48 | G7: 8.65
B8: 96h | C8: 6.96mSv/h | F8: 96 | G8: 6.96
G11: Bi214 | H11: 1194 | I11: =IF(H11="STABLE", "STABLE", IF(H11<60, H11&"s", IF(H11<3600, ROUND(H11/60,2)&"min", IF(H11<86400, ROUND(H11/3600,2)&"h", IF(H11<31536000, ROUND(H11/86400,2)&"d", ROUND(H11/31536000,2)&"y"))))) -> 19.9min | J11: =LN(2)/H11 -> 0.00058052528 | K11: =10000000*(1-EXP(-J11*3600)) -> 8762993.8
L12: 1h | M12: 6h | N12: 12h | O12: 24h
G13: F18 | H13: 6586.2 | I13: =IF(H13="STABLE", "STABLE", IF(H13<60, H13&"s", IF(H13<3600, ROUND(H13/60,2)&"min", IF(H13<86400, ROUND(H13/3600,2)&"h", IF(H13<31536000, ROUND(H13/86400,2)&"d", ROUND(H13/31536000,2)&"y"))))) -> 1.83h | J13: =LN(2)/H13 -> 0.00010524235 | K13: =160*37000000 -> 5920000000 | L13: =K13*EXP(-J13*1*3600) -> 4.0530269e+09 | M13: =K13*EXP(-J13*6*3600) -> 6.0963287e+08 | N13: =K13*EXP(-J13*12*3600) -> 62779093 | O13: =K13*EXP(-J13*24*3600) -> 665745.7
L14: 9000 | M14: 2200 | N14: 120 | O14: 1.5
L15: 4.0530269e+09 | M15: 6.0963287e+08 | N15: 62779093 | O15: 665745.7
K16: F18 | L16: 4.0530269e+09 | M16: 0 | N16: =L16*1.94 -> 7.8628722e+09
K17: F18 | L17: 6.0963287e+08 | M17: 0 | N17: =L17*1.94 -> 1.1826878e+09
K18: F18 | L18: 62779093 | M18: 0 | N18: =L18*1.94 -> 1.2179144e+08
K19: F18 | L19: 665745.7 | M19: 0 | N19: =L19*1.94 -> 1291546.7
J23: μ

Sheet New-Havar
B1: Nuclides | C1: w | D1: Error | E1: Nuclides | F1: T1/2 | G1: T1/2 | H1: λ | I1: 60μA-2h | J1: cool-2d | K1: Nuclides
B4: 1001 | C4: 0 | D4: 0 | E4: =VLOOKUP(B4,Nuclides!A:F,5,FALSE) -> 0 | F4: =VLOOKUP(B4,Nuclides!A:F,4,FALSE) -> 613.9 | G4: =IF(F4="STABLE", "STABLE", IF(F4<60, F4&"s", IF(F4<3600, ROUND(F4/60,2)&"min", IF(F4<86400, ROUND(F4/3600,2)&"h", IF(F4<31536000, ROUND(F4/86400,2)&"d", ROUND(F4/31536000,2)&"y"))))) -> 10.23min | H4: =LN(2)/F4 -> 0.0011290881 | I4: =60*6240000000000*C4*(1-EXP(-H4*2*3600)) -> 0 | J4: =I4*EXP(-H4*48*3600) -> 0 | K4: =E4 -> 0
B5: 1002 | C5: 0 | D5: 0 | E5: =VLOOKUP(B5,Nuclides!A:F,5,FALSE) -> H2 | F5: =VLOOKUP(B5,Nuclides!A:F,4,FALSE) -> STABLE | G5: =IF(F5="STABLE", "STABLE", IF(F5<60, F5&"s", IF(F5<3600, ROUND(F5/60,2)&"min", IF(F5<86400, ROUND(F5/3600,2)&"h", IF(F5<31536000, ROUND(F5/86400,2)&"d", ROUND(F5/31536000,2)&"y"))))) -> STABLE | H5: =LN(2)/F5 -> #VALUE! | I5: =60*6240000000000*C5*(1-EXP(-H5*2*3600)) -> #VALUE! | J5: =I5*EXP(-H5*48*3600) -> #VALUE! | K5: =E5 -> H2
B6: 1003 | C6: 0 | D6: 0 | E6: =VLOOKUP(B6,Nuclides!A:F,5,FALSE) -> H3 | F6: =VLOOKUP(B6,Nuclides!A:F,4,FALSE) -> 388789632 | G6: =IF(F6="STABLE", "STABLE", IF(F6<60, F6&"s", IF(F6<3600, ROUND(F6/60,2)&"min", IF(F6<86400, ROUND(F6/3600,2)&"h", IF(F6<31536000, ROUND(F6/86400,2)&"d", ROUND(F6/31536000,2)&"y"))))) -> 12.33y | H6: =LN(2)/F6 -> 1.7828335e-09 | I6: =60*6240000000000*C6*(1-EXP(-H6*2*3600)) -> 0 | J6: =I6*EXP(-H6*48*3600) -> 0 | K6: =E6 -> H3
B7: 2003 | C7: 0 | D7: 0 | E7: =VLOOKUP(B7,Nuclides!A:F,5,FALSE) -> He3 | F7: =VLOOKUP(B7,Nuclides!A:F,4,FALSE) -> STABLE | G7: =IF(F7="STABLE", "STABLE", IF(F7<60, F7&"s", IF(F7<3600, ROUND(F7/60,2)&"min", IF(F7<86400, ROUND(F7/3600,2)&"h", IF(F7<31536000, ROUND(F7/86400,2)&"d", ROUND(F7/31536000,2)&"y"))))) -> STABLE | H7: =LN(2)/F7 -> #VALUE! | I7: =60*6240000000000*C7*(1-EXP(-H7*2*3600)) -> #VALUE! | J7: =I7*EXP(-H7*48*3600) -> #VALUE! | K7: =E7 -> He3
B8: 2004 | C8: 0 | D8: 0 | E8: =VLOOKUP(B8,Nuclides!A:F,5,FALSE) -> He4 | F8: =VLOOKUP(B8,Nuclides!A:F,4,FALSE) -> STABLE | G8: =IF(F8="STABLE", "STABLE", IF(F8<60, F8&"s", IF(F8<3600, ROUND(F8/60,2)&"min", IF(F8<86400, ROUND(F8/3600,2)&"h", IF(F8<31536000, ROUND(F8/86400,2)&"d", ROUND(F8/31536000,2)&"y"))))) -> STABLE | H8: =LN(2)/F8 -> #VALUE! | I8: =60*6240000000000*C8*(1-EXP(-H8*2*3600)) -> #VALUE! | J8: =I8*EXP(-H8*48*3600) -> #VALUE! | K8: =E8 -> He4
B9: 2005 | C9: 0 | D9: 0 | E9: =VLOOKUP(B9,Nuclides!A:F,5,FALSE) -> He5 | F9: =VLOOKUP(B9,Nuclides!A:F,4,FALSE) -> 7.595e-22 | G9: =IF(F9="STABLE", "STABLE", IF(F9<60, F9&"s", IF(F9<3600, ROUND(F9/60,2)&"min", IF(F9<86400, ROUND(F9/3600,2)&"h", IF(F9<31536000, ROUND(F9/86400,2)&"d", ROUND(F9/31536000,2)&"y"))))) -> 7.595E-22s | H9: =LN(2)/F9 -> 9.1263618e+20 | I9: =60*6240000000000*C9*(1-EXP(-H9*2*3600)) -> 0 | J9: =I9*EXP(-H9*48*3600) -> 0 | K9: =E9 -> He5
B10: 2006 | C10: 0 | D10: 0 | E10: =VLOOKUP(B10,Nuclides!A:F,5,FALSE) -> He6 | F10: =VLOOKUP(B10,Nuclides!A:F,4,FALSE) -> 0.8067 | G10: =IF(F10="STABLE", "STABLE", IF(F10<60, F10&"s", IF(F10<3600, ROUND(F10/60,2)&"min", IF(F10<86400, ROUND(F10/3600,2)&"h", IF(F10<31536000, ROUND(F10/86400,2)&"d", ROUND(F10/31536000,2)&"y"))))) -> 0.8067s | H10: =LN(2)/F10 -> 0.85923786 | I10: =60*6240000000000*C10*(1-EXP(-H10*2*3600)) -> 0 | J10: =I10*EXP(-H10*48*3600) -> 0 | K10: =E10 -> He6
B11: 2007 | C11: 0 | D11: 0 | E11: =VLOOKUP(B11,Nuclides!A:F,5,FALSE) -> He7 | F11: =VLOOKUP(B11,Nuclides!A:F,4,FALSE) -> 3.038e-21 | G11: =IF(F11="STABLE", "STABLE", IF(F11<60, F11&"s", IF(F11<3600, ROUND(F11/60,2)&"min", IF(F11<86400, ROUND(F11/3600,2)&"h", IF(F11<31536000, ROUND(F11/86400,2)&"d", ROUND(F11/31536000,2)&"y"))))) -> 3.038E-21s | H11: =LN(2)/F11 -> 2.2815905e+20 | I11: =60*6240000000000*C11*(1-EXP(-H11*2*3600)) -> 0 | J11: =I11*EXP(-H11*48*3600) -> 0 | K11: =E11 -> He7
B12: 2008 | C12: 0 | D12: 0 | E12: =VLOOKUP(B12,Nuclides!A:F,5,FALSE) -> He8 | F12: =VLOOKUP(B12,Nuclides!A:F,4,FALSE) -> 0.1191 | G12: =IF(F12="STABLE", "STABLE", IF(F12<60, F12&"s", IF(F12<3600, ROUND(F12/60,2)&"min", IF(F12<86400, ROUND(F12/3600,2)&"h", IF(F12<31536000, ROUND(F12/86400,2)&"d", ROUND(F12/31536000,2)&"y"))))) -> 0.1191s | H12: =LN(2)/F12 -> 5.8198756 | I12: =60*6240000000000*C12*(1-EXP(-H12*2*3600)) -> 0 | J12: =I12*EXP(-H12*48*3600) -> 0 | K12: =E12 -> He8
B13: 3005 | C13: 0 | D13: 0 | E13: =VLOOKUP(B13,Nuclides!A:F,5,FALSE) -> Li5 | F13: =VLOOKUP(B13,Nuclides!A:F,4,FALSE) -> 3.038e-22 | G13: =IF(F13="STABLE", "STABLE", IF(F13<60, F13&"s", IF(F13<3600, ROUND(F13/60,2)&"min", IF(F13<86400, ROUND(F13/3600,2)&"h", IF(F13<31536000, ROUND(F13/86400,2)&"d", ROUND(F13/31536000,2)&"y"))))) -> 3.038E-22s | H13: =LN(2)/F13 -> 2.2815905e+21 | I13: =60*6240000000000*C13*(1-EXP(-H13*2*3600)) -> 0 | J13: =I13*EXP(-H13*48*3600) -> 0 | K13: =E13 -> Li5
B14: 3006 | C14: 1.02e-07 | D14: 0.099 | E14: =VLOOKUP(B14,Nuclides!A:F,5,FALSE) -> Li6 | F14: =VLOOKUP(B14,Nuclides!A:F,4,FALSE) -> STABLE | G14: =IF(F14="STABLE", "STABLE", IF(F14<60, F14&"s", IF(F14<3600, ROUND(F14/60,2)&"min", IF(F14<86400, ROUND(F14/3600,2)&"h", IF(F14<31536000, ROUND(F14/86400,2)&"d", ROUND(F14/31536000,2)&"y"))))) -> STABLE | H14: =LN(2)/F14 -> #VALUE! | I14: =60*6240000000000*C14*(1-EXP(-H14*2*3600)) -> #VALUE! | J14: =I14*EXP(-H14*48*3600) -> #VALUE! | K14: =E14 -> Li6
B15: 3007 | C15: 1.01e-07 | D15: 0.0995 | E15: =VLOOKUP(B15,Nuclides!A:F,5,FALSE) -> Li7 | F15: =VLOOKUP(B15,Nuclides!A:F,4,FALSE) -> STABLE | G15: =IF(F15="STABLE", "STABLE", IF(F15<60, F15&"s", IF(F15<3600, ROUND(F15/60,2)&"min", IF(F15<86400, ROUND(F15/3600,2)&"h", IF(F15<31536000, ROUND(F15/86400,2)&"d", ROUND(F15/31536000,2)&"y"))))) -> STABLE | H15: =LN(2)/F15 -> #VALUE! | I15: =60*6240000000000*C15*(1-EXP(-H15*2*3600)) -> #VALUE! | J15: =I15*EXP(-H15*48*3600) -> #VALUE! | K15: =E15 -> Li7
... B20: 4006 | C20: 0 | D20: 0 | E20: =VLOOKUP(B20,Nuclides!A:F,5,FALSE) -> Be6 | F20: =VLOOKUP(B20,Nuclides!A:F,4,FALSE) -> 4.9532609e-21 | G20: =IF(F20="STABLE", "STABLE", IF(F20<60, F20&"s", IF(F20<3600, ROUND(F20/60,2)&"min", IF(F20<86400, ROUND(F20/3600,2)&"h", IF(F20<31536000, ROUND(F20/86400,2)&"d", ROUND(F20/31536000,2)&"y"))))) -> 4.95326086956521E-21s | H20: =LN(2)/F20 -> 1.3993755e+20 | I20: =60*6240000000000*C20*(1-EXP(-H20*2*3600)) -> 0 | J20: =I20*EXP(-H20*48*3600) -> 0 | K20: =E20 -> Be6
B21: 4007 | C21: 7.9e-08 | D21: 0.1125 | E21: =VLOOKUP(B21,Nuclides!A:F,5,FALSE) -> Be7 | F21: =VLOOKUP(B21,Nuclides!A:F,4,FALSE) -> 4598208 | G21: =IF(F21="STABLE", "STABLE", IF(F21<60, F21&"s", IF(F21<3600, ROUND(F21/60,2)&"min", IF(F21<86400, ROUND(F21/3600,2)&"h", IF(F21<31536000, ROUND(F21/86400,2)&"d", ROUND(F21/31536000,2)&"y"))))) -> 53.22d | H21: =LN(2)/F21 -> 1.5074289e-07 | I21: =60*6240000000000*C21*(1-EXP(-H21*2*3600)) -> 32084.599 | J21: =I21*EXP(-H21*0.5*3600) -> 32075.895 | K21: =E21 -> Be7 | L21: =J21 -> 32075.895 | M21: 0 | O21: =K21 -> Be7 | P21: =G21 -> 53.22d | Q21: =J21 -> 32075.895
B22: 4008 | C22: 0 | D22: 0 | E22: =VLOOKUP(B22,Nuclides!A:F,5,FALSE) -> Be8 | F22: =VLOOKUP(B22,Nuclides!A:F,4,FALSE) -> 8.1813285e-17 | G22: =IF(F22="STABLE", "STABLE", IF(F22<60, F22&"s", IF(F22<3600, ROUND(F22/60,2)&"min", IF(F22<86400, ROUND(F22/3600,2)&"h", IF(F22<31536000, ROUND(F22/86400,2)&"d", ROUND(F22/31536000,2)&"y"))))) -> 8.18132854578096E-17s | H22: =LN(2)/F22 -> 8.4723059e+15 | I22: =60*6240000000000*C22*(1-EXP(-H22*2*3600)) -> 0 | J22: =I22*EXP(-H22*48*3600) -> 0 | K22: =E22 -> Be8
B23: 4009 | C23: 7.18e-07 | D23: 0.0373 | E23: =VLOOKUP(B23,Nuclides!A:F,5,FALSE) -> Be9 | F23: =VLOOKUP(B23,Nuclides!A:F,4,FALSE) -> STABLE | G23: =IF(F23="STABLE", "STABLE", IF(F23<60, F23&"s", IF(F23<3600, ROUND(F23/60,2)&"min", IF(F23<86400, ROUND(F23/3600,2)&"h", IF(F23<31536000, ROUND(F23/86400,2)&"d", ROUND(F23/31536000,2)&"y"))))) -> STABLE | H23: =LN(2)/F23 -> #VALUE! | I23: =60*6240000000000*C23*(1-EXP(-H23*2*3600)) -> #VALUE! | J23: =I23*EXP(-H23*48*3600) -> #VALUE! | K23: =E23 -> Be9
B24: 4010 | C24: 0 | D24: 0 | E24: =VLOOKUP(B24,Nuclides!A:F,5,FALSE) -> Be10 | F24: =VLOOKUP(B24,Nuclides!A:F,4,FALSE) -> 47651976000000 | G24: =IF(F24="STABLE", "STABLE", IF(F24<60, F24&"s", IF(F24<3600, ROUND(F24/60,2)&"min", IF(F24<86400, ROUND(F24/3600,2)&"h", IF(F24<31536000, ROUND(F24/86400,2)&"d", ROUND(F24/31536000,2)&"y"))))) -> 1511034.25y | H24: =LN(2)/F24 -> 1.4546032e-14 | I24: =60*6240000000000*C24*(1-EXP(-H24*2*3600)) -> 0 | J24: =I24*EXP(-H24*48*3600) -> 0 | K24: =E24 -> Be10
B25: 4011 | C25: 0 | D25: 0 | E25: =VLOOKUP(B25,Nuclides!A:F,5,FALSE) -> Be11 | F25: =VLOOKUP(B25,Nuclides!A:F,4,FALSE) -> 13.76 | G25: =IF(F25="STABLE", "STABLE", IF(F25<60, F25&"s", IF(F25<3600, ROUND(F25/60,2)&"min", IF(F25<86400, ROUND(F25/3600,2)&"h", IF(F25<31536000, ROUND(F25/86400,2)&"d", ROUND(F25/31536000,2)&"y"))))) -> 13.76s | H25: =LN(2)/F25 -> 0.050374068 | I25: =60*6240000000000*C25*(1-EXP(-H25*2*3600)) -> 0 | J25: =I25*EXP(-H25*48*3600) -> 0 | K25: =E25 -> Be11
B26: 4012 | C26: 0 | D26: 0 | E26: =VLOOKUP(B26,Nuclides!A:F,5,FALSE) -> Be12 | F26: =VLOOKUP(B26,Nuclides!A:F,4,FALSE) -> 0.02147 | G26: =IF(F26="STABLE", "STABLE", IF(F26<60, F26&"s", IF(F26<3600, ROUND(F26/60,2)&"min", IF(F26<86400, ROUND(F26/3600,2)&"h", IF(F26<31536000, ROUND(F26/86400,2)&"d", ROUND(F26/31536000,2)&"y"))))) -> 0.02147s | H26: =LN(2)/F26 -> 32.284452 | I26: =60*6240000000000*C26*(1-EXP(-H26*2*3600)) -> 0 | J26: =I26*EXP(-H26*48*3600) -> 0 | K26: =E26 -> Be12
B27: 4013 | C27: 0 | D27: 0 | E27: =VLOOKUP(B27,Nuclides!A:F,5,FALSE) -> Be13 | F27: =VLOOKUP(B27,Nuclides!A:F,4,FALSE) -> 2.7e-21 | G27: =IF(F27="STABLE", "STABLE", IF(F27<60, F27&"s", IF(F27<3600, ROUND(F27/60,2)&"min", IF(F27<86400, ROUND(F27/3600,2)&"h", IF(F27<31536000, ROUND(F27/86400,2)&"d", ROUND(F27/31536000,2)&"y"))))) -> 2.7E-21s | H27: =LN(2)/F27 -> 2.5672118e+20 | I27: =60*6240000000000*C27*(1-EXP(-H27*2*3600)) -> 0 | J27: =I27*EXP(-H27*48*3600) -> 0 | K27: =E27 -> Be13
B28: 4014 | C28: 0 | D28: 0 | E28: =VLOOKUP(B28,Nuclides!A:F,5,FALSE) -> Be14 | F28: =VLOOKUP(B28,Nuclides!A:F,4,FALSE) -> 0.00435 | G28: =IF(F28="STABLE", "STABLE", IF(F28<60, F28&"s", IF(F28<3600, ROUND(F28/60,2)&"min", IF(F28<86400, ROUND(F28/3600,2)&"h", IF(F28<31536000, ROUND(F28/86400,2)&"d", ROUND(F28/31536000,2)&"y"))))) -> 0.00435s | H28: =LN(2)/F28 -> 159.34418 | I28: =60*6240000000000*C28*(1-EXP(-H28*2*3600)) -> 0 | J28: =I28*EXP(-H28*48*3600) -> 0 | K28: =E28 -> Be14
B29: 5008 | C29: 0 | D29: 0 | E29: =VLOOKUP(B29,Nuclides!A:F,5,FALSE) -> B8 | F29: =VLOOKUP(B29,Nuclides!A:F,4,FALSE) -> 0.77 | G29: =IF(F29="STABLE", "STABLE", IF(F29<60, F29&"s", IF(F29<3600, ROUND(F29/60,2)&"min", IF(F29<86400, ROUND(F29/3600,2)&"h", IF(F29<31536000, ROUND(F29/86400,2)&"d", ROUND(F29/31536000,2)&"y"))))) -> 0.77s | H29: =LN(2)/F29 -> 0.90019114 | I29: =60*6240000000000*C29*(1-EXP(-H29*2*3600)) -> 0 | J29: =I29*EXP(-H29*48*3600) -> 0 | K29: =E29 -> B8
B30: 5009 | C30: 0 | D30: 0 | E30: =VLOOKUP(B30,Nuclides!A:F,5,FALSE) -> B9 | F30: =VLOOKUP(B30,Nuclides!A:F,4,FALSE) -> 8.4388889e-19 | G30: =IF(F30="STABLE", "STABLE", IF(F30<60, F30&"s", IF(F30<3600, ROUND(F30/60,2)&"min", IF(F30<86400, ROUND(F30/3600,2)&"h", IF(F30<31536000, ROUND(F30/86400,2)&"d", ROUND(F30/31536000,2)&"y"))))) -> 8.43888888888888E-19s | H30: =LN(2)/F30 -> 8.2137256e+17 | I30: =60*6240000000000*C30*(1-EXP(-H30*2*3600)) -> 0 | J30: =I30*EXP(-H30*48*3600) -> 0 | K30: =E30 -> B9
B31: 5010 | C31: 0 | D31: 0 | E31: =VLOOKUP(B31,Nuclides!A:F,5,FALSE) -> B10 | F31: =VLOOKUP(B31,Nuclides!A:F,4,FALSE) -> STABLE | G31: =IF(F31="STABLE", "STABLE", IF(F31<60, F31&"s", IF(F31<3600, ROUND(F31/60,2)&"min", IF(F31<86400, ROUND(F31/3600,2)&"h", IF(F31<31536000, ROUND(F31/86400,2)&"d", ROUND(F31/31536000,2)&"y"))))) -> STABLE | H31: =LN(2)/F31 -> #VALUE! | I31: =60*6240000000000*C31*(1-EXP(-H31*2*3600)) -> #VALUE! | J31: =I31*EXP(-H31*48*3600) -> #VALUE! | K31: =E31 -> B10
B32: 5011 | C32: 0 | D32: 0 | E32: =VLOOKUP(B32,Nuclides!A:F,5,FALSE) -> B11 | F32: =VLOOKUP(B32,Nuclides!A:F,4,FALSE) -> STABLE | G32: =IF(F32="STABLE", "STABLE", IF(F32<60, F32&"s", IF(F32<3600, ROUND(F32/60,2)&"min", IF(F32<86400, ROUND(F32/3600,2)&"h", IF(F32<31536000, ROUND(F32/86400,2)&"d", ROUND(F32/31536000,2)&"y"))))) -> STABLE | H32: =LN(2)/F32 -> #VALUE! | I32: =60*6240000000000*C32*(1-EXP(-H32*2*3600)) -> #VALUE! | J32: =I32*EXP(-H32*48*3600) -> #VALUE! | K32: =E32 -> B11
B33: 5012 | C33: 0 | D33: 0 | E33: =VLOOKUP(B33,Nuclides!A:F,5,FALSE) -> B12 | F33: =VLOOKUP(B33,Nuclides!A:F,4,FALSE) -> 0.0202 | G33: =IF(F33="STABLE", "STABLE", IF(F33<60, F33&"s", IF(F33<3600, ROUND(F33/60,2)&"min", IF(F33<86400, ROUND(F33/3600,2)&"h", IF(F33<31536000, ROUND(F33/86400,2)&"d", ROUND(F33/31536000,2)&"y"))))) -> 0.0202s | H33: =LN(2)/F33 -> 34.314217 | I33: =60*6240000000000*C33*(1-EXP(-H33*2*3600)) -> 0 | J33: =I33*EXP(-H33*48*3600) -> 0 | K33: =E33 -> B12
... B290: 23048 | C290: 0 | D290: 0 | E290: =VLOOKUP(B290,Nuclides!A:F,5,FALSE) -> V48 | F290: =VLOOKUP(B290,Nuclides!A:F,4,FALSE) -> 1380110.4 | G290: =IF(F290="STABLE", "STABLE", IF(F290<60, F290&"s", IF(F290<3600, ROUND(F290/60,2)&"min", IF(F290<86400, ROUND(F290/3600,2)&"h", IF(F290<31536000, ROUND(F290/86400,2)&"d", ROUND(F290/31536000,2)&"y"))))) -> 15.97d | H290: =LN(2)/F290 -> 5.0224039e-07 | I290: =60*6240000000000*C290*(1-EXP(-H290*2*3600)) -> 0 | J290: =I290*EXP(-H290*48*3600) -> 0 | K290: =E290 -> V48
B291: 23049 | C291: 5.03e-07 | D291: 0.0446 | E291: =VLOOKUP(B291,Nuclides!A:F,5,FALSE) -> V49 | F291: =VLOOKUP(B291,Nuclides!A:F,4,FALSE) -> 28512000 | G291: =IF(F291="STABLE", "STABLE", IF(F291<60, F291&"s", IF(F291<3600, ROUND(F291/60,2)&"min", IF(F291<86400, ROUND(F291/3600,2)&"h", IF(F291<31536000, ROUND(F291/86400,2)&"d", ROUND(F291/31536000,2)&"y"))))) -> 330d | H291: =LN(2)/F291 -> 2.4310718e-08 | I291: =60*6240000000000*C291*(1-EXP(-H291*2*3600)) -> 32960.675 | J291: =I291*EXP(-H291*0.5*3600) -> 32959.232 | K291: =E291 -> V49 | L291: =J291 -> 32959.232 | M291: 0 | O291: =K291 -> V49 | P291: =G291 -> 330d | Q291: =J291 -> 32959.232
B292: 23050 | C292: 1.7e-07 | D292: 0.0767 | E292: =VLOOKUP(B292,Nuclides!A:F,5,FALSE) -> V50 | F292: =VLOOKUP(B292,Nuclides!A:F,4,FALSE) -> 6.627096e+24 | G292: =IF(F292="STABLE", "STABLE", IF(F292<60, F292&"s", IF(F292<3600, ROUND(F292/60,2)&"min", IF(F292<86400, ROUND(F292/3600,2)&"h", IF(F292<31536000, ROUND(F292/86400,2)&"d", ROUND(F292/31536000,2)&"y"))))) -> 210143835616438000y | H292: =LN(2)/F292 -> 1.045929e-25 | I292: =60*6240000000000*C292*(1-EXP(-H292*2*3600)) -> 0 | J292: =I292*EXP(-H292*48*3600) -> 0 | K292: =E292 -> V50
B293: 23051 | C293: 2.5e-08 | D293: 0.2 | E293: =VLOOKUP(B293,Nuclides!A:F,5,FALSE) -> V51 | F293: =VLOOKUP(B293,Nuclides!A:F,4,FALSE) -> STABLE | G293: =IF(F293="STABLE", "STABLE", IF(F293<60, F293&"s", IF(F293<3600, ROUND(F293/60,2)&"min", IF(F293<86400, ROUND(F293/3600,2)&"h", IF(F293<31536000, ROUND(F293/86400,2)&"d", ROUND(F293/31536000,2)&"y"))))) -> STABLE | H293: =LN(2)/F293 -> #VALUE! | I293: =60*6240000000000*C293*(1-EXP(-H293*2*3600)) -> #VALUE! | J293: =I293*EXP(-H293*48*3600) -> #VALUE! | K293: =E293 -> V51
B294: 23052 | C294: 0 | D294: 0 | E294: =VLOOKUP(B294,Nuclides!A:F,5,FALSE) -> V52 | F294: =VLOOKUP(B294,Nuclides!A:F,4,FALSE) -> 224.58 | G294: =IF(F294="STABLE", "STABLE", IF(F294<60, F294&"s", IF(F294<3600, ROUND(F294/60,2)&"min", IF(F294<86400, ROUND(F294/3600,2)&"h", IF(F294<31536000, ROUND(F294/86400,2)&"d", ROUND(F294/31536000,2)&"y"))))) -> 3.74min | H294: =LN(2)/F294 -> 0.0030864154 | I294: =60*6240000000000*C294*(1-EXP(-H294*2*3600)) -> 0 | J294: =I294*EXP(-H294*48*3600) -> 0 | K294: =E294 -> V52
B295: 23053 | C295: 0 | D295: 0 | E295: =VLOOKUP(B295,Nuclides!A:F,5,FALSE) -> V53 | F295: =VLOOKUP(B295,Nuclides!A:F,4,FALSE) -> 92.58 | G295: =IF(F295="STABLE", "STABLE", IF(F295<60, F295&"s", IF(F295<3600, ROUND(F295/60,2)&"min", IF(F295<86400, ROUND(F295/3600,2)&"h", IF(F295<31536000, ROUND(F295/86400,2)&"d", ROUND(F295/31536000,2)&"y"))))) -> 1.54min | H295: =LN(2)/F295 -> 0.0074870078 | I295: =60*6240000000000*C295*(1-EXP(-H295*2*3600)) -> 0 | J295: =I295*EXP(-H295*48*3600) -> 0 | K295: =E295 -> V53
B296: 23054 | C296: 0 | D296: 0 | E296: =VLOOKUP(B296,Nuclides!A:F,5,FALSE) -> V54 | F296: =VLOOKUP(B296,Nuclides!A:F,4,FALSE) -> 49.8 | G296: =IF(F296="STABLE", "STABLE", IF(F296<60, F296&"s", IF(F296<3600, ROUND(F296/60,2)&"min", IF(F296<86400, ROUND(F296/3600,2)&"h", IF(F296<31536000, ROUND(F296/86400,2)&"d", ROUND(F296/31536000,2)&"y"))))) -> 49.8s | H296: =LN(2)/F296 -> 0.013918618 | I296: =60*6240000000000*C296*(1-EXP(-H296*2*3600)) -> 0 | J296: =I296*EXP(-H296*48*3600) -> 0 | K296: =E296 -> V54
B297: 23055 | C297: 0 | D297: 0 | E297: =VLOOKUP(B297,Nuclides!A:F,5,FALSE) -> V55 | F297: =VLOOKUP(B297,Nuclides!A:F,4,FALSE) -> 6.54 | G297: =IF(F297="STABLE", "STABLE", IF(F297<60, F297&"s", IF(F297<3600, ROUND(F297/60,2)&"min", IF(F297<86400, ROUND(F297/3600,2)&"h", IF(F297<31536000, ROUND(F297/86400,2)&"d", ROUND(F297/31536000,2)&"y"))))) -> 6.54s | H297: =LN(2)/F297 -> 0.10598581 | I297: =60*6240000000000*C297*(1-EXP(-H297*2*3600)) -> 0 | J297: =I297*EXP(-H297*48*3600) -> 0 | K297: =E297 -> V55
B298: 23056 | C298: 0 | D298: 0 | E298: =VLOOKUP(B298,Nuclides!A:F,5,FALSE) -> V56 | F298: =VLOOKUP(B298,Nuclides!A:F,4,FALSE) -> 0.216 | G298: =IF(F298="STABLE", "STABLE", IF(F298<60, F298&"s", IF(F298<3600, ROUND(F298/60,2)&"min", IF(F298<86400, ROUND(F298/3600,2)&"h", IF(F298<31536000, ROUND(F298/86400,2)&"d", ROUND(F298/31536000,2)&"y"))))) -> 0.216s | H298: =LN(2)/F298 -> 3.2090147 | I298: =60*6240000000000*C298*(1-EXP(-H298*2*3600)) -> 0 | J298: =I298*EXP(-H298*48*3600) -> 0 | K298: =E298 -> V56
B299: 24045 | C299: 0 | D299: 0 | E299: =VLOOKUP(B299,Nuclides!A:F,5,FALSE) -> Cr45 | F299: =VLOOKUP(B299,Nuclides!A:F,4,FALSE) -> 0.0609 | G299: =IF(F299="STABLE", "STABLE", IF(F299<60, F299&"s", IF(F299<3600, ROUND(F299/60,2)&"min", IF(F299<86400, ROUND(F299/3600,2)&"h", IF(F299<31536000, ROUND(F299/86400,2)&"d", ROUND(F299/31536000,2)&"y"))))) -> 0.0609s | H299: =LN(2)/F299 -> 11.381727 | I299: =60*6240000000000*C299*(1-EXP(-H299*2*3600)) -> 0 | J299: =I299*EXP(-H299*48*3600) -> 0 | K299: =E299 -> Cr45
B300: 24046 | C300: 0 | D300: 0 | E300: =VLOOKUP(B300,Nuclides!A:F,5,FALSE) -> Cr46 | F300: =VLOOKUP(B300,Nuclides!A:F,4,FALSE) -> 0.26 | G300: =IF(F300="STABLE", "STABLE", IF(F300<60, F300&"s", IF(F300<3600, ROUND(F300/60,2)&"min", IF(F300<86400, ROUND(F300/3600,2)&"h", IF(F300<31536000, ROUND(F300/86400,2)&"d", ROUND(F300/31536000,2)&"y"))))) -> 0.26s | H300: =LN(2)/F300 -> 2.6659507 | I300: =60*6240000000000*C300*(1-EXP(-H300*2*3600)) -> 0 | J300: =I300*EXP(-H300*48*3600) -> 0 | K300: =E300 -> Cr46
B301: 24047 | C301: 0 | D301: 0 | E301: =VLOOKUP(B301,Nuclides!A:F,5,FALSE) -> Cr47 | F301: =VLOOKUP(B301,Nuclides!A:F,4,FALSE) -> 0.5 | G301: =IF(F301="STABLE", "STABLE", IF(F301<60, F301&"s", IF(F301<3600, ROUND(F301/60,2)&"min", IF(F301<86400, ROUND(F301/3600,2)&"h", IF(F301<31536000, ROUND(F301/86400,2)&"d", ROUND(F301/31536000,2)&"y"))))) -> 0.5s | H301: =LN(2)/F301 -> 1.3862944 | I301: =60*6240000000000*C301*(1-EXP(-H301*2*3600)) -> 0 | J301: =I301*EXP(-H301*48*3600) -> 0 | K301: =E301 -> Cr47
B302: 24048 | C302: 0 | D302: 0 | E302: =VLOOKUP(B302,Nuclides!A:F,5,FALSE) -> Cr48 | F302: =VLOOKUP(B302,Nuclides!A:F,4,FALSE) -> 77616 | G302: =IF(F302="STABLE", "STABLE", IF(F302<60, F302&"s", IF(F302<3600, ROUND(F302/60,2)&"min", IF(F302<86400, ROUND(F302/3600,2)&"h", IF(F302<31536000, ROUND(F302/86400,2)&"d", ROUND(F302/31536000,2)&"y"))))) -> 21.56h | H302: =LN(2)/F302 -> 8.9304677e-06 | I302: =60*6240000000000*C302*(1-EXP(-H302*2*3600)) -> 0 | J302: =I302*EXP(-H302*48*3600) -> 0 | K302: =E302 -> Cr48
...

Sheet 环评
B5: 液体靶 | C5: 表面 | D5: 30cm | E5: 1m | H5: 固体靶 | I5: 表面 | J5: 30cm | K5: 1m
B6: 30min | C6: 36453.8 | D6: 557.187 | E6: 55.5452 | H6: 30min | I6: 20219.3 | J6: 299.282 | K6: 31.8656
B7: 6h | C7: 30104.1 | D7: 456.509 | E7: 45.2616 | H7: 6h | I7: 12285.6 | J7: 186.162 | K7: 19.8211
B8: 1d | C8: 22688 | D8: 347.748 | E8: 35.2393 | H8: 1d | I8: 10654 | J8: 161.387 | K8: 17.3125
B9: 2d | C9: 19018.9 | D9: 293.74 | E9: 29.7337 | H9: 2d | I9: 10161.3 | J9: 153.808 | K9: 16.4963
B10: 4d | C10: 14570.7 | D10: 222.685 | E10: 23.1145 | H10: 4d | I10: 9343.67 | J10: 141.59 | K10: 15.1633

Sheet New-Nb-Cu
