Workbook

Sheet Nuclides
B2: n | C2: z | D2: halflife/s
A3: 1001 | B3: 1 | C3: 0 | D3: 613.9
A4: 1002 | B4: 1 | C4: 1 | D4: STABLE | E4: H2
A5: 1003 | B5: 2 | C5: 1 | D5: 388789632 | E5: H3
A6: 1005 | B6: 4 | C6: 1 | D6: 7.9947368e-23 | E6: H5
A7: 1006 | B7: 5 | C7: 1 | D7: 2.848125e-22 | E7: H6
A8: 2003 | B8: 1 | C8: 2 | D8: STABLE | E8: He3
A9: 2004 | B9: 2 | C9: 2 | D9: STABLE | E9: He4
A10: 2005 | B10: 3 | C10: 2 | D10: 7.595e-22 | E10: He5
A11: 2006 | B11: 4 | C11: 2 | D11: 0.8067 | E11: He6
A12: 2007 | B12: 5 | C12: 2 | D12: 3.038e-21 | E12: He7
A13: 2008 | B13: 6 | C13: 2 | D13: 0.1191 | E13: He8
A14: 2010 | B14: 8 | C14: 2 | D14: 1.519e-21 | E14: He10
A15: 3004 | B15: 1 | C15: 3 | D15: 7.5572139e-23 | E15: Li4
A16: 3005 | B16: 2 | C16: 3 | D16: 3.038e-22 | E16: Li5
A17: 3006 | B17: 3 | C17: 3 | D17: STABLE | E17: Li6
A18: 3007 | B18: 4 | C18: 3 | D18: STABLE | E18: Li7
A19: 3008 | B19: 5 | C19: 3 | D19: 0.8399 | E19: Li8
A20: 3009 | B20: 6 | C20: 3 | D20: 0.1783 | E20: Li9
A21: 3011 | B21: 8 | C21: 3 | D21: 0.00875 | E21: Li11
A22: 4006 | B22: 2 | C22: 4 | D22: 4.9532609e-21 | E22: Be6
A23: 4007 | B23: 3 | C23: 4 | D23: 4598208 | E23: Be7
A24: 4008 | B24: 4 | C24: 4 | D24: 8.1813285e-17 | E24: Be8
A25: 4009 | B25: 5 | C25: 4 | D25: STABLE | E25: Be9
A26: 4010 | B26: 6 | C26: 4 | D26: 47651976000000 | E26: Be10
A27: 4011 | B27: 7 | C27: 4 | D27: 13.76 | E27: Be11
A28: 4012 | B28: 8 | C28: 4 | D28: 0.02147 | E28: Be12
A29: 4013 | B29: 9 | C29: 4 | D29: 2.7e-21 | E29: Be13
A30: 4014 | B30: 10 | C30: 4 | D30: 0.00435 | E30: Be14
A31: 4015 | B31: 11 | C31: 4 | D31: 7.8568966e-22 | E31: Be15
A32: 4016 | B32: 12 | C32: 4 | D32: 5.69625e-22 | E32: Be16
A33: 5007 | B33: 2 | C33: 5 | D33: 3.255e-22 | E33: B7
A34: 5008 | B34: 3 | C34: 5 | D34: 0.77 | E34: B8
A35: 5009 | B35: 4 | C35: 5 | D35: 8.4388889e-19 | E35: B9
A36: 5010 | B36: 5 | C36: 5 | D36: STABLE | E36: B10
A37: 5011 | B37: 6 | C37: 5 | D37: STABLE | E37: B11
A38: 5012 | B38: 7 | C38: 5 | D38: 0.0202 | E38: B12
A39: 5013 | B39: 8 | C39: 5 | D39: 0.01733 | E39: B13
A40: 5014 | B40: 9 | C40: 5 | D40: 0.01236 | E40: B14
A41: 5015 | B41: 10 | C41: 5 | D41: 0.01018 | E41: B15
...

Sheet 屏蔽体
A1: 1000 | B1: Nuclides | C1: w | D1: Error | E1: Nuclides | F1: T1/2 | G1: T1/2 | H1: λ | I1: 60μA-2h | J1: cool-6h | K1: Nuclides | L1: 720 | M1: 7200 | N1: 105 | O1: mass | P1: 34881400 | Q1: 169000000000 | R1: =Q1/P1 -> 4844.989
B4: 1001 | C4: 0 | D4: 0 | E4: =VLOOKUP(B4,Nuclides!A:E,5,FALSE) -> 0 | F4: =VLOOKUP(B4,Nuclides!A:E,4,FALSE) -> 613.9 | G4: =IF(F4="STABLE", "STABLE", IF(F4<60, F4&"s", IF(F4<3600, ROUND(F4/60,2)&"min", IF(F4<86400, ROUND(F4/3600,2)&"h", IF(F4<31536000, ROUND(F4/86400,2)&"d", ROUND(F4/31536000,2)&"y"))))) -> 10.23min | H4: =LN(2)/F4 -> 0.0011290881 | I4: =60*6240000000000*C4*(1-EXP(-H4*2*3600)) -> 0 | J4: =I4*EXP(-H4*10*3600) -> 0 | K4: =E4 -> 0 | L4: {=SUM(($J4*EXP(-$H4*24*3600*_xlfn.SEQUENCE(L$1-1))))+$J4} -> 0 | M4: {=SUM(($J4*EXP(-$H4*24*3600*_xlfn.SEQUENCE(M$1-1))))+$J4} -> 0
B5: 1002 | C5: 0.0382799 | D5: 0.0001 | E5: =VLOOKUP(B5,Nuclides!A:E,5,FALSE) -> H2 | F5: =VLOOKUP(B5,Nuclides!A:E,4,FALSE) -> STABLE | G5: =IF(F5="STABLE", "STABLE", IF(F5<60, F5&"s", IF(F5<3600, ROUND(F5/60,2)&"min", IF(F5<86400, ROUND(F5/3600,2)&"h", IF(F5<31536000, ROUND(F5/86400,2)&"d", ROUND(F5/31536000,2)&"y"))))) -> STABLE | H5: =LN(2)/F5 -> #VALUE! | I5: =60*6240000000000*C5*(1-EXP(-H5*2*3600)) -> #VALUE! | J5: =I5*EXP(-H5*10*3600) -> #VALUE! | K5: =E5 -> H2 | L5: {=SUM(($J5*EXP(-$H5*24*3600*_xlfn.SEQUENCE(L$1-1))))+$J5} -> #VALUE! | M5: {=SUM(($J5*EXP(-$H5*24*3600*_xlfn.SEQUENCE(M$1-1))))+$J5} -> #VALUE!
B6: 1003 | C6: 5.839e-09 | D6: 0.0021 | E6: =VLOOKUP(B6,Nuclides!A:E,5,FALSE) -> H3 | F6: =VLOOKUP(B6,Nuclides!A:E,4,FALSE) -> 388789632 | G6: =IF(F6="STABLE", "STABLE", IF(F6<60, F6&"s", IF(F6<3600, ROUND(F6/60,2)&"min", IF(F6<86400, ROUND(F6/3600,2)&"h", IF(F6<31536000, ROUND(F6/86400,2)&"d", ROUND(F6/31536000,2)&"y"))))) -> 12.33y | H6: =LN(2)/F6 -> 1.7828335e-09 | I6: =60*6240000000000*C6*(1-EXP(-H6*2*3600)) -> 28.061754 | J6: =I6*EXP(-H6*10*3600) -> 28.059953 | K6: =E6 -> H3 | L6: {=SUM(($J6*EXP(-$H6*24*3600*_xlfn.SEQUENCE(L$1-1))))+$J6} -> 19124.602 | M6: {=SUM(($J6*EXP(-$H6*24*3600*_xlfn.SEQUENCE(M$1-1))))+$J6} -> 122083.43 | O6: =K6 -> H3 | P6: =M6 -> 122083.43 | Q6: =0 -> 0 | S6: =O6 -> H3 | T6: =G6 -> 12.33y | U6: =P6 -> 122083.43 | V6: 低
B7: 2003 | C7: 0 | D7: 0 | E7: =VLOOKUP(B7,Nuclides!A:E,5,FALSE) -> He3 | F7: =VLOOKUP(B7,Nuclides!A:E,4,FALSE) -> STABLE | G7: =IF(F7="STABLE", "STABLE", IF(F7<60, F7&"s", IF(F7<3600, ROUND(F7/60,2)&"min", IF(F7<86400, ROUND(F7/3600,2)&"h", IF(F7<31536000, ROUND(F7/86400,2)&"d", ROUND(F7/31536000,2)&"y"))))) -> STABLE | H7: =LN(2)/F7 -> #VALUE! | I7: =60*6240000000000*C7*(1-EXP(-H7*2*3600)) -> #VALUE! | J7: =I7*EXP(-H7*10*3600) -> #VALUE! | K7: =E7 -> He3 | L7: {=SUM(($J7*EXP(-$H7*24*3600*_xlfn.SEQUENCE(L$1-1))))+$J7} -> #VALUE! | M7: {=SUM(($J7*EXP(-$H7*24*3600*_xlfn.SEQUENCE(M$1-1))))+$J7} -> #VALUE!
B8: 2004 | C8: 0 | D8: 0 | E8: =VLOOKUP(B8,Nuclides!A:E,5,FALSE) -> He4 | F8: =VLOOKUP(B8,Nuclides!A:E,4,FALSE) -> STABLE | G8: =IF(F8="STABLE", "STABLE", IF(F8<60, F8&"s", IF(F8<3600, ROUND(F8/60,2)&"min", IF(F8<86400, ROUND(F8/3600,2)&"h", IF(F8<31536000, ROUND(F8/86400,2)&"d", ROUND(F8/31536000,2)&"y"))))) -> STABLE | H8: =LN(2)/F8 -> #VALUE! | I8: =60*6240000000000*C8*(1-EXP(-H8*2*3600)) -> #VALUE! | J8: =I8*EXP(-H8*10*3600) -> #VALUE! | K8: =E8 -> He4 | L8: {=SUM(($J8*EXP(-$H8*24*3600*_xlfn.SEQUENCE(L$1-1))))+$J8} -> #VALUE! | M8: {=SUM(($J8*EXP(-$H8*24*3600*_xlfn.SEQUENCE(M$1-1))))+$J8} -> #VALUE!
B9: 2005 | C9: 0 | D9: 0 | E9: =VLOOKUP(B9,Nuclides!A:E,5,FALSE) -> He5 | F9: =VLOOKUP(B9,Nuclides!A:E,4,FALSE) -> 7.595e-22 | G9: =IF(F9="STABLE", "STABLE", IF(F9<60, F9&"s", IF(F9<3600, ROUND(F9/60,2)&"min", IF(F9<86400, ROUND(F9/3600,2)&"h", IF(F9<31536000, ROUND(F9/86400,2)&"d", ROUND(F9/31536000,2)&"y"))))) -> 7.595E-22s | H9: =LN(2)/F9 -> 9.1263618e+20 | I9: =60*6240000000000*C9*(1-EXP(-H9*2*3600)) -> 0 | J9: =I9*EXP(-H9*10*3600) -> 0 | K9: =E9 -> He5 | L9: {=SUM(($J9*EXP(-$H9*24*3600*_xlfn.SEQUENCE(L$1-1))))+$J9} -> 0 | M9: {=SUM(($J9*EXP(-$H9*24*3600*_xlfn.SEQUENCE(M$1-1))))+$J9} -> 0
B10: 2006 | C10: 0 | D10: 0 | E10: =VLOOKUP(B10,Nuclides!A:E,5,FALSE) -> He6 | F10: =VLOOKUP(B10,Nuclides!A:E,4,FALSE) -> 0.8067 | G10: =IF(F10="STABLE", "STABLE", IF(F10<60, F10&"s", IF(F10<3600, ROUND(F10/60,2)&"min", IF(F10<86400, ROUND(F10/3600,2)&"h", IF(F10<31536000, ROUND(F10/86400,2)&"d", ROUND(F10/31536000,2)&"y"))))) -> 0.8067s | H10: =LN(2)/F10 -> 0.85923786 | I10: =60*6240000000000*C10*(1-EXP(-H10*2*3600)) -> 0 | J10: =I10*EXP(-H10*10*3600) -> 0 | K10: =E10 -> He6 | L10: {=SUM(($J10*EXP(-$H10*24*3600*_xlfn.SEQUENCE(L$1-1))))+$J10} -> 0 | M10: {=SUM(($J10*EXP(-$H10*24*3600*_xlfn.SEQUENCE(M$1-1))))+$J10} -> 0
B11: 2007 | C11: 0 | D11: 0 | E11: =VLOOKUP(B11,Nuclides!A:E,5,FALSE) -> He7 | F11: =VLOOKUP(B11,Nuclides!A:E,4,FALSE) -> 3.038e-21 | G11: =IF(F11="STABLE", "STABLE", IF(F11<60, F11&"s", IF(F11<3600, ROUND(F11/60,2)&"min", IF(F11<86400, ROUND(F11/3600,2)&"h", IF(F11<31536000, ROUND(F11/86400,2)&"d", ROUND(F11/31536000,2)&"y"))))) -> 3.038E-21s | H11: =LN(2)/F11 -> 2.2815905e+20 | I11: =60*6240000000000*C11*(1-EXP(-H11*2*3600)) -> 0 | J11: =I11*EXP(-H11*10*3600) -> 0 | K11: =E11 -> He7 | L11: {=SUM(($J11*EXP(-$H11*24*3600*_xlfn.SEQUENCE(L$1-1))))+$J11} -> 0 | M11: {=SUM(($J11*EXP(-$H11*24*3600*_xlfn.SEQUENCE(M$1-1))))+$J11} -> 0
B12: 2008 | C12: 0 | D12: 0 | E12: =VLOOKUP(B12,Nuclides!A:E,5,FALSE) -> He8 | F12: =VLOOKUP(B12,Nuclides!A:E,4,FALSE) -> 0.1191 | G12: =IF(F12="STABLE", "STABLE", IF(F12<60, F12&"s", IF(F12<3600, ROUND(F12/60,2)&"min", IF(F12<86400, ROUND(F12/3600,2)&"h", IF(F12<31536000, ROUND(F12/86400,2)&"d", ROUND(F12/31536000,2)&"y"))))) -> 0.1191s | H12: =LN(2)/F12 -> 5.8198756 | I12: =60*6240000000000*C12*(1-EXP(-H12*2*3600)) -> 0 | J12: =I12*EXP(-H12*10*3600) -> 0 | K12: =E12 -> He8 | L12: {=SUM(($J12*EXP(-$H12*24*3600*_xlfn.SEQUENCE(L$1-1))))+$J12} -> 0 | M12: {=SUM(($J12*EXP(-$H12*24*3600*_xlfn.SEQUENCE(M$1-1))))+$J12} -> 0
B13: 3005 | C13: 0 | D13: 0 | E13: =VLOOKUP(B13,Nuclides!A:E,5,FALSE) -> Li5 | F13: =VLOOKUP(B13,Nuclides!A:E,4,FALSE) -> 3.038e-22 | G13: =IF(F13="STABLE", "STABLE", IF(F13<60, F13&"s", IF(F13<3600, ROUND(F13/60,2)&"min", IF(F13<86400, ROUND(F13/3600,2)&"h", IF(F13<31536000, ROUND(F13/86400,2)&"d", ROUND(F13/31536000,2)&"y"))))) -> 3.038E-22s | H13: =LN(2)/F13 -> 2.2815905e+21 | I13: =60*6240000000000*C13*(1-EXP(-H13*2*3600)) -> 0 | J13: =I13*EXP(-H13*10*3600) -> 0 | K13: =E13 -> Li5 | L13: {=SUM(($J13*EXP(-$H13*24*3600*_xlfn.SEQUENCE(L$1-1))))+$J13} -> 0 | M13: {=SUM(($J13*EXP(-$H13*24*3600*_xlfn.SEQUENCE(M$1-1))))+$J13} -> 0
B14: 3006 | C14: 0 | D14: 0 | E14: =VLOOKUP(B14,Nuclides!A:E,5,FALSE) -> Li6 | F14: =VLOOKUP(B14,Nuclides!A:E,4,FALSE) -> STABLE | G14: =IF(F14="STABLE", "STABLE", IF(F14<60, F14&"s", IF(F14<3600, ROUND(F14/60,2)&"min", IF(F14<86400, ROUND(F14/3600,2)&"h", IF(F14<31536000, ROUND(F14/86400,2)&"d", ROUND(F14/31536000,2)&"y"))))) -> STABLE | H14: =LN(2)/F14 -> #VALUE! | I14: =60*6240000000000*C14*(1-EXP(-H14*2*3600)) -> #VALUE! | J14: =I14*EXP(-H14*10*3600) -> #VALUE! | K14: =E14 -> Li6 | L14: {=SUM(($J14*EXP(-$H14*24*3600*_xlfn.SEQUENCE(L$1-1))))+$J14} -> #VALUE! | M14: {=SUM(($J14*EXP(-$H14*24*3600*_xlfn.SEQUENCE(M$1-1))))+$J14} -> #VALUE!
B15: 3007 | C15: 0 | D15: 0 | E15: =VLOOKUP(B15,Nuclides!A:E,5,FALSE) -> Li7 | F15: =VLOOKUP(B15,Nuclides!A:E,4,FALSE) -> STABLE | G15: =IF(F15="STABLE", "STABLE", IF(F15<60, F15&"s", IF(F15<3600, ROUND(F15/60,2)&"min", IF(F15<86400, ROUND(F15/3600,2)&"h", IF(F15<31536000, ROUND(F15/86400,2)&"d", ROUND(F15/31536000,2)&"y"))))) -> STABLE | H15: =LN(2)/F15 -> #VALUE! | I15: =60*6240000000000*C15*(1-EXP(-H15*2*3600)) -> #VALUE! | J15: =I15*EXP(-H15*10*3600) -> #VALUE! | K15: =E15 -> Li7 | L15: {=SUM(($J15*EXP(-$H15*24*3600*_xlfn.SEQUENCE(L$1-1))))+$J15} -> #VALUE! | M15: {=SUM(($J15*EXP(-$H15*24*3600*_xlfn.SEQUENCE(M$1-1))))+$J15} -> #VALUE!
B16: 3008 | C16: 0 | D16: 0 | E16: =VLOOKUP(B16,Nuclides!A:E,5,FALSE) -> Li8 | F16: =VLOOKUP(B16,Nuclides!A:E,4,FALSE) -> 0.8399 | G16: =IF(F16="STABLE", "STABLE", IF(F16<60, F16&"s", IF(F16<3600, ROUND(F16/60,2)&"min", IF(F16<86400, ROUND(F16/3600,2)&"h", IF(F16<31536000, ROUND(F16/86400,2)&"d", ROUND(F16/31536000,2)&"y"))))) -> 0.8399s | H16: =LN(2)/F16 -> 0.82527346 | I16: =60*6240000000000*C16*(1-EXP(-H16*2*3600)) -> 0 | J16: =I16*EXP(-H16*10*3600) -> 0 | K16: =E16 -> Li8 | L16: {=SUM(($J16*EXP(-$H16*24*3600*_xlfn.SEQUENCE(L$1-1))))+$J16} -> 0 | M16: {=SUM(($J16*EXP(-$H16*24*3600*_xlfn.SEQUENCE(M$1-1))))+$J16} -> 0
B17: 3009 | C17: 0 | D17: 0 | E17: =VLOOKUP(B17,Nuclides!A:E,5,FALSE) -> Li9 | F17: =VLOOKUP(B17,Nuclides!A:E,4,FALSE) -> 0.1783 | G17: =IF(F17="STABLE", "STABLE", IF(F17<60, F17&"s", IF(F17<3600, ROUND(F17/60,2)&"min", IF(F17<86400, ROUND(F17/3600,2)&"h", IF(F17<31536000, ROUND(F17/86400,2)&"d", ROUND(F17/31536000,2)&"y"))))) -> 0.1783s | H17: =LN(2)/F17 -> 3.8875333 | I17: =60*6240000000000*C17*(1-EXP(-H17*2*3600)) -> 0 | J17: =I17*EXP(-H17*10*3600) -> 0 | K17: =E17 -> Li9 | L17: {=SUM(($J17*EXP(-$H17*24*3600*_xlfn.SEQUENCE(L$1-1))))+$J17} -> 0 | M17: {=SUM(($J17*EXP(-$H17*24*3600*_xlfn.SEQUENCE(M$1-1))))+$J17} -> 0
B18: 3010 | C18: 0 | D18: 0 | E18: =VLOOKUP(B18,Nuclides!A:E,5,FALSE) -> #N/A | F18: =VLOOKUP(B18,Nuclides!A:E,4,FALSE) -> #N/A | G18: =IF(F18="STABLE", "STABLE", IF(F18<60, F18&"s", IF(F18<3600, ROUND(F18/60,2)&"min", IF(F18<86400, ROUND(F18/3600,2)&"h", IF(F18<31536000, ROUND(F18/86400,2)&"d", ROUND(F18/31536000,2)&"y"))))) -> #N/A | H18: =LN(2)/F18 -> #N/A | I18: =60*6240000000000*C18*(1-EXP(-H18*2*3600)) -> #N/A | J18: =I18*EXP(-H18*10*3600) -> #N/A | K18: =E18 -> #N/A | L18: {=SUM(($J18*EXP(-$H18*24*3600*_xlfn.SEQUENCE(L$1-1))))+$J18} -> #N/A | M18: {=SUM(($J18*EXP(-$H18*24*3600*_xlfn.SEQUENCE(M$1-1))))+$J18} -> #N/A
... B44: 6013 | C44: 3.82532e-06 | D44: 0.0003 | E44: =VLOOKUP(B44,Nuclides!A:E,5,FALSE) -> C13 | F44: =VLOOKUP(B44,Nuclides!A:E,4,FALSE) -> STABLE | G44: =IF(F44="STABLE", "STABLE", IF(F44<60, F44&"s", IF(F44<3600, ROUND(F44/60,2)&"min", IF(F44<86400, ROUND(F44/3600,2)&"h", IF(F44<31536000, ROUND(F44/86400,2)&"d", ROUND(F44/31536000,2)&"y"))))) -> STABLE | H44: =LN(2)/F44 -> #VALUE! | I44: =60*6240000000000*C44*(1-EXP(-H44*2*3600)) -> #VALUE! | J44: =I44*EXP(-H44*10*3600) -> #VALUE! | K44: =E44 -> C13 | L44: {=SUM(($J44*EXP(-$H44*24*3600*_xlfn.SEQUENCE(L$1-1))))+$J44} -> #VALUE! | M44: {=SUM(($J44*EXP(-$H44*24*3600*_xlfn.SEQUENCE(M$1-1))))+$J44} -> #VALUE!
B45: 6014 | C45: 3.55487e-05 | D45: 0.0006 | E45: =VLOOKUP(B45,Nuclides!A:E,5,FALSE) -> C14 | F45: =VLOOKUP(B45,Nuclides!A:E,4,FALSE) -> 179878320000 | G45: =IF(F45="STABLE", "STABLE", IF(F45<60, F45&"s", IF(F45<3600, ROUND(F45/60,2)&"min", IF(F45<86400, ROUND(F45/3600,2)&"h", IF(F45<31536000, ROUND(F45/86400,2)&"d", ROUND(F45/31536000,2)&"y"))))) -> 5703.9y | H45: =LN(2)/F45 -> 3.8534226e-12 | I45: =60*6240000000000*C45*(1-EXP(-H45*2*3600)) -> 369.26546 | J45: =I45*EXP(-H45*10*3600) -> 369.26541 | K45: =E45 -> C14 | L45: {=SUM(($J45*EXP(-$H45*24*3600*_xlfn.SEQUENCE(L$1-1))))+$J45} -> 265839.28 | M45: {=SUM(($J45*EXP(-$H45*24*3600*_xlfn.SEQUENCE(M$1-1))))+$J45} -> 2655527.3 | O45: =K45 -> C14 | P45: =M45 -> 2655527.3 | Q45: =0 -> 0 | S45: =O45 -> C14 | T45: =G45 -> 5703.9y | U45: =P45 -> 2655527.3 | V45: 中
B46: 6015 | C46: 0 | D46: 0 | E46: =VLOOKUP(B46,Nuclides!A:E,5,FALSE) -> C15 | F46: =VLOOKUP(B46,Nuclides!A:E,4,FALSE) -> 2.449 | G46: =IF(F46="STABLE", "STABLE", IF(F46<60, F46&"s", IF(F46<3600, ROUND(F46/60,2)&"min", IF(F46<86400, ROUND(F46/3600,2)&"h", IF(F46<31536000, ROUND(F46/86400,2)&"d", ROUND(F46/31536000,2)&"y"))))) -> 2.449s | H46: =LN(2)/F46 -> 0.28303274 | I46: =60*6240000000000*C46*(1-EXP(-H46*2*3600)) -> 0 | J46: =I46*EXP(-H46*10*3600) -> 0 | K46: =E46 -> C15 | L46: {=SUM(($J46*EXP(-$H46*24*3600*_xlfn.SEQUENCE(L$1-1))))+$J46} -> 0 | M46: {=SUM(($J46*EXP(-$H46*24*3600*_xlfn.SEQUENCE(M$1-1))))+$J46} -> 0
B47: 6016 | C47: 0 | D47: 0 | E47: =VLOOKUP(B47,Nuclides!A:E,5,FALSE) -> C16 | F47: =VLOOKUP(B47,Nuclides!A:E,4,FALSE) -> 0.747 | G47: =IF(F47="STABLE", "STABLE", IF(F47<60, F47&"s", IF(F47<3600, ROUND(F47/60,2)&"min", IF(F47<86400, ROUND(F47/3600,2)&"h", IF(F47<31536000, ROUND(F47/86400,2)&"d", ROUND(F47/31536000,2)&"y"))))) -> 0.747s | H47: =LN(2)/F47 -> 0.92790787 | I47: =60*6240000000000*C47*(1-EXP(-H47*2*3600)) -> 0 | J47: =I47*EXP(-H47*10*3600) -> 0 | K47: =E47 -> C16 | L47: {=SUM(($J47*EXP(-$H47*24*3600*_xlfn.SEQUENCE(L$1-1))))+$J47} -> 0 | M47: {=SUM(($J47*EXP(-$H47*24*3600*_xlfn.SEQUENCE(M$1-1))))+$J47} -> 0
B48: 6017 | C48: 0 | D48: 0 | E48: =VLOOKUP(B48,Nuclides!A:E,5,FALSE) -> C17 | F48: =VLOOKUP(B48,Nuclides!A:E,4,FALSE) -> 0.191 | G48: =IF(F48="STABLE", "STABLE", IF(F48<60, F48&"s", IF(F48<3600, ROUND(F48/60,2)&"min", IF(F48<86400, ROUND(F48/3600,2)&"h", IF(F48<31536000, ROUND(F48/86400,2)&"d", ROUND(F48/31536000,2)&"y"))))) -> 0.191s | H48: =LN(2)/F48 -> 3.6290428 | I48: =60*6240000000000*C48*(1-EXP(-H48*2*3600)) -> 0 | J48: =I48*EXP(-H48*10*3600) -> 0 | K48: =E48 -> C17 | L48: {=SUM(($J48*EXP(-$H48*24*3600*_xlfn.SEQUENCE(L$1-1))))+$J48} -> 0 | M48: {=SUM(($J48*EXP(-$H48*24*3600*_xlfn.SEQUENCE(M$1-1))))+$J48} -> 0
B49: 6018 | C49: 0 | D49: 0 | E49: =VLOOKUP(B49,Nuclides!A:E,5,FALSE) -> C18 | F49: =VLOOKUP(B49,Nuclides!A:E,4,FALSE) -> 0.092 | G49: =IF(F49="STABLE", "STABLE", IF(F49<60, F49&"s", IF(F49<3600, ROUND(F49/60,2)&"min", IF(F49<86400, ROUND(F49/3600,2)&"h", IF(F49<31536000, ROUND(F49/86400,2)&"d", ROUND(F49/31536000,2)&"y"))))) -> 0.092s | H49: =LN(2)/F49 -> 7.5342085 | I49: =60*6240000000000*C49*(1-EXP(-H49*2*3600)) -> 0 | J49: =I49*EXP(-H49*10*3600) -> 0 | K49: =E49 -> C18 | L49: {=SUM(($J49*EXP(-$H49*24*3600*_xlfn.SEQUENCE(L$1-1))))+$J49} -> 0 | M49: {=SUM(($J49*EXP(-$H49*24*3600*_xlfn.SEQUENCE(M$1-1))))+$J49} -> 0
B50: 6019 | C50: 0 | D50: 0 | E50: =VLOOKUP(B50,Nuclides!A:E,5,FALSE) -> C19 | F50: =VLOOKUP(B50,Nuclides!A:E,4,FALSE) -> 0.0462 | G50: =IF(F50="STABLE", "STABLE", IF(F50<60, F50&"s", IF(F50<3600, ROUND(F50/60,2)&"min", IF(F50<86400, ROUND(F50/3600,2)&"h", IF(F50<31536000, ROUND(F50/86400,2)&"d", ROUND(F50/31536000,2)&"y"))))) -> 0.0462s | H50: =LN(2)/F50 -> 15.003186 | I50: =60*6240000000000*C50*(1-EXP(-H50*2*3600)) -> 0 | J50: =I50*EXP(-H50*10*3600) -> 0 | K50: =E50 -> C19 | L50: {=SUM(($J50*EXP(-$H50*24*3600*_xlfn.SEQUENCE(L$1-1))))+$J50} -> 0 | M50: {=SUM(($J50*EXP(-$H50*24*3600*_xlfn.SEQUENCE(M$1-1))))+$J50} -> 0
B51: 6020 | C51: 0 | D51: 0 | E51: =VLOOKUP(B51,Nuclides!A:E,5,FALSE) -> C20 | F51: =VLOOKUP(B51,Nuclides!A:E,4,FALSE) -> 0.0162 | G51: =IF(F51="STABLE", "STABLE", IF(F51<60, F51&"s", IF(F51<3600, ROUND(F51/60,2)&"min", IF(F51<86400, ROUND(F51/3600,2)&"h", IF(F51<31536000, ROUND(F51/86400,2)&"d", ROUND(F51/31536000,2)&"y"))))) -> 0.0162s | H51: =LN(2)/F51 -> 42.786863 | I51: =60*6240000000000*C51*(1-EXP(-H51*2*3600)) -> 0 | J51: =I51*EXP(-H51*10*3600) -> 0 | K51: =E51 -> C20 | L51: {=SUM(($J51*EXP(-$H51*24*3600*_xlfn.SEQUENCE(L$1-1))))+$J51} -> 0 | M51: {=SUM(($J51*EXP(-$H51*24*3600*_xlfn.SEQUENCE(M$1-1))))+$J51} -> 0
B52: 7011 | C52: 0 | D52: 0 | E52: =VLOOKUP(B52,Nuclides!A:E,5,FALSE) -> N11 | F52: =VLOOKUP(B52,Nuclides!A:E,4,FALSE) -> 5.4903614e-22 | G52: =IF(F52="STABLE", "STABLE", IF(F52<60, F52&"s", IF(F52<3600, ROUND(F52/60,2)&"min", IF(F52<86400, ROUND(F52/3600,2)&"h", IF(F52<31536000, ROUND(F52/86400,2)&"d", ROUND(F52/31536000,2)&"y"))))) -> 5.49036144578313E-22s | H52: =LN(2)/F52 -> 1.2624801e+21 | I52: =60*6240000000000*C52*(1-EXP(-H52*2*3600)) -> 0 | J52: =I52*EXP(-H52*10*3600) -> 0 | K52: =E52 -> N11 | L52: {=SUM(($J52*EXP(-$H52*24*3600*_xlfn.SEQUENCE(L$1-1))))+$J52} -> 0 | M52: {=SUM(($J52*EXP(-$H52*24*3600*_xlfn.SEQUENCE(M$1-1))))+$J52} -> 0
B53: 7012 | C53: 0 | D53: 0 | E53: =VLOOKUP(B53,Nuclides!A:E,5,FALSE) -> N12 | F53: =VLOOKUP(B53,Nuclides!A:E,4,FALSE) -> 0.011 | G53: =IF(F53="STABLE", "STABLE", IF(F53<60, F53&"s", IF(F53<3600, ROUND(F53/60,2)&"min", IF(F53<86400, ROUND(F53/3600,2)&"h", IF(F53<31536000, ROUND(F53/86400,2)&"d", ROUND(F53/31536000,2)&"y"))))) -> 0.011s | H53: =LN(2)/F53 -> 63.01338 | I53: =60*6240000000000*C53*(1-EXP(-H53*2*3600)) -> 0 | J53: =I53*EXP(-H53*10*3600) -> 0 | K53: =E53 -> N12 | L53: {=SUM(($J53*EXP(-$H53*24*3600*_xlfn.SEQUENCE(L$1-1))))+$J53} -> 0 | M53: {=SUM(($J53*EXP(-$H53*24*3600*_xlfn.SEQUENCE(M$1-1))))+$J53} -> 0
B54: 7013 | C54: 0 | D54: 0 | E54: =VLOOKUP(B54,Nuclides!A:E,5,FALSE) -> N13 | F54: =VLOOKUP(B54,Nuclides!A:E,4,FALSE) -> 597.9 | G54: =IF(F54="STABLE", "STABLE", IF(F54<60, F54&"s", IF(F54<3600, ROUND(F54/60,2)&"min", IF(F54<86400, ROUND(F54/3600,2)&"h", IF(F54<31536000, ROUND(F54/86400,2)&"d", ROUND(F54/31536000,2)&"y"))))) -> 9.97min | H54: =LN(2)/F54 -> 0.0011593029 | I54: =60*6240000000000*C54*(1-EXP(-H54*2*3600)) -> 0 | J54: =I54*EXP(-H54*10*3600) -> 0 | K54: =E54 -> N13 | L54: {=SUM(($J54*EXP(-$H54*24*3600*_xlfn.SEQUENCE(L$1-1))))+$J54} -> 0 | M54: {=SUM(($J54*EXP(-$H54*24*3600*_xlfn.SEQUENCE(M$1-1))))+$J54} -> 0
B55: 7014 | C55: 0 | D55: 0 | E55: =VLOOKUP(B55,Nuclides!A:E,5,FALSE) -> N14 | F55: =VLOOKUP(B55,Nuclides!A:E,4,FALSE) -> STABLE | G55: =IF(F55="STABLE", "STABLE", IF(F55<60, F55&"s", IF(F55<3600, ROUND(F55/60,2)&"min", IF(F55<86400, ROUND(F55/3600,2)&"h", IF(F55<31536000, ROUND(F55/86400,2)&"d", ROUND(F55/31536000,2)&"y"))))) -> STABLE | H55: =LN(2)/F55 -> #VALUE! | I55: =60*6240000000000*C55*(1-EXP(-H55*2*3600)) -> #VALUE! | J55: =I55*EXP(-H55*10*3600) -> #VALUE! | K55: =E55 -> N14 | L55: {=SUM(($J55*EXP(-$H55*24*3600*_xlfn.SEQUENCE(L$1-1))))+$J55} -> #VALUE! | M55: {=SUM(($J55*EXP(-$H55*24*3600*_xlfn.SEQUENCE(M$1-1))))+$J55} -> #VALUE!
B56: 7015 | C56: 0 | D56: 0 | E56: =VLOOKUP(B56,Nuclides!A:E,5,FALSE) -> N15 | F56: =VLOOKUP(B56,Nuclides!A:E,4,FALSE) -> STABLE | G56: =IF(F56="STABLE", "STABLE", IF(F56<60, F56&"s", IF(F56<3600, ROUND(F56/60,2)&"min", IF(F56<86400, ROUND(F56/3600,2)&"h", IF(F56<31536000, ROUND(F56/86400,2)&"d", ROUND(F56/31536000,2)&"y"))))) -> STABLE | H56: =LN(2)/F56 -> #VALUE! | I56: =60*6240000000000*C56*(1-EXP(-H56*2*3600)) -> #VALUE! | J56: =I56*EXP(-H56*10*3600) -> #VALUE! | K56: =E56 -> N15 | L56: {=SUM(($J56*EXP(-$H56*24*3600*_xlfn.SEQUENCE(L$1-1))))+$J56} -> #VALUE! | M56: {=SUM(($J56*EXP(-$H56*24*3600*_xlfn.SEQUENCE(M$1-1))))+$J56} -> #VALUE!
B57: 7016 | C57: 0 | D57: 0 | E57: =VLOOKUP(B57,Nuclides!A:E,5,FALSE) -> N16 | F57: =VLOOKUP(B57,Nuclides!A:E,4,FALSE) -> 7.13 | G57: =IF(F57="STABLE", "STABLE", IF(F57<60, F57&"s", IF(F57<3600, ROUND(F57/60,2)&"min", IF(F57<86400, ROUND(F57/3600,2)&"h", IF(F57<31536000, ROUND(F57/86400,2)&"d", ROUND(F57/31536000,2)&"y"))))) -> 7.13s | H57: =LN(2)/F57 -> 0.097215593 | I57: =60*6240000000000*C57*(1-EXP(-H57*2*3600)) -> 0 | J57: =I57*EXP(-H57*10*3600) -> 0 | K57: =E57 -> N16 | L57: {=SUM(($J57*EXP(-$H57*24*3600*_xlfn.SEQUENCE(L$1-1))))+$J57} -> 0 | M57: {=SUM(($J57*EXP(-$H57*24*3600*_xlfn.SEQUENCE(M$1-1))))+$J57} -> 0
... B106: 11023 | C106: 0 | D106: 0 | E106: =VLOOKUP(B106,Nuclides!A:E,5,FALSE) -> Na23 | F106: =VLOOKUP(B106,Nuclides!A:E,4,FALSE) -> STABLE | G106: =IF(F106="STABLE", "STABLE", IF(F106<60, F106&"s", IF(F106<3600, ROUND(F106/60,2)&"min", IF(F106<86400, ROUND(F106/3600,2)&"h", IF(F106<31536000, ROUND(F106/86400,2)&"d", ROUND(F106/31536000,2)&"y"))))) -> STABLE | H106: =LN(2)/F106 -> #VALUE! | I106: =60*6240000000000*C106*(1-EXP(-H106*2*3600)) -> #VALUE! | J106: =I106*EXP(-H106*10*3600) -> #VALUE! | K106: =E106 -> Na23 | L106: {=SUM(($J106*EXP(-$H106*24*3600*_xlfn.SEQUENCE(L$1-1))))+$J106} -> #VALUE! | M106: {=SUM(($J106*EXP(-$H106*24*3600*_xlfn.SEQUENCE(M$1-1))))+$J106} -> #VALUE!
B107: 11024 | C107: 0.0042841 | D107: 0.0001 | E107: =VLOOKUP(B107,Nuclides!A:E,5,FALSE) -> Na24 | F107: =VLOOKUP(B107,Nuclides!A:E,4,FALSE) -> 53989.2 | G107: =IF(F107="STABLE", "STABLE", IF(F107<60, F107&"s", IF(F107<3600, ROUND(F107/60,2)&"min", IF(F107<86400, ROUND(F107/3600,2)&"h", IF(F107<31536000, ROUND(F107/86400,2)&"d", ROUND(F107/31536000,2)&"y"))))) -> 15h | H107: =LN(2)/F107 -> 1.2838627e-05 | I107: =60*6240000000000*C107*(1-EXP(-H107*2*3600)) -> 1.4162125e+11 | J107: =I107*EXP(-H107*10*3600) -> 8.9207553e+10 | K107: =E107 -> Na24 | L107: {=SUM(($J107*EXP(-$H107*24*3600*_xlfn.SEQUENCE(L$1-1))))+$J107} -> 1.3310662e+11 | M107: {=SUM(($J107*EXP(-$H107*24*3600*_xlfn.SEQUENCE(M$1-1))))+$J107} -> 1.3310662e+11 | O107: =K107 -> Na24 | P107: =M107 -> 1.3310662e+11 | Q107: =0 -> 0 | S107: =O107 -> Na24 | T107: =G107 -> 15h | U107: =P107 -> 1.3310662e+11 | V107: 中
B108: 11025 | C108: 0 | D108: 0 | E108: =VLOOKUP(B108,Nuclides!A:E,5,FALSE) -> Na25 | F108: =VLOOKUP(B108,Nuclides!A:E,4,FALSE) -> 59.1 | G108: =IF(F108="STABLE", "STABLE", IF(F108<60, F108&"s", IF(F108<3600, ROUND(F108/60,2)&"min", IF(F108<86400, ROUND(F108/3600,2)&"h", IF(F108<31536000, ROUND(F108/86400,2)&"d", ROUND(F108/31536000,2)&"y"))))) -> 59.1s | H108: =LN(2)/F108 -> 0.011728379 | I108: =60*6240000000000*C108*(1-EXP(-H108*2*3600)) -> 0 | J108: =I108*EXP(-H108*10*3600) -> 0 | K108: =E108 -> Na25 | L108: {=SUM(($J108*EXP(-$H108*24*3600*_xlfn.SEQUENCE(L$1-1))))+$J108} -> 0 | M108: {=SUM(($J108*EXP(-$H108*24*3600*_xlfn.SEQUENCE(M$1-1))))+$J108} -> 0
B109: 11026 | C109: 0 | D109: 0 | E109: =VLOOKUP(B109,Nuclides!A:E,5,FALSE) -> Na26 | F109: =VLOOKUP(B109,Nuclides!A:E,4,FALSE) -> 1.07128 | G109: =IF(F109="STABLE", "STABLE", IF(F109<60, F109&"s", IF(F109<3600, ROUND(F109/60,2)&"min", IF(F109<86400, ROUND(F109/3600,2)&"h", IF(F109<31536000, ROUND(F109/86400,2)&"d", ROUND(F109/31536000,2)&"y"))))) -> 1.07128s | H109: =LN(2)/F109 -> 0.64702709 | I109: =60*6240000000000*C109*(1-EXP(-H109*2*3600)) -> 0 | J109: =I109*EXP(-H109*10*3600) -> 0 | K109: =E109 -> Na26 | L109: {=SUM(($J109*EXP(-$H109*24*3600*_xlfn.SEQUENCE(L$1-1))))+$J109} -> 0 | M109: {=SUM(($J109*EXP(-$H109*24*3600*_xlfn.SEQUENCE(M$1-1))))+$J109} -> 0
B110: 11027 | C110: 0 | D110: 0 | E110: =VLOOKUP(B110,Nuclides!A:E,5,FALSE) -> Na27 | F110: =VLOOKUP(B110,Nuclides!A:E,4,FALSE) -> 0.301 | G110: =IF(F110="STABLE", "STABLE", IF(F110<60, F110&"s", IF(F110<3600, ROUND(F110/60,2)&"min", IF(F110<86400, ROUND(F110/3600,2)&"h", IF(F110<31536000, ROUND(F110/86400,2)&"d", ROUND(F110/31536000,2)&"y"))))) -> 0.301s | H110: =LN(2)/F110 -> 2.3028146 | I110: =60*6240000000000*C110*(1-EXP(-H110*2*3600)) -> 0 | J110: =I110*EXP(-H110*10*3600) -> 0 | K110: =E110 -> Na27 | L110: {=SUM(($J110*EXP(-$H110*24*3600*_xlfn.SEQUENCE(L$1-1))))+$J110} -> 0 | M110: {=SUM(($J110*EXP(-$H110*24*3600*_xlfn.SEQUENCE(M$1-1))))+$J110} -> 0
B111: 11028 | C111: 0 | D111: 0 | E111: =VLOOKUP(B111,Nuclides!A:E,5,FALSE) -> Na28 | F111: =VLOOKUP(B111,Nuclides!A:E,4,FALSE) -> 0.0305 | G111: =IF(F111="STABLE", "STABLE", IF(F111<60, F111&"s", IF(F111<3600, ROUND(F111/60,2)&"min", IF(F111<86400, ROUND(F111/3600,2)&"h", IF(F111<31536000, ROUND(F111/86400,2)&"d", ROUND(F111/31536000,2)&"y"))))) -> 0.0305s | H111: =LN(2)/F111 -> 22.726137 | I111: =60*6240000000000*C111*(1-EXP(-H111*2*3600)) -> 0 | J111: =I111*EXP(-H111*10*3600) -> 0 | K111: =E111 -> Na28 | L111: {=SUM(($J111*EXP(-$H111*24*3600*_xlfn.SEQUENCE(L$1-1))))+$J111} -> 0 | M111: {=SUM(($J111*EXP(-$H111*24*3600*_xlfn.SEQUENCE(M$1-1))))+$J111} -> 0
B112: 11029 | C112: 0 | D112: 0 | E112: =VLOOKUP(B112,Nuclides!A:E,5,FALSE) -> Na29 | F112: =VLOOKUP(B112,Nuclides!A:E,4,FALSE) -> 0.0441 | G112: =IF(F112="STABLE", "STABLE", IF(F112<60, F112&"s", IF(F112<3600, ROUND(F112/60,2)&"min", IF(F112<86400, ROUND(F112/3600,2)&"h", IF(F112<31536000, ROUND(F112/86400,2)&"d", ROUND(F112/31536000,2)&"y"))))) -> 0.0441s | H112: =LN(2)/F112 -> 15.717623 | I112: =60*6240000000000*C112*(1-EXP(-H112*2*3600)) -> 0 | J112: =I112*EXP(-H112*10*3600) -> 0 | K112: =E112 -> Na29 | L112: {=SUM(($J112*EXP(-$H112*24*3600*_xlfn.SEQUENCE(L$1-1))))+$J112} -> 0 | M112: {=SUM(($J112*EXP(-$H112*24*3600*_xlfn.SEQUENCE(M$1-1))))+$J112} -> 0
B113: 11030 | C113: 0 | D113: 0 | E113: =VLOOKUP(B113,Nuclides!A:E,5,FALSE) -> Na30 | F113: =VLOOKUP(B113,Nuclides!A:E,4,FALSE) -> 0.048 | G113: =IF(F113="STABLE", "STABLE", IF(F113<60, F113&"s", IF(F113<3600, ROUND(F113/60,2)&"min", IF(F113<86400, ROUND(F113/3600,2)&"h", IF(F113<31536000, ROUND(F113/86400,2)&"d", ROUND(F113/31536000,2)&"y"))))) -> 0.048s | H113: =LN(2)/F113 -> 14.440566 | I113: =60*6240000000000*C113*(1-EXP(-H113*2*3600)) -> 0 | J113: =I113*EXP(-H113*10*3600) -> 0 | K113: =E113 -> Na30 | L113: {=SUM(($J113*EXP(-$H113*24*3600*_xlfn.SEQUENCE(L$1-1))))+$J113} -> 0 | M113: {=SUM(($J113*EXP(-$H113*24*3600*_xlfn.SEQUENCE(M$1-1))))+$J113} -> 0
B114: 11031 | C114: 0 | D114: 0 | E114: =VLOOKUP(B114,Nuclides!A:E,5,FALSE) -> Na31 | F114: =VLOOKUP(B114,Nuclides!A:E,4,FALSE) -> 0.0174 | G114: =IF(F114="STABLE", "STABLE", IF(F114<60, F114&"s", IF(F114<3600, ROUND(F114/60,2)&"min", IF(F114<86400, ROUND(F114/3600,2)&"h", IF(F114<31536000, ROUND(F114/86400,2)&"d", ROUND(F114/31536000,2)&"y"))))) -> 0.0174s | H114: =LN(2)/F114 -> 39.836045 | I114: =60*6240000000000*C114*(1-EXP(-H114*2*3600)) -> 0 | J114: =I114*EXP(-H114*10*3600) -> 0 | K114: =E114 -> Na31 | L114: {=SUM(($J114*EXP(-$H114*24*3600*_xlfn.SEQUENCE(L$1-1))))+$J114} -> 0 | M114: {=SUM(($J114*EXP(-$H114*24*3600*_xlfn.SEQUENCE(M$1-1))))+$J114} -> 0
B115: 11032 | C115: 0 | D115: 0 | E115: =VLOOKUP(B115,Nuclides!A:E,5,FALSE) -> Na32 | F115: =VLOOKUP(B115,Nuclides!A:E,4,FALSE) -> 0.0132 | G115: =IF(F115="STABLE", "STABLE", IF(F115<60, F115&"s", IF(F115<3600, ROUND(F115/60,2)&"min", IF(F115<86400, ROUND(F115/3600,2)&"h", IF(F115<31536000, ROUND(F115/86400,2)&"d", ROUND(F115/31536000,2)&"y"))))) -> 0.0132s | H115: =LN(2)/F115 -> 52.51115 | I115: =60*6240000000000*C115*(1-EXP(-H115*2*3600)) -> 0 | J115: =I115*EXP(-H115*10*3600) -> 0 | K115: =E115 -> Na32 | L115: {=SUM(($J115*EXP(-$H115*24*3600*_xlfn.SEQUENCE(L$1-1))))+$J115} -> 0 | M115: {=SUM(($J115*EXP(-$H115*24*3600*_xlfn.SEQUENCE(M$1-1))))+$J115} -> 0
...

Sheet 1
B3: 1001 | C3: 0 | F3: 1001 | G3: 4.31085e-10 | I3: C1 | J3: 63569 | K3: 11164 | L3: 500540 | M3: 0.02 | N3: 25
B4: 1002 | C4: 0 | F4: 1002 | G4: 0.18213552 | I4: C2 | J4: 4826 | K4: 6736.7 | L4: 38000 | M4: 0.02 | N4: 25
B5: 1003 | C5: 0 | F5: 1003 | G5: 3.1964756e-08 | I5: C3 | J5: 1238.4 | K5: 1095.9 | L5: 9750.8 | M5: 0.02 | N5: 25
B6: 2003 | C6: 0 | F6: 2003 | G6: 0 | I6: C4 | J6: 1237.9 | K6: 1096 | L6: 9747.4 | M6: 0.02 | N6: 25
B7: 2004 | C7: 0 | F7: 2004 | G7: 0 | I7: C5 | J7: 1237.3 | K7: 1095.8 | L7: 9742.6 | M7: 0.02 | N7: 25
B8: 2005 | C8: 0 | F8: 2005 | G8: 0 | I8: C6 | J8: 1237.6 | K8: 1095.5 | L8: 9744.7 | M8: 0.02 | N8: 25
B9: 2006 | C9: 0 | F9: 2006 | G9: 0 | I9: C7 | J9: 110.61 | K9: 155.85 | L9: 870.91 | M9: 0.02 | N9: 25
B10: 2007 | C10: 0 | F10: 2007 | G10: 0 | I10: C8 | J10: 31296 | K10: 11407 | L10: 125190 | M10: 0.02 | N10: 25
B11: 2008 | C11: 0 | F11: 2008 | G11: 0 | I11: C9 | J11: 2470.9 | K11: 1156.9 | L11: 0 | M11: 0.02 | N11: 25
B12: 3005 | C12: 0 | F12: 3005 | G12: 0 | I12: C10 | J12: 41783 | K12: 44555 | L12: 0 | M12: 0.02 | N12: 25
B13: 3006 | C13: 0 | F13: 3006 | G13: 0 | I13: C11 | J13: 304210 | K13: 42346 | L13: 2395400 | M13: 0.02 | N13: 25
B14: 3007 | C14: 0 | F14: 3007 | G14: 0 | I14: C12 | J14: 2471.3 | K14: 1156.8 | L14: 0 | M14: 0.02 | N14: 25
... B39: 6009 | C39: 0 | F39: 6009 | G39: 0 | I39: C47 | J39: 2203900000 | K39: 0 | L39: 0 | M39: 0.02 | N39: 25
B40: 6010 | C40: 0 | F40: 6010 | G40: 0
B41: 6011 | C41: 0 | F41: 6011 | G41: 0
B42: 6012 | C42: 0 | F42: 6012 | G42: 0
B43: 6013 | C43: 0 | F43: 6013 | G43: 0.0010478212
B44: 6014 | C44: 0 | F44: 6014 | G44: 1.1653046e-05
B45: 6015 | C45: 0 | F45: 6015 | G45: 0
B46: 6016 | C46: 0 | F46: 6016 | G46: 0
B47: 6017 | C47: 0 | F47: 6017 | G47: 0
B48: 6018 | C48: 0 | F48: 6018 | G48: 0
B49: 6019 | C49: 0 | F49: 6019 | G49: 0
B50: 6020 | C50: 0 | F50: 6020 | G50: 0
B51: 7011 | C51: 0 | F51: 7011 | G51: 0
... B2192: 100240 | C2192: 0 | F2192: 100260 | G2192: 0
B2193: 100240 | C2193: 0 | F2193: total | G2193: 0.36442526
B2194: 100250 | C2194: 0 | F2194: l 2
B2195: 100250 | C2195: 0 | F2195: user bin
B2196: 100250 | C2196: 0 | F2196: l 3
B2197: 100250 | C2197: 0 | F2197: l 4
B2198: 100250 | C2198: 0 | F2198: l 5
B2199: 100250 | C2199: 0 | F2199: l 6
B2200: 100250 | C2200: 0 | F2200: l 7
B2201: 100250 | C2201: 0 | F2201: l 8
B2202: 100250 | C2202: 0 | F2202: l 11
B2203: 100260 | C2203: 0 | F2203: l 13
B2204: 100260 | C2204: 0 | F2204: l 14
B2205: 100260 | C2205: 0 | F2205: l 21
... B2207: 100260 | C2207: 0 | F2207: l 23
...

Sheet 加速器
B1: Nuclides | C1: w | D1: Error | E1: Nuclides | F1: T1/2 | G1: T1/2 | H1: λ | I1: 60μA-2h | J1: cool-6h | K1: Nuclides | L1: 720 | M1: 7200
B4: 1001 | C4: 4.31085e-10 | D4: =0 -> 0 | E4: =VLOOKUP(B4,Nuclides!A:E,5,FALSE) -> 0 | F4: =VLOOKUP(B4,Nuclides!A:E,4,FALSE) -> 613.9 | G4: =IF(F4="STABLE", "STABLE", IF(F4<60, F4&"s", IF(F4<3600, ROUND(F4/60,2)&"min", IF(F4<86400, ROUND(F4/3600,2)&"h", IF(F4<31536000, ROUND(F4/86400,2)&"d", ROUND(F4/31536000,2)&"y"))))) -> 10.23min | H4: =LN(2)/F4 -> 0.0011290881 | I4: =60*6240000000000*C4*(1-EXP(-H4*2*3600)) -> 161350.65 | J4: =I4*EXP(-H4*10*3600) -> 3.5886285e-13 | K4: =E4 -> 0 | L4: {=SUM(($J4*EXP(-$H4*24*3600*_xlfn.SEQUENCE(L$1-1))))+$J4} -> 3.5886285e-13 | M4: {=SUM(($J4*EXP(-$H4*24*3600*_xlfn.SEQUENCE(M$1-1))))+$J4} -> 3.5886285e-13
B5: 1002 | C5: 0.18213552 | D5: =0 -> 0 | E5: =VLOOKUP(B5,Nuclides!A:E,5,FALSE) -> H2 | F5: =VLOOKUP(B5,Nuclides!A:E,4,FALSE) -> STABLE | G5: =IF(F5="STABLE", "STABLE", IF(F5<60, F5&"s", IF(F5<3600, ROUND(F5/60,2)&"min", IF(F5<86400, ROUND(F5/3600,2)&"h", IF(F5<31536000, ROUND(F5/86400,2)&"d", ROUND(F5/31536000,2)&"y"))))) -> STABLE | H5: =LN(2)/F5 -> #VALUE! | I5: =60*6240000000000*C5*(1-EXP(-H5*2*3600)) -> #VALUE! | J5: =I5*EXP(-H5*10*3600) -> #VALUE! | K5: =E5 -> H2 | L5: {=SUM(($J5*EXP(-$H5*24*3600*_xlfn.SEQUENCE(L$1-1))))+$J5} -> #VALUE! | M5: {=SUM(($J5*EXP(-$H5*24*3600*_xlfn.SEQUENCE(M$1-1))))+$J5} -> #VALUE!
B6: 1003 | C6: 3.1964756e-08 | D6: =0 -> 0 | E6: =VLOOKUP(B6,Nuclides!A:E,5,FALSE) -> H3 | F6: =VLOOKUP(B6,Nuclides!A:E,4,FALSE) -> 388789632 | G6: =IF(F6="STABLE", "STABLE", IF(F6<60, F6&"s", IF(F6<3600, ROUND(F6/60,2)&"min", IF(F6<86400, ROUND(F6/3600,2)&"h", IF(F6<31536000, ROUND(F6/86400,2)&"d", ROUND(F6/31536000,2)&"y"))))) -> 12.33y | H6: =LN(2)/F6 -> 1.7828335e-09 | I6: =60*6240000000000*C6*(1-EXP(-H6*2*3600)) -> 153.61999 | J6: =I6*EXP(-H6*10*3600) -> 153.61013 | K6: =E6 -> H3 | L6: {=SUM(($J6*EXP(-$H6*24*3600*_xlfn.SEQUENCE(L$1-1))))+$J6} -> 104694.85 | M6: {=SUM(($J6*EXP(-$H6*24*3600*_xlfn.SEQUENCE(M$1-1))))+$J6} -> 668327.97 | O6: =K6 -> H3 | P6: =M6 -> 668327.97 | Q6: =0 -> 0 | S6: =O6 -> H3 | T6: =G6 -> 12.33y | U6: =P6 -> 668327.97 | V6: 低
B7: 2003 | C7: 0 | D7: =0 -> 0 | E7: =VLOOKUP(B7,Nuclides!A:E,5,FALSE) -> He3 | F7: =VLOOKUP(B7,Nuclides!A:E,4,FALSE) -> STABLE | G7: =IF(F7="STABLE", "STABLE", IF(F7<60, F7&"s", IF(F7<3600, ROUND(F7/60,2)&"min", IF(F7<86400, ROUND(F7/3600,2)&"h", IF(F7<31536000, ROUND(F7/86400,2)&"d", ROUND(F7/31536000,2)&"y"))))) -> STABLE | H7: =LN(2)/F7 -> #VALUE! | I7: =60*6240000000000*C7*(1-EXP(-H7*2*3600)) -> #VALUE! | J7: =I7*EXP(-H7*10*3600) -> #VALUE! | K7: =E7 -> He3 | L7: {=SUM(($J7*EXP(-$H7*24*3600*_xlfn.SEQUENCE(L$1-1))))+$J7} -> #VALUE! | M7: {=SUM(($J7*EXP(-$H7*24*3600*_xlfn.SEQUENCE(M$1-1))))+$J7} -> #VALUE!
B8: 2004 | C8: 0 | D8: =0 -> 0 | E8: =VLOOKUP(B8,Nuclides!A:E,5,FALSE) -> He4 | F8: =VLOOKUP(B8,Nuclides!A:E,4,FALSE) -> STABLE | G8: =IF(F8="STABLE", "STABLE", IF(F8<60, F8&"s", IF(F8<3600, ROUND(F8/60,2)&"min", IF(F8<86400, ROUND(F8/3600,2)&"h", IF(F8<31536000, ROUND(F8/86400,2)&"d", ROUND(F8/31536000,2)&"y"))))) -> STABLE | H8: =LN(2)/F8 -> #VALUE! | I8: =60*6240000000000*C8*(1-EXP(-H8*2*3600)) -> #VALUE! | J8: =I8*EXP(-H8*10*3600) -> #VALUE! | K8: =E8 -> He4 | L8: {=SUM(($J8*EXP(-$H8*24*3600*_xlfn.SEQUENCE(L$1-1))))+$J8} -> #VALUE! | M8: {=SUM(($J8*EXP(-$H8*24*3600*_xlfn.SEQUENCE(M$1-1))))+$J8} -> #VALUE!
B9: 2005 | C9: 0 | D9: =0 -> 0 | E9: =VLOOKUP(B9,Nuclides!A:E,5,FALSE) -> He5 | F9: =VLOOKUP(B9,Nuclides!A:E,4,FALSE) -> 7.595e-22 | G9: =IF(F9="STABLE", "STABLE", IF(F9<60, F9&"s", IF(F9<3600, ROUND(F9/60,2)&"min", IF(F9<86400, ROUND(F9/3600,2)&"h", IF(F9<31536000, ROUND(F9/86400,2)&"d", ROUND(F9/31536000,2)&"y"))))) -> 7.595E-22s | H9: =LN(2)/F9 -> 9.1263618e+20 | I9: =60*6240000000000*C9*(1-EXP(-H9*2*3600)) -> 0 | J9: =I9*EXP(-H9*10*3600) -> 0 | K9: =E9 -> He5 | L9: {=SUM(($J9*EXP(-$H9*24*3600*_xlfn.SEQUENCE(L$1-1))))+$J9} -> 0 | M9: {=SUM(($J9*EXP(-$H9*24*3600*_xlfn.SEQUENCE(M$1-1))))+$J9} -> 0
B10: 2006 | C10: 0 | D10: =0 -> 0 | E10: =VLOOKUP(B10,Nuclides!A:E,5,FALSE) -> He6 | F10: =VLOOKUP(B10,Nuclides!A:E,4,FALSE) -> 0.8067 | G10: =IF(F10="STABLE", "STABLE", IF(F10<60, F10&"s", IF(F10<3600, ROUND(F10/60,2)&"min", IF(F10<86400, ROUND(F10/3600,2)&"h", IF(F10<31536000, ROUND(F10/86400,2)&"d", ROUND(F10/31536000,2)&"y"))))) -> 0.8067s | H10: =LN(2)/F10 -> 0.85923786 | I10: =60*6240000000000*C10*(1-EXP(-H10*2*3600)) -> 0 | J10: =I10*EXP(-H10*10*3600) -> 0 | K10: =E10 -> He6 | L10: {=SUM(($J10*EXP(-$H10*24*3600*_xlfn.SEQUENCE(L$1-1))))+$J10} -> 0 | M10: {=SUM(($J10*EXP(-$H10*24*3600*_xlfn.SEQUENCE(M$1-1))))+$J10} -> 0
B11: 2007 | C11: 0 | D11: =0 -> 0 | E11: =VLOOKUP(B11,Nuclides!A:E,5,FALSE) -> He7 | F11: =VLOOKUP(B11,Nuclides!A:E,4,FALSE) -> 3.038e-21 | G11: =IF(F11="STABLE", "STABLE", IF(F11<60, F11&"s", IF(F11<3600, ROUND(F11/60,2)&"min", IF(F11<86400, ROUND(F11/3600,2)&"h", IF(F11<31536000, ROUND(F11/86400,2)&"d", ROUND(F11/31536000,2)&"y"))))) -> 3.038E-21s | H11: =LN(2)/F11 -> 2.2815905e+20 | I11: =60*6240000000000*C11*(1-EXP(-H11*2*3600)) -> 0 | J11: =I11*EXP(-H11*10*3600) -> 0 | K11: =E11 -> He7 | L11: {=SUM(($J11*EXP(-$H11*24*3600*_xlfn.SEQUENCE(L$1-1))))+$J11} -> 0 | M11: {=SUM(($J11*EXP(-$H11*24*3600*_xlfn.SEQUENCE(M$1-1))))+$J11} -> 0
B12: 2008 | C12: 0 | D12: =0 -> 0 | E12: =VLOOKUP(B12,Nuclides!A:E,5,FALSE) -> He8 | F12: =VLOOKUP(B12,Nuclides!A:E,4,FALSE) -> 0.1191 | G12: =IF(F12="STABLE", "STABLE", IF(F12<60, F12&"s", IF(F12<3600, ROUND(F12/60,2)&"min", IF(F12<86400, ROUND(F12/3600,2)&"h", IF(F12<31536000, ROUND(F12/86400,2)&"d", ROUND(F12/31536000,2)&"y"))))) -> 0.1191s | H12: =LN(2)/F12 -> 5.8198756 | I12: =60*6240000000000*C12*(1-EXP(-H12*2*3600)) -> 0 | J12: =I12*EXP(-H12*10*3600) -> 0 | K12: =E12 -> He8 | L12: {=SUM(($J12*EXP(-$H12*24*3600*_xlfn.SEQUENCE(L$1-1))))+$J12} -> 0 | M12: {=SUM(($J12*EXP(-$H12*24*3600*_xlfn.SEQUENCE(M$1-1))))+$J12} -> 0
B13: 3005 | C13: 0 | D13: =0 -> 0 | E13: =VLOOKUP(B13,Nuclides!A:E,5,FALSE) -> Li5 | F13: =VLOOKUP(B13,Nuclides!A:E,4,FALSE) -> 3.038e-22 | G13: =IF(F13="STABLE", "STABLE", IF(F13<60, F13&"s", IF(F13<3600, ROUND(F13/60,2)&"min", IF(F13<86400, ROUND(F13/3600,2)&"h", IF(F13<31536000, ROUND(F13/86400,2)&"d", ROUND(F13/31536000,2)&"y"))))) -> 3.038E-22s | H13: =LN(2)/F13 -> 2.2815905e+21 | I13: =60*6240000000000*C13*(1-EXP(-H13*2*3600)) -> 0 | J13: =I13*EXP(-H13*10*3600) -> 0 | K13: =E13 -> Li5 | L13: {=SUM(($J13*EXP(-$H13*24*3600*_xlfn.SEQUENCE(L$1-1))))+$J13} -> 0 | M13: {=SUM(($J13*EXP(-$H13*24*3600*_xlfn.SEQUENCE(M$1-1))))+$J13} -> 0
B14: 3006 | C14: 0 | D14: =0 -> 0 | E14: =VLOOKUP(B14,Nuclides!A:E,5,FALSE) -> Li6 | F14: =VLOOKUP(B14,Nuclides!A:E,4,FALSE) -> STABLE | G14: =IF(F14="STABLE", "STABLE", IF(F14<60, F14&"s", IF(F14<3600, ROUND(F14/60,2)&"min", IF(F14<86400, ROUND(F14/3600,2)&"h", IF(F14<31536000, ROUND(F14/86400,2)&"d", ROUND(F14/31536000,2)&"y"))))) -> STABLE | H14: =LN(2)/F14 -> #VALUE! | I14: =60*6240000000000*C14*(1-EXP(-H14*2*3600)) -> #VALUE! | J14: =I14*EXP(-H14*10*3600) -> #VALUE! | K14: =E14 -> Li6 | L14: {=SUM(($J14*EXP(-$H14*24*3600*_xlfn.SEQUENCE(L$1-1))))+$J14} -> #VALUE! | M14: {=SUM(($J14*EXP(-$H14*24*3600*_xlfn.SEQUENCE(M$1-1))))+$J14} -> #VALUE!
B15: 3007 | C15: 0 | D15: =0 -> 0 | E15: =VLOOKUP(B15,Nuclides!A:E,5,FALSE) -> Li7 | F15: =VLOOKUP(B15,Nuclides!A:E,4,FALSE) -> STABLE | G15: =IF(F15="STABLE", "STABLE", IF(F15<60, F15&"s", IF(F15<3600, ROUND(F15/60,2)&"min", IF(F15<86400, ROUND(F15/3600,2)&"h", IF(F15<31536000, ROUND(F15/86400,2)&"d", ROUND(F15/31536000,2)&"y"))))) -> STABLE | H15: =LN(2)/F15 -> #VALUE! | I15: =60*6240000000000*C15*(1-EXP(-H15*2*3600)) -> #VALUE! | J15: =I15*EXP(-H15*10*3600) -> #VALUE! | K15: =E15 -> Li7 | L15: {=SUM(($J15*EXP(-$H15*24*3600*_xlfn.SEQUENCE(L$1-1))))+$J15} -> #VALUE! | M15: {=SUM(($J15*EXP(-$H15*24*3600*_xlfn.SEQUENCE(M$1-1))))+$J15} -> #VALUE!
B16: 3008 | C16: 0 | D16: =0 -> 0 | E16: =VLOOKUP(B16,Nuclides!A:E,5,FALSE) -> Li8 | F16: =VLOOKUP(B16,Nuclides!A:E,4,FALSE) -> 0.8399 | G16: =IF(F16="STABLE", "STABLE", IF(F16<60, F16&"s", IF(F16<3600, ROUND(F16/60,2)&"min", IF(F16<86400, ROUND(F16/3600,2)&"h", IF(F16<31536000, ROUND(F16/86400,2)&"d", ROUND(F16/31536000,2)&"y"))))) -> 0.8399s | H16: =LN(2)/F16 -> 0.82527346 | I16: =60*6240000000000*C16*(1-EXP(-H16*2*3600)) -> 0 | J16: =I16*EXP(-H16*10*3600) -> 0 | K16: =E16 -> Li8 | L16: {=SUM(($J16*EXP(-$H16*24*3600*_xlfn.SEQUENCE(L$1-1))))+$J16} -> 0 | M16: {=SUM(($J16*EXP(-$H16*24*3600*_xlfn.SEQUENCE(M$1-1))))+$J16} -> 0
B17: 3009 | C17: 0 | D17: =0 -> 0 | E17: =VLOOKUP(B17,Nuclides!A:E,5,FALSE) -> Li9 | F17: =VLOOKUP(B17,Nuclides!A:E,4,FALSE) -> 0.1783 | G17: =IF(F17="STABLE", "STABLE", IF(F17<60, F17&"s", IF(F17<3600, ROUND(F17/60,2)&"min", IF(F17<86400, ROUND(F17/3600,2)&"h", IF(F17<31536000, ROUND(F17/86400,2)&"d", ROUND(F17/31536000,2)&"y"))))) -> 0.1783s | H17: =LN(2)/F17 -> 3.8875333 | I17: =60*6240000000000*C17*(1-EXP(-H17*2*3600)) -> 0 | J17: =I17*EXP(-H17*10*3600) -> 0 | K17: =E17 -> Li9 | L17: {=SUM(($J17*EXP(-$H17*24*3600*_xlfn.SEQUENCE(L$1-1))))+$J17} -> 0 | M17: {=SUM(($J17*EXP(-$H17*24*3600*_xlfn.SEQUENCE(M$1-1))))+$J17} -> 0
B18: 3010 | C18: 0 | D18: =0 -> 0 | E18: =VLOOKUP(B18,Nuclides!A:E,5,FALSE) -> #N/A | F18: =VLOOKUP(B18,Nuclides!A:E,4,FALSE) -> #N/A | G18: =IF(F18="STABLE", "STABLE", IF(F18<60, F18&"s", IF(F18<3600, ROUND(F18/60,2)&"min", IF(F18<86400, ROUND(F18/3600,2)&"h", IF(F18<31536000, ROUND(F18/86400,2)&"d", ROUND(F18/31536000,2)&"y"))))) -> #N/A | H18: =LN(2)/F18 -> #N/A | I18: =60*6240000000000*C18*(1-EXP(-H18*2*3600)) -> #N/A | J18: =I18*EXP(-H18*10*3600) -> #N/A | K18: =E18 -> #N/A | L18: {=SUM(($J18*EXP(-$H18*24*3600*_xlfn.SEQUENCE(L$1-1))))+$J18} -> #N/A | M18: {=SUM(($J18*EXP(-$H18*24*3600*_xlfn.SEQUENCE(M$1-1))))+$J18} -> #N/A
... B44: 6013 | C44: 0.0010478212 | D44: =0 -> 0 | E44: =VLOOKUP(B44,Nuclides!A:E,5,FALSE) -> C13 | F44: =VLOOKUP(B44,Nuclides!A:E,4,FALSE) -> STABLE | G44: =IF(F44="STABLE", "STABLE", IF(F44<60, F44&"s", IF(F44<3600, ROUND(F44/60,2)&"min", IF(F44<86400, ROUND(F44/3600,2)&"h", IF(F44<31536000, ROUND(F44/86400,2)&"d", ROUND(F44/31536000,2)&"y"))))) -> STABLE | H44: =LN(2)/F44 -> #VALUE! | I44: =60*6240000000000*C44*(1-EXP(-H44*2*3600)) -> #VALUE! | J44: =I44*EXP(-H44*10*3600) -> #VALUE! | K44: =E44 -> C13 | L44: {=SUM(($J44*EXP(-$H44*24*3600*_xlfn.SEQUENCE(L$1-1))))+$J44} -> #VALUE! | M44: {=SUM(($J44*EXP(-$H44*24*3600*_xlfn.SEQUENCE(M$1-1))))+$J44} -> #VALUE!
B45: 6014 | C45: 1.1653046e-05 | D45: =0 -> 0 | E45: =VLOOKUP(B45,Nuclides!A:E,5,FALSE) -> C14 | F45: =VLOOKUP(B45,Nuclides!A:E,4,FALSE) -> 179878320000 | G45: =IF(F45="STABLE", "STABLE", IF(F45<60, F45&"s", IF(F45<3600, ROUND(F45/60,2)&"min", IF(F45<86400, ROUND(F45/3600,2)&"h", IF(F45<31536000, ROUND(F45/86400,2)&"d", ROUND(F45/31536000,2)&"y"))))) -> 5703.9y | H45: =LN(2)/F45 -> 3.8534226e-12 | I45: =60*6240000000000*C45*(1-EXP(-H45*2*3600)) -> 121.04711 | J45: =I45*EXP(-H45*10*3600) -> 121.0471 | K45: =E45 -> C14 | L45: {=SUM(($J45*EXP(-$H45*24*3600*_xlfn.SEQUENCE(L$1-1))))+$J45} -> 87143.478 | M45: {=SUM(($J45*EXP(-$H45*24*3600*_xlfn.SEQUENCE(M$1-1))))+$J45} -> 870495.47 | O45: =K45 -> C14 | P45: =M45 -> 870495.47 | Q45: =0 -> 0 | S45: =O45 -> C14 | T45: =G45 -> 5703.9y | U45: =P45 -> 870495.47 | V45: 中
B46: 6015 | C46: 0 | D46: =0 -> 0 | E46: =VLOOKUP(B46,Nuclides!A:E,5,FALSE) -> C15 | F46: =VLOOKUP(B46,Nuclides!A:E,4,FALSE) -> 2.449 | G46: =IF(F46="STABLE", "STABLE", IF(F46<60, F46&"s", IF(F46<3600, ROUND(F46/60,2)&"min", IF(F46<86400, ROUND(F46/3600,2)&"h", IF(F46<31536000, ROUND(F46/86400,2)&"d", ROUND(F46/31536000,2)&"y"))))) -> 2.449s | H46: =LN(2)/F46 -> 0.28303274 | I46: =60*6240000000000*C46*(1-EXP(-H46*2*3600)) -> 0 | J46: =I46*EXP(-H46*10*3600) -> 0 | K46: =E46 -> C15 | L46: {=SUM(($J46*EXP(-$H46*24*3600*_xlfn.SEQUENCE(L$1-1))))+$J46} -> 0 | M46: {=SUM(($J46*EXP(-$H46*24*3600*_xlfn.SEQUENCE(M$1-1))))+$J46} -> 0
B47: 6016 | C47: 0 | D47: =0 -> 0 | E47: =VLOOKUP(B47,Nuclides!A:E,5,FALSE) -> C16 | F47: =VLOOKUP(B47,Nuclides!A:E,4,FALSE) -> 0.747 | G47: =IF(F47="STABLE", "STABLE", IF(F47<60, F47&"s", IF(F47<3600, ROUND(F47/60,2)&"min", IF(F47<86400, ROUND(F47/3600,2)&"h", IF(F47<31536000, ROUND(F47/86400,2)&"d", ROUND(F47/31536000,2)&"y"))))) -> 0.747s | H47: =LN(2)/F47 -> 0.92790787 | I47: =60*6240000000000*C47*(1-EXP(-H47*2*3600)) -> 0 | J47: =I47*EXP(-H47*10*3600) -> 0 | K47: =E47 -> C16 | L47: {=SUM(($J47*EXP(-$H47*24*3600*_xlfn.SEQUENCE(L$1-1))))+$J47} -> 0 | M47: {=SUM(($J47*EXP(-$H47*24*3600*_xlfn.SEQUENCE(M$1-1))))+$J47} -> 0
B48: 6017 | C48: 0 | D48: =0 -> 0 | E48: =VLOOKUP(B48,Nuclides!A:E,5,FALSE) -> C17 | F48: =VLOOKUP(B48,Nuclides!A:E,4,FALSE) -> 0.191 | G48: =IF(F48="STABLE", "STABLE", IF(F48<60, F48&"s", IF(F48<3600, ROUND(F48/60,2)&"min", IF(F48<86400, ROUND(F48/3600,2)&"h", IF(F48<31536000, ROUND(F48/86400,2)&"d", ROUND(F48/31536000,2)&"y"))))) -> 0.191s | H48: =LN(2)/F48 -> 3.6290428 | I48: =60*6240000000000*C48*(1-EXP(-H48*2*3600)) -> 0 | J48: =I48*EXP(-H48*10*3600) -> 0 | K48: =E48 -> C17 | L48: {=SUM(($J48*EXP(-$H48*24*3600*_xlfn.SEQUENCE(L$1-1))))+$J48} -> 0 | M48: {=SUM(($J48*EXP(-$H48*24*3600*_xlfn.SEQUENCE(M$1-1))))+$J48} -> 0
B49: 6018 | C49: 0 | D49: =0 -> 0 | E49: =VLOOKUP(B49,Nuclides!A:E,5,FALSE) -> C18 | F49: =VLOOKUP(B49,Nuclides!A:E,4,FALSE) -> 0.092 | G49: =IF(F49="STABLE", "STABLE", IF(F49<60, F49&"s", IF(F49<3600, ROUND(F49/60,2)&"min", IF(F49<86400, ROUND(F49/3600,2)&"h", IF(F49<31536000, ROUND(F49/86400,2)&"d", ROUND(F49/31536000,2)&"y"))))) -> 0.092s | H49: =LN(2)/F49 -> 7.5342085 | I49: =60*6240000000000*C49*(1-EXP(-H49*2*3600)) -> 0 | J49: =I49*EXP(-H49*10*3600) -> 0 | K49: =E49 -> C18 | L49: {=SUM(($J49*EXP(-$H49*24*3600*_xlfn.SEQUENCE(L$1-1))))+$J49} -> 0 | M49: {=SUM(($J49*EXP(-$H49*24*3600*_xlfn.SEQUENCE(M$1-1))))+$J49} -> 0
B50: 6019 | C50: 0 | D50: =0 -> 0 | E50: =VLOOKUP(B50,Nuclides!A:E,5,FALSE) -> C19 | F50: =VLOOKUP(B50,Nuclides!A:E,4,FALSE) -> 0.0462 | G50: =IF(F50="STABLE", "STABLE", IF(F50<60, F50&"s", IF(F50<3600, ROUND(F50/60,2)&"min", IF(F50<86400, ROUND(F50/3600,2)&"h", IF(F50<31536000, ROUND(F50/86400,2)&"d", ROUND(F50/31536000,2)&"y"))))) -> 0.0462s | H50: =LN(2)/F50 -> 15.003186 | I50: =60*6240000000000*C50*(1-EXP(-H50*2*3600)) -> 0 | J50: =I50*EXP(-H50*10*3600) -> 0 | K50: =E50 -> C19 | L50: {=SUM(($J50*EXP(-$H50*24*3600*_xlfn.SEQUENCE(L$1-1))))+$J50} -> 0 | M50: {=SUM(($J50*EXP(-$H50*24*3600*_xlfn.SEQUENCE(M$1-1))))+$J50} -> 0
B51: 6020 | C51: 0 | D51: =0 -> 0 | E51: =VLOOKUP(B51,Nuclides!A:E,5,FALSE) -> C20 | F51: =VLOOKUP(B51,Nuclides!A:E,4,FALSE) -> 0.0162 | G51: =IF(F51="STABLE", "STABLE", IF(F51<60, F51&"s", IF(F51<3600, ROUND(F51/60,2)&"min", IF(F51<86400, ROUND(F51/3600,2)&"h", IF(F51<31536000, ROUND(F51/86400,2)&"d", ROUND(F51/31536000,2)&"y"))))) -> 0.0162s | H51: =LN(2)/F51 -> 42.786863 | I51: =60*6240000000000*C51*(1-EXP(-H51*2*3600)) -> 0 | J51: =I51*EXP(-H51*10*3600) -> 0 | K51: =E51 -> C20 | L51: {=SUM(($J51*EXP(-$H51*24*3600*_xlfn.SEQUENCE(L$1-1))))+$J51} -> 0 | M51: {=SUM(($J51*EXP(-$H51*24*3600*_xlfn.SEQUENCE(M$1-1))))+$J51} -> 0
B52: 7011 | C52: 0 | D52: =0 -> 0 | E52: =VLOOKUP(B52,Nuclides!A:E,5,FALSE) -> N11 | F52: =VLOOKUP(B52,Nuclides!A:E,4,FALSE) -> 5.4903614e-22 | G52: =IF(F52="STABLE", "STABLE", IF(F52<60, F52&"s", IF(F52<3600, ROUND(F52/60,2)&"min", IF(F52<86400, ROUND(F52/3600,2)&"h", IF(F52<31536000, ROUND(F52/86400,2)&"d", ROUND(F52/31536000,2)&"y"))))) -> 5.49036144578313E-22s | H52: =LN(2)/F52 -> 1.2624801e+21 | I52: =60*6240000000000*C52*(1-EXP(-H52*2*3600)) -> 0 | J52: =I52*EXP(-H52*10*3600) -> 0 | K52: =E52 -> N11 | L52: {=SUM(($J52*EXP(-$H52*24*3600*_xlfn.SEQUENCE(L$1-1))))+$J52} -> 0 | M52: {=SUM(($J52*EXP(-$H52*24*3600*_xlfn.SEQUENCE(M$1-1))))+$J52} -> 0
B53: 7012 | C53: 0 | D53: =0 -> 0 | E53: =VLOOKUP(B53,Nuclides!A:E,5,FALSE) -> N12 | F53: =VLOOKUP(B53,Nuclides!A:E,4,FALSE) -> 0.011 | G53: =IF(F53="STABLE", "STABLE", IF(F53<60, F53&"s", IF(F53<3600, ROUND(F53/60,2)&"min", IF(F53<86400, ROUND(F53/3600,2)&"h", IF(F53<31536000, ROUND(F53/86400,2)&"d", ROUND(F53/31536000,2)&"y"))))) -> 0.011s | H53: =LN(2)/F53 -> 63.01338 | I53: =60*6240000000000*C53*(1-EXP(-H53*2*3600)) -> 0 | J53: =I53*EXP(-H53*10*3600) -> 0 | K53: =E53 -> N12 | L53: {=SUM(($J53*EXP(-$H53*24*3600*_xlfn.SEQUENCE(L$1-1))))+$J53} -> 0 | M53: {=SUM(($J53*EXP(-$H53*24*3600*_xlfn.SEQUENCE(M$1-1))))+$J53} -> 0
B54: 7013 | C54: 0 | D54: =0 -> 0 | E54: =VLOOKUP(B54,Nuclides!A:E,5,FALSE) -> N13 | F54: =VLOOKUP(B54,Nuclides!A:E,4,FALSE) -> 597.9 | G54: =IF(F54="STABLE", "STABLE", IF(F54<60, F54&"s", IF(F54<3600, ROUND(F54/60,2)&"min", IF(F54<86400, ROUND(F54/3600,2)&"h", IF(F54<31536000, ROUND(F54/86400,2)&"d", ROUND(F54/31536000,2)&"y"))))) -> 9.97min | H54: =LN(2)/F54 -> 0.0011593029 | I54: =60*6240000000000*C54*(1-EXP(-H54*2*3600)) -> 0 | J54: =I54*EXP(-H54*10*3600) -> 0 | K54: =E54 -> N13 | L54: {=SUM(($J54*EXP(-$H54*24*3600*_xlfn.SEQUENCE(L$1-1))))+$J54} -> 0 | M54: {=SUM(($J54*EXP(-$H54*24*3600*_xlfn.SEQUENCE(M$1-1))))+$J54} -> 0
B55: 7014 | C55: 0 | D55: =0 -> 0 | E55: =VLOOKUP(B55,Nuclides!A:E,5,FALSE) -> N14 | F55: =VLOOKUP(B55,Nuclides!A:E,4,FALSE) -> STABLE | G55: =IF(F55="STABLE", "STABLE", IF(F55<60, F55&"s", IF(F55<3600, ROUND(F55/60,2)&"min", IF(F55<86400, ROUND(F55/3600,2)&"h", IF(F55<31536000, ROUND(F55/86400,2)&"d", ROUND(F55/31536000,2)&"y"))))) -> STABLE | H55: =LN(2)/F55 -> #VALUE! | I55: =60*6240000000000*C55*(1-EXP(-H55*2*3600)) -> #VALUE! | J55: =I55*EXP(-H55*10*3600) -> #VALUE! | K55: =E55 -> N14 | L55: {=SUM(($J55*EXP(-$H55*24*3600*_xlfn.SEQUENCE(L$1-1))))+$J55} -> #VALUE! | M55: {=SUM(($J55*EXP(-$H55*24*3600*_xlfn.SEQUENCE(M$1-1))))+$J55} -> #VALUE!
B56: 7015 | C56: 0 | D56: =0 -> 0 | E56: =VLOOKUP(B56,Nuclides!A:E,5,FALSE) -> N15 | F56: =VLOOKUP(B56,Nuclides!A:E,4,FALSE) -> STABLE | G56: =IF(F56="STABLE", "STABLE", IF(F56<60, F56&"s", IF(F56<3600, ROUND(F56/60,2)&"min", IF(F56<86400, ROUND(F56/3600,2)&"h", IF(F56<31536000, ROUND(F56/86400,2)&"d", ROUND(F56/31536000,2)&"y"))))) -> STABLE | H56: =LN(2)/F56 -> #VALUE! | I56: =60*6240000000000*C56*(1-EXP(-H56*2*3600)) -> #VALUE! | J56: =I56*EXP(-H56*10*3600) -> #VALUE! | K56: =E56 -> N15 | L56: {=SUM(($J56*EXP(-$H56*24*3600*_xlfn.SEQUENCE(L$1-1))))+$J56} -> #VALUE! | M56: {=SUM(($J56*EXP(-$H56*24*3600*_xlfn.SEQUENCE(M$1-1))))+$J56} -> #VALUE!
B57: 7016 | C57: 0 | D57: =0 -> 0 | E57: =VLOOKUP(B57,Nuclides!A:E,5,FALSE) -> N16 | F57: =VLOOKUP(B57,Nuclides!A:E,4,FALSE) -> 7.13 | G57: =IF(F57="STABLE", "STABLE", IF(F57<60, F57&"s", IF(F57<3600, ROUND(F57/60,2)&"min", IF(F57<86400, ROUND(F57/3600,2)&"h", IF(F57<31536000, ROUND(F57/86400,2)&"d", ROUND(F57/31536000,2)&"y"))))) -> 7.13s | H57: =LN(2)/F57 -> 0.097215593 | I57: =60*6240000000000*C57*(1-EXP(-H57*2*3600)) -> 0 | J57: =I57*EXP(-H57*10*3600) -> 0 | K57: =E57 -> N16 | L57: {=SUM(($J57*EXP(-$H57*24*3600*_xlfn.SEQUENCE(L$1-1))))+$J57} -> 0 | M57: {=SUM(($J57*EXP(-$H57*24*3600*_xlfn.SEQUENCE(M$1-1))))+$J57} -> 0
... B304: 24050 | C304: 0 | D304: =0 -> 0 | E304: =VLOOKUP(B304,Nuclides!A:E,5,FALSE) -> Cr50 | F304: =VLOOKUP(B304,Nuclides!A:E,4,FALSE) -> 4.102488e+25 | G304: =IF(F304="STABLE", "STABLE", IF(F304<60, F304&"s", IF(F304<3600, ROUND(F304/60,2)&"min", IF(F304<86400, ROUND(F304/3600,2)&"h", IF(F304<31536000, ROUND(F304/86400,2)&"d", ROUND(F304/31536000,2)&"y"))))) -> 1300890410958900000y | H304: =LN(2)/F304 -> 1.6895776e-26 | I304: =60*6240000000000*C304*(1-EXP(-H304*2*3600)) -> 0 | J304: =I304*EXP(-H304*10*3600) -> 0 | K304: =E304 -> Cr50 | L304: {=SUM(($J304*EXP(-$H304*24*3600*_xlfn.SEQUENCE(L$1-1))))+$J304} -> 0 | M304: {=SUM(($J304*EXP(-$H304*24*3600*_xlfn.SEQUENCE(M$1-1))))+$J304} -> 0
B305: 24051 | C305: 8.5804676e-08 | D305: =0 -> 0 | E305: =VLOOKUP(B305,Nuclides!A:E,5,FALSE) -> Cr51 | F305: =VLOOKUP(B305,Nuclides!A:E,4,FALSE) -> 2393496 | G305: =IF(F305="STABLE", "STABLE", IF(F305<60, F305&"s", IF(F305<3600, ROUND(F305/60,2)&"min", IF(F305<86400, ROUND(F305/3600,2)&"h", IF(F305<31536000, ROUND(F305/86400,2)&"d", ROUND(F305/31536000,2)&"y"))))) -> 27.7d | H305: =LN(2)/F305 -> 2.8959613e-07 | I305: =60*6240000000000*C305*(1-EXP(-H305*2*3600)) -> 66914.364 | J305: =I305*EXP(-H305*10*3600) -> 66220.375 | K305: =E305 -> Cr51 | L305: {=SUM(($J305*EXP(-$H305*24*3600*_xlfn.SEQUENCE(L$1-1))))+$J305} -> 2679828.9 | M305: {=SUM(($J305*EXP(-$H305*24*3600*_xlfn.SEQUENCE(M$1-1))))+$J305} -> 2679828.9 | O305: =K305 -> Cr51 | P305: =M305 -> 2679828.9 | Q305: =0 -> 0 | S305: =O305 -> Cr51 | T305: =G305 -> 27.7d | U305: =P305 -> 2679828.9 | V305: 低
B306: 24052 | C306: 0 | D306: =0 -> 0 | E306: =VLOOKUP(B306,Nuclides!A:E,5,FALSE) -> Cr52 | F306: =VLOOKUP(B306,Nuclides!A:E,4,FALSE) -> STABLE | G306: =IF(F306="STABLE", "STABLE", IF(F306<60, F306&"s", IF(F306<3600, ROUND(F306/60,2)&"min", IF(F306<86400, ROUND(F306/3600,2)&"h", IF(F306<31536000, ROUND(F306/86400,2)&"d", ROUND(F306/31536000,2)&"y"))))) -> STABLE | H306: =LN(2)/F306 -> #VALUE! | I306: =60*6240000000000*C306*(1-EXP(-H306*2*3600)) -> #VALUE! | J306: =I306*EXP(-H306*10*3600) -> #VALUE! | K306: =E306 -> Cr52 | L306: {=SUM(($J306*EXP(-$H306*24*3600*_xlfn.SEQUENCE(L$1-1))))+$J306} -> #VALUE! | M306: {=SUM(($J306*EXP(-$H306*24*3600*_xlfn.SEQUENCE(M$1-1))))+$J306} -> #VALUE!
B307: 24053 | C307: 1.3415656e-06 | D307: =0 -> 0 | E307: =VLOOKUP(B307,Nuclides!A:E,5,FALSE) -> Cr53 | F307: =VLOOKUP(B307,Nuclides!A:E,4,FALSE) -> STABLE | G307: =IF(F307="STABLE", "STABLE", IF(F307<60, F307&"s", IF(F307<3600, ROUND(F307/60,2)&"min", IF(F307<86400, ROUND(F307/3600,2)&"h", IF(F307<31536000, ROUND(F307/86400,2)&"d", ROUND(F307/31536000,2)&"y"))))) -> STABLE | H307: =LN(2)/F307 -> #VALUE! | I307: =60*6240000000000*C307*(1-EXP(-H307*2*3600)) -> #VALUE! | J307: =I307*EXP(-H307*10*3600) -> #VALUE! | K307: =E307 -> Cr53 | L307: {=SUM(($J307*EXP(-$H307*24*3600*_xlfn.SEQUENCE(L$1-1))))+$J307} -> #VALUE! | M307: {=SUM(($J307*EXP(-$H307*24*3600*_xlfn.SEQUENCE(M$1-1))))+$J307} -> #VALUE!
B308: 24054 | C308: 3.0932324e-08 | D308: =0 -> 0 | E308: =VLOOKUP(B308,Nuclides!A:E,5,FALSE) -> Cr54 | F308: =VLOOKUP(B308,Nuclides!A:E,4,FALSE) -> STABLE | G308: =IF(F308="STABLE", "STABLE", IF(F308<60, F308&"s", IF(F308<3600, ROUND(F308/60,2)&"min", IF(F308<86400, ROUND(F308/3600,2)&"h", IF(F308<31536000, ROUND(F308/86400,2)&"d", ROUND(F308/31536000,2)&"y"))))) -> STABLE | H308: =LN(2)/F308 -> #VALUE! | I308: =60*6240000000000*C308*(1-EXP(-H308*2*3600)) -> #VALUE! | J308: =I308*EXP(-H308*10*3600) -> #VALUE! | K308: =E308 -> Cr54 | L308: {=SUM(($J308*EXP(-$H308*24*3600*_xlfn.SEQUENCE(L$1-1))))+$J308} -> #VALUE! | M308: {=SUM(($J308*EXP(-$H308*24*3600*_xlfn.SEQUENCE(M$1-1))))+$J308} -> #VALUE!
B309: 24055 | C309: 4.1359223e-09 | D309: =0 -> 0 | E309: =VLOOKUP(B309,Nuclides!A:E,5,FALSE) -> Cr55 | F309: =VLOOKUP(B309,Nuclides!A:E,4,FALSE) -> 209.82 | G309: =IF(F309="STABLE", "STABLE", IF(F309<60, F309&"s", IF(F309<3600, ROUND(F309/60,2)&"min", IF(F309<86400, ROUND(F309/3600,2)&"h", IF(F309<31536000, ROUND(F309/86400,2)&"d", ROUND(F309/31536000,2)&"y"))))) -> 3.5min | H309: =LN(2)/F309 -> 0.0033035325 | I309: =60*6240000000000*C309*(1-EXP(-H309*2*3600)) -> 1548489.3 | J309: =I309*EXP(-H309*10*3600) -> 3.4713242e-46 | K309: =E309 -> Cr55 | L309: {=SUM(($J309*EXP(-$H309*24*3600*_xlfn.SEQUENCE(L$1-1))))+$J309} -> 3.4713242e-46 | M309: {=SUM(($J309*EXP(-$H309*24*3600*_xlfn.SEQUENCE(M$1-1))))+$J309} -> 3.4713242e-46
B310: 24056 | C310: 0 | D310: =0 -> 0 | E310: =VLOOKUP(B310,Nuclides!A:E,5,FALSE) -> Cr56 | F310: =VLOOKUP(B310,Nuclides!A:E,4,FALSE) -> 356.4 | G310: =IF(F310="STABLE", "STABLE", IF(F310<60, F310&"s", IF(F310<3600, ROUND(F310/60,2)&"min", IF(F310<86400, ROUND(F310/3600,2)&"h", IF(F310<31536000, ROUND(F310/86400,2)&"d", ROUND(F310/31536000,2)&"y"))))) -> 5.94min | H310: =LN(2)/F310 -> 0.0019448574 | I310: =60*6240000000000*C310*(1-EXP(-H310*2*3600)) -> 0 | J310: =I310*EXP(-H310*10*3600) -> 0 | K310: =E310 -> Cr56 | L310: {=SUM(($J310*EXP(-$H310*24*3600*_xlfn.SEQUENCE(L$1-1))))+$J310} -> 0 | M310: {=SUM(($J310*EXP(-$H310*24*3600*_xlfn.SEQUENCE(M$1-1))))+$J310} -> 0
B311: 24057 | C311: 0 | D311: =0 -> 0 | E311: =VLOOKUP(B311,Nuclides!A:E,5,FALSE) -> Cr57 | F311: =VLOOKUP(B311,Nuclides!A:E,4,FALSE) -> 21.1 | G311: =IF(F311="STABLE", "STABLE", IF(F311<60, F311&"s", IF(F311<3600, ROUND(F311/60,2)&"min", IF(F311<86400, ROUND(F311/3600,2)&"h", IF(F311<31536000, ROUND(F311/86400,2)&"d", ROUND(F311/31536000,2)&"y"))))) -> 21.1s | H311: =LN(2)/F311 -> 0.032850577 | I311: =60*6240000000000*C311*(1-EXP(-H311*2*3600)) -> 0 | J311: =I311*EXP(-H311*10*3600) -> 0 | K311: =E311 -> Cr57 | L311: {=SUM(($J311*EXP(-$H311*24*3600*_xlfn.SEQUENCE(L$1-1))))+$J311} -> 0 | M311: {=SUM(($J311*EXP(-$H311*24*3600*_xlfn.SEQUENCE(M$1-1))))+$J311} -> 0
B312: 24058 | C312: 0 | D312: =0 -> 0 | E312: =VLOOKUP(B312,Nuclides!A:E,5,FALSE) -> Cr58 | F312: =VLOOKUP(B312,Nuclides!A:E,4,FALSE) -> 7 | G312: =IF(F312="STABLE", "STABLE", IF(F312<60, F312&"s", IF(F312<3600, ROUND(F312/60,2)&"min", IF(F312<86400, ROUND(F312/3600,2)&"h", IF(F312<31536000, ROUND(F312/86400,2)&"d", ROUND(F312/31536000,2)&"y"))))) -> 7s | H312: =LN(2)/F312 -> 0.099021026 | I312: =60*6240000000000*C312*(1-EXP(-H312*2*3600)) -> 0 | J312: =I312*EXP(-H312*10*3600) -> 0 | K312: =E312 -> Cr58 | L312: {=SUM(($J312*EXP(-$H312*24*3600*_xlfn.SEQUENCE(L$1-1))))+$J312} -> 0 | M312: {=SUM(($J312*EXP(-$H312*24*3600*_xlfn.SEQUENCE(M$1-1))))+$J312} -> 0
B313: 24059 | C313: 0 | D313: =0 -> 0 | E313: =VLOOKUP(B313,Nuclides!A:E,5,FALSE) -> Cr59 | F313: =VLOOKUP(B313,Nuclides!A:E,4,FALSE) -> 1.05 | G313: =IF(F313="STABLE", "STABLE", IF(F313<60, F313&"s", IF(F313<3600, ROUND(F313/60,2)&"min", IF(F313<86400, ROUND(F313/3600,2)&"h", IF(F313<31536000, ROUND(F313/86400,2)&"d", ROUND(F313/31536000,2)&"y"))))) -> 1.05s | H313: =LN(2)/F313 -> 0.66014017 | I313: =60*6240000000000*C313*(1-EXP(-H313*2*3600)) -> 0 | J313: =I313*EXP(-H313*10*3600) -> 0 | K313: =E313 -> Cr59 | L313: {=SUM(($J313*EXP(-$H313*24*3600*_xlfn.SEQUENCE(L$1-1))))+$J313} -> 0 | M313: {=SUM(($J313*EXP(-$H313*24*3600*_xlfn.SEQUENCE(M$1-1))))+$J313} -> 0
...
