Workbook

Sheet Nuclides
B2: n | C2: z | D2: halflife/s
A3: 1001 | B3: 1 | C3: 0 | D3: 613.9
A4: 1002 | B4: 1 | C4: 1 | D4: STABLE | E4: H2 | F4: =D4 -> STABLE
A5: 1003 | B5: 2 | C5: 1 | D5: 388789632 | E5: H3 | F5: =D5 -> 388789632
A6: 1005 | B6: 4 | C6: 1 | D6: 7.9947368e-23 | E6: H5 | F6: =D6 -> 7.9947368e-23
A7: 1006 | B7: 5 | C7: 1 | D7: 2.848125e-22 | E7: H6 | F7: =D7 -> 2.848125e-22
A8: 2003 | B8: 1 | C8: 2 | D8: STABLE | E8: He3 | F8: =D8 -> STABLE
A9: 2004 | B9: 2 | C9: 2 | D9: STABLE | E9: He4 | F9: =D9 -> STABLE
A10: 2005 | B10: 3 | C10: 2 | D10: 7.595e-22 | E10: He5 | F10: =D10 -> 7.595e-22
A11: 2006 | B11: 4 | C11: 2 | D11: 0.8067 | E11: He6 | F11: =D11 -> 0.8067
A12: 2007 | B12: 5 | C12: 2 | D12: 3.038e-21 | E12: He7 | F12: =D12 -> 3.038e-21
A13: 2008 | B13: 6 | C13: 2 | D13: 0.1191 | E13: He8 | F13: =D13 -> 0.1191
A14: 2010 | B14: 8 | C14: 2 | D14: 1.519e-21 | E14: He10 | F14: =D14 -> 1.519e-21
A15: 3004 | B15: 1 | C15: 3 | D15: 7.5572139e-23 | E15: Li4 | F15: =D15 -> 7.5572139e-23
A16: 3005 | B16: 2 | C16: 3 | D16: 3.038e-22 | E16: Li5 | F16: =D16 -> 3.038e-22
A17: 3006 | B17: 3 | C17: 3 | D17: STABLE | E17: Li6 | F17: =D17 -> STABLE
A18: 3007 | B18: 4 | C18: 3 | D18: STABLE | E18: Li7 | F18: =D18 -> STABLE
A19: 3008 | B19: 5 | C19: 3 | D19: 0.8399 | E19: Li8 | F19: =D19 -> 0.8399
A20: 3009 | B20: 6 | C20: 3 | D20: 0.1783 | E20: Li9 | F20: =D20 -> 0.1783
A21: 3011 | B21: 8 | C21: 3 | D21: 0.00875 | E21: Li11 | F21: =D21 -> 0.00875
A22: 4006 | B22: 2 | C22: 4 | D22: 4.9532609e-21 | E22: Be6 | F22: =D22 -> 4.9532609e-21
A23: 4007 | B23: 3 | C23: 4 | D23: 4598208 | E23: Be7 | F23: =D23 -> 4598208
A24: 4008 | B24: 4 | C24: 4 | D24: 8.1813285e-17 | E24: Be8 | F24: =D24 -> 8.1813285e-17
A25: 4009 | B25: 5 | C25: 4 | D25: STABLE | E25: Be9 | F25: =D25 -> STABLE
A26: 4010 | B26: 6 | C26: 4 | D26: 47651976000000 | E26: Be10 | F26: =D26 -> 47651976000000
A27: 4011 | B27: 7 | C27: 4 | D27: 13.76 | E27: Be11 | F27: =D27 -> 13.76
A28: 4012 | B28: 8 | C28: 4 | D28: 0.02147 | E28: Be12 | F28: =D28 -> 0.02147
A29: 4013 | B29: 9 | C29: 4 | D29: 2.7e-21 | E29: Be13 | F29: =D29 -> 2.7e-21
A30: 4014 | B30: 10 | C30: 4 | D30: 0.00435 | E30: Be14 | F30: =D30 -> 0.00435
A31: 4015 | B31: 11 | C31: 4 | D31: 7.8568966e-22 | E31: Be15 | F31: =D31 -> 7.8568966e-22
A32: 4016 | B32: 12 | C32: 4 | D32: 5.69625e-22 | E32: Be16 | F32: =D32 -> 5.69625e-22
A33: 5007 | B33: 2 | C33: 5 | D33: 3.255e-22 | E33: B7 | F33: =D33 -> 3.255e-22
A34: 5008 | B34: 3 | C34: 5 | D34: 0.77 | E34: B8 | F34: =D34 -> 0.77
A35: 5009 | B35: 4 | C35: 5 | D35: 8.4388889e-19 | E35: B9 | F35: =D35 -> 8.4388889e-19
A36: 5010 | B36: 5 | C36: 5 | D36: STABLE | E36: B10 | F36: =D36 -> STABLE
A37: 5011 | B37: 6 | C37: 5 | D37: STABLE | E37: B11 | F37: =D37 -> STABLE
A38: 5012 | B38: 7 | C38: 5 | D38: 0.0202 | E38: B12 | F38: =D38 -> 0.0202
A39: 5013 | B39: 8 | C39: 5 | D39: 0.01733 | E39: B13 | F39: =D39 -> 0.01733
A40: 5014 | B40: 9 | C40: 5 | D40: 0.01236 | E40: B14 | F40: =D40 -> 0.01236
A41: 5015 | B41: 10 | C41: 5 | D41: 0.01018 | E41: B15 | F41: =D41 -> 0.01018
...

Sheet Sheet4
B3: 1e-05 | C3: 0 | E3: =B3 -> 1e-05 | F3: =B4 -> 1.0764e-05 | G3: =B5 -> 1.1587e-05 | H3: =B6 -> 1.2473e-05 | I3: =B7 -> 1.3426e-05 | J3: =B8 -> 1.4453e-05 | K3: =B9 -> 1.5557e-05 | N3: =C3 -> 0 | O3: =C4 -> 0 | P3: =C5 -> 0 | Q3: =C6 -> 0 | R3: =C7 -> 0 | S3: =C8 -> 0 | T3: =C9 -> 0
B4: 1.0764e-05 | C4: 0 | E4: =B10 -> 1.6747e-05 | F4: =B11 -> 1.8027e-05 | G4: =B12 -> 1.9405e-05 | H4: =B13 -> 2.0888e-05 | I4: =B14 -> 2.2485e-05 | J4: =B15 -> 2.4203e-05 | K4: =B16 -> 2.6054e-05 | N4: =C10 -> 0 | O4: =C11 -> 0 | P4: =C12 -> 1.34073e-07 | Q4: =C13 -> 0 | R4: =C14 -> 0 | S4: =C15 -> 0 | T4: =C16 -> 0
B5: 1.1587e-05 | C5: 0 | E5: =B17 -> 2.8045e-05 | F5: =B18 -> 3.0189e-05 | G5: =B19 -> 3.2496e-05 | H5: =B20 -> 3.498e-05 | I5: =B21 -> 3.7654e-05 | J5: =B22 -> 4.0533e-05 | K5: =B23 -> 4.3631e-05 | N5: =C17 -> 0 | O5: =C18 -> 0 | P5: =C19 -> 0 | Q5: =C20 -> 1.56917e-07 | R5: =C21 -> 0 | S5: =C22 -> 0 | T5: =C23 -> 0
B6: 1.2473e-05 | C6: 0 | E6: =B24 -> 4.6966e-05 | F6: =B25 -> 5.0556e-05 | G6: =B26 -> 5.4421e-05 | H6: =B27 -> 5.858e-05 | I6: =B28 -> 6.3058e-05 | J6: =B29 -> 6.7878e-05 | K6: =B30 -> 7.3067e-05 | N6: =C24 -> 0 | O6: =C25 -> 0 | P6: =C26 -> 0 | Q6: =C27 -> 0 | R6: =C28 -> 0 | S6: =C29 -> 0 | T6: =C30 -> 0
B7: 1.3426e-05 | C7: 0 | E7: =B31 -> 7.8652e-05 | F7: =B32 -> 8.4664e-05 | G7: =B33 -> 9.1136e-05 | H7: =B34 -> 9.8103e-05 | I7: =B35 -> 0.0001056 | J7: =B36 -> 0.00011367 | K7: =B37 -> 0.00012236 | N7: =C31 -> 0 | O7: =C32 -> 0 | P7: =C33 -> 0 | Q7: =C34 -> 0 | R7: =C35 -> 0 | S7: =C36 -> 0 | T7: =C37 -> 0
B8: 1.4453e-05 | C8: 0 | E8: =B38 -> 0.00013172 | F8: =B39 -> 0.00014178 | G8: =B40 -> 0.00015262 | H8: =B41 -> 0.00016429 | I8: =B42 -> 0.00017685 | J8: =B43 -> 0.00019037 | K8: =B44 -> 0.00020492 | N8: =C38 -> 0 | O8: =C39 -> 0 | P8: =C40 -> 0 | Q8: =C41 -> 0 | R8: =C42 -> 0 | S8: =C43 -> 0 | T8: =C44 -> 1.70454e-07
B9: 1.5557e-05 | C9: 0 | E9: =B45 -> 0.00022058 | F9: =B46 -> 0.00023744 | G9: =B47 -> 0.00025559 | H9: =B48 -> 0.00027513 | I9: =B49 -> 0.00029616 | J9: =B50 -> 0.0003188 | K9: =B51 -> 0.00034317 | N9: =C45 -> 0 | O9: =C46 -> 0 | P9: =C47 -> 2.272e-07 | Q9: =C48 -> 0 | R9: =C49 -> 0 | S9: =C50 -> 0 | T9: =C51 -> 0
B10: 1.6747e-05 | C10: 0 | E10: =B52 -> 0.0003694 | F10: =B53 -> 0.00039764 | G10: =B54 -> 0.00042803 | H10: =B55 -> 0.00046075 | I10: =B56 -> 0.00049597 | J10: =B57 -> 0.00053388 | K10: =B58 -> 0.00057469 | N10: =C52 -> 0 | O10: =C53 -> 0 | P10: =C54 -> 0 | Q10: =C55 -> 0 | R10: =C56 -> 0 | S10: =C57 -> 0 | T10: =C58 -> 0
B11: 1.8027e-05 | C11: 0 | E11: =B59 -> 0.00061862 | F11: =B60 -> 0.00066591 | G11: =B61 -> 0.00071681 | H11: =B62 -> 0.0007716 | I11: =B63 -> 0.00083058 | J11: =B64 -> 0.00089407 | K11: =B65 -> 0.00096241 | N11: =C59 -> 0 | O11: =C60 -> 2.74774e-07 | P11: =C61 -> 3.22921e-07 | Q11: =C62 -> 0 | R11: =C63 -> 0 | S11: =C64 -> 0 | T11: =C65 -> 0
B12: 1.9405e-05 | C12: 1.34073e-07 | E12: =B66 -> 0.001036 | F12: =B67 -> 0.0011152 | G12: =B68 -> 0.0012004 | H12: =B69 -> 0.0012922 | I12: =B70 -> 0.0013909 | J12: =B71 -> 0.0014973 | K12: =B72 -> 0.0016117 | N12: =C66 -> 0 | O12: =C67 -> 1.27372e-07 | P12: =C68 -> 1.98709e-07 | Q12: =C69 -> 0 | R12: =C70 -> 0 | S12: =C71 -> 0 | T12: =C72 -> 0
B13: 2.0888e-05 | C13: 0 | E13: =B73 -> 0.0017349 | F13: =B74 -> 0.0018675 | G13: =B75 -> 0.0020103 | H13: =B76 -> 0.002164 | I13: =B77 -> 0.0023294 | J13: =B78 -> 0.0025074 | K13: =B79 -> 0.0026991 | N13: =C73 -> 0 | O13: =C74 -> 0 | P13: =C75 -> 2.05252e-07 | Q13: =C76 -> 0 | R13: =C77 -> 0 | S13: =C78 -> 0 | T13: =C79 -> 0
B14: 2.2485e-05 | C14: 0 | E14: =B80 -> 0.0029054 | F14: =B81 -> 0.0031275 | G14: =B82 -> 0.0033666 | H14: =B83 -> 0.0036239 | I14: =B84 -> 0.0039009 | J14: =B85 -> 0.0041991 | K14: =B86 -> 0.0045201 | N14: =C80 -> 0 | O14: =C81 -> 1.52854e-07 | P14: =C82 -> 4.00637e-07 | Q14: =C83 -> 0 | R14: =C84 -> 0 | S14: =C85 -> 0 | T14: =C86 -> 2.60346e-07
B15: 2.4203e-05 | C15: 0 | E15: =B87 -> 0.0048656 | F15: =B88 -> 0.0052375 | G15: =B89 -> 0.0056379 | H15: =B90 -> 0.0060688 | I15: =B91 -> 0.0065327 | J15: =B92 -> 0.0070321 | K15: =B93 -> 0.0075696 | N15: =C87 -> 1.74892e-07 | O15: =C88 -> 0 | P15: =C89 -> 0 | Q15: =C90 -> 0 | R15: =C91 -> 0 | S15: =C92 -> 0 | T15: =C93 -> 5.25824e-07
B16: 2.6054e-05 | C16: 0 | E16: =B94 -> 0.0081482 | F16: =B95 -> 0.0087711 | G16: =B96 -> 0.0094415 | H16: =B97 -> 0.010163 | I16: =B98 -> 0.01094 | J16: =B99 -> 0.011776 | K16: =B100 -> 0.012677 | N16: =C94 -> 0 | O16: =C95 -> 0 | P16: =C96 -> 3.68224e-07 | Q16: =C97 -> 0 | R16: =C98 -> 2.74854e-07 | S16: =C99 -> 1.98836e-07 | T16: =C100 -> 0
B17: 2.8045e-05 | C17: 0 | E17: =B101 -> 0.013646 | F17: =B102 -> 0.014689 | G17: =B103 -> 0.015811 | H17: =B104 -> 0.01702 | I17: =B105 -> 0.018321 | J17: =B106 -> 0.019721 | K17: =B107 -> 0.021229 | N17: =C101 -> 7.08039e-07 | O17: =C102 -> 5.84647e-07 | P17: =C103 -> 0 | Q17: =C104 -> 1.95675e-07 | R17: =C105 -> 6.70184e-08 | S17: =C106 -> 2.33135e-07 | T17: =C107 -> 5.01562e-07
B18: 3.0189e-05 | C18: 0 | E18: =B108 -> 0.022852 | F18: =B109 -> 0.024598 | G18: =B110 -> 0.026479 | H18: =B111 -> 0.028503 | I18: =B112 -> 0.030682 | J18: =B113 -> 0.033027 | K18: =B114 -> 0.035551 | N18: =C108 -> 1.7421e-07 | O18: =C109 -> 1.97186e-07 | P18: =C110 -> 3.90911e-07 | Q18: =C111 -> 0 | R18: =C112 -> 1.44735e-07 | S18: =C113 -> 6.29715e-07 | T18: =C114 -> 4.66014e-07
B19: 3.2496e-05 | C19: 0 | E19: =B115 -> 0.038269 | F19: =B116 -> 0.041194 | G19: =B117 -> 0.044343 | H19: =B118 -> 0.047733 | I19: =B119 -> 0.051381 | J19: =B120 -> 0.055309 | K19: =B121 -> 0.059537 | N19: =C115 -> 3.3836e-07 | O19: =C116 -> 6.75997e-07 | P19: =C117 -> 4.87684e-07 | Q19: =C118 -> 4.52325e-07 | R19: =C119 -> 4.19812e-07 | S19: =C120 -> 1.17442e-06 | T19: =C121 -> 0
B20: 3.498e-05 | C20: 1.56917e-07 | E20: =B122 -> 0.064088 | F20: =B123 -> 0.068986 | G20: =B124 -> 0.07426 | H20: =B125 -> 0.079936 | I20: =B126 -> 0.086046 | J20: =B127 -> 0.092624 | K20: =B128 -> 0.099704 | N20: =C122 -> 1.8676e-06 | O20: =C123 -> 9.27306e-07 | P20: =C124 -> 1.61957e-07 | Q20: =C125 -> 1.23211e-06 | R20: =C126 -> 1.10167e-06 | S20: =C127 -> 1.92598e-06 | T20: =C128 -> 2.28942e-06
B21: 3.7654e-05 | C21: 0 | E21: =B129 -> 0.10733 | F21: =B130 -> 0.11553 | G21: =B131 -> 0.12436 | H21: =B132 -> 0.13387 | I21: =B133 -> 0.1441 | J21: =B134 -> 0.15511 | K21: =B135 -> 0.16697 | N21: =C129 -> 4.84813e-07 | O21: =C130 -> 1.30352e-06 | P21: =C131 -> 2.00767e-06 | Q21: =C132 -> 2.74841e-06 | R21: =C133 -> 3.27811e-06 | S21: =C134 -> 3.45896e-06 | T21: =C135 -> 2.20631e-06
B22: 4.0533e-05 | C22: 0 | E22: =B136 -> 0.17973 | F22: =B137 -> 0.19347 | G22: =B138 -> 0.20826 | H22: =B139 -> 0.22418 | I22: =B140 -> 0.24132 | J22: =B141 -> 0.25976 | K22: =B142 -> 0.27962 | N22: =C136 -> 4.10907e-06 | O22: =C137 -> 2.86588e-06 | P22: =C138 -> 4.02076e-06 | Q22: =C139 -> 3.92982e-06 | R22: =C140 -> 6.30138e-06 | S22: =C141 -> 7.76294e-06 | T22: =C142 -> 5.62978e-06
B23: 4.3631e-05 | C23: 0 | E23: =B143 -> 0.30099 | F23: =B144 -> 0.324 | G23: =B145 -> 0.34877 | H23: =B146 -> 0.37543 | I23: =B147 -> 0.40413 | J23: =B148 -> 0.43502 | K23: =B149 -> 0.46827 | N23: =C143 -> 4.58466e-06 | O23: =C144 -> 7.00341e-06 | P23: =C145 -> 8.96694e-06 | Q23: =C146 -> 1.10827e-05 | R23: =C147 -> 6.64296e-06 | S23: =C148 -> 8.15923e-06 | T23: =C149 -> 1.00695e-05
B24: 4.6966e-05 | C24: 0 | E24: =B150 -> 0.50406 | F24: =B151 -> 0.54259 | G24: =B152 -> 0.58407 | H24: =B153 -> 0.62872 | I24: =B154 -> 0.67678 | J24: =B155 -> 0.72851 | K24: =B156 -> 0.7842 | N24: =C150 -> 9.96882e-06 | O24: =C151 -> 1.2548e-05 | P24: =C152 -> 1.44418e-05 | Q24: =C153 -> 1.28401e-05 | R24: =C154 -> 1.0852e-05 | S24: =C155 -> 1.26751e-05 | T24: =C156 -> 1.3142e-05
B25: 5.0556e-05 | C25: 0 | E25: =B157 -> 0.84414 | F25: =B158 -> 0.90866 | G25: =B159 -> 0.97812 | H25: =B160 -> 1.0529 | I25: =B161 -> 1.1334 | J25: =B162 -> 1.22 | K25: =B163 -> 1.3133 | N25: =C157 -> 1.46227e-05 | O25: =C158 -> 1.14149e-05 | P25: =C159 -> 1.29498e-05 | Q25: =C160 -> 1.19663e-05 | R25: =C161 -> 1.75551e-05 | S25: =C162 -> 1.21482e-05 | T25: =C163 -> 1.25528e-05
B26: 5.4421e-05 | C26: 0 | E26: =B164 -> 1.4136 | F26: =B165 -> 1.5217 | G26: =B166 -> 1.638 | H26: =B167 -> 1.7632 | I26: =B168 -> 1.898 | J26: =B169 -> 2.0431 | K26: =B170 -> 2.1993 | N26: =C164 -> 1.31098e-05 | O26: =C165 -> 1.47127e-05 | P26: =C166 -> 1.05967e-05 | Q26: =C167 -> 1.28626e-05 | R26: =C168 -> 8.59917e-06 | S26: =C169 -> 8.02133e-06 | T26: =C170 -> 6.74618e-06
B27: 5.858e-05 | C27: 0 | E27: =B171 -> 2.3674 | F27: =B172 -> 2.5484 | G27: =B173 -> 2.7431 | H27: =B174 -> 2.9528 | I27: =B175 -> 3.1785 | J27: =B176 -> 3.4215 | K27: =B177 -> 3.6831 | N27: =C171 -> 4.70226e-06 | O27: =C172 -> 8.66194e-06 | P27: =C173 -> 4.87924e-06 | Q27: =C174 -> 2.02962e-06 | R27: =C175 -> 5.3212e-06 | S27: =C176 -> 1.42062e-06 | T27: =C177 -> 2.31984e-06
B28: 6.3058e-05 | C28: 0 | E28: =B178 -> 3.9646 | F28: =B179 -> 4.2676 | G28: =B180 -> 4.5939 | H28: =B181 -> 4.945 | I28: =B182 -> 5.323 | J28: =B183 -> 5.7299 | K28: =B184 -> 6.1679 | N28: =C178 -> 1.10439e-06 | O28: =C179 -> 1.28899e-06 | P28: =C180 -> 1.07389e-06 | Q28: =C181 -> 1.09995e-06 | R28: =C182 -> 1.04864e-06 | S28: =C183 -> 1.10871e-06 | T28: =C184 -> 1.66288e-07
B29: 6.7878e-05 | C29: 0 | E29: =B185 -> 6.6393 | F29: =B186 -> 7.1469 | G29: =B187 -> 7.6932 | H29: =B188 -> 8.2812 | I29: =B189 -> 8.9142 | J29: =B190 -> 9.5956 | K29: =B191 -> 10.329 | N29: =C185 -> 4.9701e-07 | O29: =C186 -> 4.67686e-07 | P29: =C187 -> 2.56509e-07 | Q29: =C188 -> 1.51714e-07 | R29: =C189 -> 1.28437e-07 | S29: =C190 -> 8.6271e-07 | T29: =C191 -> 1.55413e-07
B30: 7.3067e-05 | C30: 0 | E30: =B192 -> 11.119 | F30: =B193 -> 11.969 | G30: =B194 -> 12.883 | H30: =B195 -> 13.868 | I30: =B196 -> 14.928 | J30: =B197 -> 16.069 | K30: =B198 -> 17.298 | N30: =C192 -> 0 | O30: =C193 -> 0 | P30: =C194 -> 0 | Q30: =C195 -> 2.01343e-07 | R30: =C196 -> 0 | S30: =C197 -> 0 | T30: =C198 -> 0
B31: 7.8652e-05 | C31: 0 | E31: =B199 -> 18.62 | F31: =B200 -> 20.043 | G31: =B201 -> 21.575 | H31: =B202 -> 23.225 | I31: =B203 -> 25 | J31: =B204 -> 0 | K31: =B205 -> 0 | N31: =C199 -> 0 | O31: =C200 -> 0 | P31: =C201 -> 0 | Q31: =C202 -> 0 | R31: =C203 -> 0 | S31: =C204 -> 0 | T31: =C205 -> 0
B32: 8.4664e-05 | C32: 0
B33: 9.1136e-05 | C33: 0
B34: 9.8103e-05 | C34: 0
B35: 0.0001056 | C35: 0
B36: 0.00011367 | C36: 0
B37: 0.00012236 | C37: 0
B38: 0.00013172 | C38: 0
B39: 0.00014178 | C39: 0
B40: 0.00015262 | C40: 0
B41: 0.00016429 | C41: 0
B42: 0.00017685 | C42: 0
...

Sheet Sheet1
B3: 88225 | C3: 8.929687e-05 | F3: 88225 | G3: 0.00013588226 | J3: 25049 | K3: 5e-15 | N3: 22054 | O3: 2.08564e-15
B4: 88224 | C4: 8.079628e-05 | F4: 88224 | G4: 0.00012507608 | J4: 25050 | K4: 0 | N4: 23044 | O4: 0
B5: 88226 | C5: 2.068349e-06 | F5: 88226 | G5: 3.095672e-06 | J5: 25051 | K5: 0 | N5: 23045 | O5: 0
B6: 88223 | C6: 1.300178e-06 | F6: 88223 | G6: 2.168761e-06 | J6: 25052 | K6: 0 | N6: 23046 | O6: 0
B7: 86222 | C7: 3.119224e-11 | F7: 86222 | G7: 5.016266e-11 | J7: 25053 | K7: 0 | N7: 23047 | O7: 0
B8: 87225 | C8: 3.213911e-09 | F8: 87225 | G8: 5.339445e-09 | J8: 25054 | K8: 0 | N8: 23048 | O8: 0
B9: 86221 | C9: 7.049362e-11 | F9: 86221 | G9: 1.1820044e-10 | J9: 25055 | K9: 0 | N9: 23049 | O9: 0
B10: 88222 | C10: 2.093323e-09 | F10: 88222 | G10: 3.713048e-09 | J10: 25056 | K10: 0 | N10: 23050 | O10: 0
B11: 87224 | C11: 2.737689e-10 | F11: 87224 | G11: 4.69963e-10 | J11: 25057 | K11: 0 | N11: 23051 | O11: 0
B12: 87223 | C12: 2.31121e-12 | F12: 87223 | G12: 3.985815e-12 | J12: 25058 | K12: 0 | N12: 23052 | O12: 0
B13: 86220 | C13: 4.113371e-12 | F13: 86220 | G13: 7.041e-12 | J13: 25059 | K13: 0 | N13: 23053 | O13: 0
B14: 87222 | C14: 8.397269e-14 | F14: 87222 | G14: 1.4772604e-13 | J14: 25060 | K14: 0 | N14: 23054 | O14: 0
... B29: 83217 | C29: 2.268375e-27 | F29: 83217 | G29: 3.608877e-27 | J29: 26061 | K29: 0 | N29: 24057 | O29: 0
B30: 83215 | C30: 7.553161e-31 | J30: 26062 | K30: 0 | N30: 24058 | O30: 0
B31: 88225 | C31: 4.658539e-05 | J31: 26063 | K31: 3e-15 | N31: 24059 | O31: 0
B32: 88224 | C32: 4.42798e-05 | J32: 26064 | K32: 6e-15 | N32: 25049 | O32: 1.35567e-14
B33: 88226 | C33: 1.027323e-06 | J33: 27053 | K33: 1e-14 | N33: 25050 | O33: 0
B34: 88223 | C34: 8.68583e-07 | J34: 27054 | K34: 2.3e-14 | N34: 25051 | O34: 0
B35: 87225 | C35: 2.125534e-09 | J35: 27055 | K35: 3.3e-14 | N35: 25052 | O35: 0
B36: 88222 | C36: 1.619725e-09 | J36: 27056 | K36: 2.9e-14 | N36: 25053 | O36: 0
B37: 87224 | C37: 1.961941e-10 | J37: 27057 | K37: 1.8e-14 | N37: 25054 | O37: 0
B38: 86221 | C38: 4.770682e-11 | J38: 27058 | K38: 6e-15 | N38: 25055 | O38: 1.98136e-14
B39: 86222 | C39: 1.897042e-11 | J39: 27059 | K39: 2e-15 | N39: 25056 | O39: 3.12847e-15
B40: 86220 | C40: 2.927629e-12 | J40: 27060 | K40: 0 | N40: 25057 | O40: 3.12847e-15
B41: 87223 | C41: 1.674605e-12 | J41: 27061 | K41: 0 | N41: 25058 | O41: 0
... B58: 83215 | C58: 5.871318e-31 | J58: 28066 | K58: 0 | N58: 26061 | O58: 0
J59: 28067 | K59: 6e-15 | N59: 26062 | O59: 0
J60: 28068 | K60: 7e-15 | N60: 26063 | O60: 0
J61: 29057 | K61: 5.9e-14 | N61: 26064 | O61: 0
J62: 29058 | K62: 9.5e-14 | N62: 27053 | O62: 3.12847e-15
J63: 29059 | K63: 1.65e-13 | N63: 27054 | O63: 8.34258e-15
J64: 29060 | K64: 1.69e-13 | N64: 27055 | O64: 4.17129e-14
J65: 29061 | K65: 1.1e-13 | N65: 27056 | O65: 9.48968e-14
J66: 29062 | K66: 6.6e-14 | N66: 27057 | O66: 1.54338e-13
J67: 29063 | K67: 1.3e-14 | N67: 27058 | O67: 1.83537e-13
J68: 29064 | K68: 3e-15 | N68: 27059 | O68: 1.87708e-13
J69: 29065 | K69: 1e-15 | N69: 27060 | O69: 8.34258e-14
J70: 29066 | K70: 0 | N70: 27061 | O70: 2.50277e-14
... J1677: 88227 | K1677: 5.48516e-08 | N1677: 87222 | O1677: 0
N1678: 87223 | O1678: 0
...

Sheet 226P
B3: 88225 | C3: 0.00013588226 | D3: =0 -> 0 | E3: =VLOOKUP(B3,Nuclides!A:E,5,FALSE) -> Ra225 | F3: =C3 -> 0.00013588226
B4: 88224 | C4: 0.00012507608 | D4: =0 -> 0 | E4: =VLOOKUP(B4,Nuclides!A:E,5,FALSE) -> Ra224 | F4: =C4 -> 0.00012507608
B5: 88226 | C5: 3.095672e-06 | D5: =0 -> 0 | E5: =VLOOKUP(B5,Nuclides!A:E,5,FALSE) -> Ra226 | F5: =C5 -> 3.095672e-06
B6: 88223 | C6: 2.168761e-06 | D6: =0 -> 0 | E6: =VLOOKUP(B6,Nuclides!A:E,5,FALSE) -> Ra223 | F6: =C6 -> 2.168761e-06
B7: 87225 | C7: 5.339445e-09 | D7: =0 -> 0 | E7: =VLOOKUP(B7,Nuclides!A:E,5,FALSE) -> Fr225 | F7: =C7 -> 5.339445e-09
B8: 88222 | C8: 3.713048e-09 | D8: =0 -> 0 | E8: =VLOOKUP(B8,Nuclides!A:E,5,FALSE) -> Ra222 | F8: =C8 -> 3.713048e-09
B9: 87224 | C9: 4.69963e-10 | D9: =0 -> 0 | E9: =VLOOKUP(B9,Nuclides!A:E,5,FALSE) -> Fr224 | F9: =C9 -> 4.69963e-10
B10: 86221 | C10: 1.1820044e-10 | D10: =0 -> 0 | E10: =VLOOKUP(B10,Nuclides!A:E,5,FALSE) -> Rn221 | F10: =C10 -> 1.1820044e-10
B11: 86222 | C11: 5.016266e-11 | D11: =0 -> 0 | E11: =VLOOKUP(B11,Nuclides!A:E,5,FALSE) -> Rn222 | F11: =C11 -> 5.016266e-11
B12: 86220 | C12: 7.041e-12 | D12: =0 -> 0 | E12: =VLOOKUP(B12,Nuclides!A:E,5,FALSE) -> Rn220 | F12: =C12 -> 7.041e-12
B13: 87223 | C13: 3.985815e-12 | D13: =0 -> 0 | E13: =VLOOKUP(B13,Nuclides!A:E,5,FALSE) -> Fr223 | F13: =C13 -> 3.985815e-12
B14: 87222 | C14: 1.4772604e-13 | D14: =0 -> 0 | E14: =VLOOKUP(B14,Nuclides!A:E,5,FALSE) -> Fr222 | F14: =C14 -> 1.4772604e-13
... B29: 82213 | C29: 1.785085e-27 | D29: =0 -> 0 | E29: =VLOOKUP(B29,Nuclides!A:E,5,FALSE) -> Pb213 | F29: =C29 -> 1.785085e-27

Sheet 226N
B3: 88227 | C3: 5.48516e-08 | D3: =0 -> 0 | E3: =VLOOKUP(B3,Nuclides!A:E,5,FALSE) -> Ra227 | F3: =C3 -> 5.48516e-08
B4: 88225 | C4: 2.42237e-09 | D4: =0 -> 0 | E4: =VLOOKUP(B4,Nuclides!A:E,5,FALSE) -> Ra225 | F4: =C4 -> 2.42237e-09
B5: 88224 | C5: 4.9788e-11 | D5: =0 -> 0 | E5: =VLOOKUP(B5,Nuclides!A:E,5,FALSE) -> Ra224 | F5: =C5 -> 4.9788e-11
B6: 52133 | C6: 2.683e-12 | D6: =0 -> 0 | E6: =VLOOKUP(B6,Nuclides!A:E,5,FALSE) -> Te133 | F6: =C6 -> 2.683e-12
B7: 52134 | C7: 2.67e-12 | D7: =0 -> 0 | E7: =VLOOKUP(B7,Nuclides!A:E,5,FALSE) -> Te134 | F7: =C7 -> 2.67e-12
B8: 36090 | C8: 2.665e-12 | D8: =0 -> 0 | E8: =VLOOKUP(B8,Nuclides!A:E,5,FALSE) -> Kr90 | F8: =C8 -> 2.665e-12
B9: 36091 | C9: 2.216e-12 | D9: =0 -> 0 | E9: =VLOOKUP(B9,Nuclides!A:E,5,FALSE) -> Kr91 | F9: =C9 -> 2.216e-12
B10: 42104 | C10: 2.18e-12 | D10: =0 -> 0 | E10: =VLOOKUP(B10,Nuclides!A:E,5,FALSE) -> Mo104 | F10: =C10 -> 2.18e-12
B11: 36089 | C11: 2.153e-12 | D11: =0 -> 0 | E11: =VLOOKUP(B11,Nuclides!A:E,5,FALSE) -> Kr89 | F11: =C11 -> 2.153e-12
B12: 40100 | C12: 2.132e-12 | D12: =0 -> 0 | E12: =VLOOKUP(B12,Nuclides!A:E,5,FALSE) -> Zr100 | F12: =C12 -> 2.132e-12
B13: 53135 | C13: 2.068e-12 | D13: =0 -> 0 | E13: =VLOOKUP(B13,Nuclides!A:E,5,FALSE) -> I135 | F13: =C13 -> 2.068e-12
B14: 48124 | C14: 1.963e-12 | D14: =0 -> 0 | E14: =VLOOKUP(B14,Nuclides!A:E,5,FALSE) -> Cd124 | F14: =C14 -> 1.963e-12
... B482: 64163 | C482: 1e-15 | D482: =0 -> 0 | E482: =VLOOKUP(B482,Nuclides!A:E,5,FALSE) -> Gd163 | F482: =C482 -> 1e-15

Sheet 228P
B3: 88226 | C3: 3.013874e-05 | D3: =0 -> 0 | E3: =VLOOKUP(B3,Nuclides!A:E,5,FALSE) -> Ra226 | F3: =C3 -> 3.013874e-05
B4: 88227 | C4: 2.721906e-05 | D4: =0 -> 0 | E4: =VLOOKUP(B4,Nuclides!A:E,5,FALSE) -> Ra227 | F4: =C4 -> 2.721906e-05
B5: 88228 | C5: 7.691557e-07 | D5: =0 -> 0 | E5: =VLOOKUP(B5,Nuclides!A:E,5,FALSE) -> Ra228 | F5: =C5 -> 7.691557e-07
B6: 88225 | C6: 6.814762e-07 | D6: =0 -> 0 | E6: =VLOOKUP(B6,Nuclides!A:E,5,FALSE) -> Ra225 | F6: =C6 -> 6.814762e-07
B7: 88224 | C7: 2.552777e-09 | D7: =0 -> 0 | E7: =VLOOKUP(B7,Nuclides!A:E,5,FALSE) -> Ra224 | F7: =C7 -> 2.552777e-09
B8: 87227 | C8: 6.865513e-10 | D8: =0 -> 0 | E8: =VLOOKUP(B8,Nuclides!A:E,5,FALSE) -> Fr227 | F8: =C8 -> 6.865513e-10
B9: 87226 | C9: 5.356721e-11 | D9: =0 -> 0 | E9: =VLOOKUP(B9,Nuclides!A:E,5,FALSE) -> Fr226 | F9: =C9 -> 5.356721e-11
B10: 86223 | C10: 2.385638e-12 | D10: =0 -> 0 | E10: =VLOOKUP(B10,Nuclides!A:E,5,FALSE) -> Rn223 | F10: =C10 -> 2.385638e-12
B11: 86224 | C11: 2.025199e-12 | D11: =0 -> 0 | E11: =VLOOKUP(B11,Nuclides!A:E,5,FALSE) -> Rn224 | F11: =C11 -> 2.025199e-12
B12: 87225 | C12: 5.093578e-13 | D12: =0 -> 0 | E12: =VLOOKUP(B12,Nuclides!A:E,5,FALSE) -> Fr225 | F12: =C12 -> 5.093578e-13
B13: 86222 | C13: 1.04117e-13 | D13: =0 -> 0 | E13: =VLOOKUP(B13,Nuclides!A:E,5,FALSE) -> Rn222 | F13: =C13 -> 1.04117e-13
B14: 87224 | C14: 4.187247e-15 | D14: =0 -> 0 | E14: =VLOOKUP(B14,Nuclides!A:E,5,FALSE) -> Fr224 | F14: =C14 -> 4.187247e-15
... B23: 83219 | C23: 7.041516e-30 | D23: =0 -> 0 | E23: =VLOOKUP(B23,Nuclides!A:E,5,FALSE) -> Bi219 | F23: =C23 -> 7.041516e-30

Sheet 228N
B3: 23055 | C3: 1.04282e-15 | D3: =0 -> 0 | E3: =VLOOKUP(B3,Nuclides!A:E,5,FALSE) -> V55 | F3: =C3 -> 1.04282e-15
B4: 24047 | C4: 3.12847e-15 | D4: =0 -> 0 | E4: =VLOOKUP(B4,Nuclides!A:E,5,FALSE) -> Cr47 | F4: =C4 -> 3.12847e-15
B5: 24054 | C5: 4.17129e-15 | D5: =0 -> 0 | E5: =VLOOKUP(B5,Nuclides!A:E,5,FALSE) -> Cr54 | F5: =C5 -> 4.17129e-15
B6: 24055 | C6: 1.04282e-15 | D6: =0 -> 0 | E6: =VLOOKUP(B6,Nuclides!A:E,5,FALSE) -> Cr55 | F6: =C6 -> 1.04282e-15
B7: 25049 | C7: 1.35567e-14 | D7: =0 -> 0 | E7: =VLOOKUP(B7,Nuclides!A:E,5,FALSE) -> Mn49 | F7: =C7 -> 1.35567e-14
B8: 25055 | C8: 1.98136e-14 | D8: =0 -> 0 | E8: =VLOOKUP(B8,Nuclides!A:E,5,FALSE) -> Mn55 | F8: =C8 -> 1.98136e-14
B9: 25056 | C9: 3.12847e-15 | D9: =0 -> 0 | E9: =VLOOKUP(B9,Nuclides!A:E,5,FALSE) -> Mn56 | F9: =C9 -> 3.12847e-15
B10: 25057 | C10: 3.12847e-15 | D10: =0 -> 0 | E10: =VLOOKUP(B10,Nuclides!A:E,5,FALSE) -> Mn57 | F10: =C10 -> 3.12847e-15
B11: 25062 | C11: 9.3854e-15 | D11: =0 -> 0 | E11: =VLOOKUP(B11,Nuclides!A:E,5,FALSE) -> Mn62 | F11: =C11 -> 9.3854e-15
B12: 26052 | C12: 2.60705e-14 | D12: =0 -> 0 | E12: =VLOOKUP(B12,Nuclides!A:E,5,FALSE) -> Fe52 | F12: =C12 -> 2.60705e-14
B13: 26053 | C13: 2.18993e-14 | D13: =0 -> 0 | E13: =VLOOKUP(B13,Nuclides!A:E,5,FALSE) -> Fe53 | F13: =C13 -> 2.18993e-14
B14: 26054 | C14: 3.02418e-14 | D14: =0 -> 0 | E14: =VLOOKUP(B14,Nuclides!A:E,5,FALSE) -> Fe54 | F14: =C14 -> 3.02418e-14
... B639: 88229 | C639: 1.73565e-08 | D639: =0 -> 0 | E639: =VLOOKUP(B639,Nuclides!A:E,5,FALSE) -> Ra229 | F639: =C639 -> 1.73565e-08

Sheet 226
B1: Nuclide | C1: Atom | D1: Activity_Bq | E1: half_life | H1: =B1 -> Nuclide | I1: Atom | J1: Activity_Bq | K1: half_life
B2: Ra225 | C2: 4.6917148e+17 | D2: 2.5261379e+11 | E2: 14.90 天 | G2: x2 | H2: =B2 -> Ra225 | I2: =C2*2 -> 9.3834296e+17 | J2: =D2*2 -> 5.0522758e+11 | K2: =E2 -> 14.90 天
B3: Ra224 | C3: 2.4189538e+17 | D3: 5.3022257e+11 | E3: 3.66 天 | H3: =B3 -> Ra224 | I3: =C3*2 -> 4.8379076e+17 | J3: =D3*2 -> 1.0604451e+12 | K3: =E3 -> 3.66 天
B4: Ac225 | C4: 9.3743327e+16 | D4: 7.5205929e+10 | E4: 10.00 天 | H4: =B4 -> Ac225 | I4: =C4*2 -> 1.8748665e+17 | J4: =D4*2 -> 1.5041186e+11 | K4: =E4 -> 10.00 天
B5: Ra226 | C5: 1.3373708e+16 | D5: 183595.74 | E5: 1601.06 年 | H5: =B5 -> Ra226 | I5: =C5*2 -> 2.6747415e+16 | J5: =D5*2 -> 367191.49 | K5: =E5 -> 1601.06 年
B6: Ra223 | C6: 7.0194575e+15 | D6: 4.9268465e+09 | E6: 11.43 天 | H6: =B6 -> Ra223 | I6: =C6*2 -> 1.4038915e+16 | J6: =D6*2 -> 9.8536931e+09 | K6: =E6 -> 11.43 天
B7: Ac227 | C7: 235741767745601 | D7: 237831.28 | E7: 21.79 年 | H7: =B7 -> Ac227 | I7: =C7*2 -> 471483535491202 | J7: =D7*2 -> 475662.57 | K7: =E7 -> 21.79 年
B8: Rn220 | C8: 4.2529868e+13 | D8: 5.3020608e+11 | E8: 55.60 秒 | H8: =B8 -> Rn220 | I8: =C8*2 -> 8.5059736e+13 | J8: =D8*2 -> 1.0604122e+12 | K8: =E8 -> 55.60 秒
B9: Fr221 | C9: 31873171034138 | D9: 7.5145574e+10 | E9: 4.90 分钟 | H9: =B9 -> Fr221 | I9: =C9*2 -> 63746342068276 | J9: =D9*2 -> 1.5029115e+11 | K9: =E9 -> 4.90 分钟
B10: Ra227 | C10: 1.0013584e+12 | D10: 274126680 | E10: 42.20 分钟 | H10: =B10 -> Ra227 | I10: =C10*2 -> 2.0027168e+12 | J10: =D10*2 -> 548253360 | K10: =E10 -> 42.20 分钟
B11: Rn222 | C11: 1.4707856e+11 | D11: 308602.89 | E11: 3.82 天 | H11: =B11 -> Rn222 | I11: =C11*2 -> 2.9415712e+11 | J11: =D11*2 -> 617205.78 | K11: =E11 -> 3.82 天
B12: Po216 | C12: 1.109138e+11 | D12: 5.3020405e+11 | E12: 1.45e-01 秒 | H12: =B12 -> Po216 | I12: =C12*2 -> 2.218276e+11 | J12: =D12*2 -> 1.0604081e+12 | K12: =E12 -> 1.45e-01 秒
B13: Th227 | C13: 8.9551393e+10 | D13: 38459.815 | E13: 18.68 天 | H13: =B13 -> Th227 | I13: =C13*2 -> 1.7910279e+11 | J13: =D13*2 -> 76919.63 | K13: =E13 -> 18.68 天
B14: Rn219 | C14: 2.8147295e+10 | D14: 4.9268228e+09 | E14: 3.96 秒 | H14: =B14 -> Rn219 | I14: =C14*2 -> 5.6294591e+10 | J14: =D14*2 -> 9.8536457e+09 | K14: =E14 -> 3.96 秒
... B397: Bi213 | C397: 2.4825201 | D397: 0.0006290677 | E397: 45.59 分钟 | H397: =B397 -> Bi213 | I397: =C397*2 -> 4.9650402 | J397: =D397*2 -> 0.0012581354 | K397: =E397 -> 45.59 分钟

Sheet Ra-226
B2: Nuclide | C2: Atom | D2: Activity_Bq | E2: half_life
B3: Ra225 | C3: 9.3834296e+17 | D3: 5.0522758e+11 | E3: 14.90 天
B4: Ra224 | C4: 4.8379076e+17 | D4: 1.0604451e+12 | E4: 3.66 天
B5: Ac225 | C5: 1.8748665e+17 | D5: 1.5041186e+11 | E5: 10.00 天
B6: Ra226 | C6: 2.6747415e+16 | D6: 367191.49 | E6: 1601.06 年
B7: Ra223 | C7: 1.4038915e+16 | D7: 9.8536931e+09 | E7: 11.43 天
B8: Ac227 | C8: 471483535491202 | D8: 475662.57 | E8: 21.79 年
B9: Rn220 | C9: 8.5059736e+13 | D9: 1.0604122e+12 | E9: 55.60 秒
B10: Fr221 | C10: 63746342068276 | D10: 1.5029115e+11 | E10: 4.90 分钟
B11: Ra227 | C11: 2.0027168e+12 | D11: 548253360 | E11: 42.20 分钟
B12: Rn222 | C12: 2.9415712e+11 | D12: 617205.78 | E12: 3.82 天
B13: Po216 | C13: 2.218276e+11 | D13: 1.0604081e+12 | E13: 1.45e-01 秒
B14: Th227 | C14: 1.7910279e+11 | D14: 76919.63 | E14: 18.68 天
... B398: Bi213 | C398: 4.9650402 | D398: 0.0012581354 | E398: 45.59 分钟

Sheet Ra-226-Ra-228
B1: Nuclide | C1: Atom | D1: Activity_Bq | E1: T1/2
B2: Ra225 | C2: 4.7152075e+17 | D2: 2.5387869e+11 | E2: 14.90 天
B3: Ra224 | C3: 2.4190032e+17 | D3: 5.3023338e+11 | E3: 3.66 天
B4: Ra226 | C4: 1.4322859e+17 | D4: 1966258.1 | E4: 1601.06 年
B5: Ac227 | C5: 1.1705234e+17 | D5: 1.1808985e+08 | E5: 21.79 年
B6: Ac225 | C6: 9.4212724e+16 | D6: 7.5582505e+10 | E6: 10.00 天
B7: Ra223 | C7: 7.0194652e+15 | D7: 4.9268519e+09 | E7: 11.43 天
B8: Ra228 | C8: 3.3120932e+15 | D8: 12652183 | E8: 5.75 年
B9: Ra227 | C9: 497202299130367 | D9: 1.3611152e+11 | E9: 42.20 分钟
B10: Th227 | C10: 44463636828658 | D10: 19095887 | E10: 18.68 天
B11: Rn220 | C11: 4.2530736e+13 | D11: 5.302169e+11 | E11: 55.60 秒
B12: Fr221 | C12: 3.2032768e+13 | D12: 7.5521847e+10 | E12: 4.90 分钟
B13: Th228 | C13: 5.0633413e+12 | D13: 58179.629 | E13: 1.91 年
... B545: Nd144 | C545: -2.2495359e+09 | D545: -2.1576858e-14 | E545: 2291519556164383.50 年

Sheet 228
B1: Nuclide | C1: Atom | D1: Activity_Bq | E1: T1/2
B2: Ra226 | C2: 1.2985489e+17 | D2: 1782662.3 | E2: 1601.06 年
B3: Ac227 | C3: 1.168166e+17 | D3: 1.1785202e+08 | E3: 21.79 年
B4: Ra228 | C4: 3.3120932e+15 | D4: 12652183 | E4: 5.75 年
B5: Ra225 | C5: 2.3492654e+15 | D5: 1.2649039e+09 | E5: 14.90 天
B6: Ra227 | C6: 496200940727381 | D6: 1.3583739e+11 | E6: 42.20 分钟
B7: Ac225 | C7: 469397570187569 | D7: 3.7657593e+08 | E7: 10.00 天
B8: Th227 | C8: 4.4374085e+13 | D8: 19057427 | E8: 18.68 天
B9: Th228 | C9: 5.0633413e+12 | D9: 58179.629 | E9: 1.91 年
B10: Ra224 | C10: 4.9346534e+12 | D10: 10816513 | E10: 3.66 天
B11: Rn222 | C11: 4.5763801e+11 | D11: 960224.35 | E11: 3.82 天
B12: Ac228 | C12: 3.8920941e+11 | D12: 12185158 | E12: 6.15 小时
B13: Fr221 | C13: 1.5959738e+11 | D13: 3.7627371e+08 | E13: 4.90 分钟
... B522: Nd144 | C522: -1.8992341e+09 | D522: -1.8216871e-14 | E522: 2291519556164383.50 年

Sheet 226+228
B1: Nuclide | C1: Atom | D1: Activity_Bq | E1: T1/2
B2: Ra225 | C2: 4.7152075e+17 | D2: 2.5387869e+11 | E2: 14.90 天
B3: Ra224 | C3: 2.4190032e+17 | D3: 5.3023338e+11 | E3: 3.66 天
B4: Ra226 | C4: 1.4322859e+17 | D4: 1966258.1 | E4: 1601.06 年
B5: Ac227 | C5: 1.1705234e+17 | D5: 1.1808985e+08 | E5: 21.79 年
B6: Ac225 | C6: 9.4212724e+16 | D6: 7.5582505e+10 | E6: 10.00 天
B7: Ra223 | C7: 7.0194652e+15 | D7: 4.9268519e+09 | E7: 11.43 天
B8: Ra228 | C8: 3.3120932e+15 | D8: 12652183 | E8: 5.75 年
B9: Ra227 | C9: 497202299130367 | D9: 1.3611152e+11 | E9: 42.20 分钟
B10: Th227 | C10: 44463636828658 | D10: 19095887 | E10: 18.68 天
B11: Rn220 | C11: 4.2530736e+13 | D11: 5.302169e+11 | E11: 55.60 秒
B12: Fr221 | C12: 3.2032768e+13 | D12: 7.5521847e+10 | E12: 4.90 分钟
B13: Th228 | C13: 5.0633413e+12 | D13: 58179.629 | E13: 1.91 年
... B545: Nd144 | C545: -2.2495359e+09 | D545: -2.1576858e-14 | E545: 2291519556164383.50 年
