Workbook

Sheet Nuclides
B2: n | C2: z | D2: halflife/s | F2: halflife/s
A3: 1001 | B3: 1 | C3: 0 | D3: 613.9 | F3: 613.9 | G3: 1 | H3: H
A4: 1002 | B4: 1 | C4: 1 | D4: STABLE | E4: H2 | F4: STABLE | G4: 2 | H4: He
A5: 1003 | B5: 2 | C5: 1 | D5: 388789632 | E5: H3 | F5: 388789632 | G5: 3 | H5: Li
A6: 1005 | B6: 4 | C6: 1 | D6: 7.9947368e-23 | E6: H5 | F6: 7.9947368e-23 | G6: 4 | H6: Be
A7: 1006 | B7: 5 | C7: 1 | D7: 2.848125e-22 | E7: H6 | F7: 2.848125e-22 | G7: 5 | H7: B
A8: 2003 | B8: 1 | C8: 2 | D8: STABLE | E8: He3 | F8: STABLE | G8: 6 | H8: C
A9: 2004 | B9: 2 | C9: 2 | D9: STABLE | E9: He4 | F9: STABLE | G9: 7 | H9: N
A10: 2005 | B10: 3 | C10: 2 | D10: 7.595e-22 | E10: He5 | F10: 7.595e-22 | G10: 8 | H10: O
A11: 2006 | B11: 4 | C11: 2 | D11: 0.8067 | E11: He6 | F11: 0.8067 | G11: 9 | H11: F
A12: 2007 | B12: 5 | C12: 2 | D12: 3.038e-21 | E12: He7 | F12: 3.038e-21 | G12: 10 | H12: Ne
A13: 2008 | B13: 6 | C13: 2 | D13: 0.1191 | E13: He8 | F13: 0.1191 | G13: 11 | H13: Na
A14: 2010 | B14: 8 | C14: 2 | D14: 1.519e-21 | E14: He10 | F14: 1.519e-21 | G14: 12 | H14: Mg
A15: 3004 | B15: 1 | C15: 3 | D15: 7.5572139e-23 | E15: Li4 | F15: 7.5572139e-23 | G15: 13 | H15: Al
A16: 3005 | B16: 2 | C16: 3 | D16: 3.038e-22 | E16: Li5 | F16: 3.038e-22 | G16: 14 | H16: Si
A17: 3006 | B17: 3 | C17: 3 | D17: STABLE | E17: Li6 | F17: STABLE | G17: 15 | H17: P
A18: 3007 | B18: 4 | C18: 3 | D18: STABLE | E18: Li7 | F18: STABLE | G18: 16 | H18: S
A19: 3008 | B19: 5 | C19: 3 | D19: 0.8399 | E19: Li8 | F19: 0.8399 | G19: 17 | H19: Cl
A20: 3009 | B20: 6 | C20: 3 | D20: 0.1783 | E20: Li9 | F20: 0.1783 | G20: 18 | H20: Ar
A21: 3011 | B21: 8 | C21: 3 | D21: 0.00875 | E21: Li11 | F21: 0.00875 | G21: 19 | H21: K
A22: 4006 | B22: 2 | C22: 4 | D22: 4.9532609e-21 | E22: Be6 | F22: 4.9532609e-21 | G22: 20 | H22: Ca
A23: 4007 | B23: 3 | C23: 4 | D23: 4598208 | E23: Be7 | F23: 4598208 | G23: 21 | H23: Sc
A24: 4008 | B24: 4 | C24: 4 | D24: 8.1813285e-17 | E24: Be8 | F24: 8.1813285e-17 | G24: 22 | H24: Ti
A25: 4009 | B25: 5 | C25: 4 | D25: STABLE | E25: Be9 | F25: STABLE | G25: 23 | H25: V
A26: 4010 | B26: 6 | C26: 4 | D26: 47651976000000 | E26: Be10 | F26: 47651976000000 | G26: 24 | H26: Cr
A27: 4011 | B27: 7 | C27: 4 | D27: 13.76 | E27: Be11 | F27: 13.76 | G27: 25 | H27: Mn
A28: 4012 | B28: 8 | C28: 4 | D28: 0.02147 | E28: Be12 | F28: 0.02147 | G28: 26 | H28: Fe
A29: 4013 | B29: 9 | C29: 4 | D29: 2.7e-21 | E29: Be13 | F29: 2.7e-21 | G29: 27 | H29: Co
A30: 4014 | B30: 10 | C30: 4 | D30: 0.00435 | E30: Be14 | F30: 0.00435 | G30: 28 | H30: Ni
A31: 4015 | B31: 11 | C31: 4 | D31: 7.8568966e-22 | E31: Be15 | F31: 7.8568966e-22 | G31: 29 | H31: Cu
A32: 4016 | B32: 12 | C32: 4 | D32: 5.69625e-22 | E32: Be16 | F32: 5.69625e-22 | G32: 30 | H32: Zn
A33: 5007 | B33: 2 | C33: 5 | D33: 3.255e-22 | E33: B7 | F33: 3.255e-22 | G33: 31 | H33: Ga
A34: 5008 | B34: 3 | C34: 5 | D34: 0.77 | E34: B8 | F34: 0.77 | G34: 32 | H34: Ge
A35: 5009 | B35: 4 | C35: 5 | D35: 8.4388889e-19 | E35: B9 | F35: 8.4388889e-19 | G35: 33 | H35: As
A36: 5010 | B36: 5 | C36: 5 | D36: STABLE | E36: B10 | F36: STABLE | G36: 34 | H36: Se
A37: 5011 | B37: 6 | C37: 5 | D37: STABLE | E37: B11 | F37: STABLE | G37: 35 | H37: Br
A38: 5012 | B38: 7 | C38: 5 | D38: 0.0202 | E38: B12 | F38: 0.0202 | G38: 36 | H38: Kr
A39: 5013 | B39: 8 | C39: 5 | D39: 0.01733 | E39: B13 | F39: 0.01733 | G39: 37 | H39: Rb
A40: 5014 | B40: 9 | C40: 5 | D40: 0.01236 | E40: B14 | F40: 0.01236 | G40: 38 | H40: Sr
A41: 5015 | B41: 10 | C41: 5 | D41: 0.01018 | E41: B15 | F41: 0.01018 | G41: 39 | H41: Y
...

Sheet Sheet1
B1: Model
B3: 1001 | C3: 0 | G3: 1001 | H3: 0 | L3: 1001 | M3: 0 | P3: 1001 | Q3: 0
B4: 1002 | C4: 0 | G4: 1002 | H4: 0 | L4: 1002 | M4: 0 | P4: 1002 | Q4: 0
B5: 1003 | C5: 0 | G5: 1003 | H5: 0 | L5: 1003 | M5: 0 | P5: 1003 | Q5: 0
B6: 2003 | C6: 0 | G6: 2003 | H6: 0 | L6: 2003 | M6: 0 | P6: 2003 | Q6: 0
B7: 2004 | C7: 0 | G7: 2004 | H7: 0 | L7: 2004 | M7: 0 | P7: 2004 | Q7: 0
B8: 2005 | C8: 0 | G8: 2005 | H8: 0 | L8: 2005 | M8: 0 | P8: 2005 | Q8: 0
B9: 2006 | C9: 0 | G9: 2006 | H9: 0 | L9: 2006 | M9: 0 | P9: 2006 | Q9: 3.49e-10
B10: 2007 | C10: 0 | G10: 2007 | H10: 0 | L10: 2007 | M10: 0 | P10: 2007 | Q10: 0
B11: 2008 | C11: 0 | G11: 2008 | H11: 0 | L11: 2008 | M11: 0 | P11: 2008 | Q11: 0
B12: 3005 | C12: 0 | G12: 3005 | H12: 0 | L12: 3005 | M12: 0 | P12: 3005 | Q12: 0
B13: 3006 | C13: 0 | G13: 3006 | H13: 0 | L13: 3006 | M13: 0 | P13: 3006 | Q13: 1.43983e-06
B14: 3007 | C14: 0 | G14: 3007 | H14: 0 | L14: 3007 | M14: 0 | P14: 3007 | Q14: 9.09145e-07
... B2207: 100260 | C2207: 0 | G2207: 100260 | H2207: 0 | L2207: 100260 | M2207: 0 | P2207: 100260 | Q2207: 0

Sheet Sheet2
C2: Model | J2: Library | R2: ENDF | Z2: CEM
B3: 29062 | C3: 1e-07 | D3: =VLOOKUP(B3,Nuclides!A:E,5,FALSE) -> Cu62 | E3: =VLOOKUP(Sheet2!B3,Nuclides!A:E,2,FALSE) -> 33 | F3: =VLOOKUP(B3,Nuclides!A:E,3,FALSE) -> 29 | G3: =C3*12480000000000000 -> 1248000000 | H3: =VLOOKUP(B3,Nuclides!A:E,4,FALSE) -> 580.38 | J3: 30073 | K3: 1e-07 | L3: =VLOOKUP(J3,Nuclides!A:E,5,FALSE) -> Zn73 | M3: =VLOOKUP(Sheet2!J3,Nuclides!A:E,2,FALSE) -> 43 | N3: =VLOOKUP(J3,Nuclides!A:E,3,FALSE) -> 30 | O3: =K3*12480000000000000 -> 1248000000 | R3: 24051 | S3: 6.98e-11 | T3: =VLOOKUP(R3,Nuclides!A:E,5,FALSE) -> Cr51 | U3: =VLOOKUP(Sheet2!R3,Nuclides!A:E,2,FALSE) -> 27 | V3: =VLOOKUP(R3,Nuclides!A:E,3,FALSE) -> 24 | W3: =S3*12480000000000000 -> 871104 | X3: Cr51 | Z3: 2006 | AA3: 3.49e-10 | AB3: =VLOOKUP(Z3,Nuclides!A:E,5,FALSE) -> He6 | AC3: =VLOOKUP(Sheet2!Z3,Nuclides!A:E,2,FALSE) -> 4 | AD3: =VLOOKUP(Z3,Nuclides!A:E,3,FALSE) -> 2 | AE3: =AA3*12480000000000000 -> 4355520 | AF3: He6
B4: 29073 | C4: 1e-07 | D4: =VLOOKUP(B4,Nuclides!A:E,5,FALSE) -> Cu73 | E4: =VLOOKUP(Sheet2!B4,Nuclides!A:E,2,FALSE) -> 44 | F4: =VLOOKUP(B4,Nuclides!A:E,3,FALSE) -> 29 | G4: =C4*12480000000000000 -> 1248000000 | H4: =VLOOKUP(B4,Nuclides!A:E,4,FALSE) -> 4.2 | J4: 30074 | K4: 1e-07 | L4: =VLOOKUP(J4,Nuclides!A:E,5,FALSE) -> Zn74 | M4: =VLOOKUP(Sheet2!J4,Nuclides!A:E,2,FALSE) -> 44 | N4: =VLOOKUP(J4,Nuclides!A:E,3,FALSE) -> 30 | O4: =K4*12480000000000000 -> 1248000000 | R4: 25050 | S4: 6.98e-11 | T4: =VLOOKUP(R4,Nuclides!A:E,5,FALSE) -> Mn50 | U4: =VLOOKUP(Sheet2!R4,Nuclides!A:E,2,FALSE) -> 25 | V4: =VLOOKUP(R4,Nuclides!A:E,3,FALSE) -> 25 | W4: =S4*12480000000000000 -> 871104 | X4: Mn50 | Z4: 3006 | AA4: 1.43983e-06 | AB4: =VLOOKUP(Z4,Nuclides!A:E,5,FALSE) -> Li6 | AC4: =VLOOKUP(Sheet2!Z4,Nuclides!A:E,2,FALSE) -> 3 | AD4: =VLOOKUP(Z4,Nuclides!A:E,3,FALSE) -> 3 | AE4: =AA4*12480000000000000 -> 17969078400 | AF4: Li6
B5: 30058 | C5: 1e-07 | D5: =VLOOKUP(B5,Nuclides!A:E,5,FALSE) -> Zn58 | E5: =VLOOKUP(Sheet2!B5,Nuclides!A:E,2,FALSE) -> 28 | F5: =VLOOKUP(B5,Nuclides!A:E,3,FALSE) -> 30 | G5: =C5*12480000000000000 -> 1248000000 | H5: =VLOOKUP(B5,Nuclides!A:E,4,FALSE) -> 0.086 | J5: 30075 | K5: 4e-07 | L5: =VLOOKUP(J5,Nuclides!A:E,5,FALSE) -> Zn75 | M5: =VLOOKUP(Sheet2!J5,Nuclides!A:E,2,FALSE) -> 45 | N5: =VLOOKUP(J5,Nuclides!A:E,3,FALSE) -> 30 | O5: =K5*12480000000000000 -> 4992000000 | R5: 25053 | S5: 6.98e-11 | T5: =VLOOKUP(R5,Nuclides!A:E,5,FALSE) -> Mn53 | U5: =VLOOKUP(Sheet2!R5,Nuclides!A:E,2,FALSE) -> 28 | V5: =VLOOKUP(R5,Nuclides!A:E,3,FALSE) -> 25 | W5: =S5*12480000000000000 -> 871104 | X5: Mn53 | Z5: 3007 | AA5: 9.09145e-07 | AB5: =VLOOKUP(Z5,Nuclides!A:E,5,FALSE) -> Li7 | AC5: =VLOOKUP(Sheet2!Z5,Nuclides!A:E,2,FALSE) -> 4 | AD5: =VLOOKUP(Z5,Nuclides!A:E,3,FALSE) -> 3 | AE5: =AA5*12480000000000000 -> 11346129600 | AF5: Li7
B6: 30073 | C6: 3e-07 | D6: =VLOOKUP(B6,Nuclides!A:E,5,FALSE) -> Zn73 | E6: =VLOOKUP(Sheet2!B6,Nuclides!A:E,2,FALSE) -> 43 | F6: =VLOOKUP(B6,Nuclides!A:E,3,FALSE) -> 30 | G6: =C6*12480000000000000 -> 3744000000 | H6: =VLOOKUP(B6,Nuclides!A:E,4,FALSE) -> 23.5 | J6: 30077 | K6: 2e-07 | L6: =VLOOKUP(J6,Nuclides!A:E,5,FALSE) -> Zn77 | M6: =VLOOKUP(Sheet2!J6,Nuclides!A:E,2,FALSE) -> 47 | N6: =VLOOKUP(J6,Nuclides!A:E,3,FALSE) -> 30 | O6: =K6*12480000000000000 -> 2496000000 | R6: 25060 | S6: 6.98e-11 | T6: =VLOOKUP(R6,Nuclides!A:E,5,FALSE) -> Mn60 | U6: =VLOOKUP(Sheet2!R6,Nuclides!A:E,2,FALSE) -> 35 | V6: =VLOOKUP(R6,Nuclides!A:E,3,FALSE) -> 25 | W6: =S6*12480000000000000 -> 871104 | X6: Mn60 | Z6: 3008 | AA6: 2.094e-10 | AB6: =VLOOKUP(Z6,Nuclides!A:E,5,FALSE) -> Li8 | AC6: =VLOOKUP(Sheet2!Z6,Nuclides!A:E,2,FALSE) -> 5 | AD6: =VLOOKUP(Z6,Nuclides!A:E,3,FALSE) -> 3 | AE6: =AA6*12480000000000000 -> 2613312 | AF6: Li8
B7: 30076 | C7: 1e-07 | D7: =VLOOKUP(B7,Nuclides!A:E,5,FALSE) -> Zn76 | E7: =VLOOKUP(Sheet2!B7,Nuclides!A:E,2,FALSE) -> 46 | F7: =VLOOKUP(B7,Nuclides!A:E,3,FALSE) -> 30 | G7: =C7*12480000000000000 -> 1248000000 | H7: =VLOOKUP(B7,Nuclides!A:E,4,FALSE) -> 5.7 | J7: 30078 | K7: 2e-07 | L7: =VLOOKUP(J7,Nuclides!A:E,5,FALSE) -> Zn78 | M7: =VLOOKUP(Sheet2!J7,Nuclides!A:E,2,FALSE) -> 48 | N7: =VLOOKUP(J7,Nuclides!A:E,3,FALSE) -> 30 | O7: =K7*12480000000000000 -> 2496000000 | R7: 26052 | S7: 6.98e-11 | T7: =VLOOKUP(R7,Nuclides!A:E,5,FALSE) -> Fe52 | U7: =VLOOKUP(Sheet2!R7,Nuclides!A:E,2,FALSE) -> 26 | V7: =VLOOKUP(R7,Nuclides!A:E,3,FALSE) -> 26 | W7: =S7*12480000000000000 -> 871104 | X7: Fe52 | Z7: 4007 | AA7: 3.39598e-06 | AB7: =VLOOKUP(Z7,Nuclides!A:E,5,FALSE) -> Be7 | AC7: =VLOOKUP(Sheet2!Z7,Nuclides!A:E,2,FALSE) -> 3 | AD7: =VLOOKUP(Z7,Nuclides!A:E,3,FALSE) -> 4 | AE7: =AA7*12480000000000000 -> 42381830400 | AF7: Be7
B8: 30077 | C8: 1e-07 | D8: =VLOOKUP(B8,Nuclides!A:E,5,FALSE) -> Zn77 | E8: =VLOOKUP(Sheet2!B8,Nuclides!A:E,2,FALSE) -> 47 | F8: =VLOOKUP(B8,Nuclides!A:E,3,FALSE) -> 30 | G8: =C8*12480000000000000 -> 1248000000 | H8: =VLOOKUP(B8,Nuclides!A:E,4,FALSE) -> 2.08 | J8: 31075 | K8: 2e-07 | L8: =VLOOKUP(J8,Nuclides!A:E,5,FALSE) -> Ga75 | M8: =VLOOKUP(Sheet2!J8,Nuclides!A:E,2,FALSE) -> 44 | N8: =VLOOKUP(J8,Nuclides!A:E,3,FALSE) -> 31 | O8: =K8*12480000000000000 -> 2496000000 | R8: 26053 | S8: 1.396e-10 | T8: =VLOOKUP(R8,Nuclides!A:E,5,FALSE) -> Fe53 | U8: =VLOOKUP(Sheet2!R8,Nuclides!A:E,2,FALSE) -> 27 | V8: =VLOOKUP(R8,Nuclides!A:E,3,FALSE) -> 26 | W8: =S8*12480000000000000 -> 1742208 | X8: Fe53 | Z8: 4009 | AA8: 7.84901e-07 | AB8: =VLOOKUP(Z8,Nuclides!A:E,5,FALSE) -> Be9 | AC8: =VLOOKUP(Sheet2!Z8,Nuclides!A:E,2,FALSE) -> 5 | AD8: =VLOOKUP(Z8,Nuclides!A:E,3,FALSE) -> 4 | AE8: =AA8*12480000000000000 -> 9795564480 | AF8: Be9
B9: 30078 | C9: 2e-07 | D9: =VLOOKUP(B9,Nuclides!A:E,5,FALSE) -> Zn78 | E9: =VLOOKUP(Sheet2!B9,Nuclides!A:E,2,FALSE) -> 48 | F9: =VLOOKUP(B9,Nuclides!A:E,3,FALSE) -> 30 | G9: =C9*12480000000000000 -> 2496000000 | H9: =VLOOKUP(B9,Nuclides!A:E,4,FALSE) -> 1.47 | J9: 31077 | K9: 2e-07 | L9: =VLOOKUP(J9,Nuclides!A:E,5,FALSE) -> Ga77 | M9: =VLOOKUP(Sheet2!J9,Nuclides!A:E,2,FALSE) -> 46 | N9: =VLOOKUP(J9,Nuclides!A:E,3,FALSE) -> 31 | O9: =K9*12480000000000000 -> 2496000000 | R9: 26061 | S9: 6.98e-11 | T9: =VLOOKUP(R9,Nuclides!A:E,5,FALSE) -> Fe61 | U9: =VLOOKUP(Sheet2!R9,Nuclides!A:E,2,FALSE) -> 35 | V9: =VLOOKUP(R9,Nuclides!A:E,3,FALSE) -> 26 | W9: =S9*12480000000000000 -> 871104 | X9: Fe61 | Z9: 4010 | AA9: 1.23197e-07 | AB9: =VLOOKUP(Z9,Nuclides!A:E,5,FALSE) -> Be10 | AC9: =VLOOKUP(Sheet2!Z9,Nuclides!A:E,2,FALSE) -> 6 | AD9: =VLOOKUP(Z9,Nuclides!A:E,3,FALSE) -> 4 | AE9: =AA9*12480000000000000 -> 1.5374986e+09 | AF9: Be10
B10: 31063 | C10: 1e-07 | D10: =VLOOKUP(B10,Nuclides!A:E,5,FALSE) -> Ga63 | E10: =VLOOKUP(Sheet2!B10,Nuclides!A:E,2,FALSE) -> 32 | F10: =VLOOKUP(B10,Nuclides!A:E,3,FALSE) -> 31 | G10: =C10*12480000000000000 -> 1248000000 | H10: =VLOOKUP(B10,Nuclides!A:E,4,FALSE) -> 32.4 | J10: 31078 | K10: 1e-07 | L10: =VLOOKUP(J10,Nuclides!A:E,5,FALSE) -> Ga78 | M10: =VLOOKUP(Sheet2!J10,Nuclides!A:E,2,FALSE) -> 47 | N10: =VLOOKUP(J10,Nuclides!A:E,3,FALSE) -> 31 | O10: =K10*12480000000000000 -> 1248000000 | R10: 26064 | S10: 6.98e-11 | T10: =VLOOKUP(R10,Nuclides!A:E,5,FALSE) -> Fe64 | U10: =VLOOKUP(Sheet2!R10,Nuclides!A:E,2,FALSE) -> 38 | V10: =VLOOKUP(R10,Nuclides!A:E,3,FALSE) -> 26 | W10: =S10*12480000000000000 -> 871104 | X10: Fe64 | Z10: 5008 | AA10: 5.584e-10 | AB10: =VLOOKUP(Z10,Nuclides!A:E,5,FALSE) -> B8 | AC10: =VLOOKUP(Sheet2!Z10,Nuclides!A:E,2,FALSE) -> 3 | AD10: =VLOOKUP(Z10,Nuclides!A:E,3,FALSE) -> 5 | AE10: =AA10*12480000000000000 -> 6968832 | AF10: B8
B11: 31077 | C11: 2e-07 | D11: =VLOOKUP(B11,Nuclides!A:E,5,FALSE) -> Ga77 | E11: =VLOOKUP(Sheet2!B11,Nuclides!A:E,2,FALSE) -> 46 | F11: =VLOOKUP(B11,Nuclides!A:E,3,FALSE) -> 31 | G11: =C11*12480000000000000 -> 2496000000 | H11: =VLOOKUP(B11,Nuclides!A:E,4,FALSE) -> 13.2 | J11: 31079 | K11: 4e-07 | L11: =VLOOKUP(J11,Nuclides!A:E,5,FALSE) -> Ga79 | M11: =VLOOKUP(Sheet2!J11,Nuclides!A:E,2,FALSE) -> 48 | N11: =VLOOKUP(J11,Nuclides!A:E,3,FALSE) -> 31 | O11: =K11*12480000000000000 -> 4992000000 | R11: 27053 | S11: 1.396e-10 | T11: =VLOOKUP(R11,Nuclides!A:E,5,FALSE) -> Co53 | U11: =VLOOKUP(Sheet2!R11,Nuclides!A:E,2,FALSE) -> 26 | V11: =VLOOKUP(R11,Nuclides!A:E,3,FALSE) -> 27 | W11: =S11*12480000000000000 -> 1742208 | X11: Co53 | Z11: 5010 | AA11: 6.33072e-06 | AB11: =VLOOKUP(Z11,Nuclides!A:E,5,FALSE) -> B10 | AC11: =VLOOKUP(Sheet2!Z11,Nuclides!A:E,2,FALSE) -> 5 | AD11: =VLOOKUP(Z11,Nuclides!A:E,3,FALSE) -> 5 | AE11: =AA11*12480000000000000 -> 79007385600 | AF11: B10
B12: 31079 | C12: 7e-07 | D12: =VLOOKUP(B12,Nuclides!A:E,5,FALSE) -> Ga79 | E12: =VLOOKUP(Sheet2!B12,Nuclides!A:E,2,FALSE) -> 48 | F12: =VLOOKUP(B12,Nuclides!A:E,3,FALSE) -> 31 | G12: =C12*12480000000000000 -> 8736000000 | H12: =VLOOKUP(B12,Nuclides!A:E,4,FALSE) -> 2.847 | J12: 31080 | K12: 2e-07 | L12: =VLOOKUP(J12,Nuclides!A:E,5,FALSE) -> Ga80 | M12: =VLOOKUP(Sheet2!J12,Nuclides!A:E,2,FALSE) -> 49 | N12: =VLOOKUP(J12,Nuclides!A:E,3,FALSE) -> 31 | O12: =K12*12480000000000000 -> 2496000000 | R12: 27054 | S12: 2.792e-10 | T12: =VLOOKUP(R12,Nuclides!A:E,5,FALSE) -> Co54 | U12: =VLOOKUP(Sheet2!R12,Nuclides!A:E,2,FALSE) -> 27 | V12: =VLOOKUP(R12,Nuclides!A:E,3,FALSE) -> 27 | W12: =S12*12480000000000000 -> 3484416 | X12: Co54 | Z12: 5011 | AA12: 3.32359e-05 | AB12: =VLOOKUP(Z12,Nuclides!A:E,5,FALSE) -> B11 | AC12: =VLOOKUP(Sheet2!Z12,Nuclides!A:E,2,FALSE) -> 6 | AD12: =VLOOKUP(Z12,Nuclides!A:E,3,FALSE) -> 5 | AE12: =AA12*12480000000000000 -> 414784032000 | AF12: B11
B13: 31080 | C13: 1e-07 | D13: =VLOOKUP(B13,Nuclides!A:E,5,FALSE) -> Ga80 | E13: =VLOOKUP(Sheet2!B13,Nuclides!A:E,2,FALSE) -> 49 | F13: =VLOOKUP(B13,Nuclides!A:E,3,FALSE) -> 31 | G13: =C13*12480000000000000 -> 1248000000 | H13: =VLOOKUP(B13,Nuclides!A:E,4,FALSE) -> 1.9 | J13: 31081 | K13: 2e-07 | L13: =VLOOKUP(J13,Nuclides!A:E,5,FALSE) -> Ga81 | M13: =VLOOKUP(Sheet2!J13,Nuclides!A:E,2,FALSE) -> 50 | N13: =VLOOKUP(J13,Nuclides!A:E,3,FALSE) -> 31 | O13: =K13*12480000000000000 -> 2496000000 | R13: 27055 | S13: 6.98e-11 | T13: =VLOOKUP(R13,Nuclides!A:E,5,FALSE) -> Co55 | U13: =VLOOKUP(Sheet2!R13,Nuclides!A:E,2,FALSE) -> 28 | V13: =VLOOKUP(R13,Nuclides!A:E,3,FALSE) -> 27 | W13: =S13*12480000000000000 -> 871104 | X13: Co55 | Z13: 6010 | AA13: 1.43788e-08 | AB13: =VLOOKUP(Z13,Nuclides!A:E,5,FALSE) -> C10 | AC13: =VLOOKUP(Sheet2!Z13,Nuclides!A:E,2,FALSE) -> 4 | AD13: =VLOOKUP(Z13,Nuclides!A:E,3,FALSE) -> 6 | AE13: =AA13*12480000000000000 -> 179447424 | AF13: C10
B14: 31081 | C14: 1.3e-06 | D14: =VLOOKUP(B14,Nuclides!A:E,5,FALSE) -> Ga81 | E14: =VLOOKUP(Sheet2!B14,Nuclides!A:E,2,FALSE) -> 50 | F14: =VLOOKUP(B14,Nuclides!A:E,3,FALSE) -> 31 | G14: =C14*12480000000000000 -> 16224000000 | H14: =VLOOKUP(B14,Nuclides!A:E,4,FALSE) -> 1.217 | J14: 32075 | K14: 2e-07 | L14: =VLOOKUP(J14,Nuclides!A:E,5,FALSE) -> Ge75 | M14: =VLOOKUP(Sheet2!J14,Nuclides!A:E,2,FALSE) -> 43 | N14: =VLOOKUP(J14,Nuclides!A:E,3,FALSE) -> 32 | O14: =K14*12480000000000000 -> 2496000000 | R14: 27056 | S14: 2.792e-10 | T14: =VLOOKUP(R14,Nuclides!A:E,5,FALSE) -> Co56 | U14: =VLOOKUP(Sheet2!R14,Nuclides!A:E,2,FALSE) -> 29 | V14: =VLOOKUP(R14,Nuclides!A:E,3,FALSE) -> 27 | W14: =S14*12480000000000000 -> 3484416 | X14: Co56 | Z14: 6011 | AA14: 8.16465e-06 | AB14: =VLOOKUP(Z14,Nuclides!A:E,5,FALSE) -> C11 | AC14: =VLOOKUP(Sheet2!Z14,Nuclides!A:E,2,FALSE) -> 5 | AD14: =VLOOKUP(Z14,Nuclides!A:E,3,FALSE) -> 6 | AE14: =AA14*12480000000000000 -> 101894832000 | AF14: C11
... B408: 92238 | C408: 0.000108 | D408: =VLOOKUP(B408,Nuclides!A:E,5,FALSE) -> U238 | E408: =VLOOKUP(Sheet2!B408,Nuclides!A:E,2,FALSE) -> 146 | F408: =VLOOKUP(B408,Nuclides!A:E,3,FALSE) -> 92 | G408: =C408*12480000000000000 -> 1347840000000 | H408: =VLOOKUP(B408,Nuclides!A:E,4,FALSE) -> 1.4099936e+17 | J408: 92235 | K408: 4.12e-05 | L408: =VLOOKUP(J408,Nuclides!A:E,5,FALSE) -> U235 | M408: =VLOOKUP(Sheet2!J408,Nuclides!A:E,2,FALSE) -> 143 | N408: =VLOOKUP(J408,Nuclides!A:E,3,FALSE) -> 92 | O408: =K408*12480000000000000 -> 514176000000 | R408: 47098 | S408: 1.95091e-07 | T408: =VLOOKUP(R408,Nuclides!A:E,5,FALSE) -> Ag98 | U408: =VLOOKUP(Sheet2!R408,Nuclides!A:E,2,FALSE) -> 51 | V408: =VLOOKUP(R408,Nuclides!A:E,3,FALSE) -> 47 | W408: =S408*12480000000000000 -> 2434735680 | X408: Ag98 | Z408: 46110 | AA408: 2.84086e-08 | AB408: =VLOOKUP(Z408,Nuclides!A:E,5,FALSE) -> Pd110 | AC408: =VLOOKUP(Sheet2!Z408,Nuclides!A:E,2,FALSE) -> 64 | AD408: =VLOOKUP(Z408,Nuclides!A:E,3,FALSE) -> 46 | AE408: =AA408*12480000000000000 -> 354539328 | AF408: Pd110
J409: 92236 | K409: 0.0015837 | L409: =VLOOKUP(J409,Nuclides!A:E,5,FALSE) -> U236 | M409: =VLOOKUP(Sheet2!J409,Nuclides!A:E,2,FALSE) -> 144 | N409: =VLOOKUP(J409,Nuclides!A:E,3,FALSE) -> 92 | O409: =K409*12480000000000000 -> 19764576000000 | R409: 47099 | S409: 7.40578e-08 | T409: =VLOOKUP(R409,Nuclides!A:E,5,FALSE) -> Ag99 | U409: =VLOOKUP(Sheet2!R409,Nuclides!A:E,2,FALSE) -> 52 | V409: =VLOOKUP(R409,Nuclides!A:E,3,FALSE) -> 47 | W409: =S409*12480000000000000 -> 924241344 | X409: Ag99 | Z409: 46111 | AA409: 7.53142e-08 | AB409: =VLOOKUP(Z409,Nuclides!A:E,5,FALSE) -> Pd111 | AC409: =VLOOKUP(Sheet2!Z409,Nuclides!A:E,2,FALSE) -> 65 | AD409: =VLOOKUP(Z409,Nuclides!A:E,3,FALSE) -> 46 | AE409: =AA409*12480000000000000 -> 9.3992122e+08 | AF409: Pd111
J410: 92237 | K410: 8.2e-06 | L410: =VLOOKUP(J410,Nuclides!A:E,5,FALSE) -> U237 | M410: =VLOOKUP(Sheet2!J410,Nuclides!A:E,2,FALSE) -> 145 | N410: =VLOOKUP(J410,Nuclides!A:E,3,FALSE) -> 92 | O410: =K410*12480000000000000 -> 102336000000 | R410: 47100 | S410: 2.094e-08 | T410: =VLOOKUP(R410,Nuclides!A:E,5,FALSE) -> Ag100 | U410: =VLOOKUP(Sheet2!R410,Nuclides!A:E,2,FALSE) -> 53 | V410: =VLOOKUP(R410,Nuclides!A:E,3,FALSE) -> 47 | W410: =S410*12480000000000000 -> 261331200 | X410: Ag100 | Z410: 46112 | AA410: 3.01815e-07 | AB410: =VLOOKUP(Z410,Nuclides!A:E,5,FALSE) -> Pd112 | AC410: =VLOOKUP(Sheet2!Z410,Nuclides!A:E,2,FALSE) -> 66 | AD410: =VLOOKUP(Z410,Nuclides!A:E,3,FALSE) -> 46 | AE410: =AA410*12480000000000000 -> 3766651200 | AF410: Pd112
R411: 47101 | S411: 5.7934e-09 | T411: =VLOOKUP(R411,Nuclides!A:E,5,FALSE) -> Ag101 | U411: =VLOOKUP(Sheet2!R411,Nuclides!A:E,2,FALSE) -> 54 | V411: =VLOOKUP(R411,Nuclides!A:E,3,FALSE) -> 47 | W411: =S411*12480000000000000 -> 72301632 | X411: Ag101 | Z411: 46113 | AA411: 4.3967e-07 | AB411: =VLOOKUP(Z411,Nuclides!A:E,5,FALSE) -> Pd113 | AC411: =VLOOKUP(Sheet2!Z411,Nuclides!A:E,2,FALSE) -> 67 | AD411: =VLOOKUP(Z411,Nuclides!A:E,3,FALSE) -> 46 | AE411: =AA411*12480000000000000 -> 5487081600 | AF411: Pd113
R412: 47102 | S412: 1.1866e-09 | T412: =VLOOKUP(R412,Nuclides!A:E,5,FALSE) -> Ag102 | U412: =VLOOKUP(Sheet2!R412,Nuclides!A:E,2,FALSE) -> 55 | V412: =VLOOKUP(R412,Nuclides!A:E,3,FALSE) -> 47 | W412: =S412*12480000000000000 -> 14808768 | X412: Ag102 | Z412: 46114 | AA412: 1.04833e-06 | AB412: =VLOOKUP(Z412,Nuclides!A:E,5,FALSE) -> Pd114 | AC412: =VLOOKUP(Sheet2!Z412,Nuclides!A:E,2,FALSE) -> 68 | AD412: =VLOOKUP(Z412,Nuclides!A:E,3,FALSE) -> 46 | AE412: =AA412*12480000000000000 -> 13083158400 | AF412: Pd114
R413: 47103 | S413: 2.792e-10 | T413: =VLOOKUP(R413,Nuclides!A:E,5,FALSE) -> Ag103 | U413: =VLOOKUP(Sheet2!R413,Nuclides!A:E,2,FALSE) -> 56 | V413: =VLOOKUP(R413,Nuclides!A:E,3,FALSE) -> 47 | W413: =S413*12480000000000000 -> 3484416 | X413: Ag103 | Z413: 46115 | AA413: 9.41811e-07 | AB413: =VLOOKUP(Z413,Nuclides!A:E,5,FALSE) -> Pd115 | AC413: =VLOOKUP(Sheet2!Z413,Nuclides!A:E,2,FALSE) -> 69 | AD413: =VLOOKUP(Z413,Nuclides!A:E,3,FALSE) -> 46 | AE413: =AA413*12480000000000000 -> 11753801280 | AF413: Pd115
R414: 47111 | S414: 4.886e-10 | T414: =VLOOKUP(R414,Nuclides!A:E,5,FALSE) -> Ag111 | U414: =VLOOKUP(Sheet2!R414,Nuclides!A:E,2,FALSE) -> 64 | V414: =VLOOKUP(R414,Nuclides!A:E,3,FALSE) -> 47 | W414: =S414*12480000000000000 -> 6097728 | X414: Ag111 | Z414: 46116 | AA414: 1.46845e-06 | AB414: =VLOOKUP(Z414,Nuclides!A:E,5,FALSE) -> Pd116 | AC414: =VLOOKUP(Sheet2!Z414,Nuclides!A:E,2,FALSE) -> 70 | AD414: =VLOOKUP(Z414,Nuclides!A:E,3,FALSE) -> 46 | AE414: =AA414*12480000000000000 -> 18326256000 | AF414: Pd116
R415: 47112 | S415: 3.3504e-09 | T415: =VLOOKUP(R415,Nuclides!A:E,5,FALSE) -> Ag112 | U415: =VLOOKUP(Sheet2!R415,Nuclides!A:E,2,FALSE) -> 65 | V415: =VLOOKUP(R415,Nuclides!A:E,3,FALSE) -> 47 | W415: =S415*12480000000000000 -> 41812992 | X415: Ag112 | Z415: 46117 | AA415: 8.78782e-07 | AB415: =VLOOKUP(Z415,Nuclides!A:E,5,FALSE) -> Pd117 | AC415: =VLOOKUP(Sheet2!Z415,Nuclides!A:E,2,FALSE) -> 71 | AD415: =VLOOKUP(Z415,Nuclides!A:E,3,FALSE) -> 46 | AE415: =AA415*12480000000000000 -> 10967199360 | AF415: Pd117
R416: 47113 | S416: 2.38018e-08 | T416: =VLOOKUP(R416,Nuclides!A:E,5,FALSE) -> Ag113 | U416: =VLOOKUP(Sheet2!R416,Nuclides!A:E,2,FALSE) -> 66 | V416: =VLOOKUP(R416,Nuclides!A:E,3,FALSE) -> 47 | W416: =S416*12480000000000000 -> 297046464 | X416: Ag113 | Z416: 46118 | AA416: 1.05203e-06 | AB416: =VLOOKUP(Z416,Nuclides!A:E,5,FALSE) -> Pd118 | AC416: =VLOOKUP(Sheet2!Z416,Nuclides!A:E,2,FALSE) -> 72 | AD416: =VLOOKUP(Z416,Nuclides!A:E,3,FALSE) -> 46 | AE416: =AA416*12480000000000000 -> 13129334400 | AF416: Pd118
R417: 47114 | S417: 5.85622e-08 | T417: =VLOOKUP(R417,Nuclides!A:E,5,FALSE) -> Ag114 | U417: =VLOOKUP(Sheet2!R417,Nuclides!A:E,2,FALSE) -> 67 | V417: =VLOOKUP(R417,Nuclides!A:E,3,FALSE) -> 47 | W417: =S417*12480000000000000 -> 730856256 | X417: Ag114 | Z417: 47096 | AA417: 4.92997e-07 | AB417: =VLOOKUP(Z417,Nuclides!A:E,5,FALSE) -> Ag96 | AC417: =VLOOKUP(Sheet2!Z417,Nuclides!A:E,2,FALSE) -> 49 | AD417: =VLOOKUP(Z417,Nuclides!A:E,3,FALSE) -> 47 | AE417: =AA417*12480000000000000 -> 6152602560 | AF417: Ag96
R418: 47115 | S418: 2.05421e-07 | T418: =VLOOKUP(R418,Nuclides!A:E,5,FALSE) -> Ag115 | U418: =VLOOKUP(Sheet2!R418,Nuclides!A:E,2,FALSE) -> 68 | V418: =VLOOKUP(R418,Nuclides!A:E,3,FALSE) -> 47 | W418: =S418*12480000000000000 -> 2563654080 | X418: Ag115 | Z418: 47097 | AA418: 4.58028e-07 | AB418: =VLOOKUP(Z418,Nuclides!A:E,5,FALSE) -> Ag97 | AC418: =VLOOKUP(Sheet2!Z418,Nuclides!A:E,2,FALSE) -> 50 | AD418: =VLOOKUP(Z418,Nuclides!A:E,3,FALSE) -> 47 | AE418: =AA418*12480000000000000 -> 5716189440 | AF418: Ag97
R419: 47116 | S419: 3.3846e-07 | T419: =VLOOKUP(R419,Nuclides!A:E,5,FALSE) -> Ag116 | U419: =VLOOKUP(Sheet2!R419,Nuclides!A:E,2,FALSE) -> 69 | V419: =VLOOKUP(R419,Nuclides!A:E,3,FALSE) -> 47 | W419: =S419*12480000000000000 -> 4.2239808e+09 | X419: Ag116 | Z419: 47098 | AA419: 1.86296e-07 | AB419: =VLOOKUP(Z419,Nuclides!A:E,5,FALSE) -> Ag98 | AC419: =VLOOKUP(Sheet2!Z419,Nuclides!A:E,2,FALSE) -> 51 | AD419: =VLOOKUP(Z419,Nuclides!A:E,3,FALSE) -> 47 | AE419: =AA419*12480000000000000 -> 2324974080 | AF419: Ag98
R420: 47117 | S420: 7.50908e-07 | T420: =VLOOKUP(R420,Nuclides!A:E,5,FALSE) -> Ag117 | U420: =VLOOKUP(Sheet2!R420,Nuclides!A:E,2,FALSE) -> 70 | V420: =VLOOKUP(R420,Nuclides!A:E,3,FALSE) -> 47 | W420: =S420*12480000000000000 -> 9371331840 | X420: Ag117 | Z420: 47099 | AA420: 1.06585e-07 | AB420: =VLOOKUP(Z420,Nuclides!A:E,5,FALSE) -> Ag99 | AC420: =VLOOKUP(Sheet2!Z420,Nuclides!A:E,2,FALSE) -> 52 | AD420: =VLOOKUP(Z420,Nuclides!A:E,3,FALSE) -> 47 | AE420: =AA420*12480000000000000 -> 1330180800 | AF420: Ag99
R421: 47118 | S421: 8.15404e-07 | T421: =VLOOKUP(R421,Nuclides!A:E,5,FALSE) -> Ag118 | U421: =VLOOKUP(Sheet2!R421,Nuclides!A:E,2,FALSE) -> 71 | V421: =VLOOKUP(R421,Nuclides!A:E,3,FALSE) -> 47 | W421: =S421*12480000000000000 -> 10176241920 | X421: Ag118 | Z421: 47100 | AA421: 2.98744e-08 | AB421: =VLOOKUP(Z421,Nuclides!A:E,5,FALSE) -> Ag100 | AC421: =VLOOKUP(Sheet2!Z421,Nuclides!A:E,2,FALSE) -> 53 | AD421: =VLOOKUP(Z421,Nuclides!A:E,3,FALSE) -> 47 | AE421: =AA421*12480000000000000 -> 372832512 | AF421: Ag100
R422: 47119 | S422: 1.16398e-06 | T422: =VLOOKUP(R422,Nuclides!A:E,5,FALSE) -> Ag119 | U422: =VLOOKUP(Sheet2!R422,Nuclides!A:E,2,FALSE) -> 72 | V422: =VLOOKUP(R422,Nuclides!A:E,3,FALSE) -> 47 | W422: =S422*12480000000000000 -> 1.452647e+10 | X422: Ag119 | Z422: 47101 | AA422: 1.82876e-08 | AB422: =VLOOKUP(Z422,Nuclides!A:E,5,FALSE) -> Ag101 | AC422: =VLOOKUP(Sheet2!Z422,Nuclides!A:E,2,FALSE) -> 54 | AD422: =VLOOKUP(Z422,Nuclides!A:E,3,FALSE) -> 47 | AE422: =AA422*12480000000000000 -> 228229248 | AF422: Ag101
... R817: 92237 | S817: 7.2703e-06 | T817: =VLOOKUP(R817,Nuclides!A:E,5,FALSE) -> U237 | U817: =VLOOKUP(Sheet2!R817,Nuclides!A:E,2,FALSE) -> 145 | V817: =VLOOKUP(R817,Nuclides!A:E,3,FALSE) -> 92 | W817: =S817*12480000000000000 -> 90733344000 | X817: U237 | Z817: 67153 | AA817: 6.98e-11 | AB817: =VLOOKUP(Z817,Nuclides!A:E,5,FALSE) -> Ho153 | AC817: =VLOOKUP(Sheet2!Z817,Nuclides!A:E,2,FALSE) -> 86 | AD817: =VLOOKUP(Z817,Nuclides!A:E,3,FALSE) -> 67 | AE817: =AA817*12480000000000000 -> 871104 | AF817: Ho153
R818: 20100 | S818: 0 | Z818: 67168 | AA818: 1.396e-10 | AB818: =VLOOKUP(Z818,Nuclides!A:E,5,FALSE) -> Ho168 | AC818: =VLOOKUP(Sheet2!Z818,Nuclides!A:E,2,FALSE) -> 101 | AD818: =VLOOKUP(Z818,Nuclides!A:E,3,FALSE) -> 67 | AE818: =AA818*12480000000000000 -> 1742208 | AF818: Ho168
R819: 30100 | S819: 1.3e-07 | Z819: 67169 | AA819: 2.094e-10 | AB819: =VLOOKUP(Z819,Nuclides!A:E,5,FALSE) -> Ho169 | AC819: =VLOOKUP(Sheet2!Z819,Nuclides!A:E,2,FALSE) -> 102 | AD819: =VLOOKUP(Z819,Nuclides!A:E,3,FALSE) -> 67 | AE819: =AA819*12480000000000000 -> 2613312 | AF819: Ho169
R820: 36100 | S820: 9.77e-06 | Z820: 67170 | AA820: 6.98e-11 | AB820: =VLOOKUP(Z820,Nuclides!A:E,5,FALSE) -> Ho170 | AC820: =VLOOKUP(Sheet2!Z820,Nuclides!A:E,2,FALSE) -> 103 | AD820: =VLOOKUP(Z820,Nuclides!A:E,3,FALSE) -> 67 | AE820: =AA820*12480000000000000 -> 871104 | AF820: Ho170
R821: 50100 | S821: 2.57e-05 | Z821: 68147 | AA821: 6.98e-11 | AB821: =VLOOKUP(Z821,Nuclides!A:E,5,FALSE) -> Er147 | AC821: =VLOOKUP(Sheet2!Z821,Nuclides!A:E,2,FALSE) -> 79 | AD821: =VLOOKUP(Z821,Nuclides!A:E,3,FALSE) -> 68 | AE821: =AA821*12480000000000000 -> 871104 | AF821: Er147
R822: 50100 | S822: 1.75e-09 | Z822: 68148 | AA822: 6.98e-11 | AB822: =VLOOKUP(Z822,Nuclides!A:E,5,FALSE) -> Er148 | AC822: =VLOOKUP(Sheet2!Z822,Nuclides!A:E,2,FALSE) -> 80 | AD822: =VLOOKUP(Z822,Nuclides!A:E,3,FALSE) -> 68 | AE822: =AA822*12480000000000000 -> 871104 | AF822: Er148
R823: 54100 | S823: 3.22e-05 | Z823: 68149 | AA823: 1.396e-10 | AB823: =VLOOKUP(Z823,Nuclides!A:E,5,FALSE) -> Er149 | AC823: =VLOOKUP(Sheet2!Z823,Nuclides!A:E,2,FALSE) -> 81 | AD823: =VLOOKUP(Z823,Nuclides!A:E,3,FALSE) -> 68 | AE823: =AA823*12480000000000000 -> 1742208 | AF823: Er149
R824: 55100 | S824: 3.93e-06 | Z824: 68150 | AA824: 6.98e-11 | AB824: =VLOOKUP(Z824,Nuclides!A:E,5,FALSE) -> Er150 | AC824: =VLOOKUP(Sheet2!Z824,Nuclides!A:E,2,FALSE) -> 82 | AD824: =VLOOKUP(Z824,Nuclides!A:E,3,FALSE) -> 68 | AE824: =AA824*12480000000000000 -> 871104 | AF824: Er150
Z825: 68173 | AA825: 6.98e-11 | AB825: =VLOOKUP(Z825,Nuclides!A:E,5,FALSE) -> Er173 | AC825: =VLOOKUP(Sheet2!Z825,Nuclides!A:E,2,FALSE) -> 105 | AD825: =VLOOKUP(Z825,Nuclides!A:E,3,FALSE) -> 68 | AE825: =AA825*12480000000000000 -> 871104 | AF825: Er173
Z826: 69151 | AA826: 1.396e-10 | AB826: =VLOOKUP(Z826,Nuclides!A:E,5,FALSE) -> Tm151 | AC826: =VLOOKUP(Sheet2!Z826,Nuclides!A:E,2,FALSE) -> 82 | AD826: =VLOOKUP(Z826,Nuclides!A:E,3,FALSE) -> 69 | AE826: =AA826*12480000000000000 -> 1742208 | AF826: Tm151
Z827: 69175 | AA827: 1.396e-10 | AB827: =VLOOKUP(Z827,Nuclides!A:E,5,FALSE) -> Tm175 | AC827: =VLOOKUP(Sheet2!Z827,Nuclides!A:E,2,FALSE) -> 106 | AD827: =VLOOKUP(Z827,Nuclides!A:E,3,FALSE) -> 69 | AE827: =AA827*12480000000000000 -> 1742208 | AF827: Tm175
Z828: 90230 | AA828: 2.094e-10 | AB828: =VLOOKUP(Z828,Nuclides!A:E,5,FALSE) -> Th230 | AC828: =VLOOKUP(Sheet2!Z828,Nuclides!A:E,2,FALSE) -> 140 | AD828: =VLOOKUP(Z828,Nuclides!A:E,3,FALSE) -> 90 | AE828: =AA828*12480000000000000 -> 2613312 | AF828: Th230
...

Sheet Sheet3
C5: 180 | D5: =COS(RADIANS(C5)) -> -1 | G5: =D5 -> -1 | H5: =D6 -> -0.98480775 | I5: =D7 -> 6.1257423e-17 | J5: =D8 -> 0.64278761 | K5: =D9 -> 0.70710678 | L5: =D10 -> 0.76604444
C6: 170 | D6: =COS(RADIANS(C6)) -> -0.98480775 | E6: 0.0123751 | G6: =D11 -> 0.81915204 | H6: =D12 -> 0.8660254 | I6: =D13 -> 0.90630779 | J6: =D14 -> 0.93969262 | K6: =D15 -> 0.96592583 | L6: =D16 -> 0.98480775
C7: 90 | D7: =COS(RADIANS(C7)) -> 6.1257423e-17 | E7: 1.11274 | G7: =D17 -> 0.9961947 | H7: =D18 -> 1
C8: 50 | D8: =COS(RADIANS(C8)) -> 0.64278761 | E8: 1.60018
C9: 45 | D9: =COS(RADIANS(C9)) -> 0.70710678 | E9: 0.285336
C10: =C9-5 -> 40 | D10: =COS(RADIANS(C10)) -> 0.76604444 | E10: 0.310932 | G10: =E6 -> 0.0123751 | H10: =E7 -> 1.11274 | I10: =E8 -> 1.60018 | J10: =E9 -> 0.285336 | K10: =E10 -> 0.310932 | L10: =E11 -> 0.338567
C11: =C10-5 -> 35 | D11: =COS(RADIANS(C11)) -> 0.81915204 | E11: 0.338567 | G11: =E12 -> 0.371607 | H11: =E13 -> 0.414471 | I11: =E14 -> 0.467166 | J11: =E15 -> 0.523622 | K11: =E16 -> 0.573975 | L11: =E17 -> 0.58251
C12: =C11-5 -> 30 | D12: =COS(RADIANS(C12)) -> 0.8660254 | E12: 0.371607 | G12: =E18 -> 0.388124
C13: =C12-5 -> 25 | D13: =COS(RADIANS(C13)) -> 0.90630779 | E13: 0.414471 | R13: ENDF | S13: CEM
C14: =C13-5 -> 20 | D14: =COS(RADIANS(C14)) -> 0.93969262 | E14: 0.467166 | P14: 60Ca | Q14: 0.0381
C15: =C14-5 -> 15 | D15: =COS(RADIANS(C15)) -> 0.96592583 | E15: 0.523622 | P15: 78Zn | Q15: 2080000000 | R15: 1703881920 | S15: 4069802880
C16: =C15-5 -> 10 | D16: =COS(RADIANS(C16)) -> 0.98480775 | E16: 0.573975 | P16: 94Kr | Q16: 72800000000 | R16: 96230908800 | S16: 142046112000
C17: =C16-5 -> 5 | D17: =COS(RADIANS(C17)) -> 0.9961947 | E17: 0.58251 | P17: 132Sn | Q17: 46600000000 | R17: 250205280000 | S17: 14061340800
C18: =C17-5 -> 0 | D18: =COS(RADIANS(C18)) -> 1 | E18: 0.388124 | P18: 138Sn | Q18: 1410000
P19: 142Xe | Q19: 161000000000 | R19: 319549152000 | S19: 52758451200
P20: 146Cs | Q20: 29800000000 | R20: 40022860800 | S20: 1.3002038e+10
H25: =3.9/2.3548 -> 1.6561916
H26: =H25*6 -> 9.9371497

Sheet aaa
C2: Nuclides | D2: Activity/Bq | E2: T1/2
C3: Cr51 | D3: 871104 | E3: =VLOOKUP(C3,Nuclides!E:F,2,FALSE) -> 2393496
C4: Mn50 | D4: 871104 | E4: =VLOOKUP(C4,Nuclides!E:F,2,FALSE) -> 0.28319
C5: Mn53 | D5: 871104 | E5: =VLOOKUP(C5,Nuclides!E:F,2,FALSE) -> 118025424000000
C6: Mn60 | D6: 871104 | E6: =VLOOKUP(C6,Nuclides!E:F,2,FALSE) -> 0.28
C7: Fe52 | D7: 871104 | E7: =VLOOKUP(C7,Nuclides!E:F,2,FALSE) -> 29790
C8: Fe53 | D8: 1742208 | E8: =VLOOKUP(C8,Nuclides!E:F,2,FALSE) -> 510.6
C9: Fe61 | D9: 871104 | E9: =VLOOKUP(C9,Nuclides!E:F,2,FALSE) -> 358.8
C10: Fe64 | D10: 871104 | E10: =VLOOKUP(C10,Nuclides!E:F,2,FALSE) -> 2
C11: Co53 | D11: 1742208 | E11: =VLOOKUP(C11,Nuclides!E:F,2,FALSE) -> 0.24
C12: Co54 | D12: 3484416 | E12: =VLOOKUP(C12,Nuclides!E:F,2,FALSE) -> 0.193
C13: Co55 | D13: 871104 | E13: =VLOOKUP(C13,Nuclides!E:F,2,FALSE) -> 63108
C14: Co56 | D14: 3484416 | E14: =VLOOKUP(C14,Nuclides!E:F,2,FALSE) -> 6673190.4
... C817: U237 | D817: 90733344000 | E817: =VLOOKUP(C817,Nuclides!E:F,2,FALSE) -> 583200

Sheet HEISOL
B1: ENDF | L1: CEM
C2: w | D2: Nuclides | E2: T1/2 | F2: λ | G2: EOB/10d | H2: EOI/1y | I2: Yield_Rate/s | M2: w | N2: Nuclides | O2: N | P2: Z | Q2: T1/2 | R2: λ | S2: EOB/10d | T2: EOI/1y
B3: 24051 | C3: 6.98e-11 | D3: Cr51 | E3: 2393496 | F3: 2.8959613e-07 | G3: 192830.69 | H3: 20.839793 | I3: =G3/10/24/3600 -> 0.22318367 | L3: 2006 | M3: 3.49e-10 | N3: He6 | O3: 4 | P3: 2 | Q3: 0.8067 | R3: 0.85923786 | S3: 4355520 | T3: 0
B4: 25050 | C4: 6.98e-11 | D4: Mn50 | E4: 0.28319 | F4: 2.44764 | G4: 871104 | H4: 0 | I4: =G4/10/24/3600 -> 1.0082222 | L4: 3008 | M4: 2.094e-10 | N4: Li8 | O4: 5 | P4: 3 | Q4: 0.8399 | R4: 0.82527346 | S4: 2613312 | T4: 0
B5: 25053 | C5: 6.98e-11 | D5: Mn53 | E5: 118025424000000 | F5: 5.8728633e-15 | G5: 0.0044201157 | H5: 0.0044201149 | I5: =G5/10/24/3600 -> 5.1158747e-09 | L5: 4007 | M5: 3.39598e-06 | N5: Be7 | O5: 3 | P5: 4 | Q5: 4598208 | R5: 1.5074289e-07 | S5: 5.1755386e+09 | T5: 44606107
B6: 25060 | C6: 6.98e-11 | D6: Mn60 | E6: 0.28 | F6: 2.4755256 | G6: 871104 | H6: 0 | I6: =G6/10/24/3600 -> 1.0082222 | L6: 4010 | M6: 1.23197e-07 | N6: Be10 | O6: 6 | P6: 4 | Q6: 47651976000000 | R6: 1.4546032e-14 | S6: 19.322931 | T6: 19.322922
B7: 26052 | C7: 6.98e-11 | D7: Fe52 | E7: 29790 | F7: 2.326778e-05 | G7: 871104 | H7: 0 | I7: =G7/10/24/3600 -> 1.0082222 | L7: 5008 | M7: 5.584e-10 | N7: B8 | O7: 3 | P7: 5 | Q7: 0.77 | R7: 0.90019114 | S7: 6968832 | T7: 0
B8: 26053 | C8: 1.396e-10 | D8: Fe53 | E8: 510.6 | F8: 0.001357515 | G8: 1742208 | H8: 0 | I8: =G8/10/24/3600 -> 2.0164444 | L8: 6010 | M8: 1.43788e-08 | N8: C10 | O8: 4 | P8: 6 | Q8: 19.308 | R8: 0.035899481 | S8: 179447424 | T8: 0
B9: 26061 | C9: 6.98e-11 | D9: Fe61 | E9: 358.8 | F9: 0.0019318483 | G9: 871104 | H9: 0 | I9: =G9/10/24/3600 -> 1.0082222 | L9: 6011 | M9: 8.16465e-06 | N9: C11 | O9: 5 | P9: 6 | Q9: 1221.84 | R9: 0.00056729783 | S9: 101894832000 | T9: 0
B10: 26064 | C10: 6.98e-11 | D10: Fe64 | E10: 2 | F10: 0.34657359 | G10: 871104 | H10: 0 | I10: =G10/10/24/3600 -> 1.0082222 | L10: 24045 | M10: 6.98e-11 | N10: Cr45 | O10: 21 | P10: 24 | Q10: 0.0609 | R10: 11.381727 | S10: 871104 | T10: 0
B11: 27053 | C11: 1.396e-10 | D11: Co53 | E11: 0.24 | F11: 2.8881133 | G11: 1742208 | H11: 0 | I11: =G11/10/24/3600 -> 2.0164444 | L11: 24051 | M11: 6.98e-11 | N11: Cr51 | O11: 27 | P11: 24 | Q11: 2393496 | R11: 2.8959613e-07 | S11: 192830.69 | T11: 20.839793
B12: 27054 | C12: 2.792e-10 | D12: Co54 | E12: 0.193 | F12: 3.5914362 | G12: 3484416 | H12: 0 | I12: =G12/10/24/3600 -> 4.0328889 | L12: 25050 | M12: 6.98e-11 | N12: Mn50 | O12: 25 | P12: 25 | Q12: 0.28319 | R12: 2.44764 | S12: 871104 | T12: 0
B13: 27055 | C13: 6.98e-11 | D13: Co55 | E13: 63108 | F13: 1.0983507e-05 | G13: 871038.12 | H13: 3.2426548e-145 | I13: =G13/10/24/3600 -> 1.008146 | L13: 25051 | M13: 6.98e-11 | N13: Mn51 | O13: 26 | P13: 25 | Q13: 2772 | R13: 0.0002500531 | S13: 871104 | T13: 0
B14: 27056 | C14: 2.792e-10 | D14: Co56 | E14: 6673190.4 | F14: 1.0387043e-07 | G14: 299084.39 | H14: 11302.995 | I14: =G14/10/24/3600 -> 0.34616249 | L14: 25053 | M14: 6.98e-11 | N14: Mn53 | O14: 28 | P14: 25 | Q14: 118025424000000 | R14: 5.8728633e-15 | S14: 0.0044201157 | T14: 0.0044201149
... B729: 92237 | C729: 7.2703e-06 | D729: U237 | E729: 583200 | F729: 1.188524e-06 | G729: 5.823984e+10 | H729: 3.0711561e-06 | I729: =G729/10/24/3600 -> 67407.222 | L729: 67150 | M729: 2.792e-10 | N729: Ho150 | O729: 83 | P729: 67 | Q729: 72 | R729: 0.0096270442 | S729: 3484416 | T729: 0
L730: 67153 | M730: 6.98e-11 | N730: Ho153 | O730: 86 | P730: 67 | Q730: 120.6 | R730: 0.0057474891 | S730: 871104 | T730: 0
L731: 67168 | M731: 1.396e-10 | N731: Ho168 | O731: 101 | P731: 67 | Q731: 179.4 | R731: 0.0038636967 | S731: 1742208 | T731: 0
F732: Ci | G732: =49300000000000/37000000000 -> 1332.4324 | H732: =379000000/37000000000 -> 0.010243243 | L732: 67169 | M732: 2.094e-10 | N732: Ho169 | O732: 102 | P732: 67 | Q732: 283.2 | R732: 0.0024475536 | S732: 2613312 | T732: 0
L733: 67170 | M733: 6.98e-11 | N733: Ho170 | O733: 103 | P733: 67 | Q733: 165.6 | R733: 0.0041856714 | S733: 871104 | T733: 0
L734: 68147 | M734: 6.98e-11 | N734: Er147 | O734: 79 | P734: 68 | Q734: 2.5 | R734: 0.27725887 | S734: 871104 | T734: 0
L735: 68148 | M735: 6.98e-11 | N735: Er148 | O735: 80 | P735: 68 | Q735: 4.6 | R735: 0.15068417 | S735: 871104 | T735: 0
L736: 68149 | M736: 1.396e-10 | N736: Er149 | O736: 81 | P736: 68 | Q736: 4 | R736: 0.1732868 | S736: 1742208 | T736: 0
L737: 68150 | M737: 6.98e-11 | N737: Er150 | O737: 82 | P737: 68 | Q737: 18.5 | R737: 0.037467415 | S737: 871104 | T737: 0
L738: 68173 | M738: 6.98e-11 | N738: Er173 | O738: 105 | P738: 68 | Q738: 84 | R738: 0.0082517521 | S738: 871104 | T738: 0
L739: 69151 | M739: 1.396e-10 | N739: Tm151 | O739: 82 | P739: 69 | Q739: 4.17 | R739: 0.16622235 | S739: 1742208 | T739: 0
L740: 69175 | M740: 1.396e-10 | N740: Tm175 | O740: 106 | P740: 69 | Q740: 912 | R740: 0.0007600298 | S740: 1742208 | T740: 0
L741: 90230 | M741: 2.094e-10 | N741: Th230 | O741: 140 | P741: 90 | Q741: 2379443040000 | R741: 2.9130648e-13 | S741: 0.65774128 | T741: 0.65773524
L742: 90231 | M742: 4.188e-10 | N742: Th231 | O742: 141 | P742: 90 | Q742: 91872 | R742: 7.5447055e-06 | S742: 5218911.1 | T742: 2.432019e-97
L743: 90232 | M743: 7.678e-10 | N743: Th232 | O743: 142 | P743: 90 | Q743: 4.418064e+17 | R743: 1.5688935e-18 | S743: 1.2988321e-05 | T743: 1.2988321e-05
L744: 90233 | M744: 3.49e-10 | N744: Th233 | O744: 143 | P744: 90 | Q744: 1309.8 | R744: 0.00052920078 | S744: 4355520 | T744: 0
... L763: 92238 | M763: 0.000195415 | N763: U238 | O763: 146 | P763: 92 | Q763: 1.4099936e+17 | R763: 4.9159599e-18 | S763: 10.358423 | T763: 10.358423
R765: Ci | S765: =57700000000000/37000000000 -> 1559.4595 | T765: =604000000/37000000000 -> 0.016324324

Sheet Sheet5
B2: ENDF
B3: 24051 | C3: 6.98e-11 | D3: Cr51 | E3: =VLOOKUP(B3,Nuclides!A:D,4,FALSE) -> 2393496
B4: 25050 | C4: 6.98e-11 | D4: Mn50 | E4: =VLOOKUP(B4,Nuclides!A:D,4,FALSE) -> 0.28319
B5: 25053 | C5: 6.98e-11 | D5: Mn53 | E5: =VLOOKUP(B5,Nuclides!A:D,4,FALSE) -> 118025424000000
B6: 25060 | C6: 6.98e-11 | D6: Mn60 | E6: =VLOOKUP(B6,Nuclides!A:D,4,FALSE) -> 0.28
B7: 26052 | C7: 6.98e-11 | D7: Fe52 | E7: =VLOOKUP(B7,Nuclides!A:D,4,FALSE) -> 29790
B8: 26053 | C8: 1.396e-10 | D8: Fe53 | E8: =VLOOKUP(B8,Nuclides!A:D,4,FALSE) -> 510.6
B9: 26061 | C9: 6.98e-11 | D9: Fe61 | E9: =VLOOKUP(B9,Nuclides!A:D,4,FALSE) -> 358.8
B10: 26064 | C10: 6.98e-11 | D10: Fe64 | E10: =VLOOKUP(B10,Nuclides!A:D,4,FALSE) -> 2
B11: 27053 | C11: 1.396e-10 | D11: Co53 | E11: =VLOOKUP(B11,Nuclides!A:D,4,FALSE) -> 0.24
B12: 27054 | C12: 2.792e-10 | D12: Co54 | E12: =VLOOKUP(B12,Nuclides!A:D,4,FALSE) -> 0.193
B13: 27055 | C13: 6.98e-11 | D13: Co55 | E13: =VLOOKUP(B13,Nuclides!A:D,4,FALSE) -> 63108
B14: 27056 | C14: 2.792e-10 | D14: Co56 | E14: =VLOOKUP(B14,Nuclides!A:D,4,FALSE) -> 6673190.4
... B817: 92237 | C817: 7.2703e-06 | D817: U237 | E817: =VLOOKUP(B817,Nuclides!A:D,4,FALSE) -> 583200

Sheet Sheet6
B1: ENDF
C2: w | D2: Nuclides | E2: T1/2 | F2: λ | G2: EOB/10d | H2: EOI/1y | O2: CEM
B3: 24051 | C3: 6.98e-11 | D3: Cr51 | E3: 2393496 | F3: =LN(2)/E3 -> 2.8959613e-07 | G3: =2*6240000000000000*C3*(1-EXP(-F3)) -> 0.25226831 | H3: =G3*EXP(-F3*365*24*3600) -> 2.7263395e-05 | K3: =VLOOKUP(B3,Nuclides!A:C,2,FALSE) -> 27 | L3: =VLOOKUP(B3,Nuclides!A:C,3,FALSE) -> 24 | O3: 2006 | P3: 3.49e-10 | Q3: He6 | R3: 4 | S3: 2 | T3: =VLOOKUP(O3,Nuclides!A:D,4,FALSE) -> 0.8067
B4: 25050 | C4: 6.98e-11 | D4: Mn50 | E4: 0.28319 | F4: =LN(2)/E4 -> 2.44764 | G4: =2*6240000000000000*C4*(1-EXP(-F4)) -> 795755.7 | H4: =G4*EXP(-F4*365*24*3600) -> 0 | K4: =VLOOKUP(B4,Nuclides!A:C,2,FALSE) -> 25 | L4: =VLOOKUP(B4,Nuclides!A:C,3,FALSE) -> 25 | O4: 3006 | P4: 1.43983e-06 | Q4: Li6 | R4: 3 | S4: 3 | T4: =VLOOKUP(O4,Nuclides!A:D,4,FALSE) -> STABLE
B5: 25053 | C5: 6.98e-11 | D5: Mn53 | E5: 118025424000000 | F5: =LN(2)/E5 -> 5.8728633e-15 | G5: =2*6240000000000000*C5*(1-EXP(-F5)) -> 5.1257345e-09 | H5: =G5*EXP(-F5*365*24*3600) -> 5.1257336e-09 | K5: =VLOOKUP(B5,Nuclides!A:C,2,FALSE) -> 28 | L5: =VLOOKUP(B5,Nuclides!A:C,3,FALSE) -> 25 | O5: 3007 | P5: 9.09145e-07 | Q5: Li7 | R5: 4 | S5: 3 | T5: =VLOOKUP(O5,Nuclides!A:D,4,FALSE) -> STABLE
B6: 25060 | C6: 6.98e-11 | D6: Mn60 | E6: 0.28 | F6: =LN(2)/E6 -> 2.4755256 | G6: =2*6240000000000000*C6*(1-EXP(-F6)) -> 797827.81 | H6: =G6*EXP(-F6*365*24*3600) -> 0 | K6: =VLOOKUP(B6,Nuclides!A:C,2,FALSE) -> 35 | L6: =VLOOKUP(B6,Nuclides!A:C,3,FALSE) -> 25 | O6: 3008 | P6: 2.094e-10 | Q6: Li8 | R6: 5 | S6: 3 | T6: =VLOOKUP(O6,Nuclides!A:D,4,FALSE) -> 0.8399
B7: 26052 | C7: 6.98e-11 | D7: Fe52 | E7: 29790 | F7: =LN(2)/E7 -> 2.326778e-05 | G7: =2*6240000000000000*C7*(1-EXP(-F7)) -> 20.268421 | H7: =G7*EXP(-F7*365*24*3600) -> 0 | K7: =VLOOKUP(B7,Nuclides!A:C,2,FALSE) -> 26 | L7: =VLOOKUP(B7,Nuclides!A:C,3,FALSE) -> 26 | O7: 4007 | P7: 3.39598e-06 | Q7: Be7 | R7: 3 | S7: 4 | T7: =VLOOKUP(O7,Nuclides!A:D,4,FALSE) -> 4598208
B8: 26053 | C8: 1.396e-10 | D8: Fe53 | E8: 510.6 | F8: =LN(2)/E8 -> 0.001357515 | G8: =2*6240000000000000*C8*(1-EXP(-F8)) -> 2363.469 | H8: =G8*EXP(-F8*365*24*3600) -> 0 | K8: =VLOOKUP(B8,Nuclides!A:C,2,FALSE) -> 27 | L8: =VLOOKUP(B8,Nuclides!A:C,3,FALSE) -> 26 | O8: 4009 | P8: 7.84901e-07 | Q8: Be9 | R8: 5 | S8: 4 | T8: =VLOOKUP(O8,Nuclides!A:D,4,FALSE) -> STABLE
B9: 26061 | C9: 6.98e-11 | D9: Fe61 | E9: 358.8 | F9: =LN(2)/E9 -> 0.0019318483 | G9: =2*6240000000000000*C9*(1-EXP(-F9)) -> 1681.2164 | H9: =G9*EXP(-F9*365*24*3600) -> 0 | K9: =VLOOKUP(B9,Nuclides!A:C,2,FALSE) -> 35 | L9: =VLOOKUP(B9,Nuclides!A:C,3,FALSE) -> 26 | O9: 4010 | P9: 1.23197e-07 | Q9: Be10 | R9: 6 | S9: 4 | T9: =VLOOKUP(O9,Nuclides!A:D,4,FALSE) -> 47651976000000
B10: 26064 | C10: 6.98e-11 | D10: Fe64 | E10: 2 | F10: =LN(2)/E10 -> 0.34657359 | G10: =2*6240000000000000*C10*(1-EXP(-F10)) -> 255140.45 | H10: =G10*EXP(-F10*365*24*3600) -> 0 | K10: =VLOOKUP(B10,Nuclides!A:C,2,FALSE) -> 38 | L10: =VLOOKUP(B10,Nuclides!A:C,3,FALSE) -> 26 | O10: 5008 | P10: 5.584e-10 | Q10: B8 | R10: 3 | S10: 5 | T10: =VLOOKUP(O10,Nuclides!A:D,4,FALSE) -> 0.77
B11: 27053 | C11: 1.396e-10 | D11: Co53 | E11: 0.24 | F11: =LN(2)/E11 -> 2.8881133 | G11: =2*6240000000000000*C11*(1-EXP(-F11)) -> 1645199.8 | H11: =G11*EXP(-F11*365*24*3600) -> 0 | K11: =VLOOKUP(B11,Nuclides!A:C,2,FALSE) -> 26 | L11: =VLOOKUP(B11,Nuclides!A:C,3,FALSE) -> 27 | O11: 5010 | P11: 6.33072e-06 | Q11: B10 | R11: 5 | S11: 5 | T11: =VLOOKUP(O11,Nuclides!A:D,4,FALSE) -> STABLE
B12: 27054 | C12: 2.792e-10 | D12: Co54 | E12: 0.193 | F12: =LN(2)/E12 -> 3.5914362 | G12: =2*6240000000000000*C12*(1-EXP(-F12)) -> 3388389.9 | H12: =G12*EXP(-F12*365*24*3600) -> 0 | K12: =VLOOKUP(B12,Nuclides!A:C,2,FALSE) -> 27 | L12: =VLOOKUP(B12,Nuclides!A:C,3,FALSE) -> 27 | O12: 5011 | P12: 3.32359e-05 | Q12: B11 | R12: 6 | S12: 5 | T12: =VLOOKUP(O12,Nuclides!A:D,4,FALSE) -> STABLE
B13: 27055 | C13: 6.98e-11 | D13: Co55 | E13: 63108 | F13: =LN(2)/E13 -> 1.0983507e-05 | G13: =2*6240000000000000*C13*(1-EXP(-F13)) -> 9.5677246 | H13: =G13*EXP(-F13*365*24*3600) -> 3.561822e-150 | K13: =VLOOKUP(B13,Nuclides!A:C,2,FALSE) -> 28 | L13: =VLOOKUP(B13,Nuclides!A:C,3,FALSE) -> 27 | O13: 6010 | P13: 1.43788e-08 | Q13: C10 | R13: 4 | S13: 6 | T13: =VLOOKUP(O13,Nuclides!A:D,4,FALSE) -> 19.308
B14: 27056 | C14: 2.792e-10 | D14: Co56 | E14: 6673190.4 | F14: =LN(2)/E14 -> 1.0387043e-07 | G14: =2*6240000000000000*C14*(1-EXP(-F14)) -> 0.36192778 | H14: =G14*EXP(-F14*365*24*3600) -> 0.013677973 | K14: =VLOOKUP(B14,Nuclides!A:C,2,FALSE) -> 29 | L14: =VLOOKUP(B14,Nuclides!A:C,3,FALSE) -> 27 | O14: 6011 | P14: 8.16465e-06 | Q14: C11 | R14: 5 | S14: 6 | T14: =VLOOKUP(O14,Nuclides!A:D,4,FALSE) -> 1221.84
... B729: 92237 | C729: 7.2703e-06 | D729: U237 | E729: 583200 | F729: =LN(2)/E729 -> 1.188524e-06 | G729: =2*6240000000000000*C729*(1-EXP(-F729)) -> 107838.69 | H729: =G729*EXP(-F729*365*24*3600) -> 5.6866477e-12 | K729: =VLOOKUP(B729,Nuclides!A:C,2,FALSE) -> 145 | L729: =VLOOKUP(B729,Nuclides!A:C,3,FALSE) -> 92 | O729: 61148 | P729: 4.886e-10 | Q729: Pm148 | R729: 87 | S729: 61 | T729: =VLOOKUP(O729,Nuclides!A:D,4,FALSE) -> 463795.2
B730: 20060 | C730: 0 | D730: Ca60 | O730: 61149 | P730: 4.4672e-09 | Q730: Pm149 | R730: 88 | S730: 61 | T730: =VLOOKUP(O730,Nuclides!A:D,4,FALSE) -> 191088
B731: 30078 | C731: 1.30293e-07 | D731: Zn78 | E731: =VLOOKUP(B731,Nuclides!A:F,4,FALSE) -> 1.47 | F731: =LN(2)/E731 -> 0.47152869 | G731: =2*6240000000000000*C731*(1-EXP(-F731)) -> 6.1131996e+08 | O731: 61150 | P731: 1.52164e-08 | Q731: Pm150 | R731: 89 | S731: 61 | T731: =VLOOKUP(O731,Nuclides!A:D,4,FALSE) -> 9712.8
B732: 36094 | C732: 9.76863e-06 | D732: Kr94 | E732: =VLOOKUP(B732,Nuclides!A:F,4,FALSE) -> 0.212 | F732: =LN(2)/E732 -> 3.2695622 | G732: =2*6240000000000000*C732*(1-EXP(-F732)) -> 1.1727701e+11 | O732: 61151 | P732: 7.5035e-08 | Q732: Pm151 | R732: 90 | S732: 61 | T732: =VLOOKUP(O732,Nuclides!A:D,4,FALSE) -> 102240
B733: 50132 | C733: 2.56787e-05 | D733: Sn132 | E733: =VLOOKUP(B733,Nuclides!A:F,4,FALSE) -> 39.7 | F733: =LN(2)/E733 -> 0.017459627 | G733: =2*6240000000000000*C733*(1-EXP(-F733)) -> 5.5467269e+09 | O733: 61152 | P733: 1.71499e-07 | Q733: Pm152 | R733: 91 | S733: 61 | T733: =VLOOKUP(O733,Nuclides!A:D,4,FALSE) -> 247.2
B734: 50138 | C734: 1.745e-09 | D734: Sn138 | E734: =VLOOKUP(B734,Nuclides!A:F,4,FALSE) -> 0.14 | F734: =LN(2)/E734 -> 4.9510513 | G734: =2*6240000000000000*C734*(1-EXP(-F734)) -> 21623502 | O734: 61153 | P734: 4.65008e-07 | Q734: Pm153 | R734: 92 | S734: 61 | T734: =VLOOKUP(O734,Nuclides!A:D,4,FALSE) -> 315
B735: 54142 | C735: 3.21879e-05 | D735: Xe142 | E735: =VLOOKUP(B735,Nuclides!A:F,4,FALSE) -> 1.23 | F735: =LN(2)/E735 -> 0.56353429 | G735: =2*6240000000000000*C735*(1-EXP(-F735)) -> 1.73057e+11 | O735: 61154 | P735: 6.423e-07 | Q735: Pm154 | R735: 93 | S735: 61 | T735: =VLOOKUP(O735,Nuclides!A:D,4,FALSE) -> 160.8
B736: 55146 | C736: 3.92753e-06 | D736: Cs146 | E736: =VLOOKUP(B736,Nuclides!A:F,4,FALSE) -> 0.322 | F736: =LN(2)/E736 -> 2.152631 | G736: =2*6240000000000000*C736*(1-EXP(-F736)) -> 4.3321039e+10 | O736: 61155 | P736: 8.91486e-07 | Q736: Pm155 | R736: 94 | S736: 61 | T736: =VLOOKUP(O736,Nuclides!A:D,4,FALSE) -> 41.5
O737: 62133 | P737: 7.16078e-07 | Q737: Sm133 | R737: 71 | S737: 62 | T737: =VLOOKUP(O737,Nuclides!A:D,4,FALSE) -> 2.89
O738: 62134 | P738: 7.17125e-07 | Q738: Sm134 | R738: 72 | S738: 62 | T738: =VLOOKUP(O738,Nuclides!A:D,4,FALSE) -> 9.5
O739: 62135 | P739: 3.55142e-07 | Q739: Sm135 | R739: 73 | S739: 62 | T739: =VLOOKUP(O739,Nuclides!A:D,4,FALSE) -> 10.3
O740: 62136 | P740: 2.30549e-07 | Q740: Sm136 | R740: 74 | S740: 62 | T740: =VLOOKUP(O740,Nuclides!A:D,4,FALSE) -> 47
O741: 62137 | P741: 8.1666e-08 | Q741: Sm137 | R741: 75 | S741: 62 | T741: =VLOOKUP(O741,Nuclides!A:D,4,FALSE) -> 45
O742: 62138 | P742: 3.8041e-08 | Q742: Sm138 | R742: 76 | S742: 62 | T742: =VLOOKUP(O742,Nuclides!A:D,4,FALSE) -> 186
O743: 62139 | P743: 9.3532e-09 | Q743: Sm139 | R743: 77 | S743: 62 | T743: =VLOOKUP(O743,Nuclides!A:D,4,FALSE) -> 154.2
O744: 62140 | P744: 2.0242e-09 | Q744: Sm140 | R744: 78 | S744: 62 | T744: =VLOOKUP(O744,Nuclides!A:D,4,FALSE) -> 889.2
O745: 62141 | P745: 2.792e-10 | Q745: Sm141 | R745: 79 | S745: 62 | T745: =VLOOKUP(O745,Nuclides!A:D,4,FALSE) -> 612
O746: 62150 | P746: 6.98e-11 | Q746: Sm150 | R746: 88 | S746: 62 | T746: =VLOOKUP(O746,Nuclides!A:D,4,FALSE) -> STABLE
O747: 62151 | P747: 4.886e-10 | Q747: Sm151 | R747: 89 | S747: 62 | T747: =VLOOKUP(O747,Nuclides!A:D,4,FALSE) -> 2840184000
O748: 62152 | P748: 4.537e-09 | Q748: Sm152 | R748: 90 | S748: 62 | T748: =VLOOKUP(O748,Nuclides!A:D,4,FALSE) -> STABLE
... O850: 92238 | P850: 0.000195415 | Q850: U238 | R850: 146 | S850: 92 | T850: =VLOOKUP(O850,Nuclides!A:D,4,FALSE) -> 1.4099936e+17

Sheet Sheet7
B2: CEM | C2: w | D2: Nuclides | E2: N | F2: Z | G2: T1/2 | H2: λ | I2: EOB/10d | J2: EOI/1y
B3: 2006 | C3: 3.49e-10 | D3: He6 | E3: 4 | F3: 2 | G3: 0.8067 | H3: =LN(2)/G3 -> 0.85923786 | I3: =2*6240000000000000*C3*(1-EXP(-H3*10*24*3600)) -> 4355520 | J3: =EXP(-H3*365*24*3600)*I3 -> 0
B4: 3008 | C4: 2.094e-10 | D4: Li8 | E4: 5 | F4: 3 | G4: 0.8399 | H4: =LN(2)/G4 -> 0.82527346 | I4: =2*6240000000000000*C4*(1-EXP(-H4*10*24*3600)) -> 2613312 | J4: =EXP(-H4*365*24*3600)*I4 -> 0
B5: 4007 | C5: 3.39598e-06 | D5: Be7 | E5: 3 | F5: 4 | G5: 4598208 | H5: =LN(2)/G5 -> 1.5074289e-07 | I5: =2*6240000000000000*C5*(1-EXP(-H5*10*24*3600)) -> 5.1755386e+09 | J5: =EXP(-H5*365*24*3600)*I5 -> 44606107
B6: 4010 | C6: 1.23197e-07 | D6: Be10 | E6: 6 | F6: 4 | G6: 47651976000000 | H6: =LN(2)/G6 -> 1.4546032e-14 | I6: =2*6240000000000000*C6*(1-EXP(-H6*10*24*3600)) -> 19.322931 | J6: =EXP(-H6*365*24*3600)*I6 -> 19.322922
B7: 5008 | C7: 5.584e-10 | D7: B8 | E7: 3 | F7: 5 | G7: 0.77 | H7: =LN(2)/G7 -> 0.90019114 | I7: =2*6240000000000000*C7*(1-EXP(-H7*10*24*3600)) -> 6968832 | J7: =EXP(-H7*365*24*3600)*I7 -> 0
B8: 6010 | C8: 1.43788e-08 | D8: C10 | E8: 4 | F8: 6 | G8: 19.308 | H8: =LN(2)/G8 -> 0.035899481 | I8: =2*6240000000000000*C8*(1-EXP(-H8*10*24*3600)) -> 179447424 | J8: =EXP(-H8*365*24*3600)*I8 -> 0
B9: 6011 | C9: 8.16465e-06 | D9: C11 | E9: 5 | F9: 6 | G9: 1221.84 | H9: =LN(2)/G9 -> 0.00056729783 | I9: =2*6240000000000000*C9*(1-EXP(-H9*10*24*3600)) -> 101894832000 | J9: =EXP(-H9*365*24*3600)*I9 -> 0
B10: 24045 | C10: 6.98e-11 | D10: Cr45 | E10: 21 | F10: 24 | G10: 0.0609 | H10: =LN(2)/G10 -> 11.381727 | I10: =2*6240000000000000*C10*(1-EXP(-H10*10*24*3600)) -> 871104 | J10: =EXP(-H10*365*24*3600)*I10 -> 0
B11: 24051 | C11: 6.98e-11 | D11: Cr51 | E11: 27 | F11: 24 | G11: 2393496 | H11: =LN(2)/G11 -> 2.8959613e-07 | I11: =2*6240000000000000*C11*(1-EXP(-H11*10*24*3600)) -> 192830.69 | J11: =EXP(-H11*365*24*3600)*I11 -> 20.839793
B12: 25050 | C12: 6.98e-11 | D12: Mn50 | E12: 25 | F12: 25 | G12: 0.28319 | H12: =LN(2)/G12 -> 2.44764 | I12: =2*6240000000000000*C12*(1-EXP(-H12*10*24*3600)) -> 871104 | J12: =EXP(-H12*365*24*3600)*I12 -> 0
B13: 25051 | C13: 6.98e-11 | D13: Mn51 | E13: 26 | F13: 25 | G13: 2772 | H13: =LN(2)/G13 -> 0.0002500531 | I13: =2*6240000000000000*C13*(1-EXP(-H13*10*24*3600)) -> 871104 | J13: =EXP(-H13*365*24*3600)*I13 -> 0
B14: 25053 | C14: 6.98e-11 | D14: Mn53 | E14: 28 | F14: 25 | G14: 118025424000000 | H14: =LN(2)/G14 -> 5.8728633e-15 | I14: =2*6240000000000000*C14*(1-EXP(-H14*10*24*3600)) -> 0.0044201157 | J14: =EXP(-H14*365*24*3600)*I14 -> 0.0044201149
... B763: 92238 | C763: 0.000195415 | D763: U238 | E763: 146 | F763: 92 | G763: 1.4099936e+17 | H763: =LN(2)/G763 -> 4.9159599e-18 | I763: =2*6240000000000000*C763*(1-EXP(-H763*10*24*3600)) -> 10.358423 | J763: =EXP(-H763*365*24*3600)*I763 -> 10.358423
