Workbook

Sheet Nuclides
B2: n | C2: z | D2: halflife/s | F2: halflife/s
A3: 1001 | B3: 1 | C3: 0 | D3: 613.9 | E3: H1 | F3: 613.9
A4: 1002 | B4: 1 | C4: 1 | D4: STABLE | E4: H2 | F4: STABLE
A5: 1003 | B5: 2 | C5: 1 | D5: 388789632 | E5: H3 | F5: 388789632
A6: 1005 | B6: 4 | C6: 1 | D6: 7.9947368e-23 | E6: H5 | F6: 7.9947368e-23
A7: 1006 | B7: 5 | C7: 1 | D7: 2.848125e-22 | E7: H6 | F7: 2.848125e-22
A8: 2003 | B8: 1 | C8: 2 | D8: STABLE | E8: He3 | F8: STABLE
A9: 2004 | B9: 2 | C9: 2 | D9: STABLE | E9: He4 | F9: STABLE
A10: 2005 | B10: 3 | C10: 2 | D10: 7.595e-22 | E10: He5 | F10: 7.595e-22
A11: 2006 | B11: 4 | C11: 2 | D11: 0.8067 | E11: He6 | F11: 0.8067
A12: 2007 | B12: 5 | C12: 2 | D12: 3.038e-21 | E12: He7 | F12: 3.038e-21
A13: 2008 | B13: 6 | C13: 2 | D13: 0.1191 | E13: He8 | F13: 0.1191
A14: 2010 | B14: 8 | C14: 2 | D14: 1.519e-21 | E14: He10 | F14: 1.519e-21
A15: 3004 | B15: 1 | C15: 3 | D15: 7.5572139e-23 | E15: Li4 | F15: 7.5572139e-23
A16: 3005 | B16: 2 | C16: 3 | D16: 3.038e-22 | E16: Li5 | F16: 3.038e-22
A17: 3006 | B17: 3 | C17: 3 | D17: STABLE | E17: Li6 | F17: STABLE
A18: 3007 | B18: 4 | C18: 3 | D18: STABLE | E18: Li7 | F18: STABLE
A19: 3008 | B19: 5 | C19: 3 | D19: 0.8399 | E19: Li8 | F19: 0.8399
A20: 3009 | B20: 6 | C20: 3 | D20: 0.1783 | E20: Li9 | F20: 0.1783
A21: 3011 | B21: 8 | C21: 3 | D21: 0.00875 | E21: Li11 | F21: 0.00875
A22: 4006 | B22: 2 | C22: 4 | D22: 4.9532609e-21 | E22: Be6 | F22: 4.9532609e-21
A23: 4007 | B23: 3 | C23: 4 | D23: 4598208 | E23: Be7 | F23: 4598208
A24: 4008 | B24: 4 | C24: 4 | D24: 8.1813285e-17 | E24: Be8 | F24: 8.1813285e-17
A25: 4009 | B25: 5 | C25: 4 | D25: STABLE | E25: Be9 | F25: STABLE
A26: 4010 | B26: 6 | C26: 4 | D26: 47651976000000 | E26: Be10 | F26: 47651976000000
A27: 4011 | B27: 7 | C27: 4 | D27: 13.76 | E27: Be11 | F27: 13.76
A28: 4012 | B28: 8 | C28: 4 | D28: 0.02147 | E28: Be12 | F28: 0.02147
A29: 4013 | B29: 9 | C29: 4 | D29: 2.7e-21 | E29: Be13 | F29: 2.7e-21
A30: 4014 | B30: 10 | C30: 4 | D30: 0.00435 | E30: Be14 | F30: 0.00435
A31: 4015 | B31: 11 | C31: 4 | D31: 7.8568966e-22 | E31: Be15 | F31: 7.8568966e-22
A32: 4016 | B32: 12 | C32: 4 | D32: 5.69625e-22 | E32: Be16 | F32: 5.69625e-22
A33: 5007 | B33: 2 | C33: 5 | D33: 3.255e-22 | E33: B7 | F33: 3.255e-22
A34: 5008 | B34: 3 | C34: 5 | D34: 0.77 | E34: B8 | F34: 0.77
A35: 5009 | B35: 4 | C35: 5 | D35: 8.4388889e-19 | E35: B9 | F35: 8.4388889e-19
A36: 5010 | B36: 5 | C36: 5 | D36: STABLE | E36: B10 | F36: STABLE
A37: 5011 | B37: 6 | C37: 5 | D37: STABLE | E37: B11 | F37: STABLE
A38: 5012 | B38: 7 | C38: 5 | D38: 0.0202 | E38: B12 | F38: 0.0202
A39: 5013 | B39: 8 | C39: 5 | D39: 0.01733 | E39: B13 | F39: 0.01733
A40: 5014 | B40: 9 | C40: 5 | D40: 0.01236 | E40: B14 | F40: 0.01236
A41: 5015 | B41: 10 | C41: 5 | D41: 0.01018 | E41: B15 | F41: 0.01018
...

Sheet Data
F3: 10μA-轰击时间/min
B5: 铜托 | C5: 银片-1mm | D5: 镍镀层-100μm | E5: 0.114209 | F5: =10/(E5/2.5) -> 218.89693
B7: 银托 | D7: 镍镀层-100μm | E7: 0.083366 | F7: =10/(E7/2.5) -> 299.88245
B9: 钽托 | D9: 镍镀层-100μm | E9: 0.0643774 | F9: =10/(E9/2.5) -> 388.33504
B11: 铜托 | C11: 镀金-15μm | D11: 镍镀层-100μm | E11: 13.6121 | F11: =10/(E11/2.5) -> 1.8366013
B15: 铜托 | D15: 钇片-1mm | E15: 2.7667 | F15: =10/(E15/2.5) -> 9.0360357
D17: 纯钇-1mm | E17: 2.82473 | F17: =10/(E17/2.5) -> 8.8504034
B19: 铌托 | D19: 钇片-1mm | E19: 2.82473 | F19: =10/(E19/2.5) -> 8.8504034

Sheet Cu-Au-Ni
G1: Nuclides | H1: T1/2 | I1: T1/2 | J1: λ | K1: 10μA-10min | L1: cool-30min | M1: Nuclides
C3: 1 | D3: 2 | E3: 3
B4: 1001 | C4: 0 | D4: 0 | E4: 0 | F4: =SUM(C4:E4) -> 0 | G4: =VLOOKUP(B4,Nuclides!A:F,5,FALSE) -> H1 | H4: =VLOOKUP(B4,Nuclides!A:F,4,FALSE) -> 613.9 | I4: =IF(H4="STABLE", "STABLE", IF(H4<60, H4&"s", IF(H4<3600, ROUND(H4/60,2)&"min", IF(H4<86400, ROUND(H4/3600,2)&"h", IF(H4<31536000, ROUND(H4/86400,2)&"d", ROUND(H4/31536000,2)&"y"))))) -> 10.23min | J4: =LN(2)/H4 -> 0.0011290881 | K4: =10*F4*(1-EXP(-J4*600))*6240000000000 -> 0 | L4: =EXP(-J4*30*60)*K4 -> 0 | M4: =G4 -> H1
B5: 1002 | C5: 0 | D5: 0 | E5: 0 | F5: =SUM(C5:E5) -> 0 | G5: =VLOOKUP(B5,Nuclides!A:F,5,FALSE) -> H2 | H5: =VLOOKUP(B5,Nuclides!A:F,4,FALSE) -> STABLE | I5: =IF(H5="STABLE", "STABLE", IF(H5<60, H5&"s", IF(H5<3600, ROUND(H5/60,2)&"min", IF(H5<86400, ROUND(H5/3600,2)&"h", IF(H5<31536000, ROUND(H5/86400,2)&"d", ROUND(H5/31536000,2)&"y"))))) -> STABLE | J5: =LN(2)/H5 -> #VALUE! | K5: =10*F5*(1-EXP(-J5*600))*6240000000000 -> #VALUE! | L5: =EXP(-J5*30*60)*K5 -> #VALUE! | M5: =G5 -> H2
B6: 1003 | C6: 0 | D6: 0 | E6: 0 | F6: =SUM(C6:E6) -> 0 | G6: =VLOOKUP(B6,Nuclides!A:F,5,FALSE) -> H3 | H6: =VLOOKUP(B6,Nuclides!A:F,4,FALSE) -> 388789632 | I6: =IF(H6="STABLE", "STABLE", IF(H6<60, H6&"s", IF(H6<3600, ROUND(H6/60,2)&"min", IF(H6<86400, ROUND(H6/3600,2)&"h", IF(H6<31536000, ROUND(H6/86400,2)&"d", ROUND(H6/31536000,2)&"y"))))) -> 12.33y | J6: =LN(2)/H6 -> 1.7828335e-09 | K6: =10*F6*(1-EXP(-J6*600))*6240000000000 -> 0 | L6: =EXP(-J6*30*60)*K6 -> 0 | M6: =G6 -> H3
B7: 2003 | C7: 0 | D7: 0 | E7: 0 | F7: =SUM(C7:E7) -> 0 | G7: =VLOOKUP(B7,Nuclides!A:F,5,FALSE) -> He3 | H7: =VLOOKUP(B7,Nuclides!A:F,4,FALSE) -> STABLE | I7: =IF(H7="STABLE", "STABLE", IF(H7<60, H7&"s", IF(H7<3600, ROUND(H7/60,2)&"min", IF(H7<86400, ROUND(H7/3600,2)&"h", IF(H7<31536000, ROUND(H7/86400,2)&"d", ROUND(H7/31536000,2)&"y"))))) -> STABLE | J7: =LN(2)/H7 -> #VALUE! | K7: =10*F7*(1-EXP(-J7*600))*6240000000000 -> #VALUE! | L7: =EXP(-J7*30*60)*K7 -> #VALUE! | M7: =G7 -> He3
B8: 2004 | C8: 0 | D8: 0 | E8: 0 | F8: =SUM(C8:E8) -> 0 | G8: =VLOOKUP(B8,Nuclides!A:F,5,FALSE) -> He4 | H8: =VLOOKUP(B8,Nuclides!A:F,4,FALSE) -> STABLE | I8: =IF(H8="STABLE", "STABLE", IF(H8<60, H8&"s", IF(H8<3600, ROUND(H8/60,2)&"min", IF(H8<86400, ROUND(H8/3600,2)&"h", IF(H8<31536000, ROUND(H8/86400,2)&"d", ROUND(H8/31536000,2)&"y"))))) -> STABLE | J8: =LN(2)/H8 -> #VALUE! | K8: =10*F8*(1-EXP(-J8*600))*6240000000000 -> #VALUE! | L8: =EXP(-J8*30*60)*K8 -> #VALUE! | M8: =G8 -> He4
B9: 2005 | C9: 0 | D9: 0 | E9: 0 | F9: =SUM(C9:E9) -> 0 | G9: =VLOOKUP(B9,Nuclides!A:F,5,FALSE) -> He5 | H9: =VLOOKUP(B9,Nuclides!A:F,4,FALSE) -> 7.595e-22 | I9: =IF(H9="STABLE", "STABLE", IF(H9<60, H9&"s", IF(H9<3600, ROUND(H9/60,2)&"min", IF(H9<86400, ROUND(H9/3600,2)&"h", IF(H9<31536000, ROUND(H9/86400,2)&"d", ROUND(H9/31536000,2)&"y"))))) -> 7.595E-22s | J9: =LN(2)/H9 -> 9.1263618e+20 | K9: =10*F9*(1-EXP(-J9*600))*6240000000000 -> 0 | L9: =EXP(-J9*30*60)*K9 -> 0 | M9: =G9 -> He5
B10: 2006 | C10: 0 | D10: 0 | E10: 0 | F10: =SUM(C10:E10) -> 0 | G10: =VLOOKUP(B10,Nuclides!A:F,5,FALSE) -> He6 | H10: =VLOOKUP(B10,Nuclides!A:F,4,FALSE) -> 0.8067 | I10: =IF(H10="STABLE", "STABLE", IF(H10<60, H10&"s", IF(H10<3600, ROUND(H10/60,2)&"min", IF(H10<86400, ROUND(H10/3600,2)&"h", IF(H10<31536000, ROUND(H10/86400,2)&"d", ROUND(H10/31536000,2)&"y"))))) -> 0.8067s | J10: =LN(2)/H10 -> 0.85923786 | K10: =10*F10*(1-EXP(-J10*600))*6240000000000 -> 0 | L10: =EXP(-J10*30*60)*K10 -> 0 | M10: =G10 -> He6
B11: 2007 | C11: 0 | D11: 0 | E11: 0 | F11: =SUM(C11:E11) -> 0 | G11: =VLOOKUP(B11,Nuclides!A:F,5,FALSE) -> He7 | H11: =VLOOKUP(B11,Nuclides!A:F,4,FALSE) -> 3.038e-21 | I11: =IF(H11="STABLE", "STABLE", IF(H11<60, H11&"s", IF(H11<3600, ROUND(H11/60,2)&"min", IF(H11<86400, ROUND(H11/3600,2)&"h", IF(H11<31536000, ROUND(H11/86400,2)&"d", ROUND(H11/31536000,2)&"y"))))) -> 3.038E-21s | J11: =LN(2)/H11 -> 2.2815905e+20 | K11: =10*F11*(1-EXP(-J11*600))*6240000000000 -> 0 | L11: =EXP(-J11*30*60)*K11 -> 0 | M11: =G11 -> He7
B12: 2008 | C12: 0 | D12: 0 | E12: 0 | F12: =SUM(C12:E12) -> 0 | G12: =VLOOKUP(B12,Nuclides!A:F,5,FALSE) -> He8 | H12: =VLOOKUP(B12,Nuclides!A:F,4,FALSE) -> 0.1191 | I12: =IF(H12="STABLE", "STABLE", IF(H12<60, H12&"s", IF(H12<3600, ROUND(H12/60,2)&"min", IF(H12<86400, ROUND(H12/3600,2)&"h", IF(H12<31536000, ROUND(H12/86400,2)&"d", ROUND(H12/31536000,2)&"y"))))) -> 0.1191s | J12: =LN(2)/H12 -> 5.8198756 | K12: =10*F12*(1-EXP(-J12*600))*6240000000000 -> 0 | L12: =EXP(-J12*30*60)*K12 -> 0 | M12: =G12 -> He8
B13: 3005 | C13: 0 | D13: 0 | E13: 0 | F13: =SUM(C13:E13) -> 0 | G13: =VLOOKUP(B13,Nuclides!A:F,5,FALSE) -> Li5 | H13: =VLOOKUP(B13,Nuclides!A:F,4,FALSE) -> 3.038e-22 | I13: =IF(H13="STABLE", "STABLE", IF(H13<60, H13&"s", IF(H13<3600, ROUND(H13/60,2)&"min", IF(H13<86400, ROUND(H13/3600,2)&"h", IF(H13<31536000, ROUND(H13/86400,2)&"d", ROUND(H13/31536000,2)&"y"))))) -> 3.038E-22s | J13: =LN(2)/H13 -> 2.2815905e+21 | K13: =10*F13*(1-EXP(-J13*600))*6240000000000 -> 0 | L13: =EXP(-J13*30*60)*K13 -> 0 | M13: =G13 -> Li5
B14: 3006 | C14: 0 | D14: 0 | E14: 0 | F14: =SUM(C14:E14) -> 0 | G14: =VLOOKUP(B14,Nuclides!A:F,5,FALSE) -> Li6 | H14: =VLOOKUP(B14,Nuclides!A:F,4,FALSE) -> STABLE | I14: =IF(H14="STABLE", "STABLE", IF(H14<60, H14&"s", IF(H14<3600, ROUND(H14/60,2)&"min", IF(H14<86400, ROUND(H14/3600,2)&"h", IF(H14<31536000, ROUND(H14/86400,2)&"d", ROUND(H14/31536000,2)&"y"))))) -> STABLE | J14: =LN(2)/H14 -> #VALUE! | K14: =10*F14*(1-EXP(-J14*600))*6240000000000 -> #VALUE! | L14: =EXP(-J14*30*60)*K14 -> #VALUE! | M14: =G14 -> Li6
B15: 3007 | C15: 0 | D15: 0 | E15: 0 | F15: =SUM(C15:E15) -> 0 | G15: =VLOOKUP(B15,Nuclides!A:F,5,FALSE) -> Li7 | H15: =VLOOKUP(B15,Nuclides!A:F,4,FALSE) -> STABLE | I15: =IF(H15="STABLE", "STABLE", IF(H15<60, H15&"s", IF(H15<3600, ROUND(H15/60,2)&"min", IF(H15<86400, ROUND(H15/3600,2)&"h", IF(H15<31536000, ROUND(H15/86400,2)&"d", ROUND(H15/31536000,2)&"y"))))) -> STABLE | J15: =LN(2)/H15 -> #VALUE! | K15: =10*F15*(1-EXP(-J15*600))*6240000000000 -> #VALUE! | L15: =EXP(-J15*30*60)*K15 -> #VALUE! | M15: =G15 -> Li7
... B351: 27060 | C351: 0 | D351: 0 | E351: 0 | F351: =SUM(C351:E351) -> 0 | G351: =VLOOKUP(B351,Nuclides!A:F,5,FALSE) -> Co60 | H351: =VLOOKUP(B351,Nuclides!A:F,4,FALSE) -> 166344192 | I351: =IF(H351="STABLE", "STABLE", IF(H351<60, H351&"s", IF(H351<3600, ROUND(H351/60,2)&"min", IF(H351<86400, ROUND(H351/3600,2)&"h", IF(H351<31536000, ROUND(H351/86400,2)&"d", ROUND(H351/31536000,2)&"y"))))) -> 5.27y | J351: =LN(2)/H351 -> 4.1669455e-09 | K351: =10*F351*(1-EXP(-J351*600))*6240000000000 -> 0 | L351: =EXP(-J351*30*60)*K351 -> 0 | M351: =G351 -> Co60
B352: 27061 | C352: 5.8e-06 | D352: 0 | E352: 0 | F352: =SUM(C352:E352) -> 5.8e-06 | G352: =VLOOKUP(B352,Nuclides!A:F,5,FALSE) -> Co61 | H352: =VLOOKUP(B352,Nuclides!A:F,4,FALSE) -> 5936.4 | I352: =IF(H352="STABLE", "STABLE", IF(H352<60, H352&"s", IF(H352<3600, ROUND(H352/60,2)&"min", IF(H352<86400, ROUND(H352/3600,2)&"h", IF(H352<31536000, ROUND(H352/86400,2)&"d", ROUND(H352/31536000,2)&"y"))))) -> 1.65h | J352: =LN(2)/H352 -> 0.00011676221 | K352: =10*F352*(1-EXP(-J352*600))*6240000000000 -> 24487373 | L352: =EXP(-J352*30*60)*K352 -> 19845665 | M352: =G352 -> Co61 | N352: =L352 -> 19845665 | O352: =0 -> 0
B353: 27062 | C353: 0 | D353: 0 | E353: 0 | F353: =SUM(C353:E353) -> 0 | G353: =VLOOKUP(B353,Nuclides!A:F,5,FALSE) -> Co62 | H353: =VLOOKUP(B353,Nuclides!A:F,4,FALSE) -> 90 | I353: =IF(H353="STABLE", "STABLE", IF(H353<60, H353&"s", IF(H353<3600, ROUND(H353/60,2)&"min", IF(H353<86400, ROUND(H353/3600,2)&"h", IF(H353<31536000, ROUND(H353/86400,2)&"d", ROUND(H353/31536000,2)&"y"))))) -> 1.5min | J353: =LN(2)/H353 -> 0.0077016353 | K353: =10*F353*(1-EXP(-J353*600))*6240000000000 -> 0 | L353: =EXP(-J353*30*60)*K353 -> 0 | M353: =G353 -> Co62
B354: 27063 | C354: 0 | D354: 0 | E354: 0 | F354: =SUM(C354:E354) -> 0 | G354: =VLOOKUP(B354,Nuclides!A:F,5,FALSE) -> Co63 | H354: =VLOOKUP(B354,Nuclides!A:F,4,FALSE) -> 27.4 | I354: =IF(H354="STABLE", "STABLE", IF(H354<60, H354&"s", IF(H354<3600, ROUND(H354/60,2)&"min", IF(H354<86400, ROUND(H354/3600,2)&"h", IF(H354<31536000, ROUND(H354/86400,2)&"d", ROUND(H354/31536000,2)&"y"))))) -> 27.4s | J354: =LN(2)/H354 -> 0.025297342 | K354: =10*F354*(1-EXP(-J354*600))*6240000000000 -> 0 | L354: =EXP(-J354*30*60)*K354 -> 0 | M354: =G354 -> Co63
B355: 27064 | C355: 0 | D355: 0 | E355: 0 | F355: =SUM(C355:E355) -> 0 | G355: =VLOOKUP(B355,Nuclides!A:F,5,FALSE) -> Co64 | H355: =VLOOKUP(B355,Nuclides!A:F,4,FALSE) -> 0.3 | I355: =IF(H355="STABLE", "STABLE", IF(H355<60, H355&"s", IF(H355<3600, ROUND(H355/60,2)&"min", IF(H355<86400, ROUND(H355/3600,2)&"h", IF(H355<31536000, ROUND(H355/86400,2)&"d", ROUND(H355/31536000,2)&"y"))))) -> 0.3s | J355: =LN(2)/H355 -> 2.3104906 | K355: =10*F355*(1-EXP(-J355*600))*6240000000000 -> 0 | L355: =EXP(-J355*30*60)*K355 -> 0 | M355: =G355 -> Co64
B356: 28053 | C356: 0 | D356: 0 | E356: 0 | F356: =SUM(C356:E356) -> 0 | G356: =VLOOKUP(B356,Nuclides!A:F,5,FALSE) -> Ni53 | H356: =VLOOKUP(B356,Nuclides!A:F,4,FALSE) -> 0.0552 | I356: =IF(H356="STABLE", "STABLE", IF(H356<60, H356&"s", IF(H356<3600, ROUND(H356/60,2)&"min", IF(H356<86400, ROUND(H356/3600,2)&"h", IF(H356<31536000, ROUND(H356/86400,2)&"d", ROUND(H356/31536000,2)&"y"))))) -> 0.0552s | J356: =LN(2)/H356 -> 12.557014 | K356: =10*F356*(1-EXP(-J356*600))*6240000000000 -> 0 | L356: =EXP(-J356*30*60)*K356 -> 0 | M356: =G356 -> Ni53
B357: 28054 | C357: 0 | D357: 0 | E357: 0 | F357: =SUM(C357:E357) -> 0 | G357: =VLOOKUP(B357,Nuclides!A:F,5,FALSE) -> Ni54 | H357: =VLOOKUP(B357,Nuclides!A:F,4,FALSE) -> 0.1142 | I357: =IF(H357="STABLE", "STABLE", IF(H357<60, H357&"s", IF(H357<3600, ROUND(H357/60,2)&"min", IF(H357<86400, ROUND(H357/3600,2)&"h", IF(H357<31536000, ROUND(H357/86400,2)&"d", ROUND(H357/31536000,2)&"y"))))) -> 0.1142s | J357: =LN(2)/H357 -> 6.06959 | K357: =10*F357*(1-EXP(-J357*600))*6240000000000 -> 0 | L357: =EXP(-J357*30*60)*K357 -> 0 | M357: =G357 -> Ni54
B358: 28055 | C358: 0 | D358: 0 | E358: 0 | F358: =SUM(C358:E358) -> 0 | G358: =VLOOKUP(B358,Nuclides!A:F,5,FALSE) -> Ni55 | H358: =VLOOKUP(B358,Nuclides!A:F,4,FALSE) -> 0.2047 | I358: =IF(H358="STABLE", "STABLE", IF(H358<60, H358&"s", IF(H358<3600, ROUND(H358/60,2)&"min", IF(H358<86400, ROUND(H358/3600,2)&"h", IF(H358<31536000, ROUND(H358/86400,2)&"d", ROUND(H358/31536000,2)&"y"))))) -> 0.2047s | J358: =LN(2)/H358 -> 3.3861611 | K358: =10*F358*(1-EXP(-J358*600))*6240000000000 -> 0 | L358: =EXP(-J358*30*60)*K358 -> 0 | M358: =G358 -> Ni55
B359: 28056 | C359: 0 | D359: 0 | E359: 0 | F359: =SUM(C359:E359) -> 0 | G359: =VLOOKUP(B359,Nuclides!A:F,5,FALSE) -> Ni56 | H359: =VLOOKUP(B359,Nuclides!A:F,4,FALSE) -> 524880 | I359: =IF(H359="STABLE", "STABLE", IF(H359<60, H359&"s", IF(H359<3600, ROUND(H359/60,2)&"min", IF(H359<86400, ROUND(H359/3600,2)&"h", IF(H359<31536000, ROUND(H359/86400,2)&"d", ROUND(H359/31536000,2)&"y"))))) -> 6.08d | J359: =LN(2)/H359 -> 1.3205822e-06 | K359: =10*F359*(1-EXP(-J359*600))*6240000000000 -> 0 | L359: =EXP(-J359*30*60)*K359 -> 0 | M359: =G359 -> Ni56
B360: 28057 | C360: 0 | D360: 0 | E360: 0 | F360: =SUM(C360:E360) -> 0 | G360: =VLOOKUP(B360,Nuclides!A:F,5,FALSE) -> Ni57 | H360: =VLOOKUP(B360,Nuclides!A:F,4,FALSE) -> 128160 | I360: =IF(H360="STABLE", "STABLE", IF(H360<60, H360&"s", IF(H360<3600, ROUND(H360/60,2)&"min", IF(H360<86400, ROUND(H360/3600,2)&"h", IF(H360<31536000, ROUND(H360/86400,2)&"d", ROUND(H360/31536000,2)&"y"))))) -> 1.48d | J360: =LN(2)/H360 -> 5.4084518e-06 | K360: =10*F360*(1-EXP(-J360*600))*6240000000000 -> 0 | L360: =EXP(-J360*30*60)*K360 -> 0 | M360: =G360 -> Ni57
B361: 28058 | C361: 0 | D361: 0 | E361: 0 | F361: =SUM(C361:E361) -> 0 | G361: =VLOOKUP(B361,Nuclides!A:F,5,FALSE) -> Ni58 | H361: =VLOOKUP(B361,Nuclides!A:F,4,FALSE) -> STABLE | I361: =IF(H361="STABLE", "STABLE", IF(H361<60, H361&"s", IF(H361<3600, ROUND(H361/60,2)&"min", IF(H361<86400, ROUND(H361/3600,2)&"h", IF(H361<31536000, ROUND(H361/86400,2)&"d", ROUND(H361/31536000,2)&"y"))))) -> STABLE | J361: =LN(2)/H361 -> #VALUE! | K361: =10*F361*(1-EXP(-J361*600))*6240000000000 -> #VALUE! | L361: =EXP(-J361*30*60)*K361 -> #VALUE! | M361: =G361 -> Ni58
B362: 28059 | C362: 0 | D362: 0 | E362: 0 | F362: =SUM(C362:E362) -> 0 | G362: =VLOOKUP(B362,Nuclides!A:F,5,FALSE) -> Ni59 | H362: =VLOOKUP(B362,Nuclides!A:F,4,FALSE) -> 2398377600000 | I362: =IF(H362="STABLE", "STABLE", IF(H362<60, H362&"s", IF(H362<3600, ROUND(H362/60,2)&"min", IF(H362<86400, ROUND(H362/3600,2)&"h", IF(H362<31536000, ROUND(H362/86400,2)&"d", ROUND(H362/31536000,2)&"y"))))) -> 76052.05y | J362: =LN(2)/H362 -> 2.8900669e-13 | K362: =10*F362*(1-EXP(-J362*600))*6240000000000 -> 0 | L362: =EXP(-J362*30*60)*K362 -> 0 | M362: =G362 -> Ni59
B363: 28060 | C363: 0 | D363: 0 | E363: 0.0001248 | F363: =SUM(C363:E363) -> 0.0001248 | G363: =VLOOKUP(B363,Nuclides!A:F,5,FALSE) -> Ni60 | H363: =VLOOKUP(B363,Nuclides!A:F,4,FALSE) -> STABLE | I363: =IF(H363="STABLE", "STABLE", IF(H363<60, H363&"s", IF(H363<3600, ROUND(H363/60,2)&"min", IF(H363<86400, ROUND(H363/3600,2)&"h", IF(H363<31536000, ROUND(H363/86400,2)&"d", ROUND(H363/31536000,2)&"y"))))) -> STABLE | J363: =LN(2)/H363 -> #VALUE! | K363: =10*F363*(1-EXP(-J363*600))*6240000000000 -> #VALUE! | L363: =EXP(-J363*30*60)*K363 -> #VALUE! | M363: =G363 -> Ni60
B364: 28061 | C364: 0 | D364: 0 | E364: 0 | F364: =SUM(C364:E364) -> 0 | G364: =VLOOKUP(B364,Nuclides!A:F,5,FALSE) -> Ni61 | H364: =VLOOKUP(B364,Nuclides!A:F,4,FALSE) -> STABLE | I364: =IF(H364="STABLE", "STABLE", IF(H364<60, H364&"s", IF(H364<3600, ROUND(H364/60,2)&"min", IF(H364<86400, ROUND(H364/3600,2)&"h", IF(H364<31536000, ROUND(H364/86400,2)&"d", ROUND(H364/31536000,2)&"y"))))) -> STABLE | J364: =LN(2)/H364 -> #VALUE! | K364: =10*F364*(1-EXP(-J364*600))*6240000000000 -> #VALUE! | L364: =EXP(-J364*30*60)*K364 -> #VALUE! | M364: =G364 -> Ni61
B365: 28062 | C365: 0 | D365: 0 | E365: 1.65e-05 | F365: =SUM(C365:E365) -> 1.65e-05 | G365: =VLOOKUP(B365,Nuclides!A:F,5,FALSE) -> Ni62 | H365: =VLOOKUP(B365,Nuclides!A:F,4,FALSE) -> STABLE | I365: =IF(H365="STABLE", "STABLE", IF(H365<60, H365&"s", IF(H365<3600, ROUND(H365/60,2)&"min", IF(H365<86400, ROUND(H365/3600,2)&"h", IF(H365<31536000, ROUND(H365/86400,2)&"d", ROUND(H365/31536000,2)&"y"))))) -> STABLE | J365: =LN(2)/H365 -> #VALUE! | K365: =10*F365*(1-EXP(-J365*600))*6240000000000 -> #VALUE! | L365: =EXP(-J365*30*60)*K365 -> #VALUE! | M365: =G365 -> Ni62
B366: 28063 | C366: 1.7e-06 | D366: 0 | E366: 2.6e-06 | F366: =SUM(C366:E366) -> 4.3e-06 | G366: =VLOOKUP(B366,Nuclides!A:F,5,FALSE) -> Ni63 | H366: =VLOOKUP(B366,Nuclides!A:F,4,FALSE) -> 3193629120 | I366: =IF(H366="STABLE", "STABLE", IF(H366<60, H366&"s", IF(H366<3600, ROUND(H366/60,2)&"min", IF(H366<86400, ROUND(H366/3600,2)&"h", IF(H366<31536000, ROUND(H366/86400,2)&"d", ROUND(H366/31536000,2)&"y"))))) -> 101.27y | J366: =LN(2)/H366 -> 2.170406e-10 | K366: =10*F366*(1-EXP(-J366*600))*6240000000000 -> 34.941798 | L366: =EXP(-J366*30*60)*K366 -> 34.941784 | M366: =G366 -> Ni63 | N366: =L366 -> 34.941784 | O366: =0 -> 0
B367: 28064 | C367: 0.0008535 | D367: 0 | E367: 0 | F367: =SUM(C367:E367) -> 0.0008535 | G367: =VLOOKUP(B367,Nuclides!A:F,5,FALSE) -> Ni64 | H367: =VLOOKUP(B367,Nuclides!A:F,4,FALSE) -> STABLE | I367: =IF(H367="STABLE", "STABLE", IF(H367<60, H367&"s", IF(H367<3600, ROUND(H367/60,2)&"min", IF(H367<86400, ROUND(H367/3600,2)&"h", IF(H367<31536000, ROUND(H367/86400,2)&"d", ROUND(H367/31536000,2)&"y"))))) -> STABLE | J367: =LN(2)/H367 -> #VALUE! | K367: =10*F367*(1-EXP(-J367*600))*6240000000000 -> #VALUE! | L367: =EXP(-J367*30*60)*K367 -> #VALUE! | M367: =G367 -> Ni64
B368: 28065 | C368: 0 | D368: 0 | E368: 0 | F368: =SUM(C368:E368) -> 0 | G368: =VLOOKUP(B368,Nuclides!A:F,5,FALSE) -> Ni65 | H368: =VLOOKUP(B368,Nuclides!A:F,4,FALSE) -> 9063 | I368: =IF(H368="STABLE", "STABLE", IF(H368<60, H368&"s", IF(H368<3600, ROUND(H368/60,2)&"min", IF(H368<86400, ROUND(H368/3600,2)&"h", IF(H368<31536000, ROUND(H368/86400,2)&"d", ROUND(H368/31536000,2)&"y"))))) -> 2.52h | J368: =LN(2)/H368 -> 7.6480986e-05 | K368: =10*F368*(1-EXP(-J368*600))*6240000000000 -> 0 | L368: =EXP(-J368*30*60)*K368 -> 0 | M368: =G368 -> Ni65
B369: 28066 | C369: 0 | D369: 0 | E369: 0 | F369: =SUM(C369:E369) -> 0 | G369: =VLOOKUP(B369,Nuclides!A:F,5,FALSE) -> Ni66 | H369: =VLOOKUP(B369,Nuclides!A:F,4,FALSE) -> 196560 | I369: =IF(H369="STABLE", "STABLE", IF(H369<60, H369&"s", IF(H369<3600, ROUND(H369/60,2)&"min", IF(H369<86400, ROUND(H369/3600,2)&"h", IF(H369<31536000, ROUND(H369/86400,2)&"d", ROUND(H369/31536000,2)&"y"))))) -> 2.28d | J369: =LN(2)/H369 -> 3.5263898e-06 | K369: =10*F369*(1-EXP(-J369*600))*6240000000000 -> 0 | L369: =EXP(-J369*30*60)*K369 -> 0 | M369: =G369 -> Ni66
B370: 28067 | C370: 0 | D370: 0 | E370: 0 | F370: =SUM(C370:E370) -> 0 | G370: =VLOOKUP(B370,Nuclides!A:F,5,FALSE) -> Ni67 | H370: =VLOOKUP(B370,Nuclides!A:F,4,FALSE) -> 21 | I370: =IF(H370="STABLE", "STABLE", IF(H370<60, H370&"s", IF(H370<3600, ROUND(H370/60,2)&"min", IF(H370<86400, ROUND(H370/3600,2)&"h", IF(H370<31536000, ROUND(H370/86400,2)&"d", ROUND(H370/31536000,2)&"y"))))) -> 21s | J370: =LN(2)/H370 -> 0.033007009 | K370: =10*F370*(1-EXP(-J370*600))*6240000000000 -> 0 | L370: =EXP(-J370*30*60)*K370 -> 0 | M370: =G370 -> Ni67
B371: 28068 | C371: 0 | D371: 0 | E371: 0 | F371: =SUM(C371:E371) -> 0 | G371: =VLOOKUP(B371,Nuclides!A:F,5,FALSE) -> Ni68 | H371: =VLOOKUP(B371,Nuclides!A:F,4,FALSE) -> 29 | I371: =IF(H371="STABLE", "STABLE", IF(H371<60, H371&"s", IF(H371<3600, ROUND(H371/60,2)&"min", IF(H371<86400, ROUND(H371/3600,2)&"h", IF(H371<31536000, ROUND(H371/86400,2)&"d", ROUND(H371/31536000,2)&"y"))))) -> 29s | J371: =LN(2)/H371 -> 0.023901627 | K371: =10*F371*(1-EXP(-J371*600))*6240000000000 -> 0 | L371: =EXP(-J371*30*60)*K371 -> 0 | M371: =G371 -> Ni68
B372: 29057 | C372: 0 | D372: 0 | E372: 0 | F372: =SUM(C372:E372) -> 0 | G372: =VLOOKUP(B372,Nuclides!A:F,5,FALSE) -> Cu57 | H372: =VLOOKUP(B372,Nuclides!A:F,4,FALSE) -> 0.1963 | I372: =IF(H372="STABLE", "STABLE", IF(H372<60, H372&"s", IF(H372<3600, ROUND(H372/60,2)&"min", IF(H372<86400, ROUND(H372/3600,2)&"h", IF(H372<31536000, ROUND(H372/86400,2)&"d", ROUND(H372/31536000,2)&"y"))))) -> 0.1963s | J372: =LN(2)/H372 -> 3.5310605 | K372: =10*F372*(1-EXP(-J372*600))*6240000000000 -> 0 | L372: =EXP(-J372*30*60)*K372 -> 0 | M372: =G372 -> Cu57
B373: 29058 | C373: 0 | D373: 0 | E373: 0 | F373: =SUM(C373:E373) -> 0 | G373: =VLOOKUP(B373,Nuclides!A:F,5,FALSE) -> Cu58 | H373: =VLOOKUP(B373,Nuclides!A:F,4,FALSE) -> 3.204 | I373: =IF(H373="STABLE", "STABLE", IF(H373<60, H373&"s", IF(H373<3600, ROUND(H373/60,2)&"min", IF(H373<86400, ROUND(H373/3600,2)&"h", IF(H373<31536000, ROUND(H373/86400,2)&"d", ROUND(H373/31536000,2)&"y"))))) -> 3.204s | J373: =LN(2)/H373 -> 0.21633807 | K373: =10*F373*(1-EXP(-J373*600))*6240000000000 -> 0 | L373: =EXP(-J373*30*60)*K373 -> 0 | M373: =G373 -> Cu58
B374: 29059 | C374: 0 | D374: 0 | E374: 0 | F374: =SUM(C374:E374) -> 0 | G374: =VLOOKUP(B374,Nuclides!A:F,5,FALSE) -> Cu59 | H374: =VLOOKUP(B374,Nuclides!A:F,4,FALSE) -> 81.5 | I374: =IF(H374="STABLE", "STABLE", IF(H374<60, H374&"s", IF(H374<3600, ROUND(H374/60,2)&"min", IF(H374<86400, ROUND(H374/3600,2)&"h", IF(H374<31536000, ROUND(H374/86400,2)&"d", ROUND(H374/31536000,2)&"y"))))) -> 1.36min | J374: =LN(2)/H374 -> 0.0085048734 | K374: =10*F374*(1-EXP(-J374*600))*6240000000000 -> 0 | L374: =EXP(-J374*30*60)*K374 -> 0 | M374: =G374 -> Cu59
B375: 29060 | C375: 0 | D375: 0 | E375: 0 | F375: =SUM(C375:E375) -> 0 | G375: =VLOOKUP(B375,Nuclides!A:F,5,FALSE) -> Cu60 | H375: =VLOOKUP(B375,Nuclides!A:F,4,FALSE) -> 1422 | I375: =IF(H375="STABLE", "STABLE", IF(H375<60, H375&"s", IF(H375<3600, ROUND(H375/60,2)&"min", IF(H375<86400, ROUND(H375/3600,2)&"h", IF(H375<31536000, ROUND(H375/86400,2)&"d", ROUND(H375/31536000,2)&"y"))))) -> 23.7min | J375: =LN(2)/H375 -> 0.00048744527 | K375: =10*F375*(1-EXP(-J375*600))*6240000000000 -> 0 | L375: =EXP(-J375*30*60)*K375 -> 0 | M375: =G375 -> Cu60
B376: 29061 | C376: 0 | D376: 0 | E376: 0 | F376: =SUM(C376:E376) -> 0 | G376: =VLOOKUP(B376,Nuclides!A:F,5,FALSE) -> Cu61 | H376: =VLOOKUP(B376,Nuclides!A:F,4,FALSE) -> 12020.4 | I376: =IF(H376="STABLE", "STABLE", IF(H376<60, H376&"s", IF(H376<3600, ROUND(H376/60,2)&"min", IF(H376<86400, ROUND(H376/3600,2)&"h", IF(H376<31536000, ROUND(H376/86400,2)&"d", ROUND(H376/31536000,2)&"y"))))) -> 3.34h | J376: =LN(2)/H376 -> 5.7664236e-05 | K376: =10*F376*(1-EXP(-J376*600))*6240000000000 -> 0 | L376: =EXP(-J376*30*60)*K376 -> 0 | M376: =G376 -> Cu61
...

Sheet Cu-Ag-Ni
G1: Nuclides | H1: T1/2 | I1: T1/2 | J1: λ | K1: 10μA-10min | L1: cool-30min | M1: Nuclides
C3: 1 | D3: 2 | E3: 3
B4: 1001 | C4: 0 | D4: 0 | E4: 0 | F4: =SUM(C4:E4) -> 0 | G4: =VLOOKUP(B4,Nuclides!A:F,5,FALSE) -> H1 | H4: =VLOOKUP(B4,Nuclides!A:F,4,FALSE) -> 613.9 | I4: =IF(H4="STABLE", "STABLE", IF(H4<60, H4&"s", IF(H4<3600, ROUND(H4/60,2)&"min", IF(H4<86400, ROUND(H4/3600,2)&"h", IF(H4<31536000, ROUND(H4/86400,2)&"d", ROUND(H4/31536000,2)&"y"))))) -> 10.23min | J4: =LN(2)/H4 -> 0.0011290881 | K4: =10*F4*(1-EXP(-J4*600))*6240000000000 -> 0 | L4: =EXP(-J4*30*60)*K4 -> 0 | M4: =G4 -> H1 | N4: =L4 -> 0 | O4: =0 -> 0
B5: 1002 | C5: 0 | D5: 0 | E5: 0 | F5: =SUM(C5:E5) -> 0 | G5: =VLOOKUP(B5,Nuclides!A:F,5,FALSE) -> H2 | H5: =VLOOKUP(B5,Nuclides!A:F,4,FALSE) -> STABLE | I5: =IF(H5="STABLE", "STABLE", IF(H5<60, H5&"s", IF(H5<3600, ROUND(H5/60,2)&"min", IF(H5<86400, ROUND(H5/3600,2)&"h", IF(H5<31536000, ROUND(H5/86400,2)&"d", ROUND(H5/31536000,2)&"y"))))) -> STABLE | J5: =LN(2)/H5 -> #VALUE! | K5: =10*F5*(1-EXP(-J5*600))*6240000000000 -> #VALUE! | L5: =EXP(-J5*30*60)*K5 -> #VALUE! | M5: =G5 -> H2 | N5: =L5 -> #VALUE! | O5: =0 -> 0
B6: 1003 | C6: 0 | D6: 0 | E6: 0 | F6: =SUM(C6:E6) -> 0 | G6: =VLOOKUP(B6,Nuclides!A:F,5,FALSE) -> H3 | H6: =VLOOKUP(B6,Nuclides!A:F,4,FALSE) -> 388789632 | I6: =IF(H6="STABLE", "STABLE", IF(H6<60, H6&"s", IF(H6<3600, ROUND(H6/60,2)&"min", IF(H6<86400, ROUND(H6/3600,2)&"h", IF(H6<31536000, ROUND(H6/86400,2)&"d", ROUND(H6/31536000,2)&"y"))))) -> 12.33y | J6: =LN(2)/H6 -> 1.7828335e-09 | K6: =10*F6*(1-EXP(-J6*600))*6240000000000 -> 0 | L6: =EXP(-J6*30*60)*K6 -> 0 | M6: =G6 -> H3 | N6: =L6 -> 0 | O6: =0 -> 0
B7: 2003 | C7: 0 | D7: 0 | E7: 0 | F7: =SUM(C7:E7) -> 0 | G7: =VLOOKUP(B7,Nuclides!A:F,5,FALSE) -> He3 | H7: =VLOOKUP(B7,Nuclides!A:F,4,FALSE) -> STABLE | I7: =IF(H7="STABLE", "STABLE", IF(H7<60, H7&"s", IF(H7<3600, ROUND(H7/60,2)&"min", IF(H7<86400, ROUND(H7/3600,2)&"h", IF(H7<31536000, ROUND(H7/86400,2)&"d", ROUND(H7/31536000,2)&"y"))))) -> STABLE | J7: =LN(2)/H7 -> #VALUE! | K7: =10*F7*(1-EXP(-J7*600))*6240000000000 -> #VALUE! | L7: =EXP(-J7*30*60)*K7 -> #VALUE! | M7: =G7 -> He3 | N7: =L7 -> #VALUE! | O7: =0 -> 0
B8: 2004 | C8: 0 | D8: 0 | E8: 0 | F8: =SUM(C8:E8) -> 0 | G8: =VLOOKUP(B8,Nuclides!A:F,5,FALSE) -> He4 | H8: =VLOOKUP(B8,Nuclides!A:F,4,FALSE) -> STABLE | I8: =IF(H8="STABLE", "STABLE", IF(H8<60, H8&"s", IF(H8<3600, ROUND(H8/60,2)&"min", IF(H8<86400, ROUND(H8/3600,2)&"h", IF(H8<31536000, ROUND(H8/86400,2)&"d", ROUND(H8/31536000,2)&"y"))))) -> STABLE | J8: =LN(2)/H8 -> #VALUE! | K8: =10*F8*(1-EXP(-J8*600))*6240000000000 -> #VALUE! | L8: =EXP(-J8*30*60)*K8 -> #VALUE! | M8: =G8 -> He4 | N8: =L8 -> #VALUE! | O8: =0 -> 0
B9: 2005 | C9: 0 | D9: 0 | E9: 0 | F9: =SUM(C9:E9) -> 0 | G9: =VLOOKUP(B9,Nuclides!A:F,5,FALSE) -> He5 | H9: =VLOOKUP(B9,Nuclides!A:F,4,FALSE) -> 7.595e-22 | I9: =IF(H9="STABLE", "STABLE", IF(H9<60, H9&"s", IF(H9<3600, ROUND(H9/60,2)&"min", IF(H9<86400, ROUND(H9/3600,2)&"h", IF(H9<31536000, ROUND(H9/86400,2)&"d", ROUND(H9/31536000,2)&"y"))))) -> 7.595E-22s | J9: =LN(2)/H9 -> 9.1263618e+20 | K9: =10*F9*(1-EXP(-J9*600))*6240000000000 -> 0 | L9: =EXP(-J9*30*60)*K9 -> 0 | M9: =G9 -> He5 | N9: =L9 -> 0 | O9: =0 -> 0
B10: 2006 | C10: 0 | D10: 0 | E10: 0 | F10: =SUM(C10:E10) -> 0 | G10: =VLOOKUP(B10,Nuclides!A:F,5,FALSE) -> He6 | H10: =VLOOKUP(B10,Nuclides!A:F,4,FALSE) -> 0.8067 | I10: =IF(H10="STABLE", "STABLE", IF(H10<60, H10&"s", IF(H10<3600, ROUND(H10/60,2)&"min", IF(H10<86400, ROUND(H10/3600,2)&"h", IF(H10<31536000, ROUND(H10/86400,2)&"d", ROUND(H10/31536000,2)&"y"))))) -> 0.8067s | J10: =LN(2)/H10 -> 0.85923786 | K10: =10*F10*(1-EXP(-J10*600))*6240000000000 -> 0 | L10: =EXP(-J10*30*60)*K10 -> 0 | M10: =G10 -> He6 | N10: =L10 -> 0 | O10: =0 -> 0
B11: 2007 | C11: 0 | D11: 0 | E11: 0 | F11: =SUM(C11:E11) -> 0 | G11: =VLOOKUP(B11,Nuclides!A:F,5,FALSE) -> He7 | H11: =VLOOKUP(B11,Nuclides!A:F,4,FALSE) -> 3.038e-21 | I11: =IF(H11="STABLE", "STABLE", IF(H11<60, H11&"s", IF(H11<3600, ROUND(H11/60,2)&"min", IF(H11<86400, ROUND(H11/3600,2)&"h", IF(H11<31536000, ROUND(H11/86400,2)&"d", ROUND(H11/31536000,2)&"y"))))) -> 3.038E-21s | J11: =LN(2)/H11 -> 2.2815905e+20 | K11: =10*F11*(1-EXP(-J11*600))*6240000000000 -> 0 | L11: =EXP(-J11*30*60)*K11 -> 0 | M11: =G11 -> He7 | N11: =L11 -> 0 | O11: =0 -> 0
B12: 2008 | C12: 0 | D12: 0 | E12: 0 | F12: =SUM(C12:E12) -> 0 | G12: =VLOOKUP(B12,Nuclides!A:F,5,FALSE) -> He8 | H12: =VLOOKUP(B12,Nuclides!A:F,4,FALSE) -> 0.1191 | I12: =IF(H12="STABLE", "STABLE", IF(H12<60, H12&"s", IF(H12<3600, ROUND(H12/60,2)&"min", IF(H12<86400, ROUND(H12/3600,2)&"h", IF(H12<31536000, ROUND(H12/86400,2)&"d", ROUND(H12/31536000,2)&"y"))))) -> 0.1191s | J12: =LN(2)/H12 -> 5.8198756 | K12: =10*F12*(1-EXP(-J12*600))*6240000000000 -> 0 | L12: =EXP(-J12*30*60)*K12 -> 0 | M12: =G12 -> He8 | N12: =L12 -> 0 | O12: =0 -> 0
B13: 3005 | C13: 0 | D13: 0 | E13: 0 | F13: =SUM(C13:E13) -> 0 | G13: =VLOOKUP(B13,Nuclides!A:F,5,FALSE) -> Li5 | H13: =VLOOKUP(B13,Nuclides!A:F,4,FALSE) -> 3.038e-22 | I13: =IF(H13="STABLE", "STABLE", IF(H13<60, H13&"s", IF(H13<3600, ROUND(H13/60,2)&"min", IF(H13<86400, ROUND(H13/3600,2)&"h", IF(H13<31536000, ROUND(H13/86400,2)&"d", ROUND(H13/31536000,2)&"y"))))) -> 3.038E-22s | J13: =LN(2)/H13 -> 2.2815905e+21 | K13: =10*F13*(1-EXP(-J13*600))*6240000000000 -> 0 | L13: =EXP(-J13*30*60)*K13 -> 0 | M13: =G13 -> Li5 | N13: =L13 -> 0 | O13: =0 -> 0
B14: 3006 | C14: 0 | D14: 0 | E14: 0 | F14: =SUM(C14:E14) -> 0 | G14: =VLOOKUP(B14,Nuclides!A:F,5,FALSE) -> Li6 | H14: =VLOOKUP(B14,Nuclides!A:F,4,FALSE) -> STABLE | I14: =IF(H14="STABLE", "STABLE", IF(H14<60, H14&"s", IF(H14<3600, ROUND(H14/60,2)&"min", IF(H14<86400, ROUND(H14/3600,2)&"h", IF(H14<31536000, ROUND(H14/86400,2)&"d", ROUND(H14/31536000,2)&"y"))))) -> STABLE | J14: =LN(2)/H14 -> #VALUE! | K14: =10*F14*(1-EXP(-J14*600))*6240000000000 -> #VALUE! | L14: =EXP(-J14*30*60)*K14 -> #VALUE! | M14: =G14 -> Li6 | N14: =L14 -> #VALUE! | O14: =0 -> 0
B15: 3007 | C15: 0 | D15: 0 | E15: 0 | F15: =SUM(C15:E15) -> 0 | G15: =VLOOKUP(B15,Nuclides!A:F,5,FALSE) -> Li7 | H15: =VLOOKUP(B15,Nuclides!A:F,4,FALSE) -> STABLE | I15: =IF(H15="STABLE", "STABLE", IF(H15<60, H15&"s", IF(H15<3600, ROUND(H15/60,2)&"min", IF(H15<86400, ROUND(H15/3600,2)&"h", IF(H15<31536000, ROUND(H15/86400,2)&"d", ROUND(H15/31536000,2)&"y"))))) -> STABLE | J15: =LN(2)/H15 -> #VALUE! | K15: =10*F15*(1-EXP(-J15*600))*6240000000000 -> #VALUE! | L15: =EXP(-J15*30*60)*K15 -> #VALUE! | M15: =G15 -> Li7 | N15: =L15 -> #VALUE! | O15: =0 -> 0
... B1771: 80206 | C1771: 0 | D1771: 0 | E1771: 0 | F1771: =SUM(C1771:E1771) -> 0 | G1771: =VLOOKUP(B1771,Nuclides!A:F,5,FALSE) -> Hg206 | H1771: =VLOOKUP(B1771,Nuclides!A:F,4,FALSE) -> 499.2 | I1771: =IF(H1771="STABLE", "STABLE", IF(H1771<60, H1771&"s", IF(H1771<3600, ROUND(H1771/60,2)&"min", IF(H1771<86400, ROUND(H1771/3600,2)&"h", IF(H1771<31536000, ROUND(H1771/86400,2)&"d", ROUND(H1771/31536000,2)&"y"))))) -> 8.32min | J1771: =LN(2)/H1771 -> 0.001388516 | K1771: =10*F1771*(1-EXP(-J1771*600))*6240000000000 -> 0 | L1771: =EXP(-J1771*30*60)*K1771 -> 0 | M1771: =G1771 -> Hg206 | N1771: =L1771 -> 0 | O1771: =0 -> 0

Sheet Ag-Ni
G1: Nuclides | H1: T1/2 | I1: T1/2 | J1: λ | K1: 10μA-10min | L1: cool-30min | M1: Nuclides
C4: 1 | D4: 2 | E4: 3
B5: 1001 | C5: 0 | D5: 0 | E5: 0 | F5: =SUM(C5:E5) -> 0 | G5: =VLOOKUP(B5,Nuclides!A:F,5,FALSE) -> H1 | H5: =VLOOKUP(B5,Nuclides!A:F,4,FALSE) -> 613.9 | I5: =IF(H5="STABLE", "STABLE", IF(H5<60, H5&"s", IF(H5<3600, ROUND(H5/60,2)&"min", IF(H5<86400, ROUND(H5/3600,2)&"h", IF(H5<31536000, ROUND(H5/86400,2)&"d", ROUND(H5/31536000,2)&"y"))))) -> 10.23min | J5: =LN(2)/H5 -> 0.0011290881 | K5: =10*F5*(1-EXP(-J5*600))*6240000000000 -> 0 | L5: =EXP(-J5*30*60)*K5 -> 0 | M5: =G5 -> H1 | N5: =L5 -> 0 | O5: =0 -> 0
B6: 1002 | C6: 0 | D6: 0 | E6: 0 | F6: =SUM(C6:E6) -> 0 | G6: =VLOOKUP(B6,Nuclides!A:F,5,FALSE) -> H2 | H6: =VLOOKUP(B6,Nuclides!A:F,4,FALSE) -> STABLE | I6: =IF(H6="STABLE", "STABLE", IF(H6<60, H6&"s", IF(H6<3600, ROUND(H6/60,2)&"min", IF(H6<86400, ROUND(H6/3600,2)&"h", IF(H6<31536000, ROUND(H6/86400,2)&"d", ROUND(H6/31536000,2)&"y"))))) -> STABLE | J6: =LN(2)/H6 -> #VALUE! | K6: =10*F6*(1-EXP(-J6*600))*6240000000000 -> #VALUE! | L6: =EXP(-J6*30*60)*K6 -> #VALUE! | M6: =G6 -> H2 | N6: =L6 -> #VALUE! | O6: =0 -> 0
B7: 1003 | C7: 0 | D7: 0 | E7: 0 | F7: =SUM(C7:E7) -> 0 | G7: =VLOOKUP(B7,Nuclides!A:F,5,FALSE) -> H3 | H7: =VLOOKUP(B7,Nuclides!A:F,4,FALSE) -> 388789632 | I7: =IF(H7="STABLE", "STABLE", IF(H7<60, H7&"s", IF(H7<3600, ROUND(H7/60,2)&"min", IF(H7<86400, ROUND(H7/3600,2)&"h", IF(H7<31536000, ROUND(H7/86400,2)&"d", ROUND(H7/31536000,2)&"y"))))) -> 12.33y | J7: =LN(2)/H7 -> 1.7828335e-09 | K7: =10*F7*(1-EXP(-J7*600))*6240000000000 -> 0 | L7: =EXP(-J7*30*60)*K7 -> 0 | M7: =G7 -> H3 | N7: =L7 -> 0 | O7: =0 -> 0
B8: 2003 | C8: 0 | D8: 0 | E8: 0 | F8: =SUM(C8:E8) -> 0 | G8: =VLOOKUP(B8,Nuclides!A:F,5,FALSE) -> He3 | H8: =VLOOKUP(B8,Nuclides!A:F,4,FALSE) -> STABLE | I8: =IF(H8="STABLE", "STABLE", IF(H8<60, H8&"s", IF(H8<3600, ROUND(H8/60,2)&"min", IF(H8<86400, ROUND(H8/3600,2)&"h", IF(H8<31536000, ROUND(H8/86400,2)&"d", ROUND(H8/31536000,2)&"y"))))) -> STABLE | J8: =LN(2)/H8 -> #VALUE! | K8: =10*F8*(1-EXP(-J8*600))*6240000000000 -> #VALUE! | L8: =EXP(-J8*30*60)*K8 -> #VALUE! | M8: =G8 -> He3 | N8: =L8 -> #VALUE! | O8: =0 -> 0
B9: 2004 | C9: 0 | D9: 0 | E9: 0 | F9: =SUM(C9:E9) -> 0 | G9: =VLOOKUP(B9,Nuclides!A:F,5,FALSE) -> He4 | H9: =VLOOKUP(B9,Nuclides!A:F,4,FALSE) -> STABLE | I9: =IF(H9="STABLE", "STABLE", IF(H9<60, H9&"s", IF(H9<3600, ROUND(H9/60,2)&"min", IF(H9<86400, ROUND(H9/3600,2)&"h", IF(H9<31536000, ROUND(H9/86400,2)&"d", ROUND(H9/31536000,2)&"y"))))) -> STABLE | J9: =LN(2)/H9 -> #VALUE! | K9: =10*F9*(1-EXP(-J9*600))*6240000000000 -> #VALUE! | L9: =EXP(-J9*30*60)*K9 -> #VALUE! | M9: =G9 -> He4 | N9: =L9 -> #VALUE! | O9: =0 -> 0
B10: 2005 | C10: 0 | D10: 0 | E10: 0 | F10: =SUM(C10:E10) -> 0 | G10: =VLOOKUP(B10,Nuclides!A:F,5,FALSE) -> He5 | H10: =VLOOKUP(B10,Nuclides!A:F,4,FALSE) -> 7.595e-22 | I10: =IF(H10="STABLE", "STABLE", IF(H10<60, H10&"s", IF(H10<3600, ROUND(H10/60,2)&"min", IF(H10<86400, ROUND(H10/3600,2)&"h", IF(H10<31536000, ROUND(H10/86400,2)&"d", ROUND(H10/31536000,2)&"y"))))) -> 7.595E-22s | J10: =LN(2)/H10 -> 9.1263618e+20 | K10: =10*F10*(1-EXP(-J10*600))*6240000000000 -> 0 | L10: =EXP(-J10*30*60)*K10 -> 0 | M10: =G10 -> He5 | N10: =L10 -> 0 | O10: =0 -> 0
B11: 2006 | C11: 0 | D11: 0 | E11: 0 | F11: =SUM(C11:E11) -> 0 | G11: =VLOOKUP(B11,Nuclides!A:F,5,FALSE) -> He6 | H11: =VLOOKUP(B11,Nuclides!A:F,4,FALSE) -> 0.8067 | I11: =IF(H11="STABLE", "STABLE", IF(H11<60, H11&"s", IF(H11<3600, ROUND(H11/60,2)&"min", IF(H11<86400, ROUND(H11/3600,2)&"h", IF(H11<31536000, ROUND(H11/86400,2)&"d", ROUND(H11/31536000,2)&"y"))))) -> 0.8067s | J11: =LN(2)/H11 -> 0.85923786 | K11: =10*F11*(1-EXP(-J11*600))*6240000000000 -> 0 | L11: =EXP(-J11*30*60)*K11 -> 0 | M11: =G11 -> He6 | N11: =L11 -> 0 | O11: =0 -> 0
B12: 2007 | C12: 0 | D12: 0 | E12: 0 | F12: =SUM(C12:E12) -> 0 | G12: =VLOOKUP(B12,Nuclides!A:F,5,FALSE) -> He7 | H12: =VLOOKUP(B12,Nuclides!A:F,4,FALSE) -> 3.038e-21 | I12: =IF(H12="STABLE", "STABLE", IF(H12<60, H12&"s", IF(H12<3600, ROUND(H12/60,2)&"min", IF(H12<86400, ROUND(H12/3600,2)&"h", IF(H12<31536000, ROUND(H12/86400,2)&"d", ROUND(H12/31536000,2)&"y"))))) -> 3.038E-21s | J12: =LN(2)/H12 -> 2.2815905e+20 | K12: =10*F12*(1-EXP(-J12*600))*6240000000000 -> 0 | L12: =EXP(-J12*30*60)*K12 -> 0 | M12: =G12 -> He7 | N12: =L12 -> 0 | O12: =0 -> 0
B13: 2008 | C13: 0 | D13: 0 | E13: 0 | F13: =SUM(C13:E13) -> 0 | G13: =VLOOKUP(B13,Nuclides!A:F,5,FALSE) -> He8 | H13: =VLOOKUP(B13,Nuclides!A:F,4,FALSE) -> 0.1191 | I13: =IF(H13="STABLE", "STABLE", IF(H13<60, H13&"s", IF(H13<3600, ROUND(H13/60,2)&"min", IF(H13<86400, ROUND(H13/3600,2)&"h", IF(H13<31536000, ROUND(H13/86400,2)&"d", ROUND(H13/31536000,2)&"y"))))) -> 0.1191s | J13: =LN(2)/H13 -> 5.8198756 | K13: =10*F13*(1-EXP(-J13*600))*6240000000000 -> 0 | L13: =EXP(-J13*30*60)*K13 -> 0 | M13: =G13 -> He8 | N13: =L13 -> 0 | O13: =0 -> 0
B14: 3005 | C14: 0 | D14: 0 | E14: 0 | F14: =SUM(C14:E14) -> 0 | G14: =VLOOKUP(B14,Nuclides!A:F,5,FALSE) -> Li5 | H14: =VLOOKUP(B14,Nuclides!A:F,4,FALSE) -> 3.038e-22 | I14: =IF(H14="STABLE", "STABLE", IF(H14<60, H14&"s", IF(H14<3600, ROUND(H14/60,2)&"min", IF(H14<86400, ROUND(H14/3600,2)&"h", IF(H14<31536000, ROUND(H14/86400,2)&"d", ROUND(H14/31536000,2)&"y"))))) -> 3.038E-22s | J14: =LN(2)/H14 -> 2.2815905e+21 | K14: =10*F14*(1-EXP(-J14*600))*6240000000000 -> 0 | L14: =EXP(-J14*30*60)*K14 -> 0 | M14: =G14 -> Li5 | N14: =L14 -> 0 | O14: =0 -> 0
B15: 3006 | C15: 0 | D15: 0 | E15: 0 | F15: =SUM(C15:E15) -> 0 | G15: =VLOOKUP(B15,Nuclides!A:F,5,FALSE) -> Li6 | H15: =VLOOKUP(B15,Nuclides!A:F,4,FALSE) -> STABLE | I15: =IF(H15="STABLE", "STABLE", IF(H15<60, H15&"s", IF(H15<3600, ROUND(H15/60,2)&"min", IF(H15<86400, ROUND(H15/3600,2)&"h", IF(H15<31536000, ROUND(H15/86400,2)&"d", ROUND(H15/31536000,2)&"y"))))) -> STABLE | J15: =LN(2)/H15 -> #VALUE! | K15: =10*F15*(1-EXP(-J15*600))*6240000000000 -> #VALUE! | L15: =EXP(-J15*30*60)*K15 -> #VALUE! | M15: =G15 -> Li6 | N15: =L15 -> #VALUE! | O15: =0 -> 0
B16: 3007 | C16: 0 | D16: 0 | E16: 0 | F16: =SUM(C16:E16) -> 0 | G16: =VLOOKUP(B16,Nuclides!A:F,5,FALSE) -> Li7 | H16: =VLOOKUP(B16,Nuclides!A:F,4,FALSE) -> STABLE | I16: =IF(H16="STABLE", "STABLE", IF(H16<60, H16&"s", IF(H16<3600, ROUND(H16/60,2)&"min", IF(H16<86400, ROUND(H16/3600,2)&"h", IF(H16<31536000, ROUND(H16/86400,2)&"d", ROUND(H16/31536000,2)&"y"))))) -> STABLE | J16: =LN(2)/H16 -> #VALUE! | K16: =10*F16*(1-EXP(-J16*600))*6240000000000 -> #VALUE! | L16: =EXP(-J16*30*60)*K16 -> #VALUE! | M16: =G16 -> Li7 | N16: =L16 -> #VALUE! | O16: =0 -> 0
... B1772: 80206 | C1772: 0 | D1772: 0 | E1772: 0 | F1772: =SUM(C1772:E1772) -> 0 | G1772: =VLOOKUP(B1772,Nuclides!A:F,5,FALSE) -> Hg206 | H1772: =VLOOKUP(B1772,Nuclides!A:F,4,FALSE) -> 499.2 | I1772: =IF(H1772="STABLE", "STABLE", IF(H1772<60, H1772&"s", IF(H1772<3600, ROUND(H1772/60,2)&"min", IF(H1772<86400, ROUND(H1772/3600,2)&"h", IF(H1772<31536000, ROUND(H1772/86400,2)&"d", ROUND(H1772/31536000,2)&"y"))))) -> 8.32min | J1772: =LN(2)/H1772 -> 0.001388516 | K1772: =10*F1772*(1-EXP(-J1772*600))*6240000000000 -> 0 | L1772: =EXP(-J1772*30*60)*K1772 -> 0 | M1772: =G1772 -> Hg206 | N1772: =L1772 -> 0 | O1772: =0 -> 0

Sheet Ag1-Ni
G1: Nuclides | H1: T1/2 | I1: T1/2 | J1: λ | K1: 10μA-10min | L1: cool-30min | M1: Nuclides
C5: 1 | D5: 2 | E5: 3
B6: 1001 | C6: 0 | D6: 0 | E6: 0 | F6: =SUM(C6:E6) -> 0 | G6: =VLOOKUP(B6,Nuclides!A:F,5,FALSE) -> H1 | H6: =VLOOKUP(B6,Nuclides!A:F,4,FALSE) -> 613.9 | I6: =IF(H6="STABLE", "STABLE", IF(H6<60, H6&"s", IF(H6<3600, ROUND(H6/60,2)&"min", IF(H6<86400, ROUND(H6/3600,2)&"h", IF(H6<31536000, ROUND(H6/86400,2)&"d", ROUND(H6/31536000,2)&"y"))))) -> 10.23min | J6: =LN(2)/H6 -> 0.0011290881 | K6: =10*F6*(1-EXP(-J6*600))*6240000000000 -> 0 | L6: =EXP(-J6*30*60)*K6 -> 0 | M6: =G6 -> H1 | N6: =L6 -> 0 | O6: =0 -> 0
B7: 1002 | C7: 0 | D7: 0 | E7: 0 | F7: =SUM(C7:E7) -> 0 | G7: =VLOOKUP(B7,Nuclides!A:F,5,FALSE) -> H2 | H7: =VLOOKUP(B7,Nuclides!A:F,4,FALSE) -> STABLE | I7: =IF(H7="STABLE", "STABLE", IF(H7<60, H7&"s", IF(H7<3600, ROUND(H7/60,2)&"min", IF(H7<86400, ROUND(H7/3600,2)&"h", IF(H7<31536000, ROUND(H7/86400,2)&"d", ROUND(H7/31536000,2)&"y"))))) -> STABLE | J7: =LN(2)/H7 -> #VALUE! | K7: =10*F7*(1-EXP(-J7*600))*6240000000000 -> #VALUE! | L7: =EXP(-J7*30*60)*K7 -> #VALUE! | M7: =G7 -> H2 | N7: =L7 -> #VALUE! | O7: =0 -> 0
B8: 1003 | C8: 0 | D8: 0 | E8: 0 | F8: =SUM(C8:E8) -> 0 | G8: =VLOOKUP(B8,Nuclides!A:F,5,FALSE) -> H3 | H8: =VLOOKUP(B8,Nuclides!A:F,4,FALSE) -> 388789632 | I8: =IF(H8="STABLE", "STABLE", IF(H8<60, H8&"s", IF(H8<3600, ROUND(H8/60,2)&"min", IF(H8<86400, ROUND(H8/3600,2)&"h", IF(H8<31536000, ROUND(H8/86400,2)&"d", ROUND(H8/31536000,2)&"y"))))) -> 12.33y | J8: =LN(2)/H8 -> 1.7828335e-09 | K8: =10*F8*(1-EXP(-J8*600))*6240000000000 -> 0 | L8: =EXP(-J8*30*60)*K8 -> 0 | M8: =G8 -> H3 | N8: =L8 -> 0 | O8: =0 -> 0
B9: 2003 | C9: 0 | D9: 0 | E9: 0 | F9: =SUM(C9:E9) -> 0 | G9: =VLOOKUP(B9,Nuclides!A:F,5,FALSE) -> He3 | H9: =VLOOKUP(B9,Nuclides!A:F,4,FALSE) -> STABLE | I9: =IF(H9="STABLE", "STABLE", IF(H9<60, H9&"s", IF(H9<3600, ROUND(H9/60,2)&"min", IF(H9<86400, ROUND(H9/3600,2)&"h", IF(H9<31536000, ROUND(H9/86400,2)&"d", ROUND(H9/31536000,2)&"y"))))) -> STABLE | J9: =LN(2)/H9 -> #VALUE! | K9: =10*F9*(1-EXP(-J9*600))*6240000000000 -> #VALUE! | L9: =EXP(-J9*30*60)*K9 -> #VALUE! | M9: =G9 -> He3 | N9: =L9 -> #VALUE! | O9: =0 -> 0
B10: 2004 | C10: 0 | D10: 0 | E10: 0 | F10: =SUM(C10:E10) -> 0 | G10: =VLOOKUP(B10,Nuclides!A:F,5,FALSE) -> He4 | H10: =VLOOKUP(B10,Nuclides!A:F,4,FALSE) -> STABLE | I10: =IF(H10="STABLE", "STABLE", IF(H10<60, H10&"s", IF(H10<3600, ROUND(H10/60,2)&"min", IF(H10<86400, ROUND(H10/3600,2)&"h", IF(H10<31536000, ROUND(H10/86400,2)&"d", ROUND(H10/31536000,2)&"y"))))) -> STABLE | J10: =LN(2)/H10 -> #VALUE! | K10: =10*F10*(1-EXP(-J10*600))*6240000000000 -> #VALUE! | L10: =EXP(-J10*30*60)*K10 -> #VALUE! | M10: =G10 -> He4 | N10: =L10 -> #VALUE! | O10: =0 -> 0
B11: 2005 | C11: 0 | D11: 0 | E11: 0 | F11: =SUM(C11:E11) -> 0 | G11: =VLOOKUP(B11,Nuclides!A:F,5,FALSE) -> He5 | H11: =VLOOKUP(B11,Nuclides!A:F,4,FALSE) -> 7.595e-22 | I11: =IF(H11="STABLE", "STABLE", IF(H11<60, H11&"s", IF(H11<3600, ROUND(H11/60,2)&"min", IF(H11<86400, ROUND(H11/3600,2)&"h", IF(H11<31536000, ROUND(H11/86400,2)&"d", ROUND(H11/31536000,2)&"y"))))) -> 7.595E-22s | J11: =LN(2)/H11 -> 9.1263618e+20 | K11: =10*F11*(1-EXP(-J11*600))*6240000000000 -> 0 | L11: =EXP(-J11*30*60)*K11 -> 0 | M11: =G11 -> He5 | N11: =L11 -> 0 | O11: =0 -> 0
B12: 2006 | C12: 0 | D12: 0 | E12: 0 | F12: =SUM(C12:E12) -> 0 | G12: =VLOOKUP(B12,Nuclides!A:F,5,FALSE) -> He6 | H12: =VLOOKUP(B12,Nuclides!A:F,4,FALSE) -> 0.8067 | I12: =IF(H12="STABLE", "STABLE", IF(H12<60, H12&"s", IF(H12<3600, ROUND(H12/60,2)&"min", IF(H12<86400, ROUND(H12/3600,2)&"h", IF(H12<31536000, ROUND(H12/86400,2)&"d", ROUND(H12/31536000,2)&"y"))))) -> 0.8067s | J12: =LN(2)/H12 -> 0.85923786 | K12: =10*F12*(1-EXP(-J12*600))*6240000000000 -> 0 | L12: =EXP(-J12*30*60)*K12 -> 0 | M12: =G12 -> He6 | N12: =L12 -> 0 | O12: =0 -> 0
B13: 2007 | C13: 0 | D13: 0 | E13: 0 | F13: =SUM(C13:E13) -> 0 | G13: =VLOOKUP(B13,Nuclides!A:F,5,FALSE) -> He7 | H13: =VLOOKUP(B13,Nuclides!A:F,4,FALSE) -> 3.038e-21 | I13: =IF(H13="STABLE", "STABLE", IF(H13<60, H13&"s", IF(H13<3600, ROUND(H13/60,2)&"min", IF(H13<86400, ROUND(H13/3600,2)&"h", IF(H13<31536000, ROUND(H13/86400,2)&"d", ROUND(H13/31536000,2)&"y"))))) -> 3.038E-21s | J13: =LN(2)/H13 -> 2.2815905e+20 | K13: =10*F13*(1-EXP(-J13*600))*6240000000000 -> 0 | L13: =EXP(-J13*30*60)*K13 -> 0 | M13: =G13 -> He7 | N13: =L13 -> 0 | O13: =0 -> 0
B14: 2008 | C14: 0 | D14: 0 | E14: 0 | F14: =SUM(C14:E14) -> 0 | G14: =VLOOKUP(B14,Nuclides!A:F,5,FALSE) -> He8 | H14: =VLOOKUP(B14,Nuclides!A:F,4,FALSE) -> 0.1191 | I14: =IF(H14="STABLE", "STABLE", IF(H14<60, H14&"s", IF(H14<3600, ROUND(H14/60,2)&"min", IF(H14<86400, ROUND(H14/3600,2)&"h", IF(H14<31536000, ROUND(H14/86400,2)&"d", ROUND(H14/31536000,2)&"y"))))) -> 0.1191s | J14: =LN(2)/H14 -> 5.8198756 | K14: =10*F14*(1-EXP(-J14*600))*6240000000000 -> 0 | L14: =EXP(-J14*30*60)*K14 -> 0 | M14: =G14 -> He8 | N14: =L14 -> 0 | O14: =0 -> 0
B15: 3005 | C15: 0 | D15: 0 | E15: 0 | F15: =SUM(C15:E15) -> 0 | G15: =VLOOKUP(B15,Nuclides!A:F,5,FALSE) -> Li5 | H15: =VLOOKUP(B15,Nuclides!A:F,4,FALSE) -> 3.038e-22 | I15: =IF(H15="STABLE", "STABLE", IF(H15<60, H15&"s", IF(H15<3600, ROUND(H15/60,2)&"min", IF(H15<86400, ROUND(H15/3600,2)&"h", IF(H15<31536000, ROUND(H15/86400,2)&"d", ROUND(H15/31536000,2)&"y"))))) -> 3.038E-22s | J15: =LN(2)/H15 -> 2.2815905e+21 | K15: =10*F15*(1-EXP(-J15*600))*6240000000000 -> 0 | L15: =EXP(-J15*30*60)*K15 -> 0 | M15: =G15 -> Li5 | N15: =L15 -> 0 | O15: =0 -> 0
B16: 3006 | C16: 0 | D16: 0 | E16: 0 | F16: =SUM(C16:E16) -> 0 | G16: =VLOOKUP(B16,Nuclides!A:F,5,FALSE) -> Li6 | H16: =VLOOKUP(B16,Nuclides!A:F,4,FALSE) -> STABLE | I16: =IF(H16="STABLE", "STABLE", IF(H16<60, H16&"s", IF(H16<3600, ROUND(H16/60,2)&"min", IF(H16<86400, ROUND(H16/3600,2)&"h", IF(H16<31536000, ROUND(H16/86400,2)&"d", ROUND(H16/31536000,2)&"y"))))) -> STABLE | J16: =LN(2)/H16 -> #VALUE! | K16: =10*F16*(1-EXP(-J16*600))*6240000000000 -> #VALUE! | L16: =EXP(-J16*30*60)*K16 -> #VALUE! | M16: =G16 -> Li6 | N16: =L16 -> #VALUE! | O16: =0 -> 0
B17: 3007 | C17: 0 | D17: 0 | E17: 0 | F17: =SUM(C17:E17) -> 0 | G17: =VLOOKUP(B17,Nuclides!A:F,5,FALSE) -> Li7 | H17: =VLOOKUP(B17,Nuclides!A:F,4,FALSE) -> STABLE | I17: =IF(H17="STABLE", "STABLE", IF(H17<60, H17&"s", IF(H17<3600, ROUND(H17/60,2)&"min", IF(H17<86400, ROUND(H17/3600,2)&"h", IF(H17<31536000, ROUND(H17/86400,2)&"d", ROUND(H17/31536000,2)&"y"))))) -> STABLE | J17: =LN(2)/H17 -> #VALUE! | K17: =10*F17*(1-EXP(-J17*600))*6240000000000 -> #VALUE! | L17: =EXP(-J17*30*60)*K17 -> #VALUE! | M17: =G17 -> Li7 | N17: =L17 -> #VALUE! | O17: =0 -> 0
... B1773: 80206 | C1773: 0 | D1773: 0 | E1773: 0 | F1773: =SUM(C1773:E1773) -> 0 | G1773: =VLOOKUP(B1773,Nuclides!A:F,5,FALSE) -> Hg206 | H1773: =VLOOKUP(B1773,Nuclides!A:F,4,FALSE) -> 499.2 | I1773: =IF(H1773="STABLE", "STABLE", IF(H1773<60, H1773&"s", IF(H1773<3600, ROUND(H1773/60,2)&"min", IF(H1773<86400, ROUND(H1773/3600,2)&"h", IF(H1773<31536000, ROUND(H1773/86400,2)&"d", ROUND(H1773/31536000,2)&"y"))))) -> 8.32min | J1773: =LN(2)/H1773 -> 0.001388516 | K1773: =10*F1773*(1-EXP(-J1773*600))*6240000000000 -> 0 | L1773: =EXP(-J1773*30*60)*K1773 -> 0 | M1773: =G1773 -> Hg206 | N1773: =L1773 -> 0 | O1773: =0 -> 0

Sheet Ta-Ni
G1: Nuclides | H1: T1/2 | I1: T1/2 | J1: λ | K1: 10μA*10min | L1: cool-30min | M1: Nuclides
C3: 1 | D3: 2 | E3: 3
B4: 1001 | C4: 0 | D4: 0 | E4: 0 | F4: =SUM(C4:E4) -> 0 | G4: =VLOOKUP(B4,Nuclides!A:F,5,FALSE) -> H1 | H4: =VLOOKUP(B4,Nuclides!A:F,4,FALSE) -> 613.9 | I4: =IF(H4="STABLE", "STABLE", IF(H4<60, H4&"s", IF(H4<3600, ROUND(H4/60,2)&"min", IF(H4<86400, ROUND(H4/3600,2)&"h", IF(H4<31536000, ROUND(H4/86400,2)&"d", ROUND(H4/31536000,2)&"y"))))) -> 10.23min | J4: =LN(2)/H4 -> 0.0011290881 | K4: =10*F4*(1-EXP(-J4*600))*6240000000000 -> 0 | L4: =EXP(-J4*30*60)*K4 -> 0 | M4: =G4 -> H1 | N4: =0 -> 0
B5: 1002 | C5: 0 | D5: 0 | E5: 0 | F5: =SUM(C5:E5) -> 0 | G5: =VLOOKUP(B5,Nuclides!A:F,5,FALSE) -> H2 | H5: =VLOOKUP(B5,Nuclides!A:F,4,FALSE) -> STABLE | I5: =IF(H5="STABLE", "STABLE", IF(H5<60, H5&"s", IF(H5<3600, ROUND(H5/60,2)&"min", IF(H5<86400, ROUND(H5/3600,2)&"h", IF(H5<31536000, ROUND(H5/86400,2)&"d", ROUND(H5/31536000,2)&"y"))))) -> STABLE | J5: =LN(2)/H5 -> #VALUE! | K5: =10*F5*(1-EXP(-J5*600))*6240000000000 -> #VALUE! | L5: =EXP(-J5*30*60)*K5 -> #VALUE! | M5: =G5 -> H2 | N5: =0 -> 0
B6: 1003 | C6: 0 | D6: 0 | E6: 0 | F6: =SUM(C6:E6) -> 0 | G6: =VLOOKUP(B6,Nuclides!A:F,5,FALSE) -> H3 | H6: =VLOOKUP(B6,Nuclides!A:F,4,FALSE) -> 388789632 | I6: =IF(H6="STABLE", "STABLE", IF(H6<60, H6&"s", IF(H6<3600, ROUND(H6/60,2)&"min", IF(H6<86400, ROUND(H6/3600,2)&"h", IF(H6<31536000, ROUND(H6/86400,2)&"d", ROUND(H6/31536000,2)&"y"))))) -> 12.33y | J6: =LN(2)/H6 -> 1.7828335e-09 | K6: =10*F6*(1-EXP(-J6*600))*6240000000000 -> 0 | L6: =EXP(-J6*30*60)*K6 -> 0 | M6: =G6 -> H3 | N6: =0 -> 0
B7: 2003 | C7: 0 | D7: 0 | E7: 0 | F7: =SUM(C7:E7) -> 0 | G7: =VLOOKUP(B7,Nuclides!A:F,5,FALSE) -> He3 | H7: =VLOOKUP(B7,Nuclides!A:F,4,FALSE) -> STABLE | I7: =IF(H7="STABLE", "STABLE", IF(H7<60, H7&"s", IF(H7<3600, ROUND(H7/60,2)&"min", IF(H7<86400, ROUND(H7/3600,2)&"h", IF(H7<31536000, ROUND(H7/86400,2)&"d", ROUND(H7/31536000,2)&"y"))))) -> STABLE | J7: =LN(2)/H7 -> #VALUE! | K7: =10*F7*(1-EXP(-J7*600))*6240000000000 -> #VALUE! | L7: =EXP(-J7*30*60)*K7 -> #VALUE! | M7: =G7 -> He3 | N7: =0 -> 0
B8: 2004 | C8: 0 | D8: 0 | E8: 0 | F8: =SUM(C8:E8) -> 0 | G8: =VLOOKUP(B8,Nuclides!A:F,5,FALSE) -> He4 | H8: =VLOOKUP(B8,Nuclides!A:F,4,FALSE) -> STABLE | I8: =IF(H8="STABLE", "STABLE", IF(H8<60, H8&"s", IF(H8<3600, ROUND(H8/60,2)&"min", IF(H8<86400, ROUND(H8/3600,2)&"h", IF(H8<31536000, ROUND(H8/86400,2)&"d", ROUND(H8/31536000,2)&"y"))))) -> STABLE | J8: =LN(2)/H8 -> #VALUE! | K8: =10*F8*(1-EXP(-J8*600))*6240000000000 -> #VALUE! | L8: =EXP(-J8*30*60)*K8 -> #VALUE! | M8: =G8 -> He4 | N8: =0 -> 0
B9: 2005 | C9: 0 | D9: 0 | E9: 0 | F9: =SUM(C9:E9) -> 0 | G9: =VLOOKUP(B9,Nuclides!A:F,5,FALSE) -> He5 | H9: =VLOOKUP(B9,Nuclides!A:F,4,FALSE) -> 7.595e-22 | I9: =IF(H9="STABLE", "STABLE", IF(H9<60, H9&"s", IF(H9<3600, ROUND(H9/60,2)&"min", IF(H9<86400, ROUND(H9/3600,2)&"h", IF(H9<31536000, ROUND(H9/86400,2)&"d", ROUND(H9/31536000,2)&"y"))))) -> 7.595E-22s | J9: =LN(2)/H9 -> 9.1263618e+20 | K9: =10*F9*(1-EXP(-J9*600))*6240000000000 -> 0 | L9: =EXP(-J9*30*60)*K9 -> 0 | M9: =G9 -> He5 | N9: =0 -> 0
B10: 2006 | C10: 0 | D10: 0 | E10: 0 | F10: =SUM(C10:E10) -> 0 | G10: =VLOOKUP(B10,Nuclides!A:F,5,FALSE) -> He6 | H10: =VLOOKUP(B10,Nuclides!A:F,4,FALSE) -> 0.8067 | I10: =IF(H10="STABLE", "STABLE", IF(H10<60, H10&"s", IF(H10<3600, ROUND(H10/60,2)&"min", IF(H10<86400, ROUND(H10/3600,2)&"h", IF(H10<31536000, ROUND(H10/86400,2)&"d", ROUND(H10/31536000,2)&"y"))))) -> 0.8067s | J10: =LN(2)/H10 -> 0.85923786 | K10: =10*F10*(1-EXP(-J10*600))*6240000000000 -> 0 | L10: =EXP(-J10*30*60)*K10 -> 0 | M10: =G10 -> He6 | N10: =0 -> 0
B11: 2007 | C11: 0 | D11: 0 | E11: 0 | F11: =SUM(C11:E11) -> 0 | G11: =VLOOKUP(B11,Nuclides!A:F,5,FALSE) -> He7 | H11: =VLOOKUP(B11,Nuclides!A:F,4,FALSE) -> 3.038e-21 | I11: =IF(H11="STABLE", "STABLE", IF(H11<60, H11&"s", IF(H11<3600, ROUND(H11/60,2)&"min", IF(H11<86400, ROUND(H11/3600,2)&"h", IF(H11<31536000, ROUND(H11/86400,2)&"d", ROUND(H11/31536000,2)&"y"))))) -> 3.038E-21s | J11: =LN(2)/H11 -> 2.2815905e+20 | K11: =10*F11*(1-EXP(-J11*600))*6240000000000 -> 0 | L11: =EXP(-J11*30*60)*K11 -> 0 | M11: =G11 -> He7 | N11: =0 -> 0
B12: 2008 | C12: 0 | D12: 0 | E12: 0 | F12: =SUM(C12:E12) -> 0 | G12: =VLOOKUP(B12,Nuclides!A:F,5,FALSE) -> He8 | H12: =VLOOKUP(B12,Nuclides!A:F,4,FALSE) -> 0.1191 | I12: =IF(H12="STABLE", "STABLE", IF(H12<60, H12&"s", IF(H12<3600, ROUND(H12/60,2)&"min", IF(H12<86400, ROUND(H12/3600,2)&"h", IF(H12<31536000, ROUND(H12/86400,2)&"d", ROUND(H12/31536000,2)&"y"))))) -> 0.1191s | J12: =LN(2)/H12 -> 5.8198756 | K12: =10*F12*(1-EXP(-J12*600))*6240000000000 -> 0 | L12: =EXP(-J12*30*60)*K12 -> 0 | M12: =G12 -> He8 | N12: =0 -> 0
B13: 3005 | C13: 0 | D13: 0 | E13: 0 | F13: =SUM(C13:E13) -> 0 | G13: =VLOOKUP(B13,Nuclides!A:F,5,FALSE) -> Li5 | H13: =VLOOKUP(B13,Nuclides!A:F,4,FALSE) -> 3.038e-22 | I13: =IF(H13="STABLE", "STABLE", IF(H13<60, H13&"s", IF(H13<3600, ROUND(H13/60,2)&"min", IF(H13<86400, ROUND(H13/3600,2)&"h", IF(H13<31536000, ROUND(H13/86400,2)&"d", ROUND(H13/31536000,2)&"y"))))) -> 3.038E-22s | J13: =LN(2)/H13 -> 2.2815905e+21 | K13: =10*F13*(1-EXP(-J13*600))*6240000000000 -> 0 | L13: =EXP(-J13*30*60)*K13 -> 0 | M13: =G13 -> Li5 | N13: =0 -> 0
B14: 3006 | C14: 0 | D14: 0 | E14: 0 | F14: =SUM(C14:E14) -> 0 | G14: =VLOOKUP(B14,Nuclides!A:F,5,FALSE) -> Li6 | H14: =VLOOKUP(B14,Nuclides!A:F,4,FALSE) -> STABLE | I14: =IF(H14="STABLE", "STABLE", IF(H14<60, H14&"s", IF(H14<3600, ROUND(H14/60,2)&"min", IF(H14<86400, ROUND(H14/3600,2)&"h", IF(H14<31536000, ROUND(H14/86400,2)&"d", ROUND(H14/31536000,2)&"y"))))) -> STABLE | J14: =LN(2)/H14 -> #VALUE! | K14: =10*F14*(1-EXP(-J14*600))*6240000000000 -> #VALUE! | L14: =EXP(-J14*30*60)*K14 -> #VALUE! | M14: =G14 -> Li6 | N14: =0 -> 0
B15: 3007 | C15: 0 | D15: 0 | E15: 0 | F15: =SUM(C15:E15) -> 0 | G15: =VLOOKUP(B15,Nuclides!A:F,5,FALSE) -> Li7 | H15: =VLOOKUP(B15,Nuclides!A:F,4,FALSE) -> STABLE | I15: =IF(H15="STABLE", "STABLE", IF(H15<60, H15&"s", IF(H15<3600, ROUND(H15/60,2)&"min", IF(H15<86400, ROUND(H15/3600,2)&"h", IF(H15<31536000, ROUND(H15/86400,2)&"d", ROUND(H15/31536000,2)&"y"))))) -> STABLE | J15: =LN(2)/H15 -> #VALUE! | K15: =10*F15*(1-EXP(-J15*600))*6240000000000 -> #VALUE! | L15: =EXP(-J15*30*60)*K15 -> #VALUE! | M15: =G15 -> Li7 | N15: =0 -> 0
... B351: 27060 | C351: 0 | D351: 0 | E351: 0 | F351: =SUM(C351:E351) -> 0 | G351: =VLOOKUP(B351,Nuclides!A:F,5,FALSE) -> Co60 | H351: =VLOOKUP(B351,Nuclides!A:F,4,FALSE) -> 166344192 | I351: =IF(H351="STABLE", "STABLE", IF(H351<60, H351&"s", IF(H351<3600, ROUND(H351/60,2)&"min", IF(H351<86400, ROUND(H351/3600,2)&"h", IF(H351<31536000, ROUND(H351/86400,2)&"d", ROUND(H351/31536000,2)&"y"))))) -> 5.27y | J351: =LN(2)/H351 -> 4.1669455e-09 | K351: =10*F351*(1-EXP(-J351*600))*6240000000000 -> 0 | L351: =EXP(-J351*30*60)*K351 -> 0 | M351: =G351 -> Co60 | N351: =0 -> 0
B352: 27061 | C352: 5.8e-06 | D352: 0 | E352: 0 | F352: =SUM(C352:E352) -> 5.8e-06 | G352: =VLOOKUP(B352,Nuclides!A:F,5,FALSE) -> Co61 | H352: =VLOOKUP(B352,Nuclides!A:F,4,FALSE) -> 5936.4 | I352: =IF(H352="STABLE", "STABLE", IF(H352<60, H352&"s", IF(H352<3600, ROUND(H352/60,2)&"min", IF(H352<86400, ROUND(H352/3600,2)&"h", IF(H352<31536000, ROUND(H352/86400,2)&"d", ROUND(H352/31536000,2)&"y"))))) -> 1.65h | J352: =LN(2)/H352 -> 0.00011676221 | K352: =10*F352*(1-EXP(-J352*600))*6240000000000 -> 24487373 | L352: =EXP(-J352*30*60)*K352 -> 19845665 | M352: =G352 -> Co61 | N352: =L352 -> 19845665 | O352: 0
B353: 27062 | C353: 0 | D353: 0 | E353: 0 | F353: =SUM(C353:E353) -> 0 | G353: =VLOOKUP(B353,Nuclides!A:F,5,FALSE) -> Co62 | H353: =VLOOKUP(B353,Nuclides!A:F,4,FALSE) -> 90 | I353: =IF(H353="STABLE", "STABLE", IF(H353<60, H353&"s", IF(H353<3600, ROUND(H353/60,2)&"min", IF(H353<86400, ROUND(H353/3600,2)&"h", IF(H353<31536000, ROUND(H353/86400,2)&"d", ROUND(H353/31536000,2)&"y"))))) -> 1.5min | J353: =LN(2)/H353 -> 0.0077016353 | K353: =10*F353*(1-EXP(-J353*600))*6240000000000 -> 0 | L353: =EXP(-J353*30*60)*K353 -> 0 | M353: =G353 -> Co62 | N353: =0 -> 0
B354: 27063 | C354: 0 | D354: 0 | E354: 0 | F354: =SUM(C354:E354) -> 0 | G354: =VLOOKUP(B354,Nuclides!A:F,5,FALSE) -> Co63 | H354: =VLOOKUP(B354,Nuclides!A:F,4,FALSE) -> 27.4 | I354: =IF(H354="STABLE", "STABLE", IF(H354<60, H354&"s", IF(H354<3600, ROUND(H354/60,2)&"min", IF(H354<86400, ROUND(H354/3600,2)&"h", IF(H354<31536000, ROUND(H354/86400,2)&"d", ROUND(H354/31536000,2)&"y"))))) -> 27.4s | J354: =LN(2)/H354 -> 0.025297342 | K354: =10*F354*(1-EXP(-J354*600))*6240000000000 -> 0 | L354: =EXP(-J354*30*60)*K354 -> 0 | M354: =G354 -> Co63 | N354: =0 -> 0
B355: 27064 | C355: 0 | D355: 0 | E355: 0 | F355: =SUM(C355:E355) -> 0 | G355: =VLOOKUP(B355,Nuclides!A:F,5,FALSE) -> Co64 | H355: =VLOOKUP(B355,Nuclides!A:F,4,FALSE) -> 0.3 | I355: =IF(H355="STABLE", "STABLE", IF(H355<60, H355&"s", IF(H355<3600, ROUND(H355/60,2)&"min", IF(H355<86400, ROUND(H355/3600,2)&"h", IF(H355<31536000, ROUND(H355/86400,2)&"d", ROUND(H355/31536000,2)&"y"))))) -> 0.3s | J355: =LN(2)/H355 -> 2.3104906 | K355: =10*F355*(1-EXP(-J355*600))*6240000000000 -> 0 | L355: =EXP(-J355*30*60)*K355 -> 0 | M355: =G355 -> Co64 | N355: =0 -> 0
B356: 28053 | C356: 0 | D356: 0 | E356: 0 | F356: =SUM(C356:E356) -> 0 | G356: =VLOOKUP(B356,Nuclides!A:F,5,FALSE) -> Ni53 | H356: =VLOOKUP(B356,Nuclides!A:F,4,FALSE) -> 0.0552 | I356: =IF(H356="STABLE", "STABLE", IF(H356<60, H356&"s", IF(H356<3600, ROUND(H356/60,2)&"min", IF(H356<86400, ROUND(H356/3600,2)&"h", IF(H356<31536000, ROUND(H356/86400,2)&"d", ROUND(H356/31536000,2)&"y"))))) -> 0.0552s | J356: =LN(2)/H356 -> 12.557014 | K356: =10*F356*(1-EXP(-J356*600))*6240000000000 -> 0 | L356: =EXP(-J356*30*60)*K356 -> 0 | M356: =G356 -> Ni53 | N356: =0 -> 0
B357: 28054 | C357: 0 | D357: 0 | E357: 0 | F357: =SUM(C357:E357) -> 0 | G357: =VLOOKUP(B357,Nuclides!A:F,5,FALSE) -> Ni54 | H357: =VLOOKUP(B357,Nuclides!A:F,4,FALSE) -> 0.1142 | I357: =IF(H357="STABLE", "STABLE", IF(H357<60, H357&"s", IF(H357<3600, ROUND(H357/60,2)&"min", IF(H357<86400, ROUND(H357/3600,2)&"h", IF(H357<31536000, ROUND(H357/86400,2)&"d", ROUND(H357/31536000,2)&"y"))))) -> 0.1142s | J357: =LN(2)/H357 -> 6.06959 | K357: =10*F357*(1-EXP(-J357*600))*6240000000000 -> 0 | L357: =EXP(-J357*30*60)*K357 -> 0 | M357: =G357 -> Ni54 | N357: =0 -> 0
B358: 28055 | C358: 0 | D358: 0 | E358: 0 | F358: =SUM(C358:E358) -> 0 | G358: =VLOOKUP(B358,Nuclides!A:F,5,FALSE) -> Ni55 | H358: =VLOOKUP(B358,Nuclides!A:F,4,FALSE) -> 0.2047 | I358: =IF(H358="STABLE", "STABLE", IF(H358<60, H358&"s", IF(H358<3600, ROUND(H358/60,2)&"min", IF(H358<86400, ROUND(H358/3600,2)&"h", IF(H358<31536000, ROUND(H358/86400,2)&"d", ROUND(H358/31536000,2)&"y"))))) -> 0.2047s | J358: =LN(2)/H358 -> 3.3861611 | K358: =10*F358*(1-EXP(-J358*600))*6240000000000 -> 0 | L358: =EXP(-J358*30*60)*K358 -> 0 | M358: =G358 -> Ni55 | N358: =0 -> 0
B359: 28056 | C359: 0 | D359: 0 | E359: 0 | F359: =SUM(C359:E359) -> 0 | G359: =VLOOKUP(B359,Nuclides!A:F,5,FALSE) -> Ni56 | H359: =VLOOKUP(B359,Nuclides!A:F,4,FALSE) -> 524880 | I359: =IF(H359="STABLE", "STABLE", IF(H359<60, H359&"s", IF(H359<3600, ROUND(H359/60,2)&"min", IF(H359<86400, ROUND(H359/3600,2)&"h", IF(H359<31536000, ROUND(H359/86400,2)&"d", ROUND(H359/31536000,2)&"y"))))) -> 6.08d | J359: =LN(2)/H359 -> 1.3205822e-06 | K359: =10*F359*(1-EXP(-J359*600))*6240000000000 -> 0 | L359: =EXP(-J359*30*60)*K359 -> 0 | M359: =G359 -> Ni56 | N359: =0 -> 0
B360: 28057 | C360: 0 | D360: 0 | E360: 0 | F360: =SUM(C360:E360) -> 0 | G360: =VLOOKUP(B360,Nuclides!A:F,5,FALSE) -> Ni57 | H360: =VLOOKUP(B360,Nuclides!A:F,4,FALSE) -> 128160 | I360: =IF(H360="STABLE", "STABLE", IF(H360<60, H360&"s", IF(H360<3600, ROUND(H360/60,2)&"min", IF(H360<86400, ROUND(H360/3600,2)&"h", IF(H360<31536000, ROUND(H360/86400,2)&"d", ROUND(H360/31536000,2)&"y"))))) -> 1.48d | J360: =LN(2)/H360 -> 5.4084518e-06 | K360: =10*F360*(1-EXP(-J360*600))*6240000000000 -> 0 | L360: =EXP(-J360*30*60)*K360 -> 0 | M360: =G360 -> Ni57 | N360: =0 -> 0
B361: 28058 | C361: 0 | D361: 0 | E361: 0 | F361: =SUM(C361:E361) -> 0 | G361: =VLOOKUP(B361,Nuclides!A:F,5,FALSE) -> Ni58 | H361: =VLOOKUP(B361,Nuclides!A:F,4,FALSE) -> STABLE | I361: =IF(H361="STABLE", "STABLE", IF(H361<60, H361&"s", IF(H361<3600, ROUND(H361/60,2)&"min", IF(H361<86400, ROUND(H361/3600,2)&"h", IF(H361<31536000, ROUND(H361/86400,2)&"d", ROUND(H361/31536000,2)&"y"))))) -> STABLE | J361: =LN(2)/H361 -> #VALUE! | K361: =10*F361*(1-EXP(-J361*600))*6240000000000 -> #VALUE! | L361: =EXP(-J361*30*60)*K361 -> #VALUE! | M361: =G361 -> Ni58 | N361: =0 -> 0
B362: 28059 | C362: 0 | D362: 0 | E362: 0 | F362: =SUM(C362:E362) -> 0 | G362: =VLOOKUP(B362,Nuclides!A:F,5,FALSE) -> Ni59 | H362: =VLOOKUP(B362,Nuclides!A:F,4,FALSE) -> 2398377600000 | I362: =IF(H362="STABLE", "STABLE", IF(H362<60, H362&"s", IF(H362<3600, ROUND(H362/60,2)&"min", IF(H362<86400, ROUND(H362/3600,2)&"h", IF(H362<31536000, ROUND(H362/86400,2)&"d", ROUND(H362/31536000,2)&"y"))))) -> 76052.05y | J362: =LN(2)/H362 -> 2.8900669e-13 | K362: =10*F362*(1-EXP(-J362*600))*6240000000000 -> 0 | L362: =EXP(-J362*30*60)*K362 -> 0 | M362: =G362 -> Ni59 | N362: =0 -> 0
B363: 28060 | C363: 0 | D363: 0 | E363: 0 | F363: =SUM(C363:E363) -> 0 | G363: =VLOOKUP(B363,Nuclides!A:F,5,FALSE) -> Ni60 | H363: =VLOOKUP(B363,Nuclides!A:F,4,FALSE) -> STABLE | I363: =IF(H363="STABLE", "STABLE", IF(H363<60, H363&"s", IF(H363<3600, ROUND(H363/60,2)&"min", IF(H363<86400, ROUND(H363/3600,2)&"h", IF(H363<31536000, ROUND(H363/86400,2)&"d", ROUND(H363/31536000,2)&"y"))))) -> STABLE | J363: =LN(2)/H363 -> #VALUE! | K363: =10*F363*(1-EXP(-J363*600))*6240000000000 -> #VALUE! | L363: =EXP(-J363*30*60)*K363 -> #VALUE! | M363: =G363 -> Ni60 | N363: =0 -> 0
B364: 28061 | C364: 0 | D364: 0 | E364: 0 | F364: =SUM(C364:E364) -> 0 | G364: =VLOOKUP(B364,Nuclides!A:F,5,FALSE) -> Ni61 | H364: =VLOOKUP(B364,Nuclides!A:F,4,FALSE) -> STABLE | I364: =IF(H364="STABLE", "STABLE", IF(H364<60, H364&"s", IF(H364<3600, ROUND(H364/60,2)&"min", IF(H364<86400, ROUND(H364/3600,2)&"h", IF(H364<31536000, ROUND(H364/86400,2)&"d", ROUND(H364/31536000,2)&"y"))))) -> STABLE | J364: =LN(2)/H364 -> #VALUE! | K364: =10*F364*(1-EXP(-J364*600))*6240000000000 -> #VALUE! | L364: =EXP(-J364*30*60)*K364 -> #VALUE! | M364: =G364 -> Ni61 | N364: =0 -> 0
