Workbook

Sheet Nuclides
B2: n | C2: z | D2: halflife/s | F2: halflife/s
A3: 1001 | B3: 1 | C3: 0 | D3: 613.9 | E3: H1 | F3: 613.9
A4: 1002 | B4: 1 | C4: 1 | D4: STABLE | E4: H2 | F4: STABLE
A5: 1003 | B5: 2 | C5: 1 | D5: 388789632 | E5: H3 | F5: 388789632
A6: 1005 | B6: 4 | C6: 1 | D6: 7.9947368e-23 | E6: H5 | F6: 7.9947368e-23
A7: 1006 | B7: 5 | C7: 1 | D7: 2.848125e-22 | E7: H6 | F7: 2.848125e-22
A8: 2003 | B8: 1 | C8: 2 | D8: STABLE | E8: He3 | F8: STABLE
A9: 2004 | B9: 2 | C9: 2 | D9: STABLE | E9: He4 | F9: STABLE
A10: 2005 | B10: 3 | C10: 2 | D10: 7.595e-22 | E10: He5 | F10: 7.595e-22
A11: 2006 | B11: 4 | C11: 2 | D11: 0.8067 | E11: He6 | F11: 0.8067
A12: 2007 | B12: 5 | C12: 2 | D12: 3.038e-21 | E12: He7 | F12: 3.038e-21
A13: 2008 | B13: 6 | C13: 2 | D13: 0.1191 | E13: He8 | F13: 0.1191
A14: 2010 | B14: 8 | C14: 2 | D14: 1.519e-21 | E14: He10 | F14: 1.519e-21
A15: 3004 | B15: 1 | C15: 3 | D15: 7.5572139e-23 | E15: Li4 | F15: 7.5572139e-23
A16: 3005 | B16: 2 | C16: 3 | D16: 3.038e-22 | E16: Li5 | F16: 3.038e-22
A17: 3006 | B17: 3 | C17: 3 | D17: STABLE | E17: Li6 | F17: STABLE
A18: 3007 | B18: 4 | C18: 3 | D18: STABLE | E18: Li7 | F18: STABLE
A19: 3008 | B19: 5 | C19: 3 | D19: 0.8399 | E19: Li8 | F19: 0.8399
A20: 3009 | B20: 6 | C20: 3 | D20: 0.1783 | E20: Li9 | F20: 0.1783
A21: 3011 | B21: 8 | C21: 3 | D21: 0.00875 | E21: Li11 | F21: 0.00875
A22: 4006 | B22: 2 | C22: 4 | D22: 4.9532609e-21 | E22: Be6 | F22: 4.9532609e-21
A23: 4007 | B23: 3 | C23: 4 | D23: 4598208 | E23: Be7 | F23: 4598208
A24: 4008 | B24: 4 | C24: 4 | D24: 8.1813285e-17 | E24: Be8 | F24: 8.1813285e-17
A25: 4009 | B25: 5 | C25: 4 | D25: STABLE | E25: Be9 | F25: STABLE
A26: 4010 | B26: 6 | C26: 4 | D26: 47651976000000 | E26: Be10 | F26: 47651976000000
A27: 4011 | B27: 7 | C27: 4 | D27: 13.76 | E27: Be11 | F27: 13.76
A28: 4012 | B28: 8 | C28: 4 | D28: 0.02147 | E28: Be12 | F28: 0.02147
A29: 4013 | B29: 9 | C29: 4 | D29: 2.7e-21 | E29: Be13 | F29: 2.7e-21
A30: 4014 | B30: 10 | C30: 4 | D30: 0.00435 | E30: Be14 | F30: 0.00435
A31: 4015 | B31: 11 | C31: 4 | D31: 7.8568966e-22 | E31: Be15 | F31: 7.8568966e-22
A32: 4016 | B32: 12 | C32: 4 | D32: 5.69625e-22 | E32: Be16 | F32: 5.69625e-22
A33: 5007 | B33: 2 | C33: 5 | D33: 3.255e-22 | E33: B7 | F33: 3.255e-22
A34: 5008 | B34: 3 | C34: 5 | D34: 0.77 | E34: B8 | F34: 0.77
A35: 5009 | B35: 4 | C35: 5 | D35: 8.4388889e-19 | E35: B9 | F35: 8.4388889e-19
A36: 5010 | B36: 5 | C36: 5 | D36: STABLE | E36: B10 | F36: STABLE
A37: 5011 | B37: 6 | C37: 5 | D37: STABLE | E37: B11 | F37: STABLE
A38: 5012 | B38: 7 | C38: 5 | D38: 0.0202 | E38: B12 | F38: 0.0202
A39: 5013 | B39: 8 | C39: 5 | D39: 0.01733 | E39: B13 | F39: 0.01733
A40: 5014 | B40: 9 | C40: 5 | D40: 0.01236 | E40: B14 | F40: 0.01236
A41: 5015 | B41: 10 | C41: 5 | D41: 0.01018 | E41: B15 | F41: 0.01018
...

Sheet Sheet1
C4: 1001 | D4: 1002 | E4: 1003 | F4: 1004 | G4: 1102 | H4: 1103 | I4: 1104 | J4: 1105 | K4: 1106 | L4: 1107 | M4: 1108
B5: 1001 | C5: 0 | D5: 0 | E5: 0 | F5: 0 | G5: 0 | H5: 0 | I5: 0 | J5: 0 | K5: 0 | L5: 0 | M5: 0 | N5: =SUM(C5:M5) -> 0
B6: 1002 | C6: 0 | D6: 0 | E6: 0 | F6: 0 | G6: 0 | H6: 0 | I6: 0 | J6: 0 | K6: 0 | L6: 0 | M6: 0 | N6: =SUM(C6:M6) -> 0
B7: 1003 | C7: 0 | D7: 0 | E7: 0 | F7: 0 | G7: 0 | H7: 0 | I7: 0 | J7: 0 | K7: 0 | L7: 0 | M7: 0 | N7: =SUM(C7:M7) -> 0
B8: 2003 | C8: 0 | D8: 0 | E8: 0 | F8: 0 | G8: 0 | H8: 0 | I8: 0 | J8: 0 | K8: 0 | L8: 0 | M8: 0 | N8: =SUM(C8:M8) -> 0
B9: 2004 | C9: 0 | D9: 0 | E9: 0 | F9: 0 | G9: 0 | H9: 0 | I9: 0 | J9: 0 | K9: 0 | L9: 0 | M9: 0 | N9: =SUM(C9:M9) -> 0
B10: 2005 | C10: 0 | D10: 0 | E10: 0 | F10: 0 | G10: 0 | H10: 0 | I10: 0 | J10: 0 | K10: 0 | L10: 0 | M10: 0 | N10: =SUM(C10:M10) -> 0
B11: 2006 | C11: 0 | D11: 0 | E11: 0 | F11: 0 | G11: 0 | H11: 0 | I11: 0 | J11: 0 | K11: 0 | L11: 0 | M11: 0 | N11: =SUM(C11:M11) -> 0
B12: 2007 | C12: 0 | D12: 0 | E12: 0 | F12: 0 | G12: 0 | H12: 0 | I12: 0 | J12: 0 | K12: 0 | L12: 0 | M12: 0 | N12: =SUM(C12:M12) -> 0
B13: 2008 | C13: 0 | D13: 0 | E13: 0 | F13: 0 | G13: 0 | H13: 0 | I13: 0 | J13: 0 | K13: 0 | L13: 0 | M13: 0 | N13: =SUM(C13:M13) -> 0
B14: 3005 | C14: 0 | D14: 0 | E14: 0 | F14: 0 | G14: 0 | H14: 0 | I14: 0 | J14: 0 | K14: 0 | L14: 0 | M14: 0 | N14: =SUM(C14:M14) -> 0
B15: 3006 | C15: 0 | D15: 0 | E15: 0 | F15: 0 | G15: 0 | H15: 0 | I15: 0 | J15: 0 | K15: 0 | L15: 0 | M15: 0 | N15: =SUM(C15:M15) -> 0
B16: 3007 | C16: 0 | D16: 0 | E16: 0 | F16: 0 | G16: 0 | H16: 0 | I16: 0 | J16: 0 | K16: 0 | L16: 0 | M16: 0 | N16: =SUM(C16:M16) -> 0
... B2209: 100260 | C2209: 0 | D2209: 0 | E2209: 0 | F2209: 0 | G2209: 0 | H2209: 0 | I2209: 0 | J2209: 0 | K2209: 0 | L2209: 0 | M2209: 0 | N2209: =SUM(C2209:M2209) -> 0

Sheet Fe
B1: Nuclides | C1: w | D1: Error | E1: Nuclides | F1: T1/2 | G1: T1/2 | H1: λ | I1: 60μA-2h | J1: cool-6h | K1: Nuclides | L1: 720
B5: 24051 | C5: 9.7193878e-08 | E5: =VLOOKUP(B5,Nuclides!A:F,5,FALSE) -> Cr51 | F5: =VLOOKUP(B5,Nuclides!A:F,4,FALSE) -> 2393496 | G5: =IF(F5="STABLE", "STABLE", IF(F5<60, F5&"s", IF(F5<3600, ROUND(F5/60,2)&"min", IF(F5<86400, ROUND(F5/3600,2)&"h", IF(F5<31536000, ROUND(F5/86400,2)&"d", ROUND(F5/31536000,2)&"y"))))) -> 27.7d | H5: =LN(2)/F5 -> 2.8959613e-07 | I5: =100*6240000000000*C5*(1-EXP(-H5*2*3600)) -> 126326.96 | J5: =I5*EXP(-H5*2*3600) -> 126063.83 | K5: =E5 -> Cr51 | L5: {=SUM(($J5*EXP(-$H5*12*3600*_xlfn.SEQUENCE(L$1-1))))+$J5} -> 10138521
B6: 24053 | C6: 2.615118e-07 | E6: =VLOOKUP(B6,Nuclides!A:F,5,FALSE) -> Cr53 | F6: =VLOOKUP(B6,Nuclides!A:F,4,FALSE) -> STABLE | G6: =IF(F6="STABLE", "STABLE", IF(F6<60, F6&"s", IF(F6<3600, ROUND(F6/60,2)&"min", IF(F6<86400, ROUND(F6/3600,2)&"h", IF(F6<31536000, ROUND(F6/86400,2)&"d", ROUND(F6/31536000,2)&"y"))))) -> STABLE | H6: =LN(2)/F6 -> #VALUE! | I6: =100*6240000000000*C6*(1-EXP(-H6*2*3600)) -> #VALUE! | J6: =I6*EXP(-H6*2*3600) -> #VALUE! | K6: =E6 -> Cr53 | L6: {=SUM(($J6*EXP(-$H6*12*3600*_xlfn.SEQUENCE(L$1-1))))+$J6} -> #VALUE!
B7: 24054 | C7: 1.539969e-08 | E7: =VLOOKUP(B7,Nuclides!A:F,5,FALSE) -> Cr54 | F7: =VLOOKUP(B7,Nuclides!A:F,4,FALSE) -> STABLE | G7: =IF(F7="STABLE", "STABLE", IF(F7<60, F7&"s", IF(F7<3600, ROUND(F7/60,2)&"min", IF(F7<86400, ROUND(F7/3600,2)&"h", IF(F7<31536000, ROUND(F7/86400,2)&"d", ROUND(F7/31536000,2)&"y"))))) -> STABLE | H7: =LN(2)/F7 -> #VALUE! | I7: =100*6240000000000*C7*(1-EXP(-H7*2*3600)) -> #VALUE! | J7: =I7*EXP(-H7*2*3600) -> #VALUE! | K7: =E7 -> Cr54 | L7: {=SUM(($J7*EXP(-$H7*12*3600*_xlfn.SEQUENCE(L$1-1))))+$J7} -> #VALUE!
B8: 24055 | C8: 4e-10 | E8: =VLOOKUP(B8,Nuclides!A:F,5,FALSE) -> Cr55 | F8: =VLOOKUP(B8,Nuclides!A:F,4,FALSE) -> 209.82 | G8: =IF(F8="STABLE", "STABLE", IF(F8<60, F8&"s", IF(F8<3600, ROUND(F8/60,2)&"min", IF(F8<86400, ROUND(F8/3600,2)&"h", IF(F8<31536000, ROUND(F8/86400,2)&"d", ROUND(F8/31536000,2)&"y"))))) -> 3.5min | H8: =LN(2)/F8 -> 0.0033035325 | I8: =100*6240000000000*C8*(1-EXP(-H8*2*3600)) -> 249600 | J8: =I8*EXP(-H8*2*3600) -> 1.1677825e-05 | K8: =E8 -> Cr55 | L8: {=SUM(($J8*EXP(-$H8*12*3600*_xlfn.SEQUENCE(L$1-1))))+$J8} -> 1.1677825e-05
B9: 25053 | C9: 1.669764e-08 | E9: =VLOOKUP(B9,Nuclides!A:F,5,FALSE) -> Mn53 | F9: =VLOOKUP(B9,Nuclides!A:F,4,FALSE) -> 118025424000000 | G9: =IF(F9="STABLE", "STABLE", IF(F9<60, F9&"s", IF(F9<3600, ROUND(F9/60,2)&"min", IF(F9<86400, ROUND(F9/3600,2)&"h", IF(F9<31536000, ROUND(F9/86400,2)&"d", ROUND(F9/31536000,2)&"y"))))) -> 3742561.64y | H9: =LN(2)/F9 -> 5.8728633e-15 | I9: =100*6240000000000*C9*(1-EXP(-H9*2*3600)) -> 0.0004405773 | J9: =I9*EXP(-H9*2*3600) -> 0.0004405773 | K9: =E9 -> Mn53 | L9: {=SUM(($J9*EXP(-$H9*12*3600*_xlfn.SEQUENCE(L$1-1))))+$J9} -> 0.31721563
B10: 25054 | C10: 8.2424449e-06 | E10: =VLOOKUP(B10,Nuclides!A:F,5,FALSE) -> Mn54 | F10: =VLOOKUP(B10,Nuclides!A:F,4,FALSE) -> 26974080 | G10: =IF(F10="STABLE", "STABLE", IF(F10<60, F10&"s", IF(F10<3600, ROUND(F10/60,2)&"min", IF(F10<86400, ROUND(F10/3600,2)&"h", IF(F10<31536000, ROUND(F10/86400,2)&"d", ROUND(F10/31536000,2)&"y"))))) -> 312.2d | H10: =LN(2)/F10 -> 2.5696787e-08 | I10: =100*6240000000000*C10*(1-EXP(-H10*2*3600)) -> 951506.55 | J10: =I10*EXP(-H10*2*3600) -> 951330.52 | K10: =E10 -> Mn54 | L10: {=SUM(($J10*EXP(-$H10*12*3600*_xlfn.SEQUENCE(L$1-1))))+$J10} -> 4.7189381e+08
B11: 25055 | C11: 1.9e-09 | E11: =VLOOKUP(B11,Nuclides!A:F,5,FALSE) -> Mn55 | F11: =VLOOKUP(B11,Nuclides!A:F,4,FALSE) -> STABLE | G11: =IF(F11="STABLE", "STABLE", IF(F11<60, F11&"s", IF(F11<3600, ROUND(F11/60,2)&"min", IF(F11<86400, ROUND(F11/3600,2)&"h", IF(F11<31536000, ROUND(F11/86400,2)&"d", ROUND(F11/31536000,2)&"y"))))) -> STABLE | H11: =LN(2)/F11 -> #VALUE! | I11: =100*6240000000000*C11*(1-EXP(-H11*2*3600)) -> #VALUE! | J11: =I11*EXP(-H11*2*3600) -> #VALUE! | K11: =E11 -> Mn55 | L11: {=SUM(($J11*EXP(-$H11*12*3600*_xlfn.SEQUENCE(L$1-1))))+$J11} -> #VALUE!
B12: 25056 | C12: 2.0304936e-06 | E12: =VLOOKUP(B12,Nuclides!A:F,5,FALSE) -> Mn56 | F12: =VLOOKUP(B12,Nuclides!A:F,4,FALSE) -> 9284.04 | G12: =IF(F12="STABLE", "STABLE", IF(F12<60, F12&"s", IF(F12<3600, ROUND(F12/60,2)&"min", IF(F12<86400, ROUND(F12/3600,2)&"h", IF(F12<31536000, ROUND(F12/86400,2)&"d", ROUND(F12/31536000,2)&"y"))))) -> 2.58h | H12: =LN(2)/F12 -> 7.4660081e-05 | I12: =100*6240000000000*C12*(1-EXP(-H12*2*3600)) -> 5.2686036e+08 | J12: =I12*EXP(-H12*10*3600) -> 35843872 | K12: =E12 -> Mn56 | L12: {=SUM(($J12*EXP(-$H12*12*3600*_xlfn.SEQUENCE(L$1-1))))+$J12} -> 37327383
B13: 25057 | C13: 1.51972e-08 | E13: =VLOOKUP(B13,Nuclides!A:F,5,FALSE) -> Mn57 | F13: =VLOOKUP(B13,Nuclides!A:F,4,FALSE) -> 85.4 | G13: =IF(F13="STABLE", "STABLE", IF(F13<60, F13&"s", IF(F13<3600, ROUND(F13/60,2)&"min", IF(F13<86400, ROUND(F13/3600,2)&"h", IF(F13<31536000, ROUND(F13/86400,2)&"d", ROUND(F13/31536000,2)&"y"))))) -> 1.42min | H13: =LN(2)/F13 -> 0.0081164775 | I13: =100*6240000000000*C13*(1-EXP(-H13*2*3600)) -> 9483052.8 | J13: =I13*EXP(-H13*2*3600) -> 3.9570367e-19 | K13: =E13 -> Mn57 | L13: {=SUM(($J13*EXP(-$H13*12*3600*_xlfn.SEQUENCE(L$1-1))))+$J13} -> 3.9570367e-19
B14: 25058 | C14: 1e-10 | E14: =VLOOKUP(B14,Nuclides!A:F,5,FALSE) -> Mn58 | F14: =VLOOKUP(B14,Nuclides!A:F,4,FALSE) -> 3 | G14: =IF(F14="STABLE", "STABLE", IF(F14<60, F14&"s", IF(F14<3600, ROUND(F14/60,2)&"min", IF(F14<86400, ROUND(F14/3600,2)&"h", IF(F14<31536000, ROUND(F14/86400,2)&"d", ROUND(F14/31536000,2)&"y"))))) -> 3s | H14: =LN(2)/F14 -> 0.23104906 | I14: =100*6240000000000*C14*(1-EXP(-H14*2*3600)) -> 62400 | J14: =I14*EXP(-H14*2*3600) -> 0 | K14: =E14 -> Mn58 | L14: {=SUM(($J14*EXP(-$H14*12*3600*_xlfn.SEQUENCE(L$1-1))))+$J14} -> 0
B15: 26055 | C15: 5.9174494e-05 | E15: =VLOOKUP(B15,Nuclides!A:F,5,FALSE) -> Fe55 | F15: =VLOOKUP(B15,Nuclides!A:F,4,FALSE) -> 86594054 | G15: =IF(F15="STABLE", "STABLE", IF(F15<60, F15&"s", IF(F15<3600, ROUND(F15/60,2)&"min", IF(F15<86400, ROUND(F15/3600,2)&"h", IF(F15<31536000, ROUND(F15/86400,2)&"d", ROUND(F15/31536000,2)&"y"))))) -> 2.75y | H15: =LN(2)/F15 -> 8.0045586e-09 | I15: =100*6240000000000*C15*(1-EXP(-H15*2*3600)) -> 2128023.9 | J15: =I15*EXP(-H15*2*3600) -> 2127901.3 | K15: =E15 -> Fe55 | L15: {=SUM(($J15*EXP(-$H15*12*3600*_xlfn.SEQUENCE(L$1-1))))+$J15} -> 1.3564888e+09
B16: 26056 | C16: 9.6664827e-08 | E16: =VLOOKUP(B16,Nuclides!A:F,5,FALSE) -> Fe56 | F16: =VLOOKUP(B16,Nuclides!A:F,4,FALSE) -> STABLE | G16: =IF(F16="STABLE", "STABLE", IF(F16<60, F16&"s", IF(F16<3600, ROUND(F16/60,2)&"min", IF(F16<86400, ROUND(F16/3600,2)&"h", IF(F16<31536000, ROUND(F16/86400,2)&"d", ROUND(F16/31536000,2)&"y"))))) -> STABLE | H16: =LN(2)/F16 -> #VALUE! | I16: =100*6240000000000*C16*(1-EXP(-H16*2*3600)) -> #VALUE! | J16: =I16*EXP(-H16*2*3600) -> #VALUE! | K16: =E16 -> Fe56 | L16: {=SUM(($J16*EXP(-$H16*12*3600*_xlfn.SEQUENCE(L$1-1))))+$J16} -> #VALUE!
B17: 26057 | C17: 0.00081247688 | E17: =VLOOKUP(B17,Nuclides!A:F,5,FALSE) -> Fe57 | F17: =VLOOKUP(B17,Nuclides!A:F,4,FALSE) -> STABLE | G17: =IF(F17="STABLE", "STABLE", IF(F17<60, F17&"s", IF(F17<3600, ROUND(F17/60,2)&"min", IF(F17<86400, ROUND(F17/3600,2)&"h", IF(F17<31536000, ROUND(F17/86400,2)&"d", ROUND(F17/31536000,2)&"y"))))) -> STABLE | H17: =LN(2)/F17 -> #VALUE! | I17: =100*6240000000000*C17*(1-EXP(-H17*2*3600)) -> #VALUE! | J17: =I17*EXP(-H17*2*3600) -> #VALUE! | K17: =E17 -> Fe57 | L17: {=SUM(($J17*EXP(-$H17*12*3600*_xlfn.SEQUENCE(L$1-1))))+$J17} -> #VALUE!
B18: 26058 | C18: 2.6822864e-05 | E18: =VLOOKUP(B18,Nuclides!A:F,5,FALSE) -> Fe58 | F18: =VLOOKUP(B18,Nuclides!A:F,4,FALSE) -> STABLE | G18: =IF(F18="STABLE", "STABLE", IF(F18<60, F18&"s", IF(F18<3600, ROUND(F18/60,2)&"min", IF(F18<86400, ROUND(F18/3600,2)&"h", IF(F18<31536000, ROUND(F18/86400,2)&"d", ROUND(F18/31536000,2)&"y"))))) -> STABLE | H18: =LN(2)/F18 -> #VALUE! | I18: =100*6240000000000*C18*(1-EXP(-H18*2*3600)) -> #VALUE! | J18: =I18*EXP(-H18*2*3600) -> #VALUE! | K18: =E18 -> Fe58 | L18: {=SUM(($J18*EXP(-$H18*12*3600*_xlfn.SEQUENCE(L$1-1))))+$J18} -> #VALUE!
B19: 26059 | C19: 2.9486484e-06 | E19: =VLOOKUP(B19,Nuclides!A:F,5,FALSE) -> Fe59 | F19: =VLOOKUP(B19,Nuclides!A:F,4,FALSE) -> 3844368 | G19: =IF(F19="STABLE", "STABLE", IF(F19<60, F19&"s", IF(F19<3600, ROUND(F19/60,2)&"min", IF(F19<86400, ROUND(F19/3600,2)&"h", IF(F19<31536000, ROUND(F19/86400,2)&"d", ROUND(F19/31536000,2)&"y"))))) -> 44.5d | H19: =LN(2)/F19 -> 1.8030198e-07 | I19: =100*6240000000000*C19*(1-EXP(-H19*2*3600)) -> 2387034.6 | J19: =I19*EXP(-H19*2*3600) -> 2383937.9 | K19: =E19 -> Fe59 | L19: {=SUM(($J19*EXP(-$H19*12*3600*_xlfn.SEQUENCE(L$1-1))))+$J19} -> 3.0612939e+08

Sheet 1402
B1: Nuclides | C1: w | D1: Error | E1: Nuclides | F1: T1/2 | G1: T1/2 | H1: λ | I1: 60μA-2h | J1: cool-6h | K1: Nuclides | L1: 720
B3: 1001 | C3: 0 | D3: 0 | E3: =VLOOKUP(B3,Nuclides!A:F,5,FALSE) -> H1 | F3: =VLOOKUP(B3,Nuclides!A:F,4,FALSE) -> 613.9 | G3: =IF(F3="STABLE", "STABLE", IF(F3<60, F3&"s", IF(F3<3600, ROUND(F3/60,2)&"min", IF(F3<86400, ROUND(F3/3600,2)&"h", IF(F3<31536000, ROUND(F3/86400,2)&"d", ROUND(F3/31536000,2)&"y"))))) -> 10.23min | H3: =LN(2)/F3 -> 0.0011290881 | I3: =100*6240000000000*C3*(1-EXP(-H3*2*3600)) -> 0 | J3: =I3*EXP(-H3*10*3600) -> 0 | K3: =E3 -> H1 | L3: {=SUM(($J3*EXP(-$H3*12*3600*_xlfn.SEQUENCE(L$1-1))))+$J3} -> 0
B4: 1002 | C4: 8.40714e-05 | D4: 1 | E4: =VLOOKUP(B4,Nuclides!A:F,5,FALSE) -> H2 | F4: =VLOOKUP(B4,Nuclides!A:F,4,FALSE) -> STABLE | G4: =IF(F4="STABLE", "STABLE", IF(F4<60, F4&"s", IF(F4<3600, ROUND(F4/60,2)&"min", IF(F4<86400, ROUND(F4/3600,2)&"h", IF(F4<31536000, ROUND(F4/86400,2)&"d", ROUND(F4/31536000,2)&"y"))))) -> STABLE | H4: =LN(2)/F4 -> #VALUE! | I4: =100*6240000000000*C4*(1-EXP(-H4*2*3600)) -> #VALUE! | J4: =I4*EXP(-H4*10*3600) -> #VALUE! | K4: =E4 -> H2 | L4: {=SUM(($J4*EXP(-$H4*12*3600*_xlfn.SEQUENCE(L$1-1))))+$J4} -> #VALUE!
B5: 1003 | C5: 0 | D5: 2 | E5: =VLOOKUP(B5,Nuclides!A:F,5,FALSE) -> H3 | F5: =VLOOKUP(B5,Nuclides!A:F,4,FALSE) -> 388789632 | G5: =IF(F5="STABLE", "STABLE", IF(F5<60, F5&"s", IF(F5<3600, ROUND(F5/60,2)&"min", IF(F5<86400, ROUND(F5/3600,2)&"h", IF(F5<31536000, ROUND(F5/86400,2)&"d", ROUND(F5/31536000,2)&"y"))))) -> 12.33y | H5: =LN(2)/F5 -> 1.7828335e-09 | I5: =100*6240000000000*C5*(1-EXP(-H5*2*3600)) -> 0 | J5: =I5*EXP(-H5*10*3600) -> 0 | K5: =E5 -> H3 | L5: {=SUM(($J5*EXP(-$H5*12*3600*_xlfn.SEQUENCE(L$1-1))))+$J5} -> 0
B6: 2003 | C6: 0 | D6: 3 | E6: =VLOOKUP(B6,Nuclides!A:F,5,FALSE) -> He3 | F6: =VLOOKUP(B6,Nuclides!A:F,4,FALSE) -> STABLE | G6: =IF(F6="STABLE", "STABLE", IF(F6<60, F6&"s", IF(F6<3600, ROUND(F6/60,2)&"min", IF(F6<86400, ROUND(F6/3600,2)&"h", IF(F6<31536000, ROUND(F6/86400,2)&"d", ROUND(F6/31536000,2)&"y"))))) -> STABLE | H6: =LN(2)/F6 -> #VALUE! | I6: =100*6240000000000*C6*(1-EXP(-H6*2*3600)) -> #VALUE! | J6: =I6*EXP(-H6*10*3600) -> #VALUE! | K6: =E6 -> He3 | L6: {=SUM(($J6*EXP(-$H6*12*3600*_xlfn.SEQUENCE(L$1-1))))+$J6} -> #VALUE!
B7: 2004 | C7: 0 | D7: 4 | E7: =VLOOKUP(B7,Nuclides!A:F,5,FALSE) -> He4 | F7: =VLOOKUP(B7,Nuclides!A:F,4,FALSE) -> STABLE | G7: =IF(F7="STABLE", "STABLE", IF(F7<60, F7&"s", IF(F7<3600, ROUND(F7/60,2)&"min", IF(F7<86400, ROUND(F7/3600,2)&"h", IF(F7<31536000, ROUND(F7/86400,2)&"d", ROUND(F7/31536000,2)&"y"))))) -> STABLE | H7: =LN(2)/F7 -> #VALUE! | I7: =100*6240000000000*C7*(1-EXP(-H7*2*3600)) -> #VALUE! | J7: =I7*EXP(-H7*10*3600) -> #VALUE! | K7: =E7 -> He4 | L7: {=SUM(($J7*EXP(-$H7*12*3600*_xlfn.SEQUENCE(L$1-1))))+$J7} -> #VALUE!
B8: 2005 | C8: 0 | D8: 5 | E8: =VLOOKUP(B8,Nuclides!A:F,5,FALSE) -> He5 | F8: =VLOOKUP(B8,Nuclides!A:F,4,FALSE) -> 7.595e-22 | G8: =IF(F8="STABLE", "STABLE", IF(F8<60, F8&"s", IF(F8<3600, ROUND(F8/60,2)&"min", IF(F8<86400, ROUND(F8/3600,2)&"h", IF(F8<31536000, ROUND(F8/86400,2)&"d", ROUND(F8/31536000,2)&"y"))))) -> 7.595E-22s | H8: =LN(2)/F8 -> 9.1263618e+20 | I8: =100*6240000000000*C8*(1-EXP(-H8*2*3600)) -> 0 | J8: =I8*EXP(-H8*10*3600) -> 0 | K8: =E8 -> He5 | L8: {=SUM(($J8*EXP(-$H8*12*3600*_xlfn.SEQUENCE(L$1-1))))+$J8} -> 0
B9: 2006 | C9: 0 | D9: 6 | E9: =VLOOKUP(B9,Nuclides!A:F,5,FALSE) -> He6 | F9: =VLOOKUP(B9,Nuclides!A:F,4,FALSE) -> 0.8067 | G9: =IF(F9="STABLE", "STABLE", IF(F9<60, F9&"s", IF(F9<3600, ROUND(F9/60,2)&"min", IF(F9<86400, ROUND(F9/3600,2)&"h", IF(F9<31536000, ROUND(F9/86400,2)&"d", ROUND(F9/31536000,2)&"y"))))) -> 0.8067s | H9: =LN(2)/F9 -> 0.85923786 | I9: =100*6240000000000*C9*(1-EXP(-H9*2*3600)) -> 0 | J9: =I9*EXP(-H9*10*3600) -> 0 | K9: =E9 -> He6 | L9: {=SUM(($J9*EXP(-$H9*12*3600*_xlfn.SEQUENCE(L$1-1))))+$J9} -> 0
B10: 2007 | C10: 0 | D10: 7 | E10: =VLOOKUP(B10,Nuclides!A:F,5,FALSE) -> He7 | F10: =VLOOKUP(B10,Nuclides!A:F,4,FALSE) -> 3.038e-21 | G10: =IF(F10="STABLE", "STABLE", IF(F10<60, F10&"s", IF(F10<3600, ROUND(F10/60,2)&"min", IF(F10<86400, ROUND(F10/3600,2)&"h", IF(F10<31536000, ROUND(F10/86400,2)&"d", ROUND(F10/31536000,2)&"y"))))) -> 3.038E-21s | H10: =LN(2)/F10 -> 2.2815905e+20 | I10: =100*6240000000000*C10*(1-EXP(-H10*2*3600)) -> 0 | J10: =I10*EXP(-H10*10*3600) -> 0 | K10: =E10 -> He7 | L10: {=SUM(($J10*EXP(-$H10*12*3600*_xlfn.SEQUENCE(L$1-1))))+$J10} -> 0
B11: 2008 | C11: 0 | D11: 8 | E11: =VLOOKUP(B11,Nuclides!A:F,5,FALSE) -> He8 | F11: =VLOOKUP(B11,Nuclides!A:F,4,FALSE) -> 0.1191 | G11: =IF(F11="STABLE", "STABLE", IF(F11<60, F11&"s", IF(F11<3600, ROUND(F11/60,2)&"min", IF(F11<86400, ROUND(F11/3600,2)&"h", IF(F11<31536000, ROUND(F11/86400,2)&"d", ROUND(F11/31536000,2)&"y"))))) -> 0.1191s | H11: =LN(2)/F11 -> 5.8198756 | I11: =100*6240000000000*C11*(1-EXP(-H11*2*3600)) -> 0 | J11: =I11*EXP(-H11*10*3600) -> 0 | K11: =E11 -> He8 | L11: {=SUM(($J11*EXP(-$H11*12*3600*_xlfn.SEQUENCE(L$1-1))))+$J11} -> 0
B12: 3005 | C12: 0 | D12: 9 | E12: =VLOOKUP(B12,Nuclides!A:F,5,FALSE) -> Li5 | F12: =VLOOKUP(B12,Nuclides!A:F,4,FALSE) -> 3.038e-22 | G12: =IF(F12="STABLE", "STABLE", IF(F12<60, F12&"s", IF(F12<3600, ROUND(F12/60,2)&"min", IF(F12<86400, ROUND(F12/3600,2)&"h", IF(F12<31536000, ROUND(F12/86400,2)&"d", ROUND(F12/31536000,2)&"y"))))) -> 3.038E-22s | H12: =LN(2)/F12 -> 2.2815905e+21 | I12: =100*6240000000000*C12*(1-EXP(-H12*2*3600)) -> 0 | J12: =I12*EXP(-H12*10*3600) -> 0 | K12: =E12 -> Li5 | L12: {=SUM(($J12*EXP(-$H12*12*3600*_xlfn.SEQUENCE(L$1-1))))+$J12} -> 0
B13: 3006 | C13: 0 | D13: 10 | E13: =VLOOKUP(B13,Nuclides!A:F,5,FALSE) -> Li6 | F13: =VLOOKUP(B13,Nuclides!A:F,4,FALSE) -> STABLE | G13: =IF(F13="STABLE", "STABLE", IF(F13<60, F13&"s", IF(F13<3600, ROUND(F13/60,2)&"min", IF(F13<86400, ROUND(F13/3600,2)&"h", IF(F13<31536000, ROUND(F13/86400,2)&"d", ROUND(F13/31536000,2)&"y"))))) -> STABLE | H13: =LN(2)/F13 -> #VALUE! | I13: =100*6240000000000*C13*(1-EXP(-H13*2*3600)) -> #VALUE! | J13: =I13*EXP(-H13*10*3600) -> #VALUE! | K13: =E13 -> Li6 | L13: {=SUM(($J13*EXP(-$H13*12*3600*_xlfn.SEQUENCE(L$1-1))))+$J13} -> #VALUE!
B14: 3007 | C14: 0 | D14: 11 | E14: =VLOOKUP(B14,Nuclides!A:F,5,FALSE) -> Li7 | F14: =VLOOKUP(B14,Nuclides!A:F,4,FALSE) -> STABLE | G14: =IF(F14="STABLE", "STABLE", IF(F14<60, F14&"s", IF(F14<3600, ROUND(F14/60,2)&"min", IF(F14<86400, ROUND(F14/3600,2)&"h", IF(F14<31536000, ROUND(F14/86400,2)&"d", ROUND(F14/31536000,2)&"y"))))) -> STABLE | H14: =LN(2)/F14 -> #VALUE! | I14: =100*6240000000000*C14*(1-EXP(-H14*2*3600)) -> #VALUE! | J14: =I14*EXP(-H14*10*3600) -> #VALUE! | K14: =E14 -> Li7 | L14: {=SUM(($J14*EXP(-$H14*12*3600*_xlfn.SEQUENCE(L$1-1))))+$J14} -> #VALUE!
... B43: 6013 | C43: 2.65184e-07 | D43: 40 | E43: =VLOOKUP(B43,Nuclides!A:F,5,FALSE) -> C13 | F43: =VLOOKUP(B43,Nuclides!A:F,4,FALSE) -> STABLE | G43: =IF(F43="STABLE", "STABLE", IF(F43<60, F43&"s", IF(F43<3600, ROUND(F43/60,2)&"min", IF(F43<86400, ROUND(F43/3600,2)&"h", IF(F43<31536000, ROUND(F43/86400,2)&"d", ROUND(F43/31536000,2)&"y"))))) -> STABLE | H43: =LN(2)/F43 -> #VALUE! | I43: =100*6240000000000*C43*(1-EXP(-H43*2*3600)) -> #VALUE! | J43: =I43*EXP(-H43*10*3600) -> #VALUE! | K43: =E43 -> C13 | L43: {=SUM(($J43*EXP(-$H43*12*3600*_xlfn.SEQUENCE(L$1-1))))+$J43} -> #VALUE!
B44: 6014 | C44: 1.30994e-08 | D44: 41 | E44: =VLOOKUP(B44,Nuclides!A:F,5,FALSE) -> C14 | F44: =VLOOKUP(B44,Nuclides!A:F,4,FALSE) -> 179878320000 | G44: =IF(F44="STABLE", "STABLE", IF(F44<60, F44&"s", IF(F44<3600, ROUND(F44/60,2)&"min", IF(F44<86400, ROUND(F44/3600,2)&"h", IF(F44<31536000, ROUND(F44/86400,2)&"d", ROUND(F44/31536000,2)&"y"))))) -> 5703.9y | H44: =LN(2)/F44 -> 3.8534226e-12 | I44: =100*6240000000000*C44*(1-EXP(-H44*2*3600)) -> 0.22678542 | J44: =I44*EXP(-H44*2*3600) -> 0.22678541 | K44: =E44 -> C14 | L44: {=SUM(($J44*EXP(-$H44*12*3600*_xlfn.SEQUENCE(L$1-1))))+$J44} -> 163.27572
B45: 6015 | C45: 0 | D45: 42 | E45: =VLOOKUP(B45,Nuclides!A:F,5,FALSE) -> C15 | F45: =VLOOKUP(B45,Nuclides!A:F,4,FALSE) -> 2.449 | G45: =IF(F45="STABLE", "STABLE", IF(F45<60, F45&"s", IF(F45<3600, ROUND(F45/60,2)&"min", IF(F45<86400, ROUND(F45/3600,2)&"h", IF(F45<31536000, ROUND(F45/86400,2)&"d", ROUND(F45/31536000,2)&"y"))))) -> 2.449s | H45: =LN(2)/F45 -> 0.28303274 | I45: =100*6240000000000*C45*(1-EXP(-H45*2*3600)) -> 0 | J45: =I45*EXP(-H45*10*3600) -> 0 | K45: =E45 -> C15 | L45: {=SUM(($J45*EXP(-$H45*12*3600*_xlfn.SEQUENCE(L$1-1))))+$J45} -> 0
B46: 6016 | C46: 0 | D46: 43 | E46: =VLOOKUP(B46,Nuclides!A:F,5,FALSE) -> C16 | F46: =VLOOKUP(B46,Nuclides!A:F,4,FALSE) -> 0.747 | G46: =IF(F46="STABLE", "STABLE", IF(F46<60, F46&"s", IF(F46<3600, ROUND(F46/60,2)&"min", IF(F46<86400, ROUND(F46/3600,2)&"h", IF(F46<31536000, ROUND(F46/86400,2)&"d", ROUND(F46/31536000,2)&"y"))))) -> 0.747s | H46: =LN(2)/F46 -> 0.92790787 | I46: =100*6240000000000*C46*(1-EXP(-H46*2*3600)) -> 0 | J46: =I46*EXP(-H46*10*3600) -> 0 | K46: =E46 -> C16 | L46: {=SUM(($J46*EXP(-$H46*12*3600*_xlfn.SEQUENCE(L$1-1))))+$J46} -> 0
B47: 6017 | C47: 0 | D47: 44 | E47: =VLOOKUP(B47,Nuclides!A:F,5,FALSE) -> C17 | F47: =VLOOKUP(B47,Nuclides!A:F,4,FALSE) -> 0.191 | G47: =IF(F47="STABLE", "STABLE", IF(F47<60, F47&"s", IF(F47<3600, ROUND(F47/60,2)&"min", IF(F47<86400, ROUND(F47/3600,2)&"h", IF(F47<31536000, ROUND(F47/86400,2)&"d", ROUND(F47/31536000,2)&"y"))))) -> 0.191s | H47: =LN(2)/F47 -> 3.6290428 | I47: =100*6240000000000*C47*(1-EXP(-H47*2*3600)) -> 0 | J47: =I47*EXP(-H47*10*3600) -> 0 | K47: =E47 -> C17 | L47: {=SUM(($J47*EXP(-$H47*12*3600*_xlfn.SEQUENCE(L$1-1))))+$J47} -> 0
B48: 6018 | C48: 0 | D48: 45 | E48: =VLOOKUP(B48,Nuclides!A:F,5,FALSE) -> C18 | F48: =VLOOKUP(B48,Nuclides!A:F,4,FALSE) -> 0.092 | G48: =IF(F48="STABLE", "STABLE", IF(F48<60, F48&"s", IF(F48<3600, ROUND(F48/60,2)&"min", IF(F48<86400, ROUND(F48/3600,2)&"h", IF(F48<31536000, ROUND(F48/86400,2)&"d", ROUND(F48/31536000,2)&"y"))))) -> 0.092s | H48: =LN(2)/F48 -> 7.5342085 | I48: =100*6240000000000*C48*(1-EXP(-H48*2*3600)) -> 0 | J48: =I48*EXP(-H48*10*3600) -> 0 | K48: =E48 -> C18 | L48: {=SUM(($J48*EXP(-$H48*12*3600*_xlfn.SEQUENCE(L$1-1))))+$J48} -> 0
B49: 6019 | C49: 0 | D49: 46 | E49: =VLOOKUP(B49,Nuclides!A:F,5,FALSE) -> C19 | F49: =VLOOKUP(B49,Nuclides!A:F,4,FALSE) -> 0.0462 | G49: =IF(F49="STABLE", "STABLE", IF(F49<60, F49&"s", IF(F49<3600, ROUND(F49/60,2)&"min", IF(F49<86400, ROUND(F49/3600,2)&"h", IF(F49<31536000, ROUND(F49/86400,2)&"d", ROUND(F49/31536000,2)&"y"))))) -> 0.0462s | H49: =LN(2)/F49 -> 15.003186 | I49: =100*6240000000000*C49*(1-EXP(-H49*2*3600)) -> 0 | J49: =I49*EXP(-H49*10*3600) -> 0 | K49: =E49 -> C19 | L49: {=SUM(($J49*EXP(-$H49*12*3600*_xlfn.SEQUENCE(L$1-1))))+$J49} -> 0
B50: 6020 | C50: 0 | D50: 47 | E50: =VLOOKUP(B50,Nuclides!A:F,5,FALSE) -> C20 | F50: =VLOOKUP(B50,Nuclides!A:F,4,FALSE) -> 0.0162 | G50: =IF(F50="STABLE", "STABLE", IF(F50<60, F50&"s", IF(F50<3600, ROUND(F50/60,2)&"min", IF(F50<86400, ROUND(F50/3600,2)&"h", IF(F50<31536000, ROUND(F50/86400,2)&"d", ROUND(F50/31536000,2)&"y"))))) -> 0.0162s | H50: =LN(2)/F50 -> 42.786863 | I50: =100*6240000000000*C50*(1-EXP(-H50*2*3600)) -> 0 | J50: =I50*EXP(-H50*10*3600) -> 0 | K50: =E50 -> C20 | L50: {=SUM(($J50*EXP(-$H50*12*3600*_xlfn.SEQUENCE(L$1-1))))+$J50} -> 0
B51: 7011 | C51: 0 | D51: 48 | E51: =VLOOKUP(B51,Nuclides!A:F,5,FALSE) -> N11 | F51: =VLOOKUP(B51,Nuclides!A:F,4,FALSE) -> 5.4903614e-22 | G51: =IF(F51="STABLE", "STABLE", IF(F51<60, F51&"s", IF(F51<3600, ROUND(F51/60,2)&"min", IF(F51<86400, ROUND(F51/3600,2)&"h", IF(F51<31536000, ROUND(F51/86400,2)&"d", ROUND(F51/31536000,2)&"y"))))) -> 5.49036144578313E-22s | H51: =LN(2)/F51 -> 1.2624801e+21 | I51: =100*6240000000000*C51*(1-EXP(-H51*2*3600)) -> 0 | J51: =I51*EXP(-H51*10*3600) -> 0 | K51: =E51 -> N11 | L51: {=SUM(($J51*EXP(-$H51*12*3600*_xlfn.SEQUENCE(L$1-1))))+$J51} -> 0
B52: 7012 | C52: 0 | D52: 49 | E52: =VLOOKUP(B52,Nuclides!A:F,5,FALSE) -> N12 | F52: =VLOOKUP(B52,Nuclides!A:F,4,FALSE) -> 0.011 | G52: =IF(F52="STABLE", "STABLE", IF(F52<60, F52&"s", IF(F52<3600, ROUND(F52/60,2)&"min", IF(F52<86400, ROUND(F52/3600,2)&"h", IF(F52<31536000, ROUND(F52/86400,2)&"d", ROUND(F52/31536000,2)&"y"))))) -> 0.011s | H52: =LN(2)/F52 -> 63.01338 | I52: =100*6240000000000*C52*(1-EXP(-H52*2*3600)) -> 0 | J52: =I52*EXP(-H52*10*3600) -> 0 | K52: =E52 -> N12 | L52: {=SUM(($J52*EXP(-$H52*12*3600*_xlfn.SEQUENCE(L$1-1))))+$J52} -> 0
B53: 7013 | C53: 0 | D53: 50 | E53: =VLOOKUP(B53,Nuclides!A:F,5,FALSE) -> N13 | F53: =VLOOKUP(B53,Nuclides!A:F,4,FALSE) -> 597.9 | G53: =IF(F53="STABLE", "STABLE", IF(F53<60, F53&"s", IF(F53<3600, ROUND(F53/60,2)&"min", IF(F53<86400, ROUND(F53/3600,2)&"h", IF(F53<31536000, ROUND(F53/86400,2)&"d", ROUND(F53/31536000,2)&"y"))))) -> 9.97min | H53: =LN(2)/F53 -> 0.0011593029 | I53: =100*6240000000000*C53*(1-EXP(-H53*2*3600)) -> 0 | J53: =I53*EXP(-H53*10*3600) -> 0 | K53: =E53 -> N13 | L53: {=SUM(($J53*EXP(-$H53*12*3600*_xlfn.SEQUENCE(L$1-1))))+$J53} -> 0
B54: 7014 | C54: 0 | D54: 51 | E54: =VLOOKUP(B54,Nuclides!A:F,5,FALSE) -> N14 | F54: =VLOOKUP(B54,Nuclides!A:F,4,FALSE) -> STABLE | G54: =IF(F54="STABLE", "STABLE", IF(F54<60, F54&"s", IF(F54<3600, ROUND(F54/60,2)&"min", IF(F54<86400, ROUND(F54/3600,2)&"h", IF(F54<31536000, ROUND(F54/86400,2)&"d", ROUND(F54/31536000,2)&"y"))))) -> STABLE | H54: =LN(2)/F54 -> #VALUE! | I54: =100*6240000000000*C54*(1-EXP(-H54*2*3600)) -> #VALUE! | J54: =I54*EXP(-H54*10*3600) -> #VALUE! | K54: =E54 -> N14 | L54: {=SUM(($J54*EXP(-$H54*12*3600*_xlfn.SEQUENCE(L$1-1))))+$J54} -> #VALUE!
B55: 7015 | C55: 0 | D55: 52 | E55: =VLOOKUP(B55,Nuclides!A:F,5,FALSE) -> N15 | F55: =VLOOKUP(B55,Nuclides!A:F,4,FALSE) -> STABLE | G55: =IF(F55="STABLE", "STABLE", IF(F55<60, F55&"s", IF(F55<3600, ROUND(F55/60,2)&"min", IF(F55<86400, ROUND(F55/3600,2)&"h", IF(F55<31536000, ROUND(F55/86400,2)&"d", ROUND(F55/31536000,2)&"y"))))) -> STABLE | H55: =LN(2)/F55 -> #VALUE! | I55: =100*6240000000000*C55*(1-EXP(-H55*2*3600)) -> #VALUE! | J55: =I55*EXP(-H55*10*3600) -> #VALUE! | K55: =E55 -> N15 | L55: {=SUM(($J55*EXP(-$H55*12*3600*_xlfn.SEQUENCE(L$1-1))))+$J55} -> #VALUE!
B56: 7016 | C56: 7e-10 | D56: 53 | E56: =VLOOKUP(B56,Nuclides!A:F,5,FALSE) -> N16 | F56: =VLOOKUP(B56,Nuclides!A:F,4,FALSE) -> 7.13 | G56: =IF(F56="STABLE", "STABLE", IF(F56<60, F56&"s", IF(F56<3600, ROUND(F56/60,2)&"min", IF(F56<86400, ROUND(F56/3600,2)&"h", IF(F56<31536000, ROUND(F56/86400,2)&"d", ROUND(F56/31536000,2)&"y"))))) -> 7.13s | H56: =LN(2)/F56 -> 0.097215593 | I56: =100*6240000000000*C56*(1-EXP(-H56*2*3600)) -> 436800 | J56: =I56*EXP(-H56*2*3600) -> 4.517241e-299 | K56: =E56 -> N16 | L56: {=SUM(($J56*EXP(-$H56*12*3600*_xlfn.SEQUENCE(L$1-1))))+$J56} -> 4.517241e-299
B57: 7017 | C57: 0 | D57: 54 | E57: =VLOOKUP(B57,Nuclides!A:F,5,FALSE) -> N17 | F57: =VLOOKUP(B57,Nuclides!A:F,4,FALSE) -> 4.171 | G57: =IF(F57="STABLE", "STABLE", IF(F57<60, F57&"s", IF(F57<3600, ROUND(F57/60,2)&"min", IF(F57<86400, ROUND(F57/3600,2)&"h", IF(F57<31536000, ROUND(F57/86400,2)&"d", ROUND(F57/31536000,2)&"y"))))) -> 4.171s | H57: =LN(2)/F57 -> 0.16618249 | I57: =100*6240000000000*C57*(1-EXP(-H57*2*3600)) -> 0 | J57: =I57*EXP(-H57*10*3600) -> 0 | K57: =E57 -> N17 | L57: {=SUM(($J57*EXP(-$H57*12*3600*_xlfn.SEQUENCE(L$1-1))))+$J57} -> 0
B58: 7018 | C58: 0 | D58: 55 | E58: =VLOOKUP(B58,Nuclides!A:F,5,FALSE) -> N18 | F58: =VLOOKUP(B58,Nuclides!A:F,4,FALSE) -> 0.619 | G58: =IF(F58="STABLE", "STABLE", IF(F58<60, F58&"s", IF(F58<3600, ROUND(F58/60,2)&"min", IF(F58<86400, ROUND(F58/3600,2)&"h", IF(F58<31536000, ROUND(F58/86400,2)&"d", ROUND(F58/31536000,2)&"y"))))) -> 0.619s | H58: =LN(2)/F58 -> 1.1197854 | I58: =100*6240000000000*C58*(1-EXP(-H58*2*3600)) -> 0 | J58: =I58*EXP(-H58*10*3600) -> 0 | K58: =E58 -> N18 | L58: {=SUM(($J58*EXP(-$H58*12*3600*_xlfn.SEQUENCE(L$1-1))))+$J58} -> 0
B59: 7019 | C59: 0 | D59: 56 | E59: =VLOOKUP(B59,Nuclides!A:F,5,FALSE) -> N19 | F59: =VLOOKUP(B59,Nuclides!A:F,4,FALSE) -> 0.336 | G59: =IF(F59="STABLE", "STABLE", IF(F59<60, F59&"s", IF(F59<3600, ROUND(F59/60,2)&"min", IF(F59<86400, ROUND(F59/3600,2)&"h", IF(F59<31536000, ROUND(F59/86400,2)&"d", ROUND(F59/31536000,2)&"y"))))) -> 0.336s | H59: =LN(2)/F59 -> 2.062938 | I59: =100*6240000000000*C59*(1-EXP(-H59*2*3600)) -> 0 | J59: =I59*EXP(-H59*10*3600) -> 0 | K59: =E59 -> N19 | L59: {=SUM(($J59*EXP(-$H59*12*3600*_xlfn.SEQUENCE(L$1-1))))+$J59} -> 0
B60: 7020 | C60: 0 | D60: 57 | E60: =VLOOKUP(B60,Nuclides!A:F,5,FALSE) -> N20 | F60: =VLOOKUP(B60,Nuclides!A:F,4,FALSE) -> 0.136 | G60: =IF(F60="STABLE", "STABLE", IF(F60<60, F60&"s", IF(F60<3600, ROUND(F60/60,2)&"min", IF(F60<86400, ROUND(F60/3600,2)&"h", IF(F60<31536000, ROUND(F60/86400,2)&"d", ROUND(F60/31536000,2)&"y"))))) -> 0.136s | H60: =LN(2)/F60 -> 5.0966704 | I60: =100*6240000000000*C60*(1-EXP(-H60*2*3600)) -> 0 | J60: =I60*EXP(-H60*10*3600) -> 0 | K60: =E60 -> N20 | L60: {=SUM(($J60*EXP(-$H60*12*3600*_xlfn.SEQUENCE(L$1-1))))+$J60} -> 0
B61: 7021 | C61: 0 | D61: 58 | E61: =VLOOKUP(B61,Nuclides!A:F,5,FALSE) -> N21 | F61: =VLOOKUP(B61,Nuclides!A:F,4,FALSE) -> 0.0848 | G61: =IF(F61="STABLE", "STABLE", IF(F61<60, F61&"s", IF(F61<3600, ROUND(F61/60,2)&"min", IF(F61<86400, ROUND(F61/3600,2)&"h", IF(F61<31536000, ROUND(F61/86400,2)&"d", ROUND(F61/31536000,2)&"y"))))) -> 0.0848s | H61: =LN(2)/F61 -> 8.1739054 | I61: =100*6240000000000*C61*(1-EXP(-H61*2*3600)) -> 0 | J61: =I61*EXP(-H61*10*3600) -> 0 | K61: =E61 -> N21 | L61: {=SUM(($J61*EXP(-$H61*12*3600*_xlfn.SEQUENCE(L$1-1))))+$J61} -> 0
B62: 7022 | C62: 0 | D62: 59 | E62: =VLOOKUP(B62,Nuclides!A:F,5,FALSE) -> N22 | F62: =VLOOKUP(B62,Nuclides!A:F,4,FALSE) -> 0.0195 | G62: =IF(F62="STABLE", "STABLE", IF(F62<60, F62&"s", IF(F62<3600, ROUND(F62/60,2)&"min", IF(F62<86400, ROUND(F62/3600,2)&"h", IF(F62<31536000, ROUND(F62/86400,2)&"d", ROUND(F62/31536000,2)&"y"))))) -> 0.0195s | H62: =LN(2)/F62 -> 35.546009 | I62: =100*6240000000000*C62*(1-EXP(-H62*2*3600)) -> 0 | J62: =I62*EXP(-H62*10*3600) -> 0 | K62: =E62 -> N22 | L62: {=SUM(($J62*EXP(-$H62*12*3600*_xlfn.SEQUENCE(L$1-1))))+$J62} -> 0
B63: 7023 | C63: 0 | D63: 60 | E63: =VLOOKUP(B63,Nuclides!A:F,5,FALSE) -> N23 | F63: =VLOOKUP(B63,Nuclides!A:F,4,FALSE) -> 0.0141 | G63: =IF(F63="STABLE", "STABLE", IF(F63<60, F63&"s", IF(F63<3600, ROUND(F63/60,2)&"min", IF(F63<86400, ROUND(F63/3600,2)&"h", IF(F63<31536000, ROUND(F63/86400,2)&"d", ROUND(F63/31536000,2)&"y"))))) -> 0.0141s | H63: =LN(2)/F63 -> 49.159375 | I63: =100*6240000000000*C63*(1-EXP(-H63*2*3600)) -> 0 | J63: =I63*EXP(-H63*10*3600) -> 0 | K63: =E63 -> N23 | L63: {=SUM(($J63*EXP(-$H63*12*3600*_xlfn.SEQUENCE(L$1-1))))+$J63} -> 0
B64: 8013 | C64: 0 | D64: 61 | E64: =VLOOKUP(B64,Nuclides!A:F,5,FALSE) -> O13 | F64: =VLOOKUP(B64,Nuclides!A:F,4,FALSE) -> 0.00858 | G64: =IF(F64="STABLE", "STABLE", IF(F64<60, F64&"s", IF(F64<3600, ROUND(F64/60,2)&"min", IF(F64<86400, ROUND(F64/3600,2)&"h", IF(F64<31536000, ROUND(F64/86400,2)&"d", ROUND(F64/31536000,2)&"y"))))) -> 0.00858s | H64: =LN(2)/F64 -> 80.786385 | I64: =100*6240000000000*C64*(1-EXP(-H64*2*3600)) -> 0 | J64: =I64*EXP(-H64*10*3600) -> 0 | K64: =E64 -> O13 | L64: {=SUM(($J64*EXP(-$H64*12*3600*_xlfn.SEQUENCE(L$1-1))))+$J64} -> 0
B65: 8014 | C65: 0 | D65: 62 | E65: =VLOOKUP(B65,Nuclides!A:F,5,FALSE) -> O14 | F65: =VLOOKUP(B65,Nuclides!A:F,4,FALSE) -> 70.62 | G65: =IF(F65="STABLE", "STABLE", IF(F65<60, F65&"s", IF(F65<3600, ROUND(F65/60,2)&"min", IF(F65<86400, ROUND(F65/3600,2)&"h", IF(F65<31536000, ROUND(F65/86400,2)&"d", ROUND(F65/31536000,2)&"y"))))) -> 1.18min | H65: =LN(2)/F65 -> 0.0098151682 | I65: =100*6240000000000*C65*(1-EXP(-H65*2*3600)) -> 0 | J65: =I65*EXP(-H65*10*3600) -> 0 | K65: =E65 -> O14 | L65: {=SUM(($J65*EXP(-$H65*12*3600*_xlfn.SEQUENCE(L$1-1))))+$J65} -> 0
B66: 8015 | C66: 0 | D66: 63 | E66: =VLOOKUP(B66,Nuclides!A:F,5,FALSE) -> O15 | F66: =VLOOKUP(B66,Nuclides!A:F,4,FALSE) -> 122.24 | G66: =IF(F66="STABLE", "STABLE", IF(F66<60, F66&"s", IF(F66<3600, ROUND(F66/60,2)&"min", IF(F66<86400, ROUND(F66/3600,2)&"h", IF(F66<31536000, ROUND(F66/86400,2)&"d", ROUND(F66/31536000,2)&"y"))))) -> 2.04min | H66: =LN(2)/F66 -> 0.0056703794 | I66: =100*6240000000000*C66*(1-EXP(-H66*2*3600)) -> 0 | J66: =I66*EXP(-H66*10*3600) -> 0 | K66: =E66 -> O15 | L66: {=SUM(($J66*EXP(-$H66*12*3600*_xlfn.SEQUENCE(L$1-1))))+$J66} -> 0
B67: 8016 | C67: 0 | D67: 64 | E67: =VLOOKUP(B67,Nuclides!A:F,5,FALSE) -> O16 | F67: =VLOOKUP(B67,Nuclides!A:F,4,FALSE) -> STABLE | G67: =IF(F67="STABLE", "STABLE", IF(F67<60, F67&"s", IF(F67<3600, ROUND(F67/60,2)&"min", IF(F67<86400, ROUND(F67/3600,2)&"h", IF(F67<31536000, ROUND(F67/86400,2)&"d", ROUND(F67/31536000,2)&"y"))))) -> STABLE | H67: =LN(2)/F67 -> #VALUE! | I67: =100*6240000000000*C67*(1-EXP(-H67*2*3600)) -> #VALUE! | J67: =I67*EXP(-H67*10*3600) -> #VALUE! | K67: =E67 -> O16 | L67: {=SUM(($J67*EXP(-$H67*12*3600*_xlfn.SEQUENCE(L$1-1))))+$J67} -> #VALUE!
B68: 8017 | C68: 3.38998e-08 | D68: 65 | E68: =VLOOKUP(B68,Nuclides!A:F,5,FALSE) -> O17 | F68: =VLOOKUP(B68,Nuclides!A:F,4,FALSE) -> STABLE | G68: =IF(F68="STABLE", "STABLE", IF(F68<60, F68&"s", IF(F68<3600, ROUND(F68/60,2)&"min", IF(F68<86400, ROUND(F68/3600,2)&"h", IF(F68<31536000, ROUND(F68/86400,2)&"d", ROUND(F68/31536000,2)&"y"))))) -> STABLE | H68: =LN(2)/F68 -> #VALUE! | I68: =100*6240000000000*C68*(1-EXP(-H68*2*3600)) -> #VALUE! | J68: =I68*EXP(-H68*10*3600) -> #VALUE! | K68: =E68 -> O17 | L68: {=SUM(($J68*EXP(-$H68*12*3600*_xlfn.SEQUENCE(L$1-1))))+$J68} -> #VALUE!
... B2207: 100260 | C2207: 0 | D2207: 2204 | E2207: =VLOOKUP(B2207,Nuclides!A:F,5,FALSE) -> Fm260 | F2207: =VLOOKUP(B2207,Nuclides!A:F,4,FALSE) -> 0.004 | G2207: =IF(F2207="STABLE", "STABLE", IF(F2207<60, F2207&"s", IF(F2207<3600, ROUND(F2207/60,2)&"min", IF(F2207<86400, ROUND(F2207/3600,2)&"h", IF(F2207<31536000, ROUND(F2207/86400,2)&"d", ROUND(F2207/31536000,2)&"y"))))) -> 0.004s | H2207: =LN(2)/F2207 -> 173.2868 | I2207: =100*6240000000000*C2207*(1-EXP(-H2207*2*3600)) -> 0 | J2207: =I2207*EXP(-H2207*10*3600) -> 0 | K2207: =E2207 -> Fm260 | L2207: {=SUM(($J2207*EXP(-$H2207*12*3600*_xlfn.SEQUENCE(L$1-1))))+$J2207} -> 0
...

Sheet data
B3: 水
B4: 100μA
B5: 核素/Bq | C5: 半衰期 | D5: 冷却0h | E5: 冷却2h | F5: 运行1年
B6: C14 | C6: 5703.9y | D6: 0.22678542 | E6: 0.22678541 | F6: 163.27571
B7: N16 | C7: 7.13s | D7: 436800 | E7: 4.517241e-299 | F7: 0
B11: 主磁铁
B12: 核素/Bq | C12: 半衰期 | D12: 冷却0h | E12: 冷却2h | F12: 运行1年
B13: Cr51 | C13: 27.7d | D13: 126326.96 | E13: 126063.83 | F13: 10054314
B14: Mn54 | C14: 312.2d | D14: 951506.55 | E14: 951330.52 | F14: 4.7154471e+08
B15: Mn56 | C15: 2.58h | D15: 5.2686036e+08 | E15: 3.077793e+08 | F15: 37327383
B16: Fe55 | C16: 2.75y | D16: 2128023.9 | E16: 2127901.3 | F16: 1.3561762e+09
B17: Fe59 | C17: 44.5d | D17: 2387034.6 | E17: 2383937.9 | F17: 3.0454388e+08
